Workbook

Sheet Weekly Totals
C1: ALP | E1: LEADERSHIP ALP | F1: Appts | G1: Pres | H1: Sales | I1: POS SITS | J1: POS SA | K1: VET SITS | L1: VET SA | M1: REF OBT | N1: REF SITS | O1: REF SA | P1: OTS SITS | Q1: OTS SA | R1: N1
B2: GOJCAJ RGA | C2: =SUM(C5,C17,C20,C23,C26,C29) -> #REF! | E2: =SUM(E5,E17,E20,E23,E26,E29) -> 31015.96 | F2: =SUM(F5,F17,F20,F23,F26,F29) -> 102 | G2: =SUM(G5,G17,G20,G23,G26,G29) -> #REF! | H2: =SUM(H5,H17,H20,H23,H26,H29) -> #REF! | I2: =SUM(I5,I17,I20,I23,I26,I29) -> #REF! | J2: =SUM(J5,J17,J20,J23,J26,J29) -> #REF! | K2: =SUM(K5,K17,K20,K23,K26,K29) -> #REF! | L2: =SUM(L5,L17,L20,L23,L26,L29) -> #REF! | ... R2: =SUM(R5,R17,R20,R23,R26,R29) -> #REF!
C3: # of Agents | E3: ALP per sale | F3: Show Rate | G3: Close Ratio | H3: ALP/Agent | J3: POS Close | L3: VET Close | M3: REF Per Sit | O3: REF Close | Q3: OTS Close
C4: =SUM(C7,C22,C19,C25,C28,C31) -> 64 | E4: =IFERROR(C2/H2,0) -> 0 | F4: =IFERROR((G2+R2)/F2,0) -> 0 | G4: =IFERROR(H2/G2,0) -> 0 | H4: =(C2/C4) -> #REF! | J4: =IFERROR(J2/I2,0) -> 0 | L4: =IFERROR(L2/K2,0) -> 0 | M4: =IFERROR(M2/G2,0) -> 0 | O4: =IFERROR(O2/N2,0) -> 0 | Q4: =IFERROR(Q2/P2,0) -> 0
B5: Joseph Gojcaj | C5: =SUMIF(A:A,B5,T:T) -> 27865 | E5: =SUMIFS(T:T,A:A,B5,D:D,"Y") -> 23485 | F5: =SUMIF(A:A,B5,G:G) -> 60 | G5: =SUMIF(A:A,B5,H:H) -> 29 | H5: =SUMIF(A:A,B5,I:I) -> 18 | I5: =SUMIF(A:A,B5,P:P) -> 3 | J5: =SUMIF(A:A,B5,Q:Q) -> 1 | K5: =SUMIF(A:A,B5,R:R) -> 8 | L5: =SUMIF(A:A,B5,S:S) -> 4 | M5: =SUMIF(A:A,B5,M:M) -> 79 | N5: =SUMIF(A:A,B5,N:N) -> 18 | O5: =SUMIF(A:A,B5,O:O) -> 10 | P5: =SUMIF(A:A,B5,J:J) -> 16 | Q5: =SUMIF(A:A,B5,K:K) -> 12 | R5: =SUMIF(A:A,B5,L:L) -> 7
C6: # of Agents | E6: ALP per sale | F6: Show Rate | G6: Close Ratio | H6: ALP/Agent | J6: POS Close | L6: VET Close | M6: REF Per Sit | O6: REF Close | Q6: OTS Close
C7: =COUNTIFS(A:A,B5) -> 29 | E7: =IFERROR(C5/H5,0) -> 1548.0556 | F7: =IFERROR((G5+R5)/F5,0) -> 0.6 | G7: =IFERROR(H5/G5,0) -> 0.62068966 | H7: =(C5/C7) -> 960.86207 | J7: =IFERROR(J5/I5,0) -> 0.33333333 | L7: =IFERROR(L5/K5,0) -> 0.5 | M7: =IFERROR(M5/SUM(R5+G5,0),"") -> 2.1944444 | O7: =IFERROR(O5/N5,0) -> 0.55555556 | Q7: =IFERROR(Q5/P5,0) -> 0.75
B8: Edward Leon | C8: =SUMIF(B:B,B8,T:T) -> 8108 | E8: =SUMIFS(T:T,B:B,B8,D:D,"Y") -> 6408 | F8: =SUMIF(B28:B1082,B8,G28:G1082) -> 6 | G8: =SUMIF(B28:B1082,B8,H28:H1082) -> 6 | H8: =SUMIF(B28:B1082,B8,I28:I1082) -> 2 | I8: =SUMIF(B28:B1082,B8,P28:P1082) -> 0 | J8: =SUMIF(B28:B1082,B8,Q28:Q1082) -> 0 | K8: =SUMIF(B28:B1082,B8,R28:R1082) -> 2 | L8: =SUMIF(B28:B1082,B8,S28:S1082) -> 1 | M8: =SUMIF(B28:B1082,B8,M28:M1082) -> 23 | N8: =SUMIF(B28:B1082,B8,N28:N1082) -> 3 | O8: =SUMIF(B28:B1082,B8,O28:O1082) -> 1 | P8: =SUMIF(B28:B1082,B8,J28:J1082) -> 1 | Q8: =SUMIF(B28:B1082,B8,K28:K1082) -> 1 | R8: =SUMIF(B28:B1082,B8,L28:L1082) -> 1
C9: # of Agents | E9: ALP per sale | F9: Show Rate | G9: Close Ratio | H9: ALP/Agent | J9: POS Close | L9: VET Close | M9: REF Per Sit | O9: REF Close | Q9: OTS Close
C10: =COUNTIFS(B35:B1082,B8) -> 8 | E10: =IFERROR(C8/H8,0) -> 4054 | F10: =IFERROR((G8+R8)/F8,0) -> 1.1666667 | G10: =IFERROR(H8/G8,0) -> 0.33333333 | H10: =(C8/C10) -> 1013.5 | J10: =IFERROR(J8/I8,0) -> 0 | L10: =IFERROR(L8/K8,0) -> 0.5 | M10: =IFERROR(M8/SUM(R8+G8,0),"") -> 3.2857143 | O10: =IFERROR(O8/N8,0) -> 0.33333333 | Q10: =IFERROR(Q8/P8,0) -> 1
B11: Timothy Noe | C11: =SUMIF(B:B,B11,T:T) -> 5917 | E11: =SUMIFS(T:T,B:B,B11,D:D,"Y") -> 4836 | F11: =SUMIF(B31:B1082,B11,G31:G1082) -> 22 | G11: =SUMIF(B31:B1082,B11,H31:H1082) -> 10 | H11: =SUMIF(B31:B1082,B11,I31:I1082) -> 7 | I11: =SUMIF(B31:B1082,B11,P31:P1082) -> 3 | J11: =SUMIF(B31:B1082,B11,Q31:Q1082) -> 1 | K11: =SUMIF(B31:B1082,B11,R31:R1082) -> 0 | L11: =SUMIF(B31:B1082,B11,S31:S1082) -> 0 | M11: =SUMIF(B31:B1082,B11,M31:M1082) -> 10 | N11: =SUMIF(B31:B1082,B11,N31:N1082) -> 9 | O11: =SUMIF(B31:B1082,B11,O31:O1082) -> 6 | P11: =SUMIF(B31:B1082,B11,J31:J1082) -> 6 | Q11: =SUMIF(B31:B1082,B11,K31:K1082) -> 5 | R11: =SUMIF(B31:B1082,B11,L31:L1082) -> 1
C12: # of Agents | E12: ALP per sale | F12: Show Rate | G12: Close Ratio | H12: ALP/Agent | J12: POS Close | L12: VET Close | M12: REF Per Sit | O12: REF Close | Q12: OTS Close
C13: =COUNTIFS(B36:B1082,B11) -> 4 | E13: =IFERROR(C11/H11,0) -> 845.28571 | F13: =IFERROR((G11+R11)/F11,0) -> 0.5 | G13: =IFERROR(H11/G11,0) -> 0.7 | H13: =(C11/C13) -> 1479.25 | J13: =IFERROR(J11/I11,0) -> 0.33333333 | L13: =IFERROR(L11/K11,0) -> 0 | M13: =IFERROR(M11/SUM(R11+G11,0),"") -> 0.90909091 | O13: =IFERROR(O11/N11,0) -> 0.66666667 | Q13: =IFERROR(Q11/P11,0) -> 0.83333333
B14: Javier Sandoval | C14: =SUMIF(B:B,B14,T:T) -> 13840 | E14: =SUMIFS(T:T,B:B,B14,D:D,"Y") -> 12241 | F14: =SUMIF(B34:B1082,B14,G34:G1082) -> 32 | G14: =SUMIF(B34:B1082,B14,H34:H1082) -> 13 | H14: =SUMIF(B34:B1082,B14,I34:I1082) -> 9 | I14: =SUMIF(B34:B1082,B14,P34:P1082) -> 0 | J14: =SUMIF(B34:B1082,B14,Q34:Q1082) -> 0 | K14: =SUMIF(B34:B1082,B14,R34:R1082) -> 6 | L14: =SUMIF(B34:B1082,B14,S34:S1082) -> 3 | M14: =SUMIF(B34:B1082,B14,M34:M1082) -> 46 | N14: =SUMIF(B34:B1082,B14,N34:N1082) -> 6 | O14: =SUMIF(B34:B1082,B14,O34:O1082) -> 3 | P14: =SUMIF(B34:B1082,B14,J34:J1082) -> 9 | Q14: =SUMIF(B34:B1082,B14,K34:K1082) -> 6 | R14: =SUMIF(B34:B1082,B14,L34:L1082) -> 5
C15: # of Agents | E15: ALP per sale | F15: Show Rate | G15: Close Ratio | H15: ALP/Agent | J15: POS Close | L15: VET Close | M15: REF Per Sit | O15: REF Close | Q15: OTS Close
C16: =COUNTIFS(B34:B1082,B14) -> 16 | E16: =IFERROR(C14/H14,0) -> 1537.7778 | F16: =IFERROR((G14+R14)/F14,0) -> 0.5625 | G16: =IFERROR(H14/G14,0) -> 0.69230769 | H16: =(C14/C16) -> 865 | J16: =IFERROR(J14/I14,0) -> 0 | L16: =IFERROR(L14/K14,0) -> 0.5 | M16: =IFERROR(M14/SUM(G14+R14,0),"") -> 2.5555556 | O16: =IFERROR(O14/N14,0) -> 0.5 | Q16: =IFERROR(Q14/P14,0) -> 0.66666667
B17: Jacob Brown | C17: =SUMIF(A:A,B17,T:T) -> #REF! | E17: =SUMIFS(T:T,A:A,B17,D:D,"Y") -> 0 | F17: =SUMIF(A:A,B17,G:G) -> 7 | G17: =SUMIF(A:A,B17,H:H) -> #REF! | H17: =SUMIF(A:A,B17,I:I) -> #REF! | I17: =SUMIF(A:A,B17,P:P) -> #REF! | J17: =SUMIF(A:A,B17,Q:Q) -> #REF! | K17: =SUMIF(A:A,B17,R:R) -> #REF! | L17: =SUMIF(A:A,B17,S:S) -> #REF! | M17: =SUMIF(A:A,B17,M:M) -> #REF! | N17: =SUMIF(A:A,B17,N:N) -> #REF! | O17: =SUMIF(A:A,B17,O:O) -> #REF! | P17: =SUMIF(A:A,B17,J:J) -> #REF! | Q17: =SUMIF(A:A,B17,K:K) -> #REF! | R17: =SUMIF(A:A,B17,L:L) -> #REF!
C18: # of Agents | E18: ALP per sale | F18: Show Rate | G18: Close Ratio | H18: ALP/Agent | J18: POS Close | L18: VET Close | M18: REF Per Sit | O18: REF Close | Q18: OTS Close
C19: =COUNTIFS(A:A,B17) -> 6 | E19: =IFERROR(C17/H17,0) -> 0 | F19: =IFERROR((G17+R17)/F17,0) -> 0 | G19: =IFERROR(H17/G17,0) -> 0 | H19: =(C17/C19) -> #REF! | J19: =IFERROR(J17/I17,0) -> 0 | L19: =IFERROR(L17/K17,0) -> 0 | M19: =IFERROR(M17/SUM(R17+G17,0),"") | O19: =IFERROR(O17/N17,0) -> 0 | Q19: =IFERROR(Q17/P17,0) -> 0
B20: Derron Alexander | C20: =SUMIF(A:A,B20,T:T) -> 2100 | E20: =SUMIFS(T:T,A:A,B20,D:D,"Y") -> 0 | F20: =SUMIF(A:A,B20,G:G) -> 1 | G20: =SUMIF(A:A,B20,H:H) -> 1 | H20: =SUMIF(A:A,B20,I:I) -> 1 | I20: =SUMIF(A:A,B20,P:P) -> 0 | J20: =SUMIF(A:A,B20,Q:Q) -> 0 | K20: =SUMIF(A:A,B20,R:R) -> 1 | L20: =SUMIF(A:A,B20,S:S) -> 1 | M20: =SUMIF(A:A,B20,M:M) -> 0 | N20: =SUMIF(A:A,B20,N:N) -> 0 | O20: =SUMIF(A:A,B20,O:O) -> 0 | P20: =SUMIF(A:A,B20,J:J) -> 1 | Q20: =SUMIF(A:A,B20,K:K) -> 1 | R20: =SUMIF(A:A,B20,L:L) -> 1
C21: # of Agents | E21: ALP per sale | F21: Show Rate | G21: Close Ratio | H21: ALP/Agent | J21: POS Close | L21: VET Close | M21: REF Per Sit | O21: REF Close | Q21: OTS Close
C22: =COUNTIFS(A:A,B20) -> 9 | E22: =IFERROR(C20/H20,0) -> 2100 | F22: =IFERROR((G20+R20)/F20,0) -> 2 | G22: =IFERROR(H20/G20,0) -> 1 | H22: =(C20/C22) -> 233.33333 | J22: =IFERROR(J20/I20,0) -> 0 | L22: =IFERROR(L20/K20,0) -> 1 | M22: =IFERROR(M20/SUM(R20+G20,0),"") -> 0 | O22: =IFERROR(O20/N20,0) -> 0 | Q22: =IFERROR(Q20/P20,0) -> 1
B23: David Fulfer | C23: =SUMIF(A:A,B23,T:T) -> 1262.76 | E23: =SUMIFS(T:T,A:A,B23,D:D,"Y") -> 1262.76 | F23: =SUMIF(A:A,B23,G:G) -> 3 | G23: =SUMIF(A:A,B23,H:H) -> 4 | H23: =SUMIF(A:A,B23,I:I) -> 1 | I23: =SUMIF(A:A,B23,P:P) -> 0 | J23: =SUMIF(A:A,B23,Q:Q) -> 0 | K23: =SUMIF(A:A,B23,R:R) -> 3 | L23: =SUMIF(A:A,B23,S:S) -> 1 | M23: =SUMIF(A:A,B23,M:M) -> 17 | N23: =SUMIF(A:A,B23,N:N) -> 2 | O23: =SUMIF(A:A,B23,O:O) -> 1 | P23: =SUMIF(A:A,B23,J:J) -> 3 | Q23: =SUMIF(A:A,B23,K:K) -> 1 | R23: =SUMIF(A:A,B23,L:L) -> 1
C24: # of Agents | E24: ALP per sale | F24: Show Rate | G24: Close Ratio | H24: ALP/Agent | J24: POS Close | L24: VET Close | M24: REF Per Sit | O24: REF Close | Q24: OTS Close
C25: =COUNTIFS(A:A,B23) -> 7 | E25: =IFERROR(C23/H23,0) -> 1262.76 | F25: =IFERROR((G23+R23)/F23,0) -> 1.6666667 | G25: =IFERROR(H23/G23,0) -> 0.25 | H25: =(C23/C25) -> 180.39429 | J25: =IFERROR(J23/I23,0) -> 0 | L25: =IFERROR(L23/K23,0) -> 0.33333333 | M25: =IFERROR(M23/SUM(R23+G23,0),"") -> 3.4 | O25: =IFERROR(O23/N23,0) -> 0.5 | Q25: =IFERROR(Q23/P23,0) -> 0.33333333
B26: Ashlynn Orng | C26: =SUMIF(A:A,B26,T:T) -> 11023.2 | E26: =SUMIFS(T:T,A:A,B26,D:D,"Y") -> 6268.2 | F26: =SUMIF(A:A,B26,G:G) -> 31 | G26: =SUMIF(A:A,B26,H:H) -> 27 | H26: =SUMIF(A:A,B26,I:I) -> #VALUE! | I26: =SUMIF(A:A,B26,P:P) -> 1 | J26: =SUMIF(A:A,B26,Q:Q) -> #REF! | K26: =SUMIF(A:A,B26,R:R) -> 5 | L26: =SUMIF(A:A,B26,S:S) -> 2 | M26: =SUMIF(A:A,B26,M:M) -> 88 | N26: =SUMIF(A:A,B26,N:N) -> 20 | O26: =SUMIF(A:A,B26,O:O) -> 6 | P26: =SUMIF(A:A,B26,J:J) -> 0 | Q26: =SUMIF(A:A,B26,K:K) -> 0 | R26: =SUMIF(A:A,B26,L:L) -> 0
C27: # of Agents | E27: ALP per sale | F27: Show Rate | G27: Close Ratio | H27: ALP/Agent | J27: POS Close | L27: VET Close | M27: REF Per Sit | O27: REF Close | Q27: OTS Close
C28: =COUNTIFS(A:A,B26) -> 11 | E28: =IFERROR(C26/H26,0) -> 0 | F28: =IFERROR((G26+R26)/F26,0) -> 0.87096774 | G28: =IFERROR(H26/G26,0) -> 0 | H28: =(C26/C28) -> 1002.1091 | J28: =IFERROR(J26/I26,0) -> 0 | L28: =IFERROR(L26/K26,0) -> 0.4 | M28: =IFERROR(M26/SUM(R26+G26,0),"") -> 3.2592593 | O28: =IFERROR(O26/N26,0) -> 0.3 | Q28: =IFERROR(Q26/P26,0) -> 0
B29: Kenneth Preston | C29: =SUMIF(A:A,B29,T:T) -> 0 | E29: =SUMIFS(T:T,A:A,B29,D:D,"Y") -> 0 | F29: =SUMIF(A:A,B29,G:G) -> 0 | G29: =SUMIF(A:A,B29,H:H) -> 0 | H29: =SUMIF(A:A,B29,I:I) -> 0 | I29: =SUMIF(A:A,B29,P:P) -> 0 | J29: =SUMIF(A:A,B29,Q:Q) -> 0 | K29: =SUMIF(A:A,B29,R:R) -> 0 | L29: =SUMIF(A:A,B29,S:S) -> 0 | M29: =SUMIF(A:A,B29,M:M) -> 0 | N29: =SUMIF(A:A,B29,N:N) -> 0 | O29: =SUMIF(A:A,B29,O:O) -> 0 | P29: =SUMIF(A:A,B29,J:J) -> 0 | Q29: =SUMIF(A:A,B29,K:K) -> 0 | R29: =SUMIF(A:A,B29,L:L) -> 0
C30: # of Agents | E30: ALP per sale | F30: Show Rate | G30: Close Ratio | H30: ALP/Agent | J30: POS Close | L30: VET Close | M30: REF Per Sit | O30: REF Close | Q30: OTS Close
C31: =COUNTIFS(A:A,B29) -> 2 | E31: =IFERROR(C29/H29,0) -> 0 | F31: =IFERROR((G29+R29)/F29,0) -> 0 | G31: =IFERROR(H29/G29,0) -> 0 | H31: =(C29/C31) -> 0 | J31: =IFERROR(J29/I29,0) -> 0 | L31: =IFERROR(L29/K29,0) -> 0 | M31: =IFERROR(M29/SUM(R29+G29,0),"") | O31: =IFERROR(O29/N29,0) -> 0 | Q31: =IFERROR(Q29/P29,0) -> 0
A33: MGA | B33: GA | C33: SA | E33: State | F33: Agent | G33: SETS | H33: SITS | I33: SALES | J33: OTS SITS | K33: OTS SALES | L33: N1 | M33: REF OBT | N33: REF SITS | O33: REF SALES | P33: POS SITS | Q33: POS SALES | R33: VETS SITS | S33: VET SALES | T33: ALP | U33: Close | V33: Show | W33: Code Date
A34: Joseph Gojcaj | D34: Y | E34: MI | F34: Joseph Gojcaj | G34: =('Thurs (2)'!G34+Thurs!G34+'Tues '!G34+Wed!G34+Fri!G34+'Mon '!G34+'Wed (2)'!G34+Sun!G34+Sat!G34) -> 0 | H34: =('Thurs (2)'!H34+Thurs!H34+'Tues '!H34+Wed!H34+Fri!H34+'Mon '!H34+'Wed (2)'!H34+Sun!H34+Sat!H34) -> 0 | I34: =('Thurs (2)'!I34+Thurs!I34+'Tues '!I34+Wed!I34+Fri!I34+'Mon '!I34+'Wed (2)'!I34+Sun!I34+Sat!I34) -> 0 | J34: =('Thurs (2)'!J34+Thurs!J34+'Tues '!J34+Wed!J34+Fri!J34+'Mon '!J34+'Wed (2)'!J34+Sun!J34+Sat!J34) -> 0 | K34: =('Thurs (2)'!K34+Thurs!K34+'Tues '!K34+Wed!K34+Fri!K34+'Mon '!K34+'Wed (2)'!K34+Sun!K34+Sat!K34) -> 0 | L34: =('Thurs (2)'!L34+Thurs!L34+'Tues '!L34+Wed!L34+Fri!L34+'Mon '!L34+'Wed (2)'!L34+Sun!L34+Sat!L34) -> 0 | M34: =('Thurs (2)'!M34+Thurs!M34+'Tues '!M34+Wed!M34+Fri!M34+'Mon '!M34+'Wed (2)'!M34+Sun!M34+Sat!M34) -> 0 | N34: =('Thurs (2)'!N34+Thurs!N34+'Tues '!N34+Wed!N34+Fri!N34+'Mon '!N34+'Wed (2)'!N34+Sun!N34+Sat!N34) -> 0 | ... T34: =('Thurs (2)'!T34+Thurs!T34+'Tues '!T34+Wed!T34+Fri!T34+'Mon '!T34+'Wed (2)'!T34+Sun!T34+Sat!T34) -> 0 | U34: =IFERROR(I34/H34,0) -> 0 | V34: =IFERROR(SUM(H34+L34)/G34,0) -> 0
A35: Joseph Gojcaj | B35: Edward Leon | D35: Y | E35: MI | F35: Eddie Leon | G35: =('Thurs (2)'!G35+Thurs!G35+'Tues '!G35+Wed!G35+Fri!G35+'Mon '!G35+'Wed (2)'!G35+Sun!G35+Sat!G35) -> 0 | H35: =('Thurs (2)'!H35+Thurs!H35+'Tues '!H35+Wed!H35+Fri!H35+'Mon '!H35+'Wed (2)'!H35+Sun!H35+Sat!H35) -> 0 | I35: =('Thurs (2)'!I35+Thurs!I35+'Tues '!I35+Wed!I35+Fri!I35+'Mon '!I35+'Wed (2)'!I35+Sun!I35+Sat!I35) -> 0 | J35: =('Thurs (2)'!J35+Thurs!J35+'Tues '!J35+Wed!J35+Fri!J35+'Mon '!J35+'Wed (2)'!J35+Sun!J35+Sat!J35) -> 0 | K35: =('Thurs (2)'!K35+Thurs!K35+'Tues '!K35+Wed!K35+Fri!K35+'Mon '!K35+'Wed (2)'!K35+Sun!K35+Sat!K35) -> 0 | L35: =('Thurs (2)'!L35+Thurs!L35+'Tues '!L35+Wed!L35+Fri!L35+'Mon '!L35+'Wed (2)'!L35+Sun!L35+Sat!L35) -> 0 | M35: =('Thurs (2)'!M35+Thurs!M35+'Tues '!M35+Wed!M35+Fri!M35+'Mon '!M35+'Wed (2)'!M35+Sun!M35+Sat!M35) -> 0 | N35: =('Thurs (2)'!N35+Thurs!N35+'Tues '!N35+Wed!N35+Fri!N35+'Mon '!N35+'Wed (2)'!N35+Sun!N35+Sat!N35) -> 0 | ... T35: =('Thurs (2)'!T35+Thurs!T35+'Tues '!T35+Wed!T35+Fri!T35+'Mon '!T35+'Wed (2)'!T35+Sun!T35+Sat!T35) -> 0 | U35: =IFERROR(I35/H35,0) -> 0 | V35: =IFERROR(SUM(H35+L35)/G35,0) -> 0
A36: Joseph Gojcaj | B36: Edward Leon | E36: CA | F36: Rick Argote | G36: =('Thurs (2)'!G36+Thurs!G36+'Tues '!G36+Wed!G36+Fri!G36+'Mon '!G36+'Wed (2)'!G36+Sun!G36+Sat!G36) -> 0 | H36: =('Thurs (2)'!H36+Thurs!H36+'Tues '!H36+Wed!H36+Fri!H36+'Mon '!H36+'Wed (2)'!H36+Sun!H36+Sat!H36) -> 0 | I36: =('Thurs (2)'!I36+Thurs!I36+'Tues '!I36+Wed!I36+Fri!I36+'Mon '!I36+'Wed (2)'!I36+Sun!I36+Sat!I36) -> 0 | J36: =('Thurs (2)'!J36+Thurs!J36+'Tues '!J36+Wed!J36+Fri!J36+'Mon '!J36+'Wed (2)'!J36+Sun!J36+Sat!J36) -> 0 | K36: =('Thurs (2)'!K36+Thurs!K36+'Tues '!K36+Wed!K36+Fri!K36+'Mon '!K36+'Wed (2)'!K36+Sun!K36+Sat!K36) -> 0 | L36: =('Thurs (2)'!L36+Thurs!L36+'Tues '!L36+Wed!L36+Fri!L36+'Mon '!L36+'Wed (2)'!L36+Sun!L36+Sat!L36) -> 0 | M36: =('Thurs (2)'!M36+Thurs!M36+'Tues '!M36+Wed!M36+Fri!M36+'Mon '!M36+'Wed (2)'!M36+Sun!M36+Sat!M36) -> 0 | N36: =('Thurs (2)'!N36+Thurs!N36+'Tues '!N36+Wed!N36+Fri!N36+'Mon '!N36+'Wed (2)'!N36+Sun!N36+Sat!N36) -> 0 | ... T36: =('Thurs (2)'!T36+Thurs!T36+'Tues '!T36+Wed!T36+Fri!T36+'Mon '!T36+'Wed (2)'!T36+Sun!T36+Sat!T36) -> 0 | U36: =IFERROR(I36/H36,0) -> 0 | V36: =IFERROR(SUM(H36+L36)/G36,0) -> 0
A37: Joseph Gojcaj | B37: Edward Leon | C37: Julian Hyman | D37: Y | E37: MI | F37: Julian Hyman | G37: =('Thurs (2)'!G37+Thurs!G37+'Tues '!G37+Wed!G37+Fri!G37+'Mon '!G37+'Wed (2)'!G37+Sun!G37+Sat!G37) -> 0 | H37: =('Thurs (2)'!H37+Thurs!H37+'Tues '!H37+Wed!H37+Fri!H37+'Mon '!H37+'Wed (2)'!H37+Sun!H37+Sat!H37) -> 1 | I37: =('Thurs (2)'!I37+Thurs!I37+'Tues '!I37+Wed!I37+Fri!I37+'Mon '!I37+'Wed (2)'!I37+Sun!I37+Sat!I37) -> 1 | J37: =('Thurs (2)'!J37+Thurs!J37+'Tues '!J37+Wed!J37+Fri!J37+'Mon '!J37+'Wed (2)'!J37+Sun!J37+Sat!J37) -> 1 | K37: =('Thurs (2)'!K37+Thurs!K37+'Tues '!K37+Wed!K37+Fri!K37+'Mon '!K37+'Wed (2)'!K37+Sun!K37+Sat!K37) -> 1 | L37: =('Thurs (2)'!L37+Thurs!L37+'Tues '!L37+Wed!L37+Fri!L37+'Mon '!L37+'Wed (2)'!L37+Sun!L37+Sat!L37) -> 0 | M37: =('Thurs (2)'!M37+Thurs!M37+'Tues '!M37+Wed!M37+Fri!M37+'Mon '!M37+'Wed (2)'!M37+Sun!M37+Sat!M37) -> 7 | N37: =('Thurs (2)'!N37+Thurs!N37+'Tues '!N37+Wed!N37+Fri!N37+'Mon '!N37+'Wed (2)'!N37+Sun!N37+Sat!N37) -> 0 | ... T37: =('Thurs (2)'!T37+Thurs!T37+'Tues '!T37+Wed!T37+Fri!T37+'Mon '!T37+'Wed (2)'!T37+Sun!T37+Sat!T37) -> 6408 | U37: =IFERROR(I37/H37,0) -> 1 | V37: =IFERROR(SUM(H37+L37)/G37,0) -> 0
A38: Joseph Gojcaj | B38: Edward Leon | C38: Julian Hyman | F38: Kaliyah Pyles | G38: =('Thurs (2)'!G38+Thurs!G38+'Tues '!G38+Wed!G38+Fri!G38+'Mon '!G38+'Wed (2)'!G38+Sun!G38+Sat!G38) -> 5 | H38: =('Thurs (2)'!H38+Thurs!H38+'Tues '!H38+Wed!H38+Fri!H38+'Mon '!H38+'Wed (2)'!H38+Sun!H38+Sat!H38) -> 4 | I38: =('Thurs (2)'!I38+Thurs!I38+'Tues '!I38+Wed!I38+Fri!I38+'Mon '!I38+'Wed (2)'!I38+Sun!I38+Sat!I38) -> 1 | J38: =('Thurs (2)'!J38+Thurs!J38+'Tues '!J38+Wed!J38+Fri!J38+'Mon '!J38+'Wed (2)'!J38+Sun!J38+Sat!J38) -> 0 | K38: =('Thurs (2)'!K38+Thurs!K38+'Tues '!K38+Wed!K38+Fri!K38+'Mon '!K38+'Wed (2)'!K38+Sun!K38+Sat!K38) -> 0 | L38: =('Thurs (2)'!L38+Thurs!L38+'Tues '!L38+Wed!L38+Fri!L38+'Mon '!L38+'Wed (2)'!L38+Sun!L38+Sat!L38) -> 1 | M38: =('Thurs (2)'!M38+Thurs!M38+'Tues '!M38+Wed!M38+Fri!M38+'Mon '!M38+'Wed (2)'!M38+Sun!M38+Sat!M38) -> 16 | N38: =('Thurs (2)'!N38+Thurs!N38+'Tues '!N38+Wed!N38+Fri!N38+'Mon '!N38+'Wed (2)'!N38+Sun!N38+Sat!N38) -> 3 | ... T38: =('Thurs (2)'!T38+Thurs!T38+'Tues '!T38+Wed!T38+Fri!T38+'Mon '!T38+'Wed (2)'!T38+Sun!T38+Sat!T38) -> 1700 | U38: =IFERROR(I38/H38,0) -> 0.25 | V38: =IFERROR(SUM(H38+L38)/G38,0) -> 1
A39: Joseph Gojcaj | B39: Edward Leon | C39: Julian Hyman | F39: Ethan Lasley | G39: =('Thurs (2)'!G39+Thurs!G39+'Tues '!G39+Wed!G39+Fri!G39+'Mon '!G39+'Wed (2)'!G39+Sun!G39+Sat!G39) -> 0 | H39: =('Thurs (2)'!H39+Thurs!H39+'Tues '!H39+Wed!H39+Fri!H39+'Mon '!H39+'Wed (2)'!H39+Sun!H39+Sat!H39) -> 0 | I39: =('Thurs (2)'!I39+Thurs!I39+'Tues '!I39+Wed!I39+Fri!I39+'Mon '!I39+'Wed (2)'!I39+Sun!I39+Sat!I39) -> 0 | J39: =('Thurs (2)'!J39+Thurs!J39+'Tues '!J39+Wed!J39+Fri!J39+'Mon '!J39+'Wed (2)'!J39+Sun!J39+Sat!J39) -> 0 | K39: =('Thurs (2)'!K39+Thurs!K39+'Tues '!K39+Wed!K39+Fri!K39+'Mon '!K39+'Wed (2)'!K39+Sun!K39+Sat!K39) -> 0 | L39: =('Thurs (2)'!L39+Thurs!L39+'Tues '!L39+Wed!L39+Fri!L39+'Mon '!L39+'Wed (2)'!L39+Sun!L39+Sat!L39) -> 0 | M39: =('Thurs (2)'!M39+Thurs!M39+'Tues '!M39+Wed!M39+Fri!M39+'Mon '!M39+'Wed (2)'!M39+Sun!M39+Sat!M39) -> 0 | N39: =('Thurs (2)'!N39+Thurs!N39+'Tues '!N39+Wed!N39+Fri!N39+'Mon '!N39+'Wed (2)'!N39+Sun!N39+Sat!N39) -> 0 | ... T39: =('Thurs (2)'!T39+Thurs!T39+'Tues '!T39+Wed!T39+Fri!T39+'Mon '!T39+'Wed (2)'!T39+Sun!T39+Sat!T39) -> 0 | U39: =IFERROR(I39/H39,0) -> 0 | V39: =IFERROR(SUM(H39+L39)/G39,0) -> 0
A40: Joseph Gojcaj | B40: Edward Leon | C40: Julian Hyman | E40: MI | F40: Keith Chmiel | G40: =('Thurs (2)'!G40+Thurs!G40+'Tues '!G40+Wed!G40+Fri!G40+'Mon '!G40+'Wed (2)'!G40+Sun!G40+Sat!G40) -> 1 | H40: =('Thurs (2)'!H40+Thurs!H40+'Tues '!H40+Wed!H40+Fri!H40+'Mon '!H40+'Wed (2)'!H40+Sun!H40+Sat!H40) -> 1 | I40: =('Thurs (2)'!I40+Thurs!I40+'Tues '!I40+Wed!I40+Fri!I40+'Mon '!I40+'Wed (2)'!I40+Sun!I40+Sat!I40) -> 0 | J40: =('Thurs (2)'!J40+Thurs!J40+'Tues '!J40+Wed!J40+Fri!J40+'Mon '!J40+'Wed (2)'!J40+Sun!J40+Sat!J40) -> 0 | K40: =('Thurs (2)'!K40+Thurs!K40+'Tues '!K40+Wed!K40+Fri!K40+'Mon '!K40+'Wed (2)'!K40+Sun!K40+Sat!K40) -> 0 | L40: =('Thurs (2)'!L40+Thurs!L40+'Tues '!L40+Wed!L40+Fri!L40+'Mon '!L40+'Wed (2)'!L40+Sun!L40+Sat!L40) -> 0 | M40: =('Thurs (2)'!M40+Thurs!M40+'Tues '!M40+Wed!M40+Fri!M40+'Mon '!M40+'Wed (2)'!M40+Sun!M40+Sat!M40) -> 0 | N40: =('Thurs (2)'!N40+Thurs!N40+'Tues '!N40+Wed!N40+Fri!N40+'Mon '!N40+'Wed (2)'!N40+Sun!N40+Sat!N40) -> 0 | ... T40: =('Thurs (2)'!T40+Thurs!T40+'Tues '!T40+Wed!T40+Fri!T40+'Mon '!T40+'Wed (2)'!T40+Sun!T40+Sat!T40) -> 0 | U40: =IFERROR(I40/H40,0) -> 0 | V40: =IFERROR(SUM(H40+L40)/G40,0) -> 1
A41: Joseph Gojcaj | B41: Edward Leon | C41: Julian Hyman | E41: TX | F41: Veronica Sanchez | G41: =('Thurs (2)'!G41+Thurs!G41+'Tues '!G41+Wed!G41+Fri!G41+'Mon '!G41+'Wed (2)'!G41+Sun!G41+Sat!G41) -> 0 | H41: =('Thurs (2)'!H41+Thurs!H41+'Tues '!H41+Wed!H41+Fri!H41+'Mon '!H41+'Wed (2)'!H41+Sun!H41+Sat!H41) -> 0 | I41: =('Thurs (2)'!I41+Thurs!I41+'Tues '!I41+Wed!I41+Fri!I41+'Mon '!I41+'Wed (2)'!I41+Sun!I41+Sat!I41) -> 0 | J41: =('Thurs (2)'!J41+Thurs!J41+'Tues '!J41+Wed!J41+Fri!J41+'Mon '!J41+'Wed (2)'!J41+Sun!J41+Sat!J41) -> 0 | K41: =('Thurs (2)'!K41+Thurs!K41+'Tues '!K41+Wed!K41+Fri!K41+'Mon '!K41+'Wed (2)'!K41+Sun!K41+Sat!K41) -> 0 | L41: =('Thurs (2)'!L41+Thurs!L41+'Tues '!L41+Wed!L41+Fri!L41+'Mon '!L41+'Wed (2)'!L41+Sun!L41+Sat!L41) -> 0 | M41: =('Thurs (2)'!M41+Thurs!M41+'Tues '!M41+Wed!M41+Fri!M41+'Mon '!M41+'Wed (2)'!M41+Sun!M41+Sat!M41) -> 0 | N41: =('Thurs (2)'!N41+Thurs!N41+'Tues '!N41+Wed!N41+Fri!N41+'Mon '!N41+'Wed (2)'!N41+Sun!N41+Sat!N41) -> 0 | ... T41: =('Thurs (2)'!T41+Thurs!T41+'Tues '!T41+Wed!T41+Fri!T41+'Mon '!T41+'Wed (2)'!T41+Sun!T41+Sat!T41) -> 0 | U41: =IFERROR(I41/H41,0) -> 0 | V41: =IFERROR(SUM(H41+L41)/G41,0) -> 0
...

Sheet Wed
C1: ALP | E1: LEADERSHIP ALP | F1: Appts | G1: Pres | H1: Sales | I1: POS SITS | J1: POS SA | K1: VET SITS | L1: VET SA | M1: REF OBT | N1: REF SITS | O1: REF SA | P1: OTS SITS | Q1: OTS SA | R1: N1
B2: GOJCAJ RGA | C2: =SUM(C5,C17,C20,C23,C26,C29) -> 11169 | E2: =SUM(E5,E17,E20,E23,E26,E29) -> 7470 | F2: =SUM(F5,F17,F20,F23,F26,F29) -> 15 | G2: =SUM(G5,G17,G20,G23,G26,G29) -> 9 | H2: =SUM(H5,H17,H20,H23,H26,H29) -> 7 | I2: =SUM(I5,I17,I20,I23,I26,I29) -> 0 | J2: =SUM(J5,J17,J20,J23,J26,J29) -> 0 | K2: =SUM(K5,K17,K20,K23,K26,K29) -> 3 | L2: =SUM(L5,L17,L20,L23,L26,L29) -> 2 | ... R2: =SUM(R5,R17,R20,R23,R26,R29) -> 3
C3: # of Agents | E3: ALP per sale | F3: Show Rate | G3: Close Ratio | H3: ALP/Agent | J3: POS Close | L3: VET Close | M3: REF Per Sit | O3: REF Close | Q3: OTS Close
C4: =SUM(C7,C22,C19,C25,C28,C31) -> 64 | E4: =IFERROR(C2/H2,0) -> 1595.5714 | F4: =IFERROR((G2+R2)/F2,0) -> 0.8 | G4: =IFERROR(H2/G2,0) -> 0.77777778 | H4: =(C2/C4) -> 174.51562 | J4: =IFERROR(J2/I2,0) -> 0 | L4: =IFERROR(L2/K2,0) -> 0.66666667 | M4: =IFERROR(M2/G2,0) -> 3 | O4: =IFERROR(O2/N2,0) -> 0.5 | Q4: =IFERROR(Q2/P2,0) -> 0.75
B5: Joseph Gojcaj | C5: =SUMIF(A:A,B5,T:T) -> 6339 | E5: =SUMIFS(T:T,A:A,B5,D:D,"Y") -> 4740 | F5: =SUMIF(A:A,B5,G:G) -> 7 | G5: =SUMIF(A:A,B5,H:H) -> 3 | H5: =SUMIF(A:A,B5,I:I) -> 3 | I5: =SUMIF(A:A,B5,P:P) -> 0 | J5: =SUMIF(A:A,B5,Q:Q) -> 0 | K5: =SUMIF(A:A,B5,R:R) -> 0 | L5: =SUMIF(A:A,B5,S:S) -> 0 | M5: =SUMIF(A:A,B5,M:M) -> 18 | N5: =SUMIF(A:A,B5,N:N) -> 2 | O5: =SUMIF(A:A,B5,O:O) -> 1 | P5: =SUMIF(A:A,B5,J:J) -> 2 | Q5: =SUMIF(A:A,B5,K:K) -> 2 | R5: =SUMIF(A:A,B5,L:L) -> 1
C6: # of Agents | E6: ALP per sale | F6: Show Rate | G6: Close Ratio | H6: ALP/Agent | J6: POS Close | L6: VET Close | M6: REF Per Sit | O6: REF Close | Q6: OTS Close
C7: =COUNTIFS(A:A,B5) -> 29 | E7: =IFERROR(C5/H5,0) -> 2113 | F7: =IFERROR((G5+R5)/F5,0) -> 0.57142857 | G7: =IFERROR(H5/G5,0) -> 1 | H7: =(C5/C7) -> 218.58621 | J7: =IFERROR(J5/I5,0) -> 0 | L7: =IFERROR(L5/K5,0) -> 0 | M7: =IFERROR(M5/SUM(R5+G5,0),"") -> 4.5 | O7: =IFERROR(O5/N5,0) -> 0.5 | Q7: =IFERROR(Q5/P5,0) -> 1
B8: Edward Leon | C8: =SUMIF(B:B,B8,T:T) -> 0 | E8: =SUMIFS(T:T,B:B,B8,D:D,"Y") -> 0 | F8: =SUMIF(B28:B1137,B8,G28:G1137) -> 0 | G8: =SUMIF(B28:B1137,B8,H28:H1137) -> 0 | H8: =SUMIF(B28:B1137,B8,I28:I1137) -> 0 | I8: =SUMIF(B28:B1137,B8,P28:P1137) -> 0 | J8: =SUMIF(B28:B1137,B8,Q28:Q1137) -> 0 | K8: =SUMIF(B28:B1137,B8,R28:R1137) -> 0 | L8: =SUMIF(B28:B1137,B8,S28:S1137) -> 0 | M8: =SUMIF(B28:B1137,B8,M28:M1137) -> 0 | N8: =SUMIF(B28:B1137,B8,N28:N1137) -> 0 | O8: =SUMIF(B28:B1137,B8,O28:O1137) -> 0 | P8: =SUMIF(B28:B1137,B8,J28:J1137) -> 0 | Q8: =SUMIF(B28:B1137,B8,K28:K1137) -> 0 | R8: =SUMIF(B28:B1137,B8,L28:L1137) -> 0
C9: # of Agents | E9: ALP per sale | F9: Show Rate | G9: Close Ratio | H9: ALP/Agent | J9: POS Close | L9: VET Close | M9: REF Per Sit | O9: REF Close | Q9: OTS Close
C10: =COUNTIFS(B35:B1137,B8) -> 8 | E10: =IFERROR(C8/H8,0) -> 0 | F10: =IFERROR((G8+R8)/F8,0) -> 0 | G10: =IFERROR(H8/G8,0) -> 0 | H10: =(C8/C10) -> 0 | J10: =IFERROR(J8/I8,0) -> 0 | L10: =IFERROR(L8/K8,0) -> 0 | M10: =IFERROR(M8/SUM(R8+G8,0),"") | O10: =IFERROR(O8/N8,0) -> 0 | Q10: =IFERROR(Q8/P8,0) -> 0
B11: Timothy Noe | C11: =SUMIF(B:B,B11,T:T) -> 0 | E11: =SUMIFS(T:T,B:B,B11,D:D,"Y") -> 0 | F11: =SUMIF(B31:B1137,B11,G31:G1137) -> 0 | G11: =SUMIF(B31:B1137,B11,H31:H1137) -> 0 | H11: =SUMIF(B31:B1137,B11,I31:I1137) -> 0 | I11: =SUMIF(B31:B1137,B11,P31:P1137) -> 0 | J11: =SUMIF(B31:B1137,B11,Q31:Q1137) -> 0 | K11: =SUMIF(B31:B1137,B11,R31:R1137) -> 0 | L11: =SUMIF(B31:B1137,B11,S31:S1137) -> 0 | M11: =SUMIF(B31:B1137,B11,M31:M1137) -> 0 | N11: =SUMIF(B31:B1137,B11,N31:N1137) -> 0 | O11: =SUMIF(B31:B1137,B11,O31:O1137) -> 0 | P11: =SUMIF(B31:B1137,B11,J31:J1137) -> 0 | Q11: =SUMIF(B31:B1137,B11,K31:K1137) -> 0 | R11: =SUMIF(B31:B1137,B11,L31:L1137) -> 0
C12: # of Agents | E12: ALP per sale | F12: Show Rate | G12: Close Ratio | H12: ALP/Agent | J12: POS Close | L12: VET Close | M12: REF Per Sit | O12: REF Close | Q12: OTS Close
C13: =COUNTIFS(B36:B1137,B11) -> 4 | E13: =IFERROR(C11/H11,0) -> 0 | F13: =IFERROR((G11+R11)/F11,0) -> 0 | G13: =IFERROR(H11/G11,0) -> 0 | H13: =(C11/C13) -> 0 | J13: =IFERROR(J11/I11,0) -> 0 | L13: =IFERROR(L11/K11,0) -> 0 | M13: =IFERROR(M11/SUM(R11+G11,0),"") | O13: =IFERROR(O11/N11,0) -> 0 | Q13: =IFERROR(Q11/P11,0) -> 0
B14: Javier Sandoval | C14: =SUMIF(B:B,B14,T:T) -> 6339 | E14: =SUMIFS(T:T,B:B,B14,D:D,"Y") -> 4740 | F14: =SUMIF(B34:B1137,B14,G34:G1137) -> 7 | G14: =SUMIF(B34:B1137,B14,H34:H1137) -> 3 | H14: =SUMIF(B34:B1137,B14,I34:I1137) -> 3 | I14: =SUMIF(B34:B1137,B14,P34:P1137) -> 0 | J14: =SUMIF(B34:B1137,B14,Q34:Q1137) -> 0 | K14: =SUMIF(B34:B1137,B14,R34:R1137) -> 0 | L14: =SUMIF(B34:B1137,B14,S34:S1137) -> 0 | M14: =SUMIF(B34:B1137,B14,M34:M1137) -> 18 | N14: =SUMIF(B34:B1137,B14,N34:N1137) -> 2 | O14: =SUMIF(B34:B1137,B14,O34:O1137) -> 1 | P14: =SUMIF(B34:B1137,B14,J34:J1137) -> 2 | Q14: =SUMIF(B34:B1137,B14,K34:K1137) -> 2 | R14: =SUMIF(B34:B1137,B14,L34:L1137) -> 1
C15: # of Agents | E15: ALP per sale | F15: Show Rate | G15: Close Ratio | H15: ALP/Agent | J15: POS Close | L15: VET Close | M15: REF Per Sit | O15: REF Close | Q15: OTS Close
C16: =COUNTIFS(B34:B1137,B14) -> 16 | E16: =IFERROR(C14/H14,0) -> 2113 | F16: =IFERROR((G14+R14)/F14,0) -> 0.57142857 | G16: =IFERROR(H14/G14,0) -> 1 | H16: =(C14/C16) -> 396.1875 | J16: =IFERROR(J14/I14,0) -> 0 | L16: =IFERROR(L14/K14,0) -> 0 | M16: =IFERROR(M14/SUM(G14+R14,0),"") -> 4.5 | O16: =IFERROR(O14/N14,0) -> 0.5 | Q16: =IFERROR(Q14/P14,0) -> 1
B17: Jacob Brown | C17: =SUMIF(A:A,B17,T:T) -> 0 | E17: =SUMIFS(T:T,A:A,B17,D:D,"Y") -> 0 | F17: =SUMIF(A:A,B17,G:G) -> 1 | G17: =SUMIF(A:A,B17,H:H) -> 1 | H17: =SUMIF(A:A,B17,I:I) -> 0 | I17: =SUMIF(A:A,B17,P:P) -> 0 | J17: =SUMIF(A:A,B17,Q:Q) -> 0 | K17: =SUMIF(A:A,B17,R:R) -> 1 | L17: =SUMIF(A:A,B17,S:S) -> 0 | M17: =SUMIF(A:A,B17,M:M) -> 2 | N17: =SUMIF(A:A,B17,N:N) -> 0 | O17: =SUMIF(A:A,B17,O:O) -> 0 | P17: =SUMIF(A:A,B17,J:J) -> 1 | Q17: =SUMIF(A:A,B17,K:K) -> 0 | R17: =SUMIF(A:A,B17,L:L) -> 1
C18: # of Agents | E18: ALP per sale | F18: Show Rate | G18: Close Ratio | H18: ALP/Agent | J18: POS Close | L18: VET Close | M18: REF Per Sit | O18: REF Close | Q18: OTS Close
C19: =COUNTIFS(A:A,B17) -> 6 | E19: =IFERROR(C17/H17,0) -> 0 | F19: =IFERROR((G17+R17)/F17,0) -> 2 | G19: =IFERROR(H17/G17,0) -> 0 | H19: =(C17/C19) -> 0 | J19: =IFERROR(J17/I17,0) -> 0 | L19: =IFERROR(L17/K17,0) -> 0 | M19: =IFERROR(M17/SUM(R17+G17,0),"") -> 1 | O19: =IFERROR(O17/N17,0) -> 0 | Q19: =IFERROR(Q17/P17,0) -> 0
B20: Derron Alexander | C20: =SUMIF(A:A,B20,T:T) -> 2100 | E20: =SUMIFS(T:T,A:A,B20,D:D,"Y") -> 0 | F20: =SUMIF(A:A,B20,G:G) -> 1 | G20: =SUMIF(A:A,B20,H:H) -> 1 | H20: =SUMIF(A:A,B20,I:I) -> 1 | I20: =SUMIF(A:A,B20,P:P) -> 0 | J20: =SUMIF(A:A,B20,Q:Q) -> 0 | K20: =SUMIF(A:A,B20,R:R) -> 1 | L20: =SUMIF(A:A,B20,S:S) -> 1 | M20: =SUMIF(A:A,B20,M:M) -> 0 | N20: =SUMIF(A:A,B20,N:N) -> 0 | O20: =SUMIF(A:A,B20,O:O) -> 0 | P20: =SUMIF(A:A,B20,J:J) -> 1 | Q20: =SUMIF(A:A,B20,K:K) -> 1 | R20: =SUMIF(A:A,B20,L:L) -> 1
C21: # of Agents | E21: ALP per sale | F21: Show Rate | G21: Close Ratio | H21: ALP/Agent | J21: POS Close | L21: VET Close | M21: REF Per Sit | O21: REF Close | Q21: OTS Close
C22: =COUNTIFS(A:A,B20) -> 9 | E22: =IFERROR(C20/H20,0) -> 2100 | F22: =IFERROR((G20+R20)/F20,0) -> 2 | G22: =IFERROR(H20/G20,0) -> 1 | H22: =(C20/C22) -> 233.33333 | J22: =IFERROR(J20/I20,0) -> 0 | L22: =IFERROR(L20/K20,0) -> 1 | M22: =IFERROR(M20/SUM(R20+G20,0),"") -> 0 | O22: =IFERROR(O20/N20,0) -> 0 | Q22: =IFERROR(Q20/P20,0) -> 1
B23: David Fulfer | C23: =SUMIF(A:A,B23,T:T) -> 0 | E23: =SUMIFS(T:T,A:A,B23,D:D,"Y") -> 0 | F23: =SUMIF(A:A,B23,G:G) -> 0 | G23: =SUMIF(A:A,B23,H:H) -> 0 | H23: =SUMIF(A:A,B23,I:I) -> 0 | I23: =SUMIF(A:A,B23,P:P) -> 0 | J23: =SUMIF(A:A,B23,Q:Q) -> 0 | K23: =SUMIF(A:A,B23,R:R) -> 0 | L23: =SUMIF(A:A,B23,S:S) -> 0 | M23: =SUMIF(A:A,B23,M:M) -> 0 | N23: =SUMIF(A:A,B23,N:N) -> 0 | O23: =SUMIF(A:A,B23,O:O) -> 0 | P23: =SUMIF(A:A,B23,J:J) -> 0 | Q23: =SUMIF(A:A,B23,K:K) -> 0 | R23: =SUMIF(A:A,B23,L:L) -> 0
C24: # of Agents | E24: ALP per sale | F24: Show Rate | G24: Close Ratio | H24: ALP/Agent | J24: POS Close | L24: VET Close | M24: REF Per Sit | O24: REF Close | Q24: OTS Close
C25: =COUNTIFS(A:A,B23) -> 7 | E25: =IFERROR(C23/H23,0) -> 0 | F25: =IFERROR((G23+R23)/F23,0) -> 0 | G25: =IFERROR(H23/G23,0) -> 0 | H25: =(C23/C25) -> 0 | J25: =IFERROR(J23/I23,0) -> 0 | L25: =IFERROR(L23/K23,0) -> 0 | M25: =IFERROR(M23/SUM(R23+G23,0),"") | O25: =IFERROR(O23/N23,0) -> 0 | Q25: =IFERROR(Q23/P23,0) -> 0
B26: Ashlynn Orng | C26: =SUMIF(A:A,B26,T:T) -> 2730 | E26: =SUMIFS(T:T,A:A,B26,D:D,"Y") -> 2730 | F26: =SUMIF(A:A,B26,G:G) -> 6 | G26: =SUMIF(A:A,B26,H:H) -> 4 | H26: =SUMIF(A:A,B26,I:I) -> 3 | I26: =SUMIF(A:A,B26,P:P) -> 0 | J26: =SUMIF(A:A,B26,Q:Q) -> 0 | K26: =SUMIF(A:A,B26,R:R) -> 1 | L26: =SUMIF(A:A,B26,S:S) -> 1 | M26: =SUMIF(A:A,B26,M:M) -> 7 | N26: =SUMIF(A:A,B26,N:N) -> 2 | O26: =SUMIF(A:A,B26,O:O) -> 1 | P26: =SUMIF(A:A,B26,J:J) -> 0 | Q26: =SUMIF(A:A,B26,K:K) -> 0 | R26: =SUMIF(A:A,B26,L:L) -> 0
C27: # of Agents | E27: ALP per sale | F27: Show Rate | G27: Close Ratio | H27: ALP/Agent | J27: POS Close | L27: VET Close | M27: REF Per Sit | O27: REF Close | Q27: OTS Close
C28: =COUNTIFS(A:A,B26) -> 11 | E28: =IFERROR(C26/H26,0) -> 910 | F28: =IFERROR((G26+R26)/F26,0) -> 0.66666667 | G28: =IFERROR(H26/G26,0) -> 0.75 | H28: =(C26/C28) -> 248.18182 | J28: =IFERROR(J26/I26,0) -> 0 | L28: =IFERROR(L26/K26,0) -> 1 | M28: =IFERROR(M26/SUM(R26+G26,0),"") -> 1.75 | O28: =IFERROR(O26/N26,0) -> 0.5 | Q28: =IFERROR(Q26/P26,0) -> 0
B29: Kenneth Preston | C29: =SUMIF(A:A,B29,T:T) -> 0 | E29: =SUMIFS(T:T,A:A,B29,D:D,"Y") -> 0 | F29: =SUMIF(A:A,B29,G:G) -> 0 | G29: =SUMIF(A:A,B29,H:H) -> 0 | H29: =SUMIF(A:A,B29,I:I) -> 0 | I29: =SUMIF(A:A,B29,P:P) -> 0 | J29: =SUMIF(A:A,B29,Q:Q) -> 0 | K29: =SUMIF(A:A,B29,R:R) -> 0 | L29: =SUMIF(A:A,B29,S:S) -> 0 | M29: =SUMIF(A:A,B29,M:M) -> 0 | N29: =SUMIF(A:A,B29,N:N) -> 0 | O29: =SUMIF(A:A,B29,O:O) -> 0 | P29: =SUMIF(A:A,B29,J:J) -> 0 | Q29: =SUMIF(A:A,B29,K:K) -> 0 | R29: =SUMIF(A:A,B29,L:L) -> 0
C30: # of Agents | E30: ALP per sale | F30: Show Rate | G30: Close Ratio | H30: ALP/Agent | J30: POS Close | L30: VET Close | M30: REF Per Sit | O30: REF Close | Q30: OTS Close
C31: =COUNTIFS(A:A,B29) -> 2 | E31: =IFERROR(C29/H29,0) -> 0 | F31: =IFERROR((G29+R29)/F29,0) -> 0 | G31: =IFERROR(H29/G29,0) -> 0 | H31: =(C29/C31) -> 0 | J31: =IFERROR(J29/I29,0) -> 0 | L31: =IFERROR(L29/K29,0) -> 0 | M31: =IFERROR(M29/SUM(R29+G29,0),"") | O31: =IFERROR(O29/N29,0) -> 0 | Q31: =IFERROR(Q29/P29,0) -> 0
A33: MGA | B33: GA | C33: SA | E33: State | F33: Agent | G33: SETS | H33: SITS | I33: SALES | J33: OTS SITS | K33: OTS SALES | L33: N1 | M33: REF OBT | N33: REF SITS | O33: REF SALES | P33: POS SITS | Q33: POS SALES | R33: VETS SITS | S33: VET SALES | T33: ALP | U33: Close | V33: Show | W33: Code Date
A34: Joseph Gojcaj | D34: Y | E34: MI | F34: Joseph Gojcaj | U34: =IFERROR(I34/H34,0) -> 0 | V34: =IFERROR(SUM(H34+L34)/G34,0) -> 0
A35: Joseph Gojcaj | B35: Edward Leon | D35: Y | E35: MI | F35: Eddie Leon | U35: =IFERROR(I35/H35,0) -> 0 | V35: =IFERROR(SUM(H35+L35)/G35,0) -> 0
A36: Joseph Gojcaj | B36: Edward Leon | E36: CA | F36: Rick Argote | U36: =IFERROR(I36/H36,0) -> 0 | V36: =IFERROR(SUM(H36+L36)/G36,0) -> 0
A37: Joseph Gojcaj | B37: Edward Leon | C37: Julian Hyman | D37: Y | E37: MI | F37: Julian Hyman | U37: =IFERROR(I37/H37,0) -> 0 | V37: =IFERROR(SUM(H37+L37)/G37,0) -> 0
A38: Joseph Gojcaj | B38: Edward Leon | C38: Julian Hyman | F38: Kaliyah Pyles | U38: =IFERROR(I38/H38,0) -> 0 | V38: =IFERROR(SUM(H38+L38)/G38,0) -> 0
A39: Joseph Gojcaj | B39: Edward Leon | C39: Julian Hyman | F39: Ethan Lasley | U39: =IFERROR(I39/H39,0) -> 0 | V39: =IFERROR(SUM(H39+L39)/G39,0) -> 0
A40: Joseph Gojcaj | B40: Edward Leon | C40: Julian Hyman | E40: MI | F40: Keith Chmiel | U40: =IFERROR(I40/H40,0) -> 0 | V40: =IFERROR(SUM(H40+L40)/G40,0) -> 0
A41: Joseph Gojcaj | B41: Edward Leon | C41: Julian Hyman | E41: TX | F41: Veronica Sanchez | U41: =IFERROR(I41/H41,0) -> 0 | V41: =IFERROR(SUM(H41+L41)/G41,0) -> 0
...

Sheet Thurs
C1: ALP | E1: LEADERSHIP ALP | F1: Appts | G1: Pres | H1: Sales | I1: POS SITS | J1: POS SA | K1: VET SITS | L1: VET SA | M1: REF OBT | N1: REF SITS | O1: REF SA | P1: OTS SITS | Q1: OTS SA | R1: N1
B2: GOJCAJ RGA | C2: =SUM(C5,C17,C20,C23,C26,C29) -> 1750 | E2: =SUM(E5,E17,E20,E23,E26,E29) -> 1750 | F2: =SUM(F5,F17,F20,F23,F26,F29) -> 4 | G2: =SUM(G5,G17,G20,G23,G26,G29) -> 3 | H2: =SUM(H5,H17,H20,H23,H26,H29) -> 2 | I2: =SUM(I5,I17,I20,I23,I26,I29) -> 0 | J2: =SUM(J5,J17,J20,J23,J26,J29) -> 0 | K2: =SUM(K5,K17,K20,K23,K26,K29) -> 1 | L2: =SUM(L5,L17,L20,L23,L26,L29) -> 0 | ... R2: =SUM(R5,R17,R20,R23,R26,R29) -> 0
C3: # of Agents | E3: ALP per sale | F3: Show Rate | G3: Close Ratio | H3: ALP/Agent | J3: POS Close | L3: VET Close | M3: REF Per Sit | O3: REF Close | Q3: OTS Close
C4: =SUM(C7,C22,C19,C25,C28,C31) -> 64 | E4: =IFERROR(C2/H2,0) -> 875 | F4: =IFERROR((G2+R2)/F2,0) -> 0.75 | G4: =IFERROR(H2/G2,0) -> 0.66666667 | H4: =(C2/C4) -> 27.34375 | J4: =IFERROR(J2/I2,0) -> 0 | L4: =IFERROR(L2/K2,0) -> 0 | M4: =IFERROR(M2/G2,0) -> 1.6666667 | O4: =IFERROR(O2/N2,0) -> 1 | Q4: =IFERROR(Q2/P2,0) -> 1
B5: Joseph Gojcaj | C5: =SUMIF(A:A,B5,T:T) -> 1750 | E5: =SUMIFS(T:T,A:A,B5,D:D,"Y") -> 1750 | F5: =SUMIF(A:A,B5,G:G) -> 4 | G5: =SUMIF(A:A,B5,H:H) -> 2 | H5: =SUMIF(A:A,B5,I:I) -> 2 | I5: =SUMIF(A:A,B5,P:P) -> 0 | J5: =SUMIF(A:A,B5,Q:Q) -> 0 | K5: =SUMIF(A:A,B5,R:R) -> 0 | L5: =SUMIF(A:A,B5,S:S) -> 0 | M5: =SUMIF(A:A,B5,M:M) -> 2 | N5: =SUMIF(A:A,B5,N:N) -> 1 | O5: =SUMIF(A:A,B5,O:O) -> 1 | P5: =SUMIF(A:A,B5,J:J) -> 1 | Q5: =SUMIF(A:A,B5,K:K) -> 2 | R5: =SUMIF(A:A,B5,L:L) -> 0
C6: # of Agents | E6: ALP per sale | F6: Show Rate | G6: Close Ratio | H6: ALP/Agent | J6: POS Close | L6: VET Close | M6: REF Per Sit | O6: REF Close | Q6: OTS Close
C7: =COUNTIFS(A:A,B5) -> 29 | E7: =IFERROR(C5/H5,0) -> 875 | F7: =IFERROR((G5+R5)/F5,0) -> 0.5 | G7: =IFERROR(H5/G5,0) -> 1 | H7: =(C5/C7) -> 60.344828 | J7: =IFERROR(J5/I5,0) -> 0 | L7: =IFERROR(L5/K5,0) -> 0 | M7: =IFERROR(M5/SUM(R5+G5,0),"") -> 1 | O7: =IFERROR(O5/N5,0) -> 1 | Q7: =IFERROR(Q5/P5,0) -> 2
B8: Edward Leon | C8: =SUMIF(B:B,B8,T:T) -> 0 | E8: =SUMIFS(T:T,B:B,B8,D:D,"Y") -> 0 | F8: =SUMIF(B28:B1137,B8,G28:G1137) -> 0 | G8: =SUMIF(B28:B1137,B8,H28:H1137) -> 0 | H8: =SUMIF(B28:B1137,B8,I28:I1137) -> 0 | I8: =SUMIF(B28:B1137,B8,P28:P1137) -> 0 | J8: =SUMIF(B28:B1137,B8,Q28:Q1137) -> 0 | K8: =SUMIF(B28:B1137,B8,R28:R1137) -> 0 | L8: =SUMIF(B28:B1137,B8,S28:S1137) -> 0 | M8: =SUMIF(B28:B1137,B8,M28:M1137) -> 0 | N8: =SUMIF(B28:B1137,B8,N28:N1137) -> 0 | O8: =SUMIF(B28:B1137,B8,O28:O1137) -> 0 | P8: =SUMIF(B28:B1137,B8,J28:J1137) -> 0 | Q8: =SUMIF(B28:B1137,B8,K28:K1137) -> 0 | R8: =SUMIF(B28:B1137,B8,L28:L1137) -> 0
C9: # of Agents | E9: ALP per sale | F9: Show Rate | G9: Close Ratio | H9: ALP/Agent | J9: POS Close | L9: VET Close | M9: REF Per Sit | O9: REF Close | Q9: OTS Close
C10: =COUNTIFS(B35:B1137,B8) -> 8 | E10: =IFERROR(C8/H8,0) -> 0 | F10: =IFERROR((G8+R8)/F8,0) -> 0 | G10: =IFERROR(H8/G8,0) -> 0 | H10: =(C8/C10) -> 0 | J10: =IFERROR(J8/I8,0) -> 0 | L10: =IFERROR(L8/K8,0) -> 0 | M10: =IFERROR(M8/SUM(R8+G8,0),"") | O10: =IFERROR(O8/N8,0) -> 0 | Q10: =IFERROR(Q8/P8,0) -> 0
B11: Timothy Noe | C11: =SUMIF(B:B,B11,T:T) -> 0 | E11: =SUMIFS(T:T,B:B,B11,D:D,"Y") -> 0 | F11: =SUMIF(B31:B1137,B11,G31:G1137) -> 0 | G11: =SUMIF(B31:B1137,B11,H31:H1137) -> 0 | H11: =SUMIF(B31:B1137,B11,I31:I1137) -> 0 | I11: =SUMIF(B31:B1137,B11,P31:P1137) -> 0 | J11: =SUMIF(B31:B1137,B11,Q31:Q1137) -> 0 | K11: =SUMIF(B31:B1137,B11,R31:R1137) -> 0 | L11: =SUMIF(B31:B1137,B11,S31:S1137) -> 0 | M11: =SUMIF(B31:B1137,B11,M31:M1137) -> 0 | N11: =SUMIF(B31:B1137,B11,N31:N1137) -> 0 | O11: =SUMIF(B31:B1137,B11,O31:O1137) -> 0 | P11: =SUMIF(B31:B1137,B11,J31:J1137) -> 0 | Q11: =SUMIF(B31:B1137,B11,K31:K1137) -> 0 | R11: =SUMIF(B31:B1137,B11,L31:L1137) -> 0
C12: # of Agents | E12: ALP per sale | F12: Show Rate | G12: Close Ratio | H12: ALP/Agent | J12: POS Close | L12: VET Close | M12: REF Per Sit | O12: REF Close | Q12: OTS Close
C13: =COUNTIFS(B36:B1137,B11) -> 4 | E13: =IFERROR(C11/H11,0) -> 0 | F13: =IFERROR((G11+R11)/F11,0) -> 0 | G13: =IFERROR(H11/G11,0) -> 0 | H13: =(C11/C13) -> 0 | J13: =IFERROR(J11/I11,0) -> 0 | L13: =IFERROR(L11/K11,0) -> 0 | M13: =IFERROR(M11/SUM(R11+G11,0),"") | O13: =IFERROR(O11/N11,0) -> 0 | Q13: =IFERROR(Q11/P11,0) -> 0
B14: Javier Sandoval | C14: =SUMIF(B:B,B14,T:T) -> 1750 | E14: =SUMIFS(T:T,B:B,B14,D:D,"Y") -> 1750 | F14: =SUMIF(B34:B1137,B14,G34:G1137) -> 4 | G14: =SUMIF(B34:B1137,B14,H34:H1137) -> 2 | H14: =SUMIF(B34:B1137,B14,I34:I1137) -> 2 | I14: =SUMIF(B34:B1137,B14,P34:P1137) -> 0 | J14: =SUMIF(B34:B1137,B14,Q34:Q1137) -> 0 | K14: =SUMIF(B34:B1137,B14,R34:R1137) -> 0 | L14: =SUMIF(B34:B1137,B14,S34:S1137) -> 0 | M14: =SUMIF(B34:B1137,B14,M34:M1137) -> 2 | N14: =SUMIF(B34:B1137,B14,N34:N1137) -> 1 | O14: =SUMIF(B34:B1137,B14,O34:O1137) -> 1 | P14: =SUMIF(B34:B1137,B14,J34:J1137) -> 1 | Q14: =SUMIF(B34:B1137,B14,K34:K1137) -> 2 | R14: =SUMIF(B34:B1137,B14,L34:L1137) -> 0
C15: # of Agents | E15: ALP per sale | F15: Show Rate | G15: Close Ratio | H15: ALP/Agent | J15: POS Close | L15: VET Close | M15: REF Per Sit | O15: REF Close | Q15: OTS Close
C16: =COUNTIFS(B34:B1137,B14) -> 16 | E16: =IFERROR(C14/H14,0) -> 875 | F16: =IFERROR((G14+R14)/F14,0) -> 0.5 | G16: =IFERROR(H14/G14,0) -> 1 | H16: =(C14/C16) -> 109.375 | J16: =IFERROR(J14/I14,0) -> 0 | L16: =IFERROR(L14/K14,0) -> 0 | M16: =IFERROR(M14/SUM(G14+R14,0),"") -> 1 | O16: =IFERROR(O14/N14,0) -> 1 | Q16: =IFERROR(Q14/P14,0) -> 2
B17: Jacob Brown | C17: =SUMIF(A:A,B17,T:T) -> 0 | E17: =SUMIFS(T:T,A:A,B17,D:D,"Y") -> 0 | F17: =SUMIF(A:A,B17,G:G) -> 0 | G17: =SUMIF(A:A,B17,H:H) -> 0 | H17: =SUMIF(A:A,B17,I:I) -> 0 | I17: =SUMIF(A:A,B17,P:P) -> 0 | J17: =SUMIF(A:A,B17,Q:Q) -> 0 | K17: =SUMIF(A:A,B17,R:R) -> 0 | L17: =SUMIF(A:A,B17,S:S) -> 0 | M17: =SUMIF(A:A,B17,M:M) -> 0 | N17: =SUMIF(A:A,B17,N:N) -> 0 | O17: =SUMIF(A:A,B17,O:O) -> 0 | P17: =SUMIF(A:A,B17,J:J) -> 0 | Q17: =SUMIF(A:A,B17,K:K) -> 0 | R17: =SUMIF(A:A,B17,L:L) -> 0
C18: # of Agents | E18: ALP per sale | F18: Show Rate | G18: Close Ratio | H18: ALP/Agent | J18: POS Close | L18: VET Close | M18: REF Per Sit | O18: REF Close | Q18: OTS Close
C19: =COUNTIFS(A:A,B17) -> 6 | E19: =IFERROR(C17/H17,0) -> 0 | F19: =IFERROR((G17+R17)/F17,0) -> 0 | G19: =IFERROR(H17/G17,0) -> 0 | H19: =(C17/C19) -> 0 | J19: =IFERROR(J17/I17,0) -> 0 | L19: =IFERROR(L17/K17,0) -> 0 | M19: =IFERROR(M17/SUM(R17+G17,0),"") | O19: =IFERROR(O17/N17,0) -> 0 | Q19: =IFERROR(Q17/P17,0) -> 0
B20: Derron Alexander | C20: =SUMIF(A:A,B20,T:T) -> 0 | E20: =SUMIFS(T:T,A:A,B20,D:D,"Y") -> 0 | F20: =SUMIF(A:A,B20,G:G) -> 0 | G20: =SUMIF(A:A,B20,H:H) -> 0 | H20: =SUMIF(A:A,B20,I:I) -> 0 | I20: =SUMIF(A:A,B20,P:P) -> 0 | J20: =SUMIF(A:A,B20,Q:Q) -> 0 | K20: =SUMIF(A:A,B20,R:R) -> 0 | L20: =SUMIF(A:A,B20,S:S) -> 0 | M20: =SUMIF(A:A,B20,M:M) -> 0 | N20: =SUMIF(A:A,B20,N:N) -> 0 | O20: =SUMIF(A:A,B20,O:O) -> 0 | P20: =SUMIF(A:A,B20,J:J) -> 0 | Q20: =SUMIF(A:A,B20,K:K) -> 0 | R20: =SUMIF(A:A,B20,L:L) -> 0
C21: # of Agents | E21: ALP per sale | F21: Show Rate | G21: Close Ratio | H21: ALP/Agent | J21: POS Close | L21: VET Close | M21: REF Per Sit | O21: REF Close | Q21: OTS Close
C22: =COUNTIFS(A:A,B20) -> 9 | E22: =IFERROR(C20/H20,0) -> 0 | F22: =IFERROR((G20+R20)/F20,0) -> 0 | G22: =IFERROR(H20/G20,0) -> 0 | H22: =(C20/C22) -> 0 | J22: =IFERROR(J20/I20,0) -> 0 | L22: =IFERROR(L20/K20,0) -> 0 | M22: =IFERROR(M20/SUM(R20+G20,0),"") | O22: =IFERROR(O20/N20,0) -> 0 | Q22: =IFERROR(Q20/P20,0) -> 0
B23: David Fulfer | C23: =SUMIF(A:A,B23,T:T) -> 0 | E23: =SUMIFS(T:T,A:A,B23,D:D,"Y") -> 0 | F23: =SUMIF(A:A,B23,G:G) -> 0 | G23: =SUMIF(A:A,B23,H:H) -> 1 | H23: =SUMIF(A:A,B23,I:I) -> 0 | I23: =SUMIF(A:A,B23,P:P) -> 0 | J23: =SUMIF(A:A,B23,Q:Q) -> 0 | K23: =SUMIF(A:A,B23,R:R) -> 1 | L23: =SUMIF(A:A,B23,S:S) -> 0 | M23: =SUMIF(A:A,B23,M:M) -> 3 | N23: =SUMIF(A:A,B23,N:N) -> 0 | O23: =SUMIF(A:A,B23,O:O) -> 0 | P23: =SUMIF(A:A,B23,J:J) -> 1 | Q23: =SUMIF(A:A,B23,K:K) -> 0 | R23: =SUMIF(A:A,B23,L:L) -> 0
C24: # of Agents | E24: ALP per sale | F24: Show Rate | G24: Close Ratio | H24: ALP/Agent | J24: POS Close | L24: VET Close | M24: REF Per Sit | O24: REF Close | Q24: OTS Close
C25: =COUNTIFS(A:A,B23) -> 7 | E25: =IFERROR(C23/H23,0) -> 0 | F25: =IFERROR((G23+R23)/F23,0) -> 0 | G25: =IFERROR(H23/G23,0) -> 0 | H25: =(C23/C25) -> 0 | J25: =IFERROR(J23/I23,0) -> 0 | L25: =IFERROR(L23/K23,0) -> 0 | M25: =IFERROR(M23/SUM(R23+G23,0),"") -> 3 | O25: =IFERROR(O23/N23,0) -> 0 | Q25: =IFERROR(Q23/P23,0) -> 0
B26: Ashlynn Orng | C26: =SUMIF(A:A,B26,T:T) -> 0 | E26: =SUMIFS(T:T,A:A,B26,D:D,"Y") -> 0 | F26: =SUMIF(A:A,B26,G:G) -> 0 | G26: =SUMIF(A:A,B26,H:H) -> 0 | H26: =SUMIF(A:A,B26,I:I) -> 0 | I26: =SUMIF(A:A,B26,P:P) -> 0 | J26: =SUMIF(A:A,B26,Q:Q) -> 0 | K26: =SUMIF(A:A,B26,R:R) -> 0 | L26: =SUMIF(A:A,B26,S:S) -> 0 | M26: =SUMIF(A:A,B26,M:M) -> 0 | N26: =SUMIF(A:A,B26,N:N) -> 0 | O26: =SUMIF(A:A,B26,O:O) -> 0 | P26: =SUMIF(A:A,B26,J:J) -> 0 | Q26: =SUMIF(A:A,B26,K:K) -> 0 | R26: =SUMIF(A:A,B26,L:L) -> 0
C27: # of Agents | E27: ALP per sale | F27: Show Rate | G27: Close Ratio | H27: ALP/Agent | J27: POS Close | L27: VET Close | M27: REF Per Sit | O27: REF Close | Q27: OTS Close
C28: =COUNTIFS(A:A,B26) -> 11 | E28: =IFERROR(C26/H26,0) -> 0 | F28: =IFERROR((G26+R26)/F26,0) -> 0 | G28: =IFERROR(H26/G26,0) -> 0 | H28: =(C26/C28) -> 0 | J28: =IFERROR(J26/I26,0) -> 0 | L28: =IFERROR(L26/K26,0) -> 0 | M28: =IFERROR(M26/SUM(R26+G26,0),"") | O28: =IFERROR(O26/N26,0) -> 0 | Q28: =IFERROR(Q26/P26,0) -> 0
B29: Kenneth Preston | C29: =SUMIF(A:A,B29,T:T) -> 0 | E29: =SUMIFS(T:T,A:A,B29,D:D,"Y") -> 0 | F29: =SUMIF(A:A,B29,G:G) -> 0 | G29: =SUMIF(A:A,B29,H:H) -> 0 | H29: =SUMIF(A:A,B29,I:I) -> 0 | I29: =SUMIF(A:A,B29,P:P) -> 0 | J29: =SUMIF(A:A,B29,Q:Q) -> 0 | K29: =SUMIF(A:A,B29,R:R) -> 0 | L29: =SUMIF(A:A,B29,S:S) -> 0 | M29: =SUMIF(A:A,B29,M:M) -> 0 | N29: =SUMIF(A:A,B29,N:N) -> 0 | O29: =SUMIF(A:A,B29,O:O) -> 0 | P29: =SUMIF(A:A,B29,J:J) -> 0 | Q29: =SUMIF(A:A,B29,K:K) -> 0 | R29: =SUMIF(A:A,B29,L:L) -> 0
C30: # of Agents | E30: ALP per sale | F30: Show Rate | G30: Close Ratio | H30: ALP/Agent | J30: POS Close | L30: VET Close | M30: REF Per Sit | O30: REF Close | Q30: OTS Close
C31: =COUNTIFS(A:A,B29) -> 2 | E31: =IFERROR(C29/H29,0) -> 0 | F31: =IFERROR((G29+R29)/F29,0) -> 0 | G31: =IFERROR(H29/G29,0) -> 0 | H31: =(C29/C31) -> 0 | J31: =IFERROR(J29/I29,0) -> 0 | L31: =IFERROR(L29/K29,0) -> 0 | M31: =IFERROR(M29/SUM(R29+G29,0),"") | O31: =IFERROR(O29/N29,0) -> 0 | Q31: =IFERROR(Q29/P29,0) -> 0
A33: MGA | B33: GA | C33: SA | E33: State | F33: Agent | G33: SETS | H33: SITS | I33: SALES | J33: OTS SITS | K33: OTS SALES | L33: N1 | M33: REF OBT | N33: REF SITS | O33: REF SALES | P33: POS SITS | Q33: POS SALES | R33: VETS SITS | S33: VET SALES | T33: ALP | U33: Close | V33: Show | W33: Code Date
A34: Joseph Gojcaj | D34: Y | E34: MI | F34: Joseph Gojcaj | U34: =IFERROR(I34/H34,0) -> 0 | V34: =IFERROR(SUM(H34+L34)/G34,0) -> 0
A35: Joseph Gojcaj | B35: Edward Leon | D35: Y | E35: MI | F35: Eddie Leon | U35: =IFERROR(I35/H35,0) -> 0 | V35: =IFERROR(SUM(H35+L35)/G35,0) -> 0
A36: Joseph Gojcaj | B36: Edward Leon | E36: CA | F36: Rick Argote | U36: =IFERROR(I36/H36,0) -> 0 | V36: =IFERROR(SUM(H36+L36)/G36,0) -> 0
A37: Joseph Gojcaj | B37: Edward Leon | C37: Julian Hyman | D37: Y | E37: MI | F37: Julian Hyman | U37: =IFERROR(I37/H37,0) -> 0 | V37: =IFERROR(SUM(H37+L37)/G37,0) -> 0
A38: Joseph Gojcaj | B38: Edward Leon | C38: Julian Hyman | F38: Kaliyah Pyles | U38: =IFERROR(I38/H38,0) -> 0 | V38: =IFERROR(SUM(H38+L38)/G38,0) -> 0
A39: Joseph Gojcaj | B39: Edward Leon | C39: Julian Hyman | F39: Ethan Lasley | U39: =IFERROR(I39/H39,0) -> 0 | V39: =IFERROR(SUM(H39+L39)/G39,0) -> 0
A40: Joseph Gojcaj | B40: Edward Leon | C40: Julian Hyman | E40: MI | F40: Keith Chmiel | U40: =IFERROR(I40/H40,0) -> 0 | V40: =IFERROR(SUM(H40+L40)/G40,0) -> 0
A41: Joseph Gojcaj | B41: Edward Leon | C41: Julian Hyman | E41: TX | F41: Veronica Sanchez | U41: =IFERROR(I41/H41,0) -> 0 | V41: =IFERROR(SUM(H41+L41)/G41,0) -> 0
...

Sheet Fri
C1: ALP | E1: LEADERSHIP ALP | F1: Appts | G1: Pres | H1: Sales | I1: POS SITS | J1: POS SA | K1: VET SITS | L1: VET SA | M1: REF OBT | N1: REF SITS | O1: REF SA | P1: OTS SITS | Q1: OTS SA | R1: N1
B2: GOJCAJ RGA | C2: =SUM(C5,C17,C20,C23,C26,C29) -> 1893 | E2: =SUM(E5,E17,E20,E23,E26,E29) -> 1893 | F2: =SUM(F5,F17,F20,F23,F26,F29) -> 4 | G2: =SUM(G5,G17,G20,G23,G26,G29) -> 4 | H2: =SUM(H5,H17,H20,H23,H26,H29) -> 1 | I2: =SUM(I5,I17,I20,I23,I26,I29) -> 0 | J2: =SUM(J5,J17,J20,J23,J26,J29) -> 0 | K2: =SUM(K5,K17,K20,K23,K26,K29) -> 1 | L2: =SUM(L5,L17,L20,L23,L26,L29) -> 1 | ... R2: =SUM(R5,R17,R20,R23,R26,R29) -> 1
C3: # of Agents | E3: ALP per sale | F3: Show Rate | G3: Close Ratio | H3: ALP/Agent | J3: POS Close | L3: VET Close | M3: REF Per Sit | O3: REF Close | Q3: OTS Close
C4: =SUM(C7,C22,C19,C25,C28,C31) -> 64 | E4: =IFERROR(C2/H2,0) -> 1893 | F4: =IFERROR((G2+R2)/F2,0) -> 1.25 | G4: =IFERROR(H2/G2,0) -> 0.25 | H4: =(C2/C4) -> 29.578125 | J4: =IFERROR(J2/I2,0) -> 0 | L4: =IFERROR(L2/K2,0) -> 1 | M4: =IFERROR(M2/G2,0) -> 5.25 | O4: =IFERROR(O2/N2,0) -> 0 | Q4: =IFERROR(Q2/P2,0) -> 0.33333333
B5: Joseph Gojcaj | C5: =SUMIF(A:A,B5,T:T) -> 1893 | E5: =SUMIFS(T:T,A:A,B5,D:D,"Y") -> 1893 | F5: =SUMIF(A:A,B5,G:G) -> 4 | G5: =SUMIF(A:A,B5,H:H) -> 3 | H5: =SUMIF(A:A,B5,I:I) -> 1 | I5: =SUMIF(A:A,B5,P:P) -> 0 | J5: =SUMIF(A:A,B5,Q:Q) -> 0 | K5: =SUMIF(A:A,B5,R:R) -> 1 | L5: =SUMIF(A:A,B5,S:S) -> 1 | M5: =SUMIF(A:A,B5,M:M) -> 10 | N5: =SUMIF(A:A,B5,N:N) -> 1 | O5: =SUMIF(A:A,B5,O:O) -> 0 | P5: =SUMIF(A:A,B5,J:J) -> 3 | Q5: =SUMIF(A:A,B5,K:K) -> 1 | R5: =SUMIF(A:A,B5,L:L) -> 1
C6: # of Agents | E6: ALP per sale | F6: Show Rate | G6: Close Ratio | H6: ALP/Agent | J6: POS Close | L6: VET Close | M6: REF Per Sit | O6: REF Close | Q6: OTS Close
C7: =COUNTIFS(A:A,B5) -> 29 | E7: =IFERROR(C5/H5,0) -> 1893 | F7: =IFERROR((G5+R5)/F5,0) -> 1 | G7: =IFERROR(H5/G5,0) -> 0.33333333 | H7: =(C5/C7) -> 65.275862 | J7: =IFERROR(J5/I5,0) -> 0 | L7: =IFERROR(L5/K5,0) -> 1 | M7: =IFERROR(M5/SUM(R5+G5,0),"") -> 2.5 | O7: =IFERROR(O5/N5,0) -> 0 | Q7: =IFERROR(Q5/P5,0) -> 0.33333333
B8: Edward Leon | C8: =SUMIF(B:B,B8,T:T) -> 0 | E8: =SUMIFS(T:T,B:B,B8,D:D,"Y") -> 0 | F8: =SUMIF(B28:B1137,B8,G28:G1137) -> 0 | G8: =SUMIF(B28:B1137,B8,H28:H1137) -> 0 | H8: =SUMIF(B28:B1137,B8,I28:I1137) -> 0 | I8: =SUMIF(B28:B1137,B8,P28:P1137) -> 0 | J8: =SUMIF(B28:B1137,B8,Q28:Q1137) -> 0 | K8: =SUMIF(B28:B1137,B8,R28:R1137) -> 0 | L8: =SUMIF(B28:B1137,B8,S28:S1137) -> 0 | M8: =SUMIF(B28:B1137,B8,M28:M1137) -> 0 | N8: =SUMIF(B28:B1137,B8,N28:N1137) -> 0 | O8: =SUMIF(B28:B1137,B8,O28:O1137) -> 0 | P8: =SUMIF(B28:B1137,B8,J28:J1137) -> 0 | Q8: =SUMIF(B28:B1137,B8,K28:K1137) -> 0 | R8: =SUMIF(B28:B1137,B8,L28:L1137) -> 0
C9: # of Agents | E9: ALP per sale | F9: Show Rate | G9: Close Ratio | H9: ALP/Agent | J9: POS Close | L9: VET Close | M9: REF Per Sit | O9: REF Close | Q9: OTS Close
C10: =COUNTIFS(B35:B1137,B8) -> 8 | E10: =IFERROR(C8/H8,0) -> 0 | F10: =IFERROR((G8+R8)/F8,0) -> 0 | G10: =IFERROR(H8/G8,0) -> 0 | H10: =(C8/C10) -> 0 | J10: =IFERROR(J8/I8,0) -> 0 | L10: =IFERROR(L8/K8,0) -> 0 | M10: =IFERROR(M8/SUM(R8+G8,0),"") | O10: =IFERROR(O8/N8,0) -> 0 | Q10: =IFERROR(Q8/P8,0) -> 0
B11: Timothy Noe | C11: =SUMIF(B:B,B11,T:T) -> 0 | E11: =SUMIFS(T:T,B:B,B11,D:D,"Y") -> 0 | F11: =SUMIF(B31:B1137,B11,G31:G1137) -> 0 | G11: =SUMIF(B31:B1137,B11,H31:H1137) -> 0 | H11: =SUMIF(B31:B1137,B11,I31:I1137) -> 0 | I11: =SUMIF(B31:B1137,B11,P31:P1137) -> 0 | J11: =SUMIF(B31:B1137,B11,Q31:Q1137) -> 0 | K11: =SUMIF(B31:B1137,B11,R31:R1137) -> 0 | L11: =SUMIF(B31:B1137,B11,S31:S1137) -> 0 | M11: =SUMIF(B31:B1137,B11,M31:M1137) -> 0 | N11: =SUMIF(B31:B1137,B11,N31:N1137) -> 0 | O11: =SUMIF(B31:B1137,B11,O31:O1137) -> 0 | P11: =SUMIF(B31:B1137,B11,J31:J1137) -> 0 | Q11: =SUMIF(B31:B1137,B11,K31:K1137) -> 0 | R11: =SUMIF(B31:B1137,B11,L31:L1137) -> 0
C12: # of Agents | E12: ALP per sale | F12: Show Rate | G12: Close Ratio | H12: ALP/Agent | J12: POS Close | L12: VET Close | M12: REF Per Sit | O12: REF Close | Q12: OTS Close
C13: =COUNTIFS(B36:B1137,B11) -> 4 | E13: =IFERROR(C11/H11,0) -> 0 | F13: =IFERROR((G11+R11)/F11,0) -> 0 | G13: =IFERROR(H11/G11,0) -> 0 | H13: =(C11/C13) -> 0 | J13: =IFERROR(J11/I11,0) -> 0 | L13: =IFERROR(L11/K11,0) -> 0 | M13: =IFERROR(M11/SUM(R11+G11,0),"") | O13: =IFERROR(O11/N11,0) -> 0 | Q13: =IFERROR(Q11/P11,0) -> 0
B14: Javier Sandoval | C14: =SUMIF(B:B,B14,T:T) -> 1893 | E14: =SUMIFS(T:T,B:B,B14,D:D,"Y") -> 1893 | F14: =SUMIF(B34:B1137,B14,G34:G1137) -> 4 | G14: =SUMIF(B34:B1137,B14,H34:H1137) -> 3 | H14: =SUMIF(B34:B1137,B14,I34:I1137) -> 1 | I14: =SUMIF(B34:B1137,B14,P34:P1137) -> 0 | J14: =SUMIF(B34:B1137,B14,Q34:Q1137) -> 0 | K14: =SUMIF(B34:B1137,B14,R34:R1137) -> 1 | L14: =SUMIF(B34:B1137,B14,S34:S1137) -> 1 | M14: =SUMIF(B34:B1137,B14,M34:M1137) -> 10 | N14: =SUMIF(B34:B1137,B14,N34:N1137) -> 1 | O14: =SUMIF(B34:B1137,B14,O34:O1137) -> 0 | P14: =SUMIF(B34:B1137,B14,J34:J1137) -> 3 | Q14: =SUMIF(B34:B1137,B14,K34:K1137) -> 1 | R14: =SUMIF(B34:B1137,B14,L34:L1137) -> 1
C15: # of Agents | E15: ALP per sale | F15: Show Rate | G15: Close Ratio | H15: ALP/Agent | J15: POS Close | L15: VET Close | M15: REF Per Sit | O15: REF Close | Q15: OTS Close
C16: =COUNTIFS(B34:B1137,B14) -> 16 | E16: =IFERROR(C14/H14,0) -> 1893 | F16: =IFERROR((G14+R14)/F14,0) -> 1 | G16: =IFERROR(H14/G14,0) -> 0.33333333 | H16: =(C14/C16) -> 118.3125 | J16: =IFERROR(J14/I14,0) -> 0 | L16: =IFERROR(L14/K14,0) -> 1 | M16: =IFERROR(M14/SUM(G14+R14,0),"") -> 2.5 | O16: =IFERROR(O14/N14,0) -> 0 | Q16: =IFERROR(Q14/P14,0) -> 0.33333333
B17: Jacob Brown | C17: =SUMIF(A:A,B17,T:T) -> 0 | E17: =SUMIFS(T:T,A:A,B17,D:D,"Y") -> 0 | F17: =SUMIF(A:A,B17,G:G) -> 0 | G17: =SUMIF(A:A,B17,H:H) -> 0 | H17: =SUMIF(A:A,B17,I:I) -> 0 | I17: =SUMIF(A:A,B17,P:P) -> 0 | J17: =SUMIF(A:A,B17,Q:Q) -> 0 | K17: =SUMIF(A:A,B17,R:R) -> 0 | L17: =SUMIF(A:A,B17,S:S) -> 0 | M17: =SUMIF(A:A,B17,M:M) -> 0 | N17: =SUMIF(A:A,B17,N:N) -> 0 | O17: =SUMIF(A:A,B17,O:O) -> 0 | P17: =SUMIF(A:A,B17,J:J) -> 0 | Q17: =SUMIF(A:A,B17,K:K) -> 0 | R17: =SUMIF(A:A,B17,L:L) -> 0
C18: # of Agents | E18: ALP per sale | F18: Show Rate | G18: Close Ratio | H18: ALP/Agent | J18: POS Close | L18: VET Close | M18: REF Per Sit | O18: REF Close | Q18: OTS Close
C19: =COUNTIFS(A:A,B17) -> 6 | E19: =IFERROR(C17/H17,0) -> 0 | F19: =IFERROR((G17+R17)/F17,0) -> 0 | G19: =IFERROR(H17/G17,0) -> 0 | H19: =(C17/C19) -> 0 | J19: =IFERROR(J17/I17,0) -> 0 | L19: =IFERROR(L17/K17,0) -> 0 | M19: =IFERROR(M17/SUM(R17+G17,0),"") | O19: =IFERROR(O17/N17,0) -> 0 | Q19: =IFERROR(Q17/P17,0) -> 0
B20: Derron Alexander | C20: =SUMIF(A:A,B20,T:T) -> 0 | E20: =SUMIFS(T:T,A:A,B20,D:D,"Y") -> 0 | F20: =SUMIF(A:A,B20,G:G) -> 0 | G20: =SUMIF(A:A,B20,H:H) -> 0 | H20: =SUMIF(A:A,B20,I:I) -> 0 | I20: =SUMIF(A:A,B20,P:P) -> 0 | J20: =SUMIF(A:A,B20,Q:Q) -> 0 | K20: =SUMIF(A:A,B20,R:R) -> 0 | L20: =SUMIF(A:A,B20,S:S) -> 0 | M20: =SUMIF(A:A,B20,M:M) -> 0 | N20: =SUMIF(A:A,B20,N:N) -> 0 | O20: =SUMIF(A:A,B20,O:O) -> 0 | P20: =SUMIF(A:A,B20,J:J) -> 0 | Q20: =SUMIF(A:A,B20,K:K) -> 0 | R20: =SUMIF(A:A,B20,L:L) -> 0
C21: # of Agents | E21: ALP per sale | F21: Show Rate | G21: Close Ratio | H21: ALP/Agent | J21: POS Close | L21: VET Close | M21: REF Per Sit | O21: REF Close | Q21: OTS Close
C22: =COUNTIFS(A:A,B20) -> 9 | E22: =IFERROR(C20/H20,0) -> 0 | F22: =IFERROR((G20+R20)/F20,0) -> 0 | G22: =IFERROR(H20/G20,0) -> 0 | H22: =(C20/C22) -> 0 | J22: =IFERROR(J20/I20,0) -> 0 | L22: =IFERROR(L20/K20,0) -> 0 | M22: =IFERROR(M20/SUM(R20+G20,0),"") | O22: =IFERROR(O20/N20,0) -> 0 | Q22: =IFERROR(Q20/P20,0) -> 0
B23: David Fulfer | C23: =SUMIF(A:A,B23,T:T) -> 0 | E23: =SUMIFS(T:T,A:A,B23,D:D,"Y") -> 0 | F23: =SUMIF(A:A,B23,G:G) -> 0 | G23: =SUMIF(A:A,B23,H:H) -> 1 | H23: =SUMIF(A:A,B23,I:I) -> 0 | I23: =SUMIF(A:A,B23,P:P) -> 0 | J23: =SUMIF(A:A,B23,Q:Q) -> 0 | K23: =SUMIF(A:A,B23,R:R) -> 0 | L23: =SUMIF(A:A,B23,S:S) -> 0 | M23: =SUMIF(A:A,B23,M:M) -> 11 | N23: =SUMIF(A:A,B23,N:N) -> 1 | O23: =SUMIF(A:A,B23,O:O) -> 0 | P23: =SUMIF(A:A,B23,J:J) -> 0 | Q23: =SUMIF(A:A,B23,K:K) -> 0 | R23: =SUMIF(A:A,B23,L:L) -> 0
C24: # of Agents | E24: ALP per sale | F24: Show Rate | G24: Close Ratio | H24: ALP/Agent | J24: POS Close | L24: VET Close | M24: REF Per Sit | O24: REF Close | Q24: OTS Close
C25: =COUNTIFS(A:A,B23) -> 7 | E25: =IFERROR(C23/H23,0) -> 0 | F25: =IFERROR((G23+R23)/F23,0) -> 0 | G25: =IFERROR(H23/G23,0) -> 0 | H25: =(C23/C25) -> 0 | J25: =IFERROR(J23/I23,0) -> 0 | L25: =IFERROR(L23/K23,0) -> 0 | M25: =IFERROR(M23/SUM(R23+G23,0),"") -> 11 | O25: =IFERROR(O23/N23,0) -> 0 | Q25: =IFERROR(Q23/P23,0) -> 0
B26: Ashlynn Orng | C26: =SUMIF(A:A,B26,T:T) -> 0 | E26: =SUMIFS(T:T,A:A,B26,D:D,"Y") -> 0 | F26: =SUMIF(A:A,B26,G:G) -> 0 | G26: =SUMIF(A:A,B26,H:H) -> 0 | H26: =SUMIF(A:A,B26,I:I) -> 0 | I26: =SUMIF(A:A,B26,P:P) -> 0 | J26: =SUMIF(A:A,B26,Q:Q) -> 0 | K26: =SUMIF(A:A,B26,R:R) -> 0 | L26: =SUMIF(A:A,B26,S:S) -> 0 | M26: =SUMIF(A:A,B26,M:M) -> 0 | N26: =SUMIF(A:A,B26,N:N) -> 0 | O26: =SUMIF(A:A,B26,O:O) -> 0 | P26: =SUMIF(A:A,B26,J:J) -> 0 | Q26: =SUMIF(A:A,B26,K:K) -> 0 | R26: =SUMIF(A:A,B26,L:L) -> 0
C27: # of Agents | E27: ALP per sale | F27: Show Rate | G27: Close Ratio | H27: ALP/Agent | J27: POS Close | L27: VET Close | M27: REF Per Sit | O27: REF Close | Q27: OTS Close
C28: =COUNTIFS(A:A,B26) -> 11 | E28: =IFERROR(C26/H26,0) -> 0 | F28: =IFERROR((G26+R26)/F26,0) -> 0 | G28: =IFERROR(H26/G26,0) -> 0 | H28: =(C26/C28) -> 0 | J28: =IFERROR(J26/I26,0) -> 0 | L28: =IFERROR(L26/K26,0) -> 0 | M28: =IFERROR(M26/SUM(R26+G26,0),"") | O28: =IFERROR(O26/N26,0) -> 0 | Q28: =IFERROR(Q26/P26,0) -> 0
B29: Kenneth Preston | C29: =SUMIF(A:A,B29,T:T) -> 0 | E29: =SUMIFS(T:T,A:A,B29,D:D,"Y") -> 0 | F29: =SUMIF(A:A,B29,G:G) -> 0 | G29: =SUMIF(A:A,B29,H:H) -> 0 | H29: =SUMIF(A:A,B29,I:I) -> 0 | I29: =SUMIF(A:A,B29,P:P) -> 0 | J29: =SUMIF(A:A,B29,Q:Q) -> 0 | K29: =SUMIF(A:A,B29,R:R) -> 0 | L29: =SUMIF(A:A,B29,S:S) -> 0 | M29: =SUMIF(A:A,B29,M:M) -> 0 | N29: =SUMIF(A:A,B29,N:N) -> 0 | O29: =SUMIF(A:A,B29,O:O) -> 0 | P29: =SUMIF(A:A,B29,J:J) -> 0 | Q29: =SUMIF(A:A,B29,K:K) -> 0 | R29: =SUMIF(A:A,B29,L:L) -> 0
C30: # of Agents | E30: ALP per sale | F30: Show Rate | G30: Close Ratio | H30: ALP/Agent | J30: POS Close | L30: VET Close | M30: REF Per Sit | O30: REF Close | Q30: OTS Close
C31: =COUNTIFS(A:A,B29) -> 2 | E31: =IFERROR(C29/H29,0) -> 0 | F31: =IFERROR((G29+R29)/F29,0) -> 0 | G31: =IFERROR(H29/G29,0) -> 0 | H31: =(C29/C31) -> 0 | J31: =IFERROR(J29/I29,0) -> 0 | L31: =IFERROR(L29/K29,0) -> 0 | M31: =IFERROR(M29/SUM(R29+G29,0),"") | O31: =IFERROR(O29/N29,0) -> 0 | Q31: =IFERROR(Q29/P29,0) -> 0
A33: MGA | B33: GA | C33: SA | E33: State | F33: Agent | G33: SETS | H33: SITS | I33: SALES | J33: OTS SITS | K33: OTS SALES | L33: N1 | M33: REF OBT | N33: REF SITS | O33: REF SALES | P33: POS SITS | Q33: POS SALES | R33: VETS SITS | S33: VET SALES | T33: ALP | U33: Close | V33: Show | W33: Code Date
A34: Joseph Gojcaj | D34: Y | E34: MI | F34: Joseph Gojcaj | U34: =IFERROR(I34/H34,0) -> 0 | V34: =IFERROR(SUM(H34+L34)/G34,0) -> 0
A35: Joseph Gojcaj | B35: Edward Leon | D35: Y | E35: MI | F35: Eddie Leon | U35: =IFERROR(I35/H35,0) -> 0 | V35: =IFERROR(SUM(H35+L35)/G35,0) -> 0
A36: Joseph Gojcaj | B36: Edward Leon | E36: CA | F36: Rick Argote | U36: =IFERROR(I36/H36,0) -> 0 | V36: =IFERROR(SUM(H36+L36)/G36,0) -> 0
A37: Joseph Gojcaj | B37: Edward Leon | C37: Julian Hyman | D37: Y | E37: MI | F37: Julian Hyman | U37: =IFERROR(I37/H37,0) -> 0 | V37: =IFERROR(SUM(H37+L37)/G37,0) -> 0
A38: Joseph Gojcaj | B38: Edward Leon | C38: Julian Hyman | F38: Kaliyah Pyles | U38: =IFERROR(I38/H38,0) -> 0 | V38: =IFERROR(SUM(H38+L38)/G38,0) -> 0
A39: Joseph Gojcaj | B39: Edward Leon | C39: Julian Hyman | F39: Ethan Lasley | U39: =IFERROR(I39/H39,0) -> 0 | V39: =IFERROR(SUM(H39+L39)/G39,0) -> 0
A40: Joseph Gojcaj | B40: Edward Leon | C40: Julian Hyman | E40: MI | F40: Keith Chmiel | U40: =IFERROR(I40/H40,0) -> 0 | V40: =IFERROR(SUM(H40+L40)/G40,0) -> 0
A41: Joseph Gojcaj | B41: Edward Leon | C41: Julian Hyman | E41: TX | F41: Veronica Sanchez | U41: =IFERROR(I41/H41,0) -> 0 | V41: =IFERROR(SUM(H41+L41)/G41,0) -> 0
...

Sheet Sat
C1: ALP | E1: LEADERSHIP ALP | F1: Appts | G1: Pres | H1: Sales | I1: POS SITS | J1: POS SA | K1: VET SITS | L1: VET SA | M1: REF OBT | N1: REF SITS | O1: REF SA | P1: OTS SITS | Q1: OTS SA | R1: N1
B2: GOJCAJ RGA | C2: =SUM(C5,C17,C20,C23,C26,C29) -> 4677 | E2: =SUM(E5,E17,E20,E23,E26,E29) -> 3596 | F2: =SUM(F5,F17,F20,F23,F26,F29) -> 10 | G2: =SUM(G5,G17,G20,G23,G26,G29) -> 7 | H2: =SUM(H5,H17,H20,H23,H26,H29) -> 5 | I2: =SUM(I5,I17,I20,I23,I26,I29) -> 1 | J2: =SUM(J5,J17,J20,J23,J26,J29) -> 1 | K2: =SUM(K5,K17,K20,K23,K26,K29) -> 0 | L2: =SUM(L5,L17,L20,L23,L26,L29) -> 0 | ... R2: =SUM(R5,R17,R20,R23,R26,R29) -> 0
C3: # of Agents | E3: ALP per sale | F3: Show Rate | G3: Close Ratio | H3: ALP/Agent | J3: POS Close | L3: VET Close | M3: REF Per Sit | O3: REF Close | Q3: OTS Close
C4: =SUM(C7,C22,C19,C25,C28,C31) -> 64 | E4: =IFERROR(C2/H2,0) -> 935.4 | F4: =IFERROR((G2+R2)/F2,0) -> 0.7 | G4: =IFERROR(H2/G2,0) -> 0.71428571 | H4: =(C2/C4) -> 73.078125 | J4: =IFERROR(J2/I2,0) -> 1 | L4: =IFERROR(L2/K2,0) -> 0 | M4: =IFERROR(M2/G2,0) -> 0.71428571 | O4: =IFERROR(O2/N2,0) -> 0.57142857 | Q4: =IFERROR(Q2/P2,0) -> 0.8
B5: Joseph Gojcaj | C5: =SUMIF(A:A,B5,T:T) -> 4677 | E5: =SUMIFS(T:T,A:A,B5,D:D,"Y") -> 3596 | F5: =SUMIF(A:A,B5,G:G) -> 10 | G5: =SUMIF(A:A,B5,H:H) -> 7 | H5: =SUMIF(A:A,B5,I:I) -> 5 | I5: =SUMIF(A:A,B5,P:P) -> 1 | J5: =SUMIF(A:A,B5,Q:Q) -> 1 | K5: =SUMIF(A:A,B5,R:R) -> 0 | L5: =SUMIF(A:A,B5,S:S) -> 0 | M5: =SUMIF(A:A,B5,M:M) -> 5 | N5: =SUMIF(A:A,B5,N:N) -> 7 | O5: =SUMIF(A:A,B5,O:O) -> 4 | P5: =SUMIF(A:A,B5,J:J) -> 5 | Q5: =SUMIF(A:A,B5,K:K) -> 4 | R5: =SUMIF(A:A,B5,L:L) -> 0
C6: # of Agents | E6: ALP per sale | F6: Show Rate | G6: Close Ratio | H6: ALP/Agent | J6: POS Close | L6: VET Close | M6: REF Per Sit | O6: REF Close | Q6: OTS Close
C7: =COUNTIFS(A:A,B5) -> 29 | E7: =IFERROR(C5/H5,0) -> 935.4 | F7: =IFERROR((G5+R5)/F5,0) -> 0.7 | G7: =IFERROR(H5/G5,0) -> 0.71428571 | H7: =(C5/C7) -> 161.27586 | J7: =IFERROR(J5/I5,0) -> 1 | L7: =IFERROR(L5/K5,0) -> 0 | M7: =IFERROR(M5/SUM(R5+G5,0),"") -> 0.71428571 | O7: =IFERROR(O5/N5,0) -> 0.57142857 | Q7: =IFERROR(Q5/P5,0) -> 0.8
B8: Edward Leon | C8: =SUMIF(B:B,B8,T:T) -> 0 | E8: =SUMIFS(T:T,B:B,B8,D:D,"Y") -> 0 | F8: =SUMIF(B28:B1137,B8,G28:G1137) -> 0 | G8: =SUMIF(B28:B1137,B8,H28:H1137) -> 0 | H8: =SUMIF(B28:B1137,B8,I28:I1137) -> 0 | I8: =SUMIF(B28:B1137,B8,P28:P1137) -> 0 | J8: =SUMIF(B28:B1137,B8,Q28:Q1137) -> 0 | K8: =SUMIF(B28:B1137,B8,R28:R1137) -> 0 | L8: =SUMIF(B28:B1137,B8,S28:S1137) -> 0 | M8: =SUMIF(B28:B1137,B8,M28:M1137) -> 0 | N8: =SUMIF(B28:B1137,B8,N28:N1137) -> 0 | O8: =SUMIF(B28:B1137,B8,O28:O1137) -> 0 | P8: =SUMIF(B28:B1137,B8,J28:J1137) -> 0 | Q8: =SUMIF(B28:B1137,B8,K28:K1137) -> 0 | R8: =SUMIF(B28:B1137,B8,L28:L1137) -> 0
C9: # of Agents | E9: ALP per sale | F9: Show Rate | G9: Close Ratio | H9: ALP/Agent | J9: POS Close | L9: VET Close | M9: REF Per Sit | O9: REF Close | Q9: OTS Close
