Workbook

Sheet Weekly Totals
C1: ALP | E1: LEADERSHIP ALP | F1: Appts | G1: Pres | H1: Sales | I1: POS SITS | J1: POS SA | K1: VET SITS | L1: VET SA | M1: REF OBT | N1: REF SITS | O1: REF SA | P1: OTS SITS | Q1: OTS SA | R1: N1
B2: GOJCAJ RGA | C2: =SUM(C5,C20,C23,C26,C29,C32) -> 55124.44 | E2: =SUM(E5,E20,E23,E26,E29,E32) -> 39695.44 | F2: =SUM(F5,F20,F23,F26,F29,F32) -> 167 | G2: =SUM(G5,G20,G23,G26,G29,G32) -> 97 | H2: =SUM(H5,H20,H23,H26,H29,H32) -> 36 | I2: =SUM(I5,I20,I23,I26,I29,I32) -> 20 | J2: =SUM(J5,J20,J23,J26,J29,J32) -> 9 | K2: =SUM(K5,K20,K23,K26,K29,K32) -> 26 | L2: =SUM(L5,L20,L23,L26,L29,L32) -> 9 | ... R2: =SUM(R5,R20,R23,R26,R29,R32) -> 11
C3: # of Agents | E3: ALP per sale | F3: Show Rate | G3: Close Ratio | H3: ALP/Agent | J3: POS Close | L3: VET Close | M3: REF Per Sit | O3: REF Close | Q3: OTS Close
C4: =SUM(C7,C25,C22,C28,C31,C34) -> 63 | E4: =IFERROR(C2/H2,0) -> 1531.2344 | F4: =IFERROR((G2+R2)/F2,0) -> 0.64670659 | G4: =IFERROR(H2/G2,0) -> 0.37113402 | H4: =(C2/C4) -> 874.99111 | J4: =IFERROR(J2/I2,0) -> 0.45 | L4: =IFERROR(L2/K2,0) -> 0.34615385 | M4: =IFERROR(M2/G2,0) -> 0 | O4: =IFERROR(O2/N2,0) -> 0.41666667 | Q4: =IFERROR(Q2/P2,0) -> 1.6774194
B5: Joseph Gojcaj | C5: =SUMIF(A:A,B5,T:T) -> 40104 | E5: =SUMIFS(T:T,A:A,B5,D:D,"Y") -> 31695 | F5: =SUMIF(A:A,B5,G:G) -> 139 | G5: =SUMIF(A:A,B5,H:H) -> 73 | H5: =SUMIF(A:A,B5,I:I) -> 26 | I5: =SUMIF(A:A,B5,P:P) -> 20 | J5: =SUMIF(A:A,B5,Q:Q) -> 9 | K5: =SUMIF(A:A,B5,R:R) -> 21 | L5: =SUMIF(A:A,B5,S:S) -> 6 | M5: =SUMIF(A:A,B5,M:M) -> 221 | N5: =SUMIF(A:A,B5,N:N) -> 28 | O5: =SUMIF(A:A,B5,O:O) -> 11 | P5: =SUMIF(A:A,B5,J:J) -> 24 | Q5: =SUMIF(A:A,B5,K:K) -> 7 | R5: =SUMIF(A:A,B5,L:L) -> 11
C6: # of Agents | E6: ALP per sale | F6: Show Rate | G6: Close Ratio | H6: ALP/Agent | J6: POS Close | L6: VET Close | M6: REF Per Sit | O6: REF Close | Q6: OTS Close
C7: =COUNTIFS(A:A,B5) -> 24 | E7: =IFERROR(C5/H5,0) -> 1542.4615 | F7: =IFERROR((G5+R5)/F5,0) -> 0.60431655 | G7: =IFERROR(H5/G5,0) -> 0.35616438 | H7: =(C5/C7) -> 1671 | J7: =IFERROR(J5/I5,0) -> 0.45 | L7: =IFERROR(L5/K5,0) -> 0.28571429 | M7: =IFERROR(M5/SUM(R5+G5,0),"") -> 2.6309524 | O7: =IFERROR(O5/N5,0) -> 0.39285714 | Q7: =IFERROR(Q5/P5,0) -> 0.29166667
B8: Jacob Brown | C8: =SUMIF(B:B,B8,T:T) -> 1543 | E8: =SUMIFS(T:T,B:B,B8,D:D,"Y") -> 0 | F8: =SUMIF(B37:B1091,B8,G37:G1091) -> 7 | G8: =SUMIF(B37:B1091,B8,H37:H1091) -> 9 | H8: =SUMIF(B37:B1091,B8,I37:I1091) -> 2 | I8: =SUMIF(B37:B1091,B8,P37:P1091) -> 0 | J8: =SUMIF(B37:B1091,B8,Q37:Q1091) -> 0 | K8: =SUMIF(B37:B1091,B8,R37:R1091) -> 2 | L8: =SUMIF(B37:B1091,B8,S37:S1091) -> 0 | M8: =SUMIF(B37:B1091,B8,M37:M1091) -> 21 | N8: =SUMIF(B37:B1091,B8,N37:N1091) -> 8 | O8: =SUMIF(B37:B1091,B8,O37:O1091) -> 2 | P8: =SUMIF(B37:B1091,B8,J37:J1091) -> 9 | Q8: =SUMIF(B37:B1091,B8,K37:K1091) -> 2 | R8: =SUMIF(B37:B1091,B8,L37:L1091) -> 4
C9: # of Agents | E9: ALP per sale | F9: Show Rate | G9: Close Ratio | H9: ALP/Agent | J9: POS Close | L9: VET Close | M9: REF Per Sit | O9: REF Close | Q9: OTS Close
C10: =COUNTIFS(B37:B1091,B8) -> 5 | E10: =IFERROR(C8/H8,0) -> 771.5 | F10: =IFERROR((G8+R8)/F8,0) -> 1.8571429 | G10: =IFERROR(H8/G8,0) -> 0.22222222 | H10: =(C8/C10) -> 308.6 | J10: =IFERROR(J8/I8,0) -> 0 | L10: =IFERROR(L8/K8,0) -> 0 | M10: =IFERROR(M8/SUM(G8+R8,0),"") -> 1.6153846 | O10: =IFERROR(O8/N8,0) -> 0.25 | Q10: =IFERROR(Q8/P8,0) -> 0.22222222
B11: Edward Leon | C11: =SUMIF(B:B,B11,T:T) -> 8970 | E11: =SUMIFS(T:T,B:B,B11,D:D,"Y") -> 3543 | F11: =SUMIF(B39:B1091,B11,G39:G1091) -> 43 | G11: =SUMIF(B39:B1091,B11,H39:H1091) -> 26 | H11: =SUMIF(B39:B1091,B11,I39:I1091) -> 5 | I11: =SUMIF(B39:B1091,B11,P39:P1091) -> 0 | J11: =SUMIF(B39:B1091,B11,Q39:Q1091) -> 0 | K11: =SUMIF(B39:B1091,B11,R39:R1091) -> 12 | L11: =SUMIF(B39:B1091,B11,S39:S1091) -> 3 | M11: =SUMIF(B39:B1091,B11,M39:M1091) -> 119 | N11: =SUMIF(B39:B1091,B11,N39:N1091) -> 8 | O11: =SUMIF(B39:B1091,B11,O39:O1091) -> 2 | P11: =SUMIF(B39:B1091,B11,J39:J1091) -> 10 | Q11: =SUMIF(B39:B1091,B11,K39:K1091) -> 1 | R11: =SUMIF(B39:B1091,B11,L39:L1091) -> 4
C12: # of Agents | E12: ALP per sale | F12: Show Rate | G12: Close Ratio | H12: ALP/Agent | J12: POS Close | L12: VET Close | M12: REF Per Sit | O12: REF Close | Q12: OTS Close
C13: =COUNTIFS(B39:B1091,B11) -> 7 | E13: =IFERROR(C11/H11,0) -> 1794 | F13: =IFERROR((G11+R11)/F11,0) -> 0.69767442 | G13: =IFERROR(H11/G11,0) -> 0.19230769 | H13: =(C11/C13) -> 1281.4286 | J13: =IFERROR(J11/I11,0) -> 0 | L13: =IFERROR(L11/K11,0) -> 0.25 | M13: =IFERROR(M11/SUM(R11+G11,0),"") -> 3.9666667 | O13: =IFERROR(O11/N11,0) -> 0.25 | Q13: =IFERROR(Q11/P11,0) -> 0.1
B14: Melissa Elam | C14: =SUMIF(B:B,B14,T:T) -> 5204 | E14: =SUMIFS(T:T,B:B,B14,D:D,"Y") -> 5204 | F14: =SUMIF(B39:B1091,B14,G39:G1091) -> 25 | G14: =SUMIF(B39:B1091,B14,H39:H1091) -> 9 | H14: =SUMIF(B39:B1091,B14,I39:I1091) -> 2 | I14: =SUMIF(B39:B1091,B14,P39:P1091) -> 0 | J14: =SUMIF(B39:B1091,B14,Q39:Q1091) -> 0 | K14: =SUMIF(B39:B1091,B14,R39:R1091) -> 6 | L14: =SUMIF(B39:B1091,B14,S39:S1091) -> 2 | M14: =SUMIF(B39:B1091,B14,M39:M1091) -> 29 | N14: =SUMIF(B39:B1091,B14,N39:N1091) -> 3 | O14: =SUMIF(B39:B1091,B14,O39:O1091) -> 0 | P14: =SUMIF(B39:B1091,B14,J39:J1091) -> 1 | Q14: =SUMIF(B39:B1091,B14,K39:K1091) -> 1 | R14: =SUMIF(B39:B1091,B14,L39:L1091) -> 2
C15: # of Agents | E15: ALP per sale | F15: Show Rate | G15: Close Ratio | H15: ALP/Agent | J15: POS Close | L15: VET Close | M15: REF Per Sit | O15: REF Close | Q15: OTS Close
C16: =COUNTIFS(B39:B1091,B14) -> 7 | E16: =IFERROR(C14/H14,0) -> 2602 | F16: =IFERROR((G14+R14)/F14,0) -> 0.44 | G16: =IFERROR(H14/G14,0) -> 0.22222222 | H16: =(C14/C16) -> 743.42857 | J16: =IFERROR(J14/I14,0) -> 0 | L16: =IFERROR(L14/K14,0) -> 0.33333333 | M16: =IFERROR(M14/SUM(R14+G14,0),"") -> 2.6363636 | O16: =IFERROR(O14/N14,0) -> 0 | Q16: =IFERROR(Q14/P14,0) -> 1
B17: Timothy Noe | C17: =SUMIF(B:B,B17,T:T) -> 24387 | E17: =SUMIFS(T:T,B:B,B17,D:D,"Y") -> 22948 | F17: =SUMIF(B44:B1091,B17,G44:G1091) -> 64 | G17: =SUMIF(B44:B1091,B17,H44:H1091) -> 29 | H17: =SUMIF(B44:B1091,B17,I44:I1091) -> 17 | I17: =SUMIF(B44:B1091,B17,P44:P1091) -> 20 | J17: =SUMIF(B44:B1091,B17,Q44:Q1091) -> 9 | K17: =SUMIF(B44:B1091,B17,R44:R1091) -> 1 | L17: =SUMIF(B44:B1091,B17,S44:S1091) -> 1 | M17: =SUMIF(B44:B1091,B17,M44:M1091) -> 52 | N17: =SUMIF(B44:B1091,B17,N44:N1091) -> 9 | O17: =SUMIF(B44:B1091,B17,O44:O1091) -> 7 | P17: =SUMIF(B44:B1091,B17,J44:J1091) -> 4 | Q17: =SUMIF(B44:B1091,B17,K44:K1091) -> 3 | R17: =SUMIF(B44:B1091,B17,L44:L1091) -> 1
C18: # of Agents | E18: ALP per sale | F18: Show Rate | G18: Close Ratio | H18: ALP/Agent | J18: POS Close | L18: VET Close | M18: REF Per Sit | O18: REF Close | Q18: OTS Close
C19: =COUNTIFS(B44:B1091,B17) -> 4 | E19: =IFERROR(C17/H17,0) -> 1434.5294 | F19: =IFERROR((G17+R17)/F17,0) -> 0.46875 | G19: =IFERROR(H17/G17,0) -> 0.5862069 | H19: =(C17/C19) -> 6096.75 | J19: =IFERROR(J17/I17,0) -> 0.45 | L19: =IFERROR(L17/K17,0) -> 1 | M19: =IFERROR(M17/SUM(R17+G17,0),"") -> 1.7333333 | O19: =IFERROR(O17/N17,0) -> 0.77777778 | Q19: =IFERROR(Q17/P17,0) -> 0.75
B20: Javier Sandoval | C20: =SUMIF(A:A,B20,T:T) -> 0 | E20: =SUMIFS(T:T,A:A,B20,D:D,"Y") -> 0 | F20: =SUMIF(A:A,B20,G:G) -> 0 | G20: =SUMIF(A:A,B20,H:H) -> 0 | H20: =SUMIF(A:A,B20,I:I) -> 0 | I20: =SUMIF(A:A,B20,P:P) -> 0 | J20: =SUMIF(A:A,B20,Q:Q) -> 0 | K20: =SUMIF(A:A,B20,R:R) -> 0 | L20: =SUMIF(A:A,B20,S:S) -> 0 | M20: =SUMIF(A:A,B20,M:M) -> 0 | N20: =SUMIF(A:A,B20,N:N) -> 0 | O20: =SUMIF(A:A,B20,O:O) -> 0 | P20: =SUMIF(A:A,B20,J:J) -> 0 | Q20: =SUMIF(A:A,B20,K:K) -> 0 | R20: =SUMIF(A:A,B20,L:L) -> 0
C21: # of Agents | E21: ALP per sale | F21: Show Rate | G21: Close Ratio | H21: ALP/Agent | J21: POS Close | L21: VET Close | M21: REF Per Sit | O21: REF Close | Q21: OTS Close
C22: =COUNTIFS(A:A,B20) -> 5 | E22: =IFERROR(C20/H20,0) -> 0 | F22: =IFERROR((G20+R20)/F20,0) -> 0 | G22: =IFERROR(H20/G20,0) -> 0 | H22: =(C20/C22) -> 0 | J22: =IFERROR(J20/I20,0) -> 0 | L22: =IFERROR(L20/K20,0) -> 0 | M22: =IFERROR(M20/SUM(R20+G20,0),"") | O22: =IFERROR(O20/N20,0) -> 0 | Q22: =IFERROR(Q20/P20,0) -> 0
B23: Derron Alexander | C23: =SUMIF(A:A,B23,T:T) -> 0 | E23: =SUMIFS(T:T,A:A,B23,D:D,"Y") -> 0 | F23: =SUMIF(A:A,B23,G:G) -> 0 | G23: =SUMIF(A:A,B23,H:H) -> 0 | H23: =SUMIF(A:A,B23,I:I) -> 0 | I23: =SUMIF(A:A,B23,P:P) -> 0 | J23: =SUMIF(A:A,B23,Q:Q) -> 0 | K23: =SUMIF(A:A,B23,R:R) -> 0 | L23: =SUMIF(A:A,B23,S:S) -> 0 | M23: =SUMIF(A:A,B23,M:M) -> 0 | N23: =SUMIF(A:A,B23,N:N) -> 0 | O23: =SUMIF(A:A,B23,O:O) -> 0 | P23: =SUMIF(A:A,B23,J:J) -> 0 | Q23: =SUMIF(A:A,B23,K:K) -> 0 | R23: =SUMIF(A:A,B23,L:L) -> 0
C24: # of Agents | E24: ALP per sale | F24: Show Rate | G24: Close Ratio | H24: ALP/Agent | J24: POS Close | L24: VET Close | M24: REF Per Sit | O24: REF Close | Q24: OTS Close
C25: =COUNTIFS(A:A,B23) -> 10 | E25: =IFERROR(C23/H23,0) -> 0 | F25: =IFERROR((G23+R23)/F23,0) -> 0 | G25: =IFERROR(H23/G23,0) -> 0 | H25: =(C23/C25) -> 0 | J25: =IFERROR(J23/I23,0) -> 0 | L25: =IFERROR(L23/K23,0) -> 0 | M25: =IFERROR(M23/SUM(R23+G23,0),"") | O25: =IFERROR(O23/N23,0) -> 0 | Q25: =IFERROR(Q23/P23,0) -> 0
B26: David Fulfer | C26: =SUMIF(A:A,B26,T:T) -> 8000.44 | E26: =SUMIFS(T:T,A:A,B26,D:D,"Y") -> 8000.44 | F26: =SUMIF(A:A,B26,G:G) -> 5 | G26: =SUMIF(A:A,B26,H:H) -> 4 | H26: =SUMIF(A:A,B26,I:I) -> 5 | I26: =SUMIF(A:A,B26,P:P) -> 0 | J26: =SUMIF(A:A,B26,Q:Q) -> 0 | K26: =SUMIF(A:A,B26,R:R) -> 2 | L26: =SUMIF(A:A,B26,S:S) -> 2 | M26: =SUMIF(A:A,B26,M:M) -> 22 | N26: =SUMIF(A:A,B26,N:N) -> 4 | O26: =SUMIF(A:A,B26,O:O) -> 5 | P26: =SUMIF(A:A,B26,J:J) -> 2 | Q26: =SUMIF(A:A,B26,K:K) -> 2 | R26: =SUMIF(A:A,B26,L:L) -> 0
C27: # of Agents | E27: ALP per sale | F27: Show Rate | G27: Close Ratio | H27: ALP/Agent | J27: POS Close | L27: VET Close | M27: REF Per Sit | O27: REF Close | Q27: OTS Close
C28: =COUNTIFS(A:A,B26) -> 5 | E28: =IFERROR(C26/H26,0) -> 1600.088 | F28: =IFERROR((G26+R26)/F26,0) -> 0.8 | G28: =IFERROR(H26/G26,0) -> 1.25 | H28: =(C26/C28) -> 1600.088 | J28: =IFERROR(J26/I26,0) -> 0 | L28: =IFERROR(L26/K26,0) -> 1 | M28: =IFERROR(M26/SUM(R26+G26,0),"") -> 5.5 | O28: =IFERROR(O26/N26,0) -> 1.25 | Q28: =IFERROR(Q26/P26,0) -> 1
B29: Ashlynn Orng | C29: =SUMIF(A:A,B29,T:T) -> 7020 | E29: =SUMIFS(T:T,A:A,B29,D:D,"Y") -> 0 | F29: =SUMIF(A:A,B29,G:G) -> 23 | G29: =SUMIF(A:A,B29,H:H) -> 20 | H29: =SUMIF(A:A,B29,I:I) -> 5 | I29: =SUMIF(A:A,B29,P:P) -> 0 | J29: =SUMIF(A:A,B29,Q:Q) -> 0 | K29: =SUMIF(A:A,B29,R:R) -> 3 | L29: =SUMIF(A:A,B29,S:S) -> 1 | M29: =SUMIF(A:A,B29,M:M) -> #REF! | N29: =SUMIF(A:A,B29,N:N) -> 16 | O29: =SUMIF(A:A,B29,O:O) -> 4 | P29: =SUMIF(A:A,B29,J:J) -> 5 | Q29: =SUMIF(A:A,B29,K:K) -> 43 | R29: =SUMIF(A:A,B29,L:L) -> 0
C30: # of Agents | E30: ALP per sale | F30: Show Rate | G30: Close Ratio | H30: ALP/Agent | J30: POS Close | L30: VET Close | M30: REF Per Sit | O30: REF Close | Q30: OTS Close
C31: =COUNTIFS(A:A,B29) -> 17 | E31: =IFERROR(C29/H29,0) -> 1404 | F31: =IFERROR((G29+R29)/F29,0) -> 0.86956522 | G31: =IFERROR(H29/G29,0) -> 0.25 | H31: =(C29/C31) -> 412.94118 | J31: =IFERROR(J29/I29,0) -> 0 | L31: =IFERROR(L29/K29,0) -> 0.33333333 | M31: =IFERROR(M29/SUM(R29+G29,0),"") | O31: =IFERROR(O29/N29,0) -> 0.25 | Q31: =IFERROR(Q29/P29,0) -> 8.6
B32: Kenneth Preston | C32: =SUMIF(A:A,B32,T:T) -> 0 | E32: =SUMIFS(T:T,A:A,B32,D:D,"Y") -> 0 | F32: =SUMIF(A:A,B32,G:G) -> 0 | G32: =SUMIF(A:A,B32,H:H) -> 0 | H32: =SUMIF(A:A,B32,I:I) -> 0 | I32: =SUMIF(A:A,B32,P:P) -> 0 | J32: =SUMIF(A:A,B32,Q:Q) -> 0 | K32: =SUMIF(A:A,B32,R:R) -> 0 | L32: =SUMIF(A:A,B32,S:S) -> 0 | M32: =SUMIF(A:A,B32,M:M) -> 0 | N32: =SUMIF(A:A,B32,N:N) -> 0 | O32: =SUMIF(A:A,B32,O:O) -> 0 | P32: =SUMIF(A:A,B32,J:J) -> 0 | Q32: =SUMIF(A:A,B32,K:K) -> 0 | R32: =SUMIF(A:A,B32,L:L) -> 0
C33: # of Agents | E33: ALP per sale | F33: Show Rate | G33: Close Ratio | H33: ALP/Agent | J33: POS Close | L33: VET Close | M33: REF Per Sit | O33: REF Close | Q33: OTS Close
C34: =COUNTIFS(A:A,B32) -> 2 | E34: =IFERROR(C32/H32,0) -> 0 | F34: =IFERROR((G32+R32)/F32,0) -> 0 | G34: =IFERROR(H32/G32,0) -> 0 | H34: =(C32/C34) -> 0 | J34: =IFERROR(J32/I32,0) -> 0 | L34: =IFERROR(L32/K32,0) -> 0 | M34: =IFERROR(M32/SUM(R32+G32,0),"") | O34: =IFERROR(O32/N32,0) -> 0 | Q34: =IFERROR(Q32/P32,0) -> 0
A36: MGA | B36: GA | C36: SA | E36: State | F36: Agent | G36: SETS | H36: SITS | I36: SALES | J36: OTS SITS | K36: OTS SALES | L36: N1 | M36: REF OBT | N36: REF SITS | O36: REF SALES | P36: POS SITS | Q36: POS SALES | R36: VETS SITS | S36: VET SALES | T36: ALP | U36: Close | V36: Show | W36: Code Date
A37: Joseph Gojcaj | D37: Y | E37: MI | F37: Joseph Gojcaj | G37: =('Thurs (2)'!G37+Thurs!G37+'Tues '!G37+Wed!G37+Fri!G37+'Mon '!G37+'Wed (2)'!G37+Sun!G37+Sat!G37) -> 0 | H37: =('Thurs (2)'!H37+Thurs!H37+'Tues '!H37+Wed!H37+Fri!H37+'Mon '!H37+'Wed (2)'!H37+Sun!H37+Sat!H37) -> 0 | I37: =('Thurs (2)'!I37+Thurs!I37+'Tues '!I37+Wed!I37+Fri!I37+'Mon '!I37+'Wed (2)'!I37+Sun!I37+Sat!I37) -> 0 | J37: =('Thurs (2)'!J37+Thurs!J37+'Tues '!J37+Wed!J37+Fri!J37+'Mon '!J37+'Wed (2)'!J37+Sun!J37+Sat!J37) -> 0 | K37: =('Thurs (2)'!K37+Thurs!K37+'Tues '!K37+Wed!K37+Fri!K37+'Mon '!K37+'Wed (2)'!K37+Sun!K37+Sat!K37) -> 0 | L37: =('Thurs (2)'!L37+Thurs!L37+'Tues '!L37+Wed!L37+Fri!L37+'Mon '!L37+'Wed (2)'!L37+Sun!L37+Sat!L37) -> 0 | M37: =('Thurs (2)'!M37+Thurs!M37+'Tues '!M37+Wed!M37+Fri!M37+'Mon '!M37+'Wed (2)'!M37+Sun!M37+Sat!M37) -> 0 | N37: =('Thurs (2)'!N37+Thurs!N37+'Tues '!N37+Wed!N37+Fri!N37+'Mon '!N37+'Wed (2)'!N37+Sun!N37+Sat!N37) -> 0 | ... T37: =('Thurs (2)'!T37+Thurs!T37+'Tues '!T37+Wed!T37+Fri!T37+'Mon '!T37+'Wed (2)'!T37+Sun!T37+Sat!T37) -> 0 | U37: =IFERROR(I37/H37,0) -> 0 | V37: =IFERROR(SUM(H37+L37)/G37,0) -> 0
A38: Joseph Gojcaj | B38: Jacob Brown | D38: Y | E38: MI | F38: Jacob Brown | G38: =('Thurs (2)'!G38+Thurs!G38+'Tues '!G38+Wed!G38+Fri!G38+'Mon '!G38+'Wed (2)'!G38+Sun!G38+Sat!G38) -> 0 | H38: =('Thurs (2)'!H38+Thurs!H38+'Tues '!H38+Wed!H38+Fri!H38+'Mon '!H38+'Wed (2)'!H38+Sun!H38+Sat!H38) -> 0 | I38: =('Thurs (2)'!I38+Thurs!I38+'Tues '!I38+Wed!I38+Fri!I38+'Mon '!I38+'Wed (2)'!I38+Sun!I38+Sat!I38) -> 0 | J38: =('Thurs (2)'!J38+Thurs!J38+'Tues '!J38+Wed!J38+Fri!J38+'Mon '!J38+'Wed (2)'!J38+Sun!J38+Sat!J38) -> 0 | K38: =('Thurs (2)'!K38+Thurs!K38+'Tues '!K38+Wed!K38+Fri!K38+'Mon '!K38+'Wed (2)'!K38+Sun!K38+Sat!K38) -> 0 | L38: =('Thurs (2)'!L38+Thurs!L38+'Tues '!L38+Wed!L38+Fri!L38+'Mon '!L38+'Wed (2)'!L38+Sun!L38+Sat!L38) -> 0 | M38: =('Thurs (2)'!M38+Thurs!M38+'Tues '!M38+Wed!M38+Fri!M38+'Mon '!M38+'Wed (2)'!M38+Sun!M38+Sat!M38) -> 0 | N38: =('Thurs (2)'!N38+Thurs!N38+'Tues '!N38+Wed!N38+Fri!N38+'Mon '!N38+'Wed (2)'!N38+Sun!N38+Sat!N38) -> 0 | ... T38: =('Thurs (2)'!T38+Thurs!T38+'Tues '!T38+Wed!T38+Fri!T38+'Mon '!T38+'Wed (2)'!T38+Sun!T38+Sat!T38) -> 0 | U38: =IFERROR(I38/H38,0) -> 0 | V38: =IFERROR(SUM(H38+L38)/G38,0) -> 0
A39: Joseph Gojcaj | B39: Jacob Brown | C39: Kristen Fox | D39: Y | E39: NC | F39: Kristen Fox | G39: =('Thurs (2)'!G39+Thurs!G39+'Tues '!G39+Wed!G39+Fri!G39+'Mon '!G39+'Wed (2)'!G39+Sun!G39+Sat!G39) -> 5 | H39: =('Thurs (2)'!H39+Thurs!H39+'Tues '!H39+Wed!H39+Fri!H39+'Mon '!H39+'Wed (2)'!H39+Sun!H39+Sat!H39) -> 3 | I39: =('Thurs (2)'!I39+Thurs!I39+'Tues '!I39+Wed!I39+Fri!I39+'Mon '!I39+'Wed (2)'!I39+Sun!I39+Sat!I39) -> 0 | J39: =('Thurs (2)'!J39+Thurs!J39+'Tues '!J39+Wed!J39+Fri!J39+'Mon '!J39+'Wed (2)'!J39+Sun!J39+Sat!J39) -> 3 | K39: =('Thurs (2)'!K39+Thurs!K39+'Tues '!K39+Wed!K39+Fri!K39+'Mon '!K39+'Wed (2)'!K39+Sun!K39+Sat!K39) -> 0 | L39: =('Thurs (2)'!L39+Thurs!L39+'Tues '!L39+Wed!L39+Fri!L39+'Mon '!L39+'Wed (2)'!L39+Sun!L39+Sat!L39) -> 2 | M39: =('Thurs (2)'!M39+Thurs!M39+'Tues '!M39+Wed!M39+Fri!M39+'Mon '!M39+'Wed (2)'!M39+Sun!M39+Sat!M39) -> 1 | N39: =('Thurs (2)'!N39+Thurs!N39+'Tues '!N39+Wed!N39+Fri!N39+'Mon '!N39+'Wed (2)'!N39+Sun!N39+Sat!N39) -> 2 | ... T39: =('Thurs (2)'!T39+Thurs!T39+'Tues '!T39+Wed!T39+Fri!T39+'Mon '!T39+'Wed (2)'!T39+Sun!T39+Sat!T39) -> 0 | U39: =IFERROR(I39/H39,0) -> 0 | V39: =IFERROR(SUM(H39+L39)/G39,0) -> 1
A40: Joseph Gojcaj | B40: Jacob Brown | C40: Kristen Fox | F40: Marci Dyer | G40: =('Thurs (2)'!G40+Thurs!G40+'Tues '!G40+Wed!G40+Fri!G40+'Mon '!G40+'Wed (2)'!G40+Sun!G40+Sat!G40) -> 1 | H40: =('Thurs (2)'!H40+Thurs!H40+'Tues '!H40+Wed!H40+Fri!H40+'Mon '!H40+'Wed (2)'!H40+Sun!H40+Sat!H40) -> 1 | I40: =('Thurs (2)'!I40+Thurs!I40+'Tues '!I40+Wed!I40+Fri!I40+'Mon '!I40+'Wed (2)'!I40+Sun!I40+Sat!I40) -> 1 | J40: =('Thurs (2)'!J40+Thurs!J40+'Tues '!J40+Wed!J40+Fri!J40+'Mon '!J40+'Wed (2)'!J40+Sun!J40+Sat!J40) -> 1 | K40: =('Thurs (2)'!K40+Thurs!K40+'Tues '!K40+Wed!K40+Fri!K40+'Mon '!K40+'Wed (2)'!K40+Sun!K40+Sat!K40) -> 1 | L40: =('Thurs (2)'!L40+Thurs!L40+'Tues '!L40+Wed!L40+Fri!L40+'Mon '!L40+'Wed (2)'!L40+Sun!L40+Sat!L40) -> 0 | M40: =('Thurs (2)'!M40+Thurs!M40+'Tues '!M40+Wed!M40+Fri!M40+'Mon '!M40+'Wed (2)'!M40+Sun!M40+Sat!M40) -> 2 | N40: =('Thurs (2)'!N40+Thurs!N40+'Tues '!N40+Wed!N40+Fri!N40+'Mon '!N40+'Wed (2)'!N40+Sun!N40+Sat!N40) -> 1 | ... T40: =('Thurs (2)'!T40+Thurs!T40+'Tues '!T40+Wed!T40+Fri!T40+'Mon '!T40+'Wed (2)'!T40+Sun!T40+Sat!T40) -> 238 | U40: =IFERROR(I40/H40,0) -> 1 | V40: =IFERROR(SUM(H40+L40)/G40,0) -> 1
A41: Joseph Gojcaj | B41: Jacob Brown | C41: Joylynn Harris | D41: Y | E41: CA | F41: Joylynn Harris | G41: =('Thurs (2)'!G41+Thurs!G41+'Tues '!G41+Wed!G41+Fri!G41+'Mon '!G41+'Wed (2)'!G41+Sun!G41+Sat!G41) -> 0 | H41: =('Thurs (2)'!H41+Thurs!H41+'Tues '!H41+Wed!H41+Fri!H41+'Mon '!H41+'Wed (2)'!H41+Sun!H41+Sat!H41) -> 4 | I41: =('Thurs (2)'!I41+Thurs!I41+'Tues '!I41+Wed!I41+Fri!I41+'Mon '!I41+'Wed (2)'!I41+Sun!I41+Sat!I41) -> 0 | J41: =('Thurs (2)'!J41+Thurs!J41+'Tues '!J41+Wed!J41+Fri!J41+'Mon '!J41+'Wed (2)'!J41+Sun!J41+Sat!J41) -> 4 | K41: =('Thurs (2)'!K41+Thurs!K41+'Tues '!K41+Wed!K41+Fri!K41+'Mon '!K41+'Wed (2)'!K41+Sun!K41+Sat!K41) -> 0 | L41: =('Thurs (2)'!L41+Thurs!L41+'Tues '!L41+Wed!L41+Fri!L41+'Mon '!L41+'Wed (2)'!L41+Sun!L41+Sat!L41) -> 2 | M41: =('Thurs (2)'!M41+Thurs!M41+'Tues '!M41+Wed!M41+Fri!M41+'Mon '!M41+'Wed (2)'!M41+Sun!M41+Sat!M41) -> 14 | N41: =('Thurs (2)'!N41+Thurs!N41+'Tues '!N41+Wed!N41+Fri!N41+'Mon '!N41+'Wed (2)'!N41+Sun!N41+Sat!N41) -> 4 | ... T41: =('Thurs (2)'!T41+Thurs!T41+'Tues '!T41+Wed!T41+Fri!T41+'Mon '!T41+'Wed (2)'!T41+Sun!T41+Sat!T41) -> 0 | U41: =IFERROR(I41/H41,0) -> 0 | V41: =IFERROR(SUM(H41+L41)/G41,0) -> 0
...

Sheet Wed
C1: ALP | E1: LEADERSHIP ALP | F1: Appts | G1: Pres | H1: Sales | I1: POS SITS | J1: POS SA | K1: VET SITS | L1: VET SA | M1: REF OBT | N1: REF SITS | O1: REF SA | P1: OTS SITS | Q1: OTS SA | R1: N1
B2: GOJCAJ RGA | C2: =SUM(C5,C20,C23,C26,C29,C32) -> 9931 | E2: =SUM(E5,E20,E23,E26,E29,E32) -> 6723 | F2: =SUM(F5,F20,F23,F26,F29,F32) -> 30 | G2: =SUM(G5,G20,G23,G26,G29,G32) -> 16 | H2: =SUM(H5,H20,H23,H26,H29,H32) -> 8 | I2: =SUM(I5,I20,I23,I26,I29,I32) -> 6 | J2: =SUM(J5,J20,J23,J26,J29,J32) -> 3 | K2: =SUM(K5,K20,K23,K26,K29,K32) -> 4 | L2: =SUM(L5,L20,L23,L26,L29,L32) -> 2 | ... R2: =SUM(R5,R20,R23,R26,R29,R32) -> 0
C3: # of Agents | E3: ALP per sale | F3: Show Rate | G3: Close Ratio | H3: ALP/Agent | J3: POS Close | L3: VET Close | M3: REF Per Sit | O3: REF Close | Q3: OTS Close
C4: =SUM(C7,C25,C22,C28,C31,C34) -> 63 | E4: =IFERROR(C2/H2,0) -> 1241.375 | F4: =IFERROR((G2+R2)/F2,0) -> 0.53333333 | G4: =IFERROR(H2/G2,0) -> 0.5 | H4: =(C2/C4) -> 157.63492 | J4: =IFERROR(J2/I2,0) -> 0.5 | L4: =IFERROR(L2/K2,0) -> 0.5 | M4: =IFERROR(M2/G2,0) -> 2.5625 | O4: =IFERROR(O2/N2,0) -> 0.75 | Q4: =IFERROR(Q2/P2,0) -> 0.6
B5: Joseph Gojcaj | C5: =SUMIF(A:A,B5,T:T) -> 9114 | E5: =SUMIFS(T:T,A:A,B5,D:D,"Y") -> 5906 | F5: =SUMIF(A:A,B5,G:G) -> 30 | G5: =SUMIF(A:A,B5,H:H) -> 16 | H5: =SUMIF(A:A,B5,I:I) -> 7 | I5: =SUMIF(A:A,B5,P:P) -> 6 | J5: =SUMIF(A:A,B5,Q:Q) -> 3 | K5: =SUMIF(A:A,B5,R:R) -> 4 | L5: =SUMIF(A:A,B5,S:S) -> 2 | M5: =SUMIF(A:A,B5,M:M) -> 41 | N5: =SUMIF(A:A,B5,N:N) -> 4 | O5: =SUMIF(A:A,B5,O:O) -> 2 | P5: =SUMIF(A:A,B5,J:J) -> 5 | Q5: =SUMIF(A:A,B5,K:K) -> 3 | R5: =SUMIF(A:A,B5,L:L) -> 0
C6: # of Agents | E6: ALP per sale | F6: Show Rate | G6: Close Ratio | H6: ALP/Agent | J6: POS Close | L6: VET Close | M6: REF Per Sit | O6: REF Close | Q6: OTS Close
C7: =COUNTIFS(A:A,B5) -> 24 | E7: =IFERROR(C5/H5,0) -> 1302 | F7: =IFERROR((G5+R5)/F5,0) -> 0.53333333 | G7: =IFERROR(H5/G5,0) -> 0.4375 | H7: =(C5/C7) -> 379.75 | J7: =IFERROR(J5/I5,0) -> 0.5 | L7: =IFERROR(L5/K5,0) -> 0.5 | M7: =IFERROR(M5/SUM(R5+G5,0),"") -> 2.5625 | O7: =IFERROR(O5/N5,0) -> 0.5 | Q7: =IFERROR(Q5/P5,0) -> 0.6
B8: Jacob Brown | C8: =SUMIF(B:B,B8,T:T) -> 0 | E8: =SUMIFS(T:T,B:B,B8,D:D,"Y") -> 0 | F8: =SUMIF(B37:B1137,B8,G37:G1137) -> 0 | G8: =SUMIF(B37:B1137,B8,H37:H1137) -> 0 | H8: =SUMIF(B37:B1137,B8,I37:I1137) -> 0 | I8: =SUMIF(B37:B1137,B8,P37:P1137) -> 0 | J8: =SUMIF(B37:B1137,B8,Q37:Q1137) -> 0 | K8: =SUMIF(B37:B1137,B8,R37:R1137) -> 0 | L8: =SUMIF(B37:B1137,B8,S37:S1137) -> 0 | M8: =SUMIF(B37:B1137,B8,M37:M1137) -> 0 | N8: =SUMIF(B37:B1137,B8,N37:N1137) -> 0 | O8: =SUMIF(B37:B1137,B8,O37:O1137) -> 0 | P8: =SUMIF(B37:B1137,B8,J37:J1137) -> 0 | Q8: =SUMIF(B37:B1137,B8,K37:K1137) -> 0 | R8: =SUMIF(B37:B1137,B8,L37:L1137) -> 0
C9: # of Agents | E9: ALP per sale | F9: Show Rate | G9: Close Ratio | H9: ALP/Agent | J9: POS Close | L9: VET Close | M9: REF Per Sit | O9: REF Close | Q9: OTS Close
C10: =COUNTIFS(B37:B1137,B8) -> 5 | E10: =IFERROR(C8/H8,0) -> 0 | F10: =IFERROR((G8+R8)/F8,0) -> 0 | G10: =IFERROR(H8/G8,0) -> 0 | H10: =(C8/C10) -> 0 | J10: =IFERROR(J8/I8,0) -> 0 | L10: =IFERROR(L8/K8,0) -> 0 | M10: =IFERROR(M8/SUM(G8+R8,0),"") | O10: =IFERROR(O8/N8,0) -> 0 | Q10: =IFERROR(Q8/P8,0) -> 0
B11: Edward Leon | C11: =SUMIF(B:B,B11,T:T) -> 1769 | E11: =SUMIFS(T:T,B:B,B11,D:D,"Y") -> 0 | F11: =SUMIF(B39:B1137,B11,G39:G1137) -> 9 | G11: =SUMIF(B39:B1137,B11,H39:H1137) -> 5 | H11: =SUMIF(B39:B1137,B11,I39:I1137) -> 1 | I11: =SUMIF(B39:B1137,B11,P39:P1137) -> 0 | J11: =SUMIF(B39:B1137,B11,Q39:Q1137) -> 0 | K11: =SUMIF(B39:B1137,B11,R39:R1137) -> 3 | L11: =SUMIF(B39:B1137,B11,S39:S1137) -> 1 | M11: =SUMIF(B39:B1137,B11,M39:M1137) -> 26 | N11: =SUMIF(B39:B1137,B11,N39:N1137) -> 0 | O11: =SUMIF(B39:B1137,B11,O39:O1137) -> 0 | P11: =SUMIF(B39:B1137,B11,J39:J1137) -> 2 | Q11: =SUMIF(B39:B1137,B11,K39:K1137) -> 1 | R11: =SUMIF(B39:B1137,B11,L39:L1137) -> 0
C12: # of Agents | E12: ALP per sale | F12: Show Rate | G12: Close Ratio | H12: ALP/Agent | J12: POS Close | L12: VET Close | M12: REF Per Sit | O12: REF Close | Q12: OTS Close
C13: =COUNTIFS(B39:B1137,B11) -> 7 | E13: =IFERROR(C11/H11,0) -> 1769 | F13: =IFERROR((G11+R11)/F11,0) -> 0.55555556 | G13: =IFERROR(H11/G11,0) -> 0.2 | H13: =(C11/C13) -> 252.71429 | J13: =IFERROR(J11/I11,0) -> 0 | L13: =IFERROR(L11/K11,0) -> 0.33333333 | M13: =IFERROR(M11/SUM(R11+G11,0),"") -> 5.2 | O13: =IFERROR(O11/N11,0) -> 0 | Q13: =IFERROR(Q11/P11,0) -> 0.5
B14: Melissa Elam | C14: =SUMIF(B:B,B14,T:T) -> 0 | E14: =SUMIFS(T:T,B:B,B14,D:D,"Y") -> 0 | F14: =SUMIF(B39:B1137,B14,G39:G1137) -> 5 | G14: =SUMIF(B39:B1137,B14,H39:H1137) -> 0 | H14: =SUMIF(B39:B1137,B14,I39:I1137) -> 0 | I14: =SUMIF(B39:B1137,B14,P39:P1137) -> 0 | J14: =SUMIF(B39:B1137,B14,Q39:Q1137) -> 0 | K14: =SUMIF(B39:B1137,B14,R39:R1137) -> 0 | L14: =SUMIF(B39:B1137,B14,S39:S1137) -> 0 | M14: =SUMIF(B39:B1137,B14,M39:M1137) -> 0 | N14: =SUMIF(B39:B1137,B14,N39:N1137) -> 0 | O14: =SUMIF(B39:B1137,B14,O39:O1137) -> 0 | P14: =SUMIF(B39:B1137,B14,J39:J1137) -> 0 | Q14: =SUMIF(B39:B1137,B14,K39:K1137) -> 0 | R14: =SUMIF(B39:B1137,B14,L39:L1137) -> 0
C15: # of Agents | E15: ALP per sale | F15: Show Rate | G15: Close Ratio | H15: ALP/Agent | J15: POS Close | L15: VET Close | M15: REF Per Sit | O15: REF Close | Q15: OTS Close
C16: =COUNTIFS(B39:B1137,B14) -> 7 | E16: =IFERROR(C14/H14,0) -> 0 | F16: =IFERROR((G14+R14)/F14,0) -> 0 | G16: =IFERROR(H14/G14,0) -> 0 | H16: =(C14/C16) -> 0 | J16: =IFERROR(J14/I14,0) -> 0 | L16: =IFERROR(L14/K14,0) -> 0 | M16: =IFERROR(M14/SUM(R14+G14,0),"") | O16: =IFERROR(O14/N14,0) -> 0 | Q16: =IFERROR(Q14/P14,0) -> 0
B17: Timothy Noe | C17: =SUMIF(B:B,B17,T:T) -> 7345 | E17: =SUMIFS(T:T,B:B,B17,D:D,"Y") -> 5906 | F17: =SUMIF(B44:B1137,B17,G44:G1137) -> 16 | G17: =SUMIF(B44:B1137,B17,H44:H1137) -> 11 | H17: =SUMIF(B44:B1137,B17,I44:I1137) -> 6 | I17: =SUMIF(B44:B1137,B17,P44:P1137) -> 6 | J17: =SUMIF(B44:B1137,B17,Q44:Q1137) -> 3 | K17: =SUMIF(B44:B1137,B17,R44:R1137) -> 1 | L17: =SUMIF(B44:B1137,B17,S44:S1137) -> 1 | M17: =SUMIF(B44:B1137,B17,M44:M1137) -> 15 | N17: =SUMIF(B44:B1137,B17,N44:N1137) -> 4 | O17: =SUMIF(B44:B1137,B17,O44:O1137) -> 2 | P17: =SUMIF(B44:B1137,B17,J44:J1137) -> 3 | Q17: =SUMIF(B44:B1137,B17,K44:K1137) -> 2 | R17: =SUMIF(B44:B1137,B17,L44:L1137) -> 0
C18: # of Agents | E18: ALP per sale | F18: Show Rate | G18: Close Ratio | H18: ALP/Agent | J18: POS Close | L18: VET Close | M18: REF Per Sit | O18: REF Close | Q18: OTS Close
C19: =COUNTIFS(B44:B1137,B17) -> 4 | E19: =IFERROR(C17/H17,0) -> 1224.1667 | F19: =IFERROR((G17+R17)/F17,0) -> 0.6875 | G19: =IFERROR(H17/G17,0) -> 0.54545455 | H19: =(C17/C19) -> 1836.25 | J19: =IFERROR(J17/I17,0) -> 0.5 | L19: =IFERROR(L17/K17,0) -> 1 | M19: =IFERROR(M17/SUM(R17+G17,0),"") -> 1.3636364 | O19: =IFERROR(O17/N17,0) -> 0.5 | Q19: =IFERROR(Q17/P17,0) -> 0.66666667
B20: Javier Sandoval | C20: =SUMIF(A:A,B20,T:T) -> 0 | E20: =SUMIFS(T:T,A:A,B20,D:D,"Y") -> 0 | F20: =SUMIF(A:A,B20,G:G) -> 0 | G20: =SUMIF(A:A,B20,H:H) -> 0 | H20: =SUMIF(A:A,B20,I:I) -> 0 | I20: =SUMIF(A:A,B20,P:P) -> 0 | J20: =SUMIF(A:A,B20,Q:Q) -> 0 | K20: =SUMIF(A:A,B20,R:R) -> 0 | L20: =SUMIF(A:A,B20,S:S) -> 0 | M20: =SUMIF(A:A,B20,M:M) -> 0 | N20: =SUMIF(A:A,B20,N:N) -> 0 | O20: =SUMIF(A:A,B20,O:O) -> 0 | P20: =SUMIF(A:A,B20,J:J) -> 0 | Q20: =SUMIF(A:A,B20,K:K) -> 0 | R20: =SUMIF(A:A,B20,L:L) -> 0
C21: # of Agents | E21: ALP per sale | F21: Show Rate | G21: Close Ratio | H21: ALP/Agent | J21: POS Close | L21: VET Close | M21: REF Per Sit | O21: REF Close | Q21: OTS Close
C22: =COUNTIFS(A:A,B20) -> 5 | E22: =IFERROR(C20/H20,0) -> 0 | F22: =IFERROR((G20+R20)/F20,0) -> 0 | G22: =IFERROR(H20/G20,0) -> 0 | H22: =(C20/C22) -> 0 | J22: =IFERROR(J20/I20,0) -> 0 | L22: =IFERROR(L20/K20,0) -> 0 | M22: =IFERROR(M20/SUM(R20+G20,0),"") | O22: =IFERROR(O20/N20,0) -> 0 | Q22: =IFERROR(Q20/P20,0) -> 0
B23: Derron Alexander | C23: =SUMIF(A:A,B23,T:T) -> 0 | E23: =SUMIFS(T:T,A:A,B23,D:D,"Y") -> 0 | F23: =SUMIF(A:A,B23,G:G) -> 0 | G23: =SUMIF(A:A,B23,H:H) -> 0 | H23: =SUMIF(A:A,B23,I:I) -> 0 | I23: =SUMIF(A:A,B23,P:P) -> 0 | J23: =SUMIF(A:A,B23,Q:Q) -> 0 | K23: =SUMIF(A:A,B23,R:R) -> 0 | L23: =SUMIF(A:A,B23,S:S) -> 0 | M23: =SUMIF(A:A,B23,M:M) -> 0 | N23: =SUMIF(A:A,B23,N:N) -> 0 | O23: =SUMIF(A:A,B23,O:O) -> 0 | P23: =SUMIF(A:A,B23,J:J) -> 0 | Q23: =SUMIF(A:A,B23,K:K) -> 0 | R23: =SUMIF(A:A,B23,L:L) -> 0
C24: # of Agents | E24: ALP per sale | F24: Show Rate | G24: Close Ratio | H24: ALP/Agent | J24: POS Close | L24: VET Close | M24: REF Per Sit | O24: REF Close | Q24: OTS Close
C25: =COUNTIFS(A:A,B23) -> 10 | E25: =IFERROR(C23/H23,0) -> 0 | F25: =IFERROR((G23+R23)/F23,0) -> 0 | G25: =IFERROR(H23/G23,0) -> 0 | H25: =(C23/C25) -> 0 | J25: =IFERROR(J23/I23,0) -> 0 | L25: =IFERROR(L23/K23,0) -> 0 | M25: =IFERROR(M23/SUM(R23+G23,0),"") | O25: =IFERROR(O23/N23,0) -> 0 | Q25: =IFERROR(Q23/P23,0) -> 0
B26: David Fulfer | C26: =SUMIF(A:A,B26,T:T) -> 817 | E26: =SUMIFS(T:T,A:A,B26,D:D,"Y") -> 817 | F26: =SUMIF(A:A,B26,G:G) -> 0 | G26: =SUMIF(A:A,B26,H:H) -> 0 | H26: =SUMIF(A:A,B26,I:I) -> 1 | I26: =SUMIF(A:A,B26,P:P) -> 0 | J26: =SUMIF(A:A,B26,Q:Q) -> 0 | K26: =SUMIF(A:A,B26,R:R) -> 0 | L26: =SUMIF(A:A,B26,S:S) -> 0 | M26: =SUMIF(A:A,B26,M:M) -> 0 | N26: =SUMIF(A:A,B26,N:N) -> 0 | O26: =SUMIF(A:A,B26,O:O) -> 1 | P26: =SUMIF(A:A,B26,J:J) -> 0 | Q26: =SUMIF(A:A,B26,K:K) -> 0 | R26: =SUMIF(A:A,B26,L:L) -> 0
C27: # of Agents | E27: ALP per sale | F27: Show Rate | G27: Close Ratio | H27: ALP/Agent | J27: POS Close | L27: VET Close | M27: REF Per Sit | O27: REF Close | Q27: OTS Close
C28: =COUNTIFS(A:A,B26) -> 5 | E28: =IFERROR(C26/H26,0) -> 817 | F28: =IFERROR((G26+R26)/F26,0) -> 0 | G28: =IFERROR(H26/G26,0) -> 0 | H28: =(C26/C28) -> 163.4 | J28: =IFERROR(J26/I26,0) -> 0 | L28: =IFERROR(L26/K26,0) -> 0 | M28: =IFERROR(M26/SUM(R26+G26,0),"") | O28: =IFERROR(O26/N26,0) -> 0 | Q28: =IFERROR(Q26/P26,0) -> 0
B29: Ashlynn Orng | C29: =SUMIF(A:A,B29,T:T) -> 0 | E29: =SUMIFS(T:T,A:A,B29,D:D,"Y") -> 0 | F29: =SUMIF(A:A,B29,G:G) -> 0 | G29: =SUMIF(A:A,B29,H:H) -> 0 | H29: =SUMIF(A:A,B29,I:I) -> 0 | I29: =SUMIF(A:A,B29,P:P) -> 0 | J29: =SUMIF(A:A,B29,Q:Q) -> 0 | K29: =SUMIF(A:A,B29,R:R) -> 0 | L29: =SUMIF(A:A,B29,S:S) -> 0 | M29: =SUMIF(A:A,B29,M:M) -> 0 | N29: =SUMIF(A:A,B29,N:N) -> 0 | O29: =SUMIF(A:A,B29,O:O) -> 0 | P29: =SUMIF(A:A,B29,J:J) -> 0 | Q29: =SUMIF(A:A,B29,K:K) -> 0 | R29: =SUMIF(A:A,B29,L:L) -> 0
C30: # of Agents | E30: ALP per sale | F30: Show Rate | G30: Close Ratio | H30: ALP/Agent | J30: POS Close | L30: VET Close | M30: REF Per Sit | O30: REF Close | Q30: OTS Close
C31: =COUNTIFS(A:A,B29) -> 17 | E31: =IFERROR(C29/H29,0) -> 0 | F31: =IFERROR((G29+R29)/F29,0) -> 0 | G31: =IFERROR(H29/G29,0) -> 0 | H31: =(C29/C31) -> 0 | J31: =IFERROR(J29/I29,0) -> 0 | L31: =IFERROR(L29/K29,0) -> 0 | M31: =IFERROR(M29/SUM(R29+G29,0),"") | O31: =IFERROR(O29/N29,0) -> 0 | Q31: =IFERROR(Q29/P29,0) -> 0
B32: Kenneth Preston | C32: =SUMIF(A:A,B32,T:T) -> 0 | E32: =SUMIFS(T:T,A:A,B32,D:D,"Y") -> 0 | F32: =SUMIF(A:A,B32,G:G) -> 0 | G32: =SUMIF(A:A,B32,H:H) -> 0 | H32: =SUMIF(A:A,B32,I:I) -> 0 | I32: =SUMIF(A:A,B32,P:P) -> 0 | J32: =SUMIF(A:A,B32,Q:Q) -> 0 | K32: =SUMIF(A:A,B32,R:R) -> 0 | L32: =SUMIF(A:A,B32,S:S) -> 0 | M32: =SUMIF(A:A,B32,M:M) -> 0 | N32: =SUMIF(A:A,B32,N:N) -> 0 | O32: =SUMIF(A:A,B32,O:O) -> 0 | P32: =SUMIF(A:A,B32,J:J) -> 0 | Q32: =SUMIF(A:A,B32,K:K) -> 0 | R32: =SUMIF(A:A,B32,L:L) -> 0
C33: # of Agents | E33: ALP per sale | F33: Show Rate | G33: Close Ratio | H33: ALP/Agent | J33: POS Close | L33: VET Close | M33: REF Per Sit | O33: REF Close | Q33: OTS Close
C34: =COUNTIFS(A:A,B32) -> 2 | E34: =IFERROR(C32/H32,0) -> 0 | F34: =IFERROR((G32+R32)/F32,0) -> 0 | G34: =IFERROR(H32/G32,0) -> 0 | H34: =(C32/C34) -> 0 | J34: =IFERROR(J32/I32,0) -> 0 | L34: =IFERROR(L32/K32,0) -> 0 | M34: =IFERROR(M32/SUM(R32+G32,0),"") | O34: =IFERROR(O32/N32,0) -> 0 | Q34: =IFERROR(Q32/P32,0) -> 0
A36: MGA | B36: GA | C36: SA | E36: State | F36: Agent | G36: SETS | H36: SITS | I36: SALES | J36: OTS SITS | K36: OTS SALES | L36: N1 | M36: REF OBT | N36: REF SITS | O36: REF SALES | P36: POS SITS | Q36: POS SALES | R36: VETS SITS | S36: VET SALES | T36: ALP | U36: Close | V36: Show | W36: Code Date
A37: Joseph Gojcaj | D37: Y | E37: MI | F37: Joseph Gojcaj | U37: =IFERROR(I37/H37,0) -> 0 | V37: =IFERROR(SUM(H37+L37)/G37,0) -> 0
A38: Joseph Gojcaj | B38: Jacob Brown | D38: Y | E38: MI | F38: Jacob Brown | U38: =IFERROR(I38/H38,0) -> 0 | V38: =IFERROR(SUM(H38+L38)/G38,0) -> 0
A39: Joseph Gojcaj | B39: Jacob Brown | C39: Kristen Fox | D39: Y | E39: NC | F39: Kristen Fox | G39: 0 | H39: 0 | I39: 0 | J39: 0 | K39: 0 | L39: 0 | M39: 0 | N39: 0 | O39: 0 | P39: 0 | Q39: 0 | R39: 0 | S39: 0 | U39: =IFERROR(I39/H39,0) -> 0 | V39: =IFERROR(SUM(H39+L39)/G39,0) -> 0
A40: Joseph Gojcaj | B40: Jacob Brown | C40: Kristen Fox | F40: Marci Dyer | G40: 0 | H40: 0 | I40: 0 | J40: 0 | K40: 0 | L40: 0 | M40: 0 | N40: 0 | O40: 0 | P40: 0 | Q40: 0 | R40: 0 | S40: 0 | U40: =IFERROR(I40/H40,0) -> 0 | V40: =IFERROR(SUM(H40+L40)/G40,0) -> 0
A41: Joseph Gojcaj | B41: Jacob Brown | C41: Joylynn Harris | D41: Y | E41: CA | F41: Joylynn Harris | G41: 0 | H41: 0 | I41: 0 | J41: 0 | K41: 0 | L41: 0 | M41: 0 | N41: 0 | O41: 0 | P41: 0 | Q41: 0 | R41: 0 | S41: 0 | T41: 0 | U41: =IFERROR(I41/H41,0) -> 0 | V41: =IFERROR(SUM(H41+L41)/G41,0) -> 0
...

Sheet Thurs
C1: ALP | E1: LEADERSHIP ALP | F1: Appts | G1: Pres | H1: Sales | I1: POS SITS | J1: POS SA | K1: VET SITS | L1: VET SA | M1: REF OBT | N1: REF SITS | O1: REF SA | P1: OTS SITS | Q1: OTS SA | R1: N1
B2: GOJCAJ RGA | C2: =SUM(C5,C20,C23,C26,C29,C32) -> 7636.32 | E2: =SUM(E5,E20,E23,E26,E29,E32) -> 5933.32 | F2: =SUM(F5,F20,F23,F26,F29,F32) -> 20 | G2: =SUM(G5,G20,G23,G26,G29,G32) -> 12 | H2: =SUM(H5,H20,H23,H26,H29,H32) -> 4 | I2: =SUM(I5,I20,I23,I26,I29,I32) -> 1 | J2: =SUM(J5,J20,J23,J26,J29,J32) -> 1 | K2: =SUM(K5,K20,K23,K26,K29,K32) -> 4 | L2: =SUM(L5,L20,L23,L26,L29,L32) -> 0 | ... R2: =SUM(R5,R20,R23,R26,R29,R32) -> 3
C3: # of Agents | E3: ALP per sale | F3: Show Rate | G3: Close Ratio | H3: ALP/Agent | J3: POS Close | L3: VET Close | M3: REF Per Sit | O3: REF Close | Q3: OTS Close
C4: =SUM(C7,C25,C22,C28,C31,C34) -> 63 | E4: =IFERROR(C2/H2,0) -> 1909.08 | F4: =IFERROR((G2+R2)/F2,0) -> 0.75 | G4: =IFERROR(H2/G2,0) -> 0.33333333 | H4: =(C2/C4) -> 121.21143 | J4: =IFERROR(J2/I2,0) -> 1 | L4: =IFERROR(L2/K2,0) -> 0 | M4: =IFERROR(M2/G2,0) -> 3.5 | O4: =IFERROR(O2/N2,0) -> 0.5 | Q4: =IFERROR(Q2/P2,0) -> 0.2
B5: Joseph Gojcaj | C5: =SUMIF(A:A,B5,T:T) -> 4110 | E5: =SUMIFS(T:T,A:A,B5,D:D,"Y") -> 2407 | F5: =SUMIF(A:A,B5,G:G) -> 19 | G5: =SUMIF(A:A,B5,H:H) -> 10 | H5: =SUMIF(A:A,B5,I:I) -> 2 | I5: =SUMIF(A:A,B5,P:P) -> 1 | J5: =SUMIF(A:A,B5,Q:Q) -> 1 | K5: =SUMIF(A:A,B5,R:R) -> 4 | L5: =SUMIF(A:A,B5,S:S) -> 0 | M5: =SUMIF(A:A,B5,M:M) -> 30 | N5: =SUMIF(A:A,B5,N:N) -> 4 | O5: =SUMIF(A:A,B5,O:O) -> 1 | P5: =SUMIF(A:A,B5,J:J) -> 4 | Q5: =SUMIF(A:A,B5,K:K) -> 0 | R5: =SUMIF(A:A,B5,L:L) -> 3
C6: # of Agents | E6: ALP per sale | F6: Show Rate | G6: Close Ratio | H6: ALP/Agent | J6: POS Close | L6: VET Close | M6: REF Per Sit | O6: REF Close | Q6: OTS Close
C7: =COUNTIFS(A:A,B5) -> 24 | E7: =IFERROR(C5/H5,0) -> 2055 | F7: =IFERROR((G5+R5)/F5,0) -> 0.68421053 | G7: =IFERROR(H5/G5,0) -> 0.2 | H7: =(C5/C7) -> 171.25 | J7: =IFERROR(J5/I5,0) -> 1 | L7: =IFERROR(L5/K5,0) -> 0 | M7: =IFERROR(M5/SUM(R5+G5,0),"") -> 2.3076923 | O7: =IFERROR(O5/N5,0) -> 0.25 | Q7: =IFERROR(Q5/P5,0) -> 0
B8: Jacob Brown | C8: =SUMIF(B:B,B8,T:T) -> 0 | E8: =SUMIFS(T:T,B:B,B8,D:D,"Y") -> 0 | F8: =SUMIF(B37:B1137,B8,G37:G1137) -> 2 | G8: =SUMIF(B37:B1137,B8,H37:H1137) -> 1 | H8: =SUMIF(B37:B1137,B8,I37:I1137) -> 0 | I8: =SUMIF(B37:B1137,B8,P37:P1137) -> 0 | J8: =SUMIF(B37:B1137,B8,Q37:Q1137) -> 0 | K8: =SUMIF(B37:B1137,B8,R37:R1137) -> 1 | L8: =SUMIF(B37:B1137,B8,S37:S1137) -> 0 | M8: =SUMIF(B37:B1137,B8,M37:M1137) -> 1 | N8: =SUMIF(B37:B1137,B8,N37:N1137) -> 1 | O8: =SUMIF(B37:B1137,B8,O37:O1137) -> 0 | P8: =SUMIF(B37:B1137,B8,J37:J1137) -> 1 | Q8: =SUMIF(B37:B1137,B8,K37:K1137) -> 0 | R8: =SUMIF(B37:B1137,B8,L37:L1137) -> 1
C9: # of Agents | E9: ALP per sale | F9: Show Rate | G9: Close Ratio | H9: ALP/Agent | J9: POS Close | L9: VET Close | M9: REF Per Sit | O9: REF Close | Q9: OTS Close
C10: =COUNTIFS(B37:B1137,B8) -> 5 | E10: =IFERROR(C8/H8,0) -> 0 | F10: =IFERROR((G8+R8)/F8,0) -> 1 | G10: =IFERROR(H8/G8,0) -> 0 | H10: =(C8/C10) -> 0 | J10: =IFERROR(J8/I8,0) -> 0 | L10: =IFERROR(L8/K8,0) -> 0 | M10: =IFERROR(M8/SUM(G8+R8,0),"") -> 0.5 | O10: =IFERROR(O8/N8,0) -> 0 | Q10: =IFERROR(Q8/P8,0) -> 0
B11: Edward Leon | C11: =SUMIF(B:B,B11,T:T) -> 1703 | E11: =SUMIFS(T:T,B:B,B11,D:D,"Y") -> 0 | F11: =SUMIF(B39:B1137,B11,G39:G1137) -> 7 | G11: =SUMIF(B39:B1137,B11,H39:H1137) -> 5 | H11: =SUMIF(B39:B1137,B11,I39:I1137) -> 1 | I11: =SUMIF(B39:B1137,B11,P39:P1137) -> 0 | J11: =SUMIF(B39:B1137,B11,Q39:Q1137) -> 0 | K11: =SUMIF(B39:B1137,B11,R39:R1137) -> 1 | L11: =SUMIF(B39:B1137,B11,S39:S1137) -> 0 | M11: =SUMIF(B39:B1137,B11,M39:M1137) -> 17 | N11: =SUMIF(B39:B1137,B11,N39:N1137) -> 2 | O11: =SUMIF(B39:B1137,B11,O39:O1137) -> 1 | P11: =SUMIF(B39:B1137,B11,J39:J1137) -> 3 | Q11: =SUMIF(B39:B1137,B11,K39:K1137) -> 0 | R11: =SUMIF(B39:B1137,B11,L39:L1137) -> 1
C12: # of Agents | E12: ALP per sale | F12: Show Rate | G12: Close Ratio | H12: ALP/Agent | J12: POS Close | L12: VET Close | M12: REF Per Sit | O12: REF Close | Q12: OTS Close
C13: =COUNTIFS(B39:B1137,B11) -> 7 | E13: =IFERROR(C11/H11,0) -> 1703 | F13: =IFERROR((G11+R11)/F11,0) -> 0.85714286 | G13: =IFERROR(H11/G11,0) -> 0.2 | H13: =(C11/C13) -> 243.28571 | J13: =IFERROR(J11/I11,0) -> 0 | L13: =IFERROR(L11/K11,0) -> 0 | M13: =IFERROR(M11/SUM(R11+G11,0),"") -> 2.8333333 | O13: =IFERROR(O11/N11,0) -> 0.5 | Q13: =IFERROR(Q11/P11,0) -> 0
B14: Melissa Elam | C14: =SUMIF(B:B,B14,T:T) -> 0 | E14: =SUMIFS(T:T,B:B,B14,D:D,"Y") -> 0 | F14: =SUMIF(B39:B1137,B14,G39:G1137) -> 4 | G14: =SUMIF(B39:B1137,B14,H39:H1137) -> 3 | H14: =SUMIF(B39:B1137,B14,I39:I1137) -> 0 | I14: =SUMIF(B39:B1137,B14,P39:P1137) -> 0 | J14: =SUMIF(B39:B1137,B14,Q39:Q1137) -> 0 | K14: =SUMIF(B39:B1137,B14,R39:R1137) -> 2 | L14: =SUMIF(B39:B1137,B14,S39:S1137) -> 0 | M14: =SUMIF(B39:B1137,B14,M39:M1137) -> 6 | N14: =SUMIF(B39:B1137,B14,N39:N1137) -> 1 | O14: =SUMIF(B39:B1137,B14,O39:O1137) -> 0 | P14: =SUMIF(B39:B1137,B14,J39:J1137) -> 0 | Q14: =SUMIF(B39:B1137,B14,K39:K1137) -> 0 | R14: =SUMIF(B39:B1137,B14,L39:L1137) -> 1
C15: # of Agents | E15: ALP per sale | F15: Show Rate | G15: Close Ratio | H15: ALP/Agent | J15: POS Close | L15: VET Close | M15: REF Per Sit | O15: REF Close | Q15: OTS Close
C16: =COUNTIFS(B39:B1137,B14) -> 7 | E16: =IFERROR(C14/H14,0) -> 0 | F16: =IFERROR((G14+R14)/F14,0) -> 1 | G16: =IFERROR(H14/G14,0) -> 0 | H16: =(C14/C16) -> 0 | J16: =IFERROR(J14/I14,0) -> 0 | L16: =IFERROR(L14/K14,0) -> 0 | M16: =IFERROR(M14/SUM(R14+G14,0),"") -> 1.5 | O16: =IFERROR(O14/N14,0) -> 0 | Q16: =IFERROR(Q14/P14,0) -> 0
B17: Timothy Noe | C17: =SUMIF(B:B,B17,T:T) -> 2407 | E17: =SUMIFS(T:T,B:B,B17,D:D,"Y") -> 2407 | F17: =SUMIF(B44:B1137,B17,G44:G1137) -> 6 | G17: =SUMIF(B44:B1137,B17,H44:H1137) -> 1 | H17: =SUMIF(B44:B1137,B17,I44:I1137) -> 1 | I17: =SUMIF(B44:B1137,B17,P44:P1137) -> 1 | J17: =SUMIF(B44:B1137,B17,Q44:Q1137) -> 1 | K17: =SUMIF(B44:B1137,B17,R44:R1137) -> 0 | L17: =SUMIF(B44:B1137,B17,S44:S1137) -> 0 | M17: =SUMIF(B44:B1137,B17,M44:M1137) -> 6 | N17: =SUMIF(B44:B1137,B17,N44:N1137) -> 0 | O17: =SUMIF(B44:B1137,B17,O44:O1137) -> 0 | P17: =SUMIF(B44:B1137,B17,J44:J1137) -> 0 | Q17: =SUMIF(B44:B1137,B17,K44:K1137) -> 0 | R17: =SUMIF(B44:B1137,B17,L44:L1137) -> 0
C18: # of Agents | E18: ALP per sale | F18: Show Rate | G18: Close Ratio | H18: ALP/Agent | J18: POS Close | L18: VET Close | M18: REF Per Sit | O18: REF Close | Q18: OTS Close
C19: =COUNTIFS(B44:B1137,B17) -> 4 | E19: =IFERROR(C17/H17,0) -> 2407 | F19: =IFERROR((G17+R17)/F17,0) -> 0.16666667 | G19: =IFERROR(H17/G17,0) -> 1 | H19: =(C17/C19) -> 601.75 | J19: =IFERROR(J17/I17,0) -> 1 | L19: =IFERROR(L17/K17,0) -> 0 | M19: =IFERROR(M17/SUM(R17+G17,0),"") -> 6 | O19: =IFERROR(O17/N17,0) -> 0 | Q19: =IFERROR(Q17/P17,0) -> 0
B20: Javier Sandoval | C20: =SUMIF(A:A,B20,T:T) -> 0 | E20: =SUMIFS(T:T,A:A,B20,D:D,"Y") -> 0 | F20: =SUMIF(A:A,B20,G:G) -> 0 | G20: =SUMIF(A:A,B20,H:H) -> 0 | H20: =SUMIF(A:A,B20,I:I) -> 0 | I20: =SUMIF(A:A,B20,P:P) -> 0 | J20: =SUMIF(A:A,B20,Q:Q) -> 0 | K20: =SUMIF(A:A,B20,R:R) -> 0 | L20: =SUMIF(A:A,B20,S:S) -> 0 | M20: =SUMIF(A:A,B20,M:M) -> 0 | N20: =SUMIF(A:A,B20,N:N) -> 0 | O20: =SUMIF(A:A,B20,O:O) -> 0 | P20: =SUMIF(A:A,B20,J:J) -> 0 | Q20: =SUMIF(A:A,B20,K:K) -> 0 | R20: =SUMIF(A:A,B20,L:L) -> 0
C21: # of Agents | E21: ALP per sale | F21: Show Rate | G21: Close Ratio | H21: ALP/Agent | J21: POS Close | L21: VET Close | M21: REF Per Sit | O21: REF Close | Q21: OTS Close
C22: =COUNTIFS(A:A,B20) -> 5 | E22: =IFERROR(C20/H20,0) -> 0 | F22: =IFERROR((G20+R20)/F20,0) -> 0 | G22: =IFERROR(H20/G20,0) -> 0 | H22: =(C20/C22) -> 0 | J22: =IFERROR(J20/I20,0) -> 0 | L22: =IFERROR(L20/K20,0) -> 0 | M22: =IFERROR(M20/SUM(R20+G20,0),"") | O22: =IFERROR(O20/N20,0) -> 0 | Q22: =IFERROR(Q20/P20,0) -> 0
B23: Derron Alexander | C23: =SUMIF(A:A,B23,T:T) -> 0 | E23: =SUMIFS(T:T,A:A,B23,D:D,"Y") -> 0 | F23: =SUMIF(A:A,B23,G:G) -> 0 | G23: =SUMIF(A:A,B23,H:H) -> 0 | H23: =SUMIF(A:A,B23,I:I) -> 0 | I23: =SUMIF(A:A,B23,P:P) -> 0 | J23: =SUMIF(A:A,B23,Q:Q) -> 0 | K23: =SUMIF(A:A,B23,R:R) -> 0 | L23: =SUMIF(A:A,B23,S:S) -> 0 | M23: =SUMIF(A:A,B23,M:M) -> 0 | N23: =SUMIF(A:A,B23,N:N) -> 0 | O23: =SUMIF(A:A,B23,O:O) -> 0 | P23: =SUMIF(A:A,B23,J:J) -> 0 | Q23: =SUMIF(A:A,B23,K:K) -> 0 | R23: =SUMIF(A:A,B23,L:L) -> 0
C24: # of Agents | E24: ALP per sale | F24: Show Rate | G24: Close Ratio | H24: ALP/Agent | J24: POS Close | L24: VET Close | M24: REF Per Sit | O24: REF Close | Q24: OTS Close
C25: =COUNTIFS(A:A,B23) -> 10 | E25: =IFERROR(C23/H23,0) -> 0 | F25: =IFERROR((G23+R23)/F23,0) -> 0 | G25: =IFERROR(H23/G23,0) -> 0 | H25: =(C23/C25) -> 0 | J25: =IFERROR(J23/I23,0) -> 0 | L25: =IFERROR(L23/K23,0) -> 0 | M25: =IFERROR(M23/SUM(R23+G23,0),"") | O25: =IFERROR(O23/N23,0) -> 0 | Q25: =IFERROR(Q23/P23,0) -> 0
B26: David Fulfer | C26: =SUMIF(A:A,B26,T:T) -> 3526.32 | E26: =SUMIFS(T:T,A:A,B26,D:D,"Y") -> 3526.32 | F26: =SUMIF(A:A,B26,G:G) -> 1 | G26: =SUMIF(A:A,B26,H:H) -> 2 | H26: =SUMIF(A:A,B26,I:I) -> 2 | I26: =SUMIF(A:A,B26,P:P) -> 0 | J26: =SUMIF(A:A,B26,Q:Q) -> 0 | K26: =SUMIF(A:A,B26,R:R) -> 0 | L26: =SUMIF(A:A,B26,S:S) -> 0 | M26: =SUMIF(A:A,B26,M:M) -> 12 | N26: =SUMIF(A:A,B26,N:N) -> 2 | O26: =SUMIF(A:A,B26,O:O) -> 2 | P26: =SUMIF(A:A,B26,J:J) -> 1 | Q26: =SUMIF(A:A,B26,K:K) -> 1 | R26: =SUMIF(A:A,B26,L:L) -> 0
C27: # of Agents | E27: ALP per sale | F27: Show Rate | G27: Close Ratio | H27: ALP/Agent | J27: POS Close | L27: VET Close | M27: REF Per Sit | O27: REF Close | Q27: OTS Close
C28: =COUNTIFS(A:A,B26) -> 5 | E28: =IFERROR(C26/H26,0) -> 1763.16 | F28: =IFERROR((G26+R26)/F26,0) -> 2 | G28: =IFERROR(H26/G26,0) -> 1 | H28: =(C26/C28) -> 705.264 | J28: =IFERROR(J26/I26,0) -> 0 | L28: =IFERROR(L26/K26,0) -> 0 | M28: =IFERROR(M26/SUM(R26+G26,0),"") -> 6 | O28: =IFERROR(O26/N26,0) -> 1 | Q28: =IFERROR(Q26/P26,0) -> 1
B29: Ashlynn Orng | C29: =SUMIF(A:A,B29,T:T) -> 0 | E29: =SUMIFS(T:T,A:A,B29,D:D,"Y") -> 0 | F29: =SUMIF(A:A,B29,G:G) -> 0 | G29: =SUMIF(A:A,B29,H:H) -> 0 | H29: =SUMIF(A:A,B29,I:I) -> 0 | I29: =SUMIF(A:A,B29,P:P) -> 0 | J29: =SUMIF(A:A,B29,Q:Q) -> 0 | K29: =SUMIF(A:A,B29,R:R) -> 0 | L29: =SUMIF(A:A,B29,S:S) -> 0 | M29: =SUMIF(A:A,B29,M:M) -> 0 | N29: =SUMIF(A:A,B29,N:N) -> 0 | O29: =SUMIF(A:A,B29,O:O) -> 0 | P29: =SUMIF(A:A,B29,J:J) -> 0 | Q29: =SUMIF(A:A,B29,K:K) -> 0 | R29: =SUMIF(A:A,B29,L:L) -> 0
C30: # of Agents | E30: ALP per sale | F30: Show Rate | G30: Close Ratio | H30: ALP/Agent | J30: POS Close | L30: VET Close | M30: REF Per Sit | O30: REF Close | Q30: OTS Close
C31: =COUNTIFS(A:A,B29) -> 17 | E31: =IFERROR(C29/H29,0) -> 0 | F31: =IFERROR((G29+R29)/F29,0) -> 0 | G31: =IFERROR(H29/G29,0) -> 0 | H31: =(C29/C31) -> 0 | J31: =IFERROR(J29/I29,0) -> 0 | L31: =IFERROR(L29/K29,0) -> 0 | M31: =IFERROR(M29/SUM(R29+G29,0),"") | O31: =IFERROR(O29/N29,0) -> 0 | Q31: =IFERROR(Q29/P29,0) -> 0
B32: Kenneth Preston | C32: =SUMIF(A:A,B32,T:T) -> 0 | E32: =SUMIFS(T:T,A:A,B32,D:D,"Y") -> 0 | F32: =SUMIF(A:A,B32,G:G) -> 0 | G32: =SUMIF(A:A,B32,H:H) -> 0 | H32: =SUMIF(A:A,B32,I:I) -> 0 | I32: =SUMIF(A:A,B32,P:P) -> 0 | J32: =SUMIF(A:A,B32,Q:Q) -> 0 | K32: =SUMIF(A:A,B32,R:R) -> 0 | L32: =SUMIF(A:A,B32,S:S) -> 0 | M32: =SUMIF(A:A,B32,M:M) -> 0 | N32: =SUMIF(A:A,B32,N:N) -> 0 | O32: =SUMIF(A:A,B32,O:O) -> 0 | P32: =SUMIF(A:A,B32,J:J) -> 0 | Q32: =SUMIF(A:A,B32,K:K) -> 0 | R32: =SUMIF(A:A,B32,L:L) -> 0
C33: # of Agents | E33: ALP per sale | F33: Show Rate | G33: Close Ratio | H33: ALP/Agent | J33: POS Close | L33: VET Close | M33: REF Per Sit | O33: REF Close | Q33: OTS Close
C34: =COUNTIFS(A:A,B32) -> 2 | E34: =IFERROR(C32/H32,0) -> 0 | F34: =IFERROR((G32+R32)/F32,0) -> 0 | G34: =IFERROR(H32/G32,0) -> 0 | H34: =(C32/C34) -> 0 | J34: =IFERROR(J32/I32,0) -> 0 | L34: =IFERROR(L32/K32,0) -> 0 | M34: =IFERROR(M32/SUM(R32+G32,0),"") | O34: =IFERROR(O32/N32,0) -> 0 | Q34: =IFERROR(Q32/P32,0) -> 0
A36: MGA | B36: GA | C36: SA | E36: State | F36: Agent | G36: SETS | H36: SITS | I36: SALES | J36: OTS SITS | K36: OTS SALES | L36: N1 | M36: REF OBT | N36: REF SITS | O36: REF SALES | P36: POS SITS | Q36: POS SALES | R36: VETS SITS | S36: VET SALES | T36: ALP | U36: Close | V36: Show | W36: Code Date
A37: Joseph Gojcaj | D37: Y | E37: MI | F37: Joseph Gojcaj | U37: =IFERROR(I37/H37,0) -> 0 | V37: =IFERROR(SUM(H37+L37)/G37,0) -> 0
A38: Joseph Gojcaj | B38: Jacob Brown | D38: Y | E38: MI | F38: Jacob Brown | U38: =IFERROR(I38/H38,0) -> 0 | V38: =IFERROR(SUM(H38+L38)/G38,0) -> 0
A39: Joseph Gojcaj | B39: Jacob Brown | C39: Kristen Fox | D39: Y | E39: NC | F39: Kristen Fox | G39: 2 | H39: 1 | I39: 0 | J39: 1 | K39: 0 | L39: 1 | M39: 1 | N39: 1 | O39: 0 | P39: 0 | Q39: 0 | R39: 1 | S39: 0 | U39: =IFERROR(I39/H39,0) -> 0 | V39: =IFERROR(SUM(H39+L39)/G39,0) -> 1
A40: Joseph Gojcaj | B40: Jacob Brown | C40: Kristen Fox | F40: Marci Dyer | G40: 0 | H40: 0 | I40: 0 | J40: 0 | K40: 0 | L40: 0 | M40: 0 | N40: 0 | O40: 0 | P40: 0 | Q40: 0 | R40: 0 | S40: 0 | U40: =IFERROR(I40/H40,0) -> 0 | V40: =IFERROR(SUM(H40+L40)/G40,0) -> 0
A41: Joseph Gojcaj | B41: Jacob Brown | C41: Joylynn Harris | D41: Y | E41: CA | F41: Joylynn Harris | G41: 0 | H41: 0 | I41: 0 | J41: 0 | K41: 0 | L41: 0 | M41: 0 | N41: 0 | O41: 0 | P41: 0 | Q41: 0 | R41: 0 | S41: 0 | T41: 0 | U41: =IFERROR(I41/H41,0) -> 0 | V41: =IFERROR(SUM(H41+L41)/G41,0) -> 0
...

Sheet Fri
C1: ALP | E1: LEADERSHIP ALP | F1: Appts | G1: Pres | H1: Sales | I1: POS SITS | J1: POS SA | K1: VET SITS | L1: VET SA | M1: REF OBT | N1: REF SITS | O1: REF SA | P1: OTS SITS | Q1: OTS SA | R1: N1
B2: GOJCAJ RGA | C2: =SUM(C5,C20,C23,C26,C29,C32) -> 7941.24 | E2: =SUM(E5,E20,E23,E26,E29,E32) -> 5986.24 | F2: =SUM(F5,F20,F23,F26,F29,F32) -> 26 | G2: =SUM(G5,G20,G23,G26,G29,G32) -> 14 | H2: =SUM(H5,H20,H23,H26,H29,H32) -> 6 | I2: =SUM(I5,I20,I23,I26,I29,I32) -> 3 | J2: =SUM(J5,J20,J23,J26,J29,J32) -> 2 | K2: =SUM(K5,K20,K23,K26,K29,K32) -> 5 | L2: =SUM(L5,L20,L23,L26,L29,L32) -> 2 | ... R2: =SUM(R5,R20,R23,R26,R29,R32) -> 0
C3: # of Agents | E3: ALP per sale | F3: Show Rate | G3: Close Ratio | H3: ALP/Agent | J3: POS Close | L3: VET Close | M3: REF Per Sit | O3: REF Close | Q3: OTS Close
C4: =SUM(C7,C25,C22,C28,C31,C34) -> 63 | E4: =IFERROR(C2/H2,0) -> 1323.54 | F4: =IFERROR((G2+R2)/F2,0) -> 0.53846154 | G4: =IFERROR(H2/G2,0) -> 0.42857143 | H4: =(C2/C4) -> 126.05143 | J4: =IFERROR(J2/I2,0) -> 0.66666667 | L4: =IFERROR(L2/K2,0) -> 0.4 | M4: =IFERROR(M2/G2,0) -> 3.4285714 | O4: =IFERROR(O2/N2,0) -> 0.6 | Q4: =IFERROR(Q2/P2,0) -> 0.33333333
B5: Joseph Gojcaj | C5: =SUMIF(A:A,B5,T:T) -> 7110 | E5: =SUMIFS(T:T,A:A,B5,D:D,"Y") -> 5155 | F5: =SUMIF(A:A,B5,G:G) -> 26 | G5: =SUMIF(A:A,B5,H:H) -> 13 | H5: =SUMIF(A:A,B5,I:I) -> 5 | I5: =SUMIF(A:A,B5,P:P) -> 3 | J5: =SUMIF(A:A,B5,Q:Q) -> 2 | K5: =SUMIF(A:A,B5,R:R) -> 4 | L5: =SUMIF(A:A,B5,S:S) -> 1 | M5: =SUMIF(A:A,B5,M:M) -> 46 | N5: =SUMIF(A:A,B5,N:N) -> 4 | O5: =SUMIF(A:A,B5,O:O) -> 2 | P5: =SUMIF(A:A,B5,J:J) -> 5 | Q5: =SUMIF(A:A,B5,K:K) -> 1 | R5: =SUMIF(A:A,B5,L:L) -> 0
C6: # of Agents | E6: ALP per sale | F6: Show Rate | G6: Close Ratio | H6: ALP/Agent | J6: POS Close | L6: VET Close | M6: REF Per Sit | O6: REF Close | Q6: OTS Close
C7: =COUNTIFS(A:A,B5) -> 24 | E7: =IFERROR(C5/H5,0) -> 1422 | F7: =IFERROR((G5+R5)/F5,0) -> 0.5 | G7: =IFERROR(H5/G5,0) -> 0.38461538 | H7: =(C5/C7) -> 296.25 | J7: =IFERROR(J5/I5,0) -> 0.66666667 | L7: =IFERROR(L5/K5,0) -> 0.25 | M7: =IFERROR(M5/SUM(R5+G5,0),"") -> 3.5384615 | O7: =IFERROR(O5/N5,0) -> 0.5 | Q7: =IFERROR(Q5/P5,0) -> 0.2
B8: Jacob Brown | C8: =SUMIF(B:B,B8,T:T) -> 0 | E8: =SUMIFS(T:T,B:B,B8,D:D,"Y") -> 0 | F8: =SUMIF(B37:B1137,B8,G37:G1137) -> 1 | G8: =SUMIF(B37:B1137,B8,H37:H1137) -> 2 | H8: =SUMIF(B37:B1137,B8,I37:I1137) -> 0 | I8: =SUMIF(B37:B1137,B8,P37:P1137) -> 0 | J8: =SUMIF(B37:B1137,B8,Q37:Q1137) -> 0 | K8: =SUMIF(B37:B1137,B8,R37:R1137) -> 1 | L8: =SUMIF(B37:B1137,B8,S37:S1137) -> 0 | M8: =SUMIF(B37:B1137,B8,M37:M1137) -> 7 | N8: =SUMIF(B37:B1137,B8,N37:N1137) -> 1 | O8: =SUMIF(B37:B1137,B8,O37:O1137) -> 0 | P8: =SUMIF(B37:B1137,B8,J37:J1137) -> 2 | Q8: =SUMIF(B37:B1137,B8,K37:K1137) -> 0 | R8: =SUMIF(B37:B1137,B8,L37:L1137) -> 0
C9: # of Agents | E9: ALP per sale | F9: Show Rate | G9: Close Ratio | H9: ALP/Agent | J9: POS Close | L9: VET Close | M9: REF Per Sit | O9: REF Close | Q9: OTS Close
C10: =COUNTIFS(B37:B1137,B8) -> 5 | E10: =IFERROR(C8/H8,0) -> 0 | F10: =IFERROR((G8+R8)/F8,0) -> 2 | G10: =IFERROR(H8/G8,0) -> 0 | H10: =(C8/C10) -> 0 | J10: =IFERROR(J8/I8,0) -> 0 | L10: =IFERROR(L8/K8,0) -> 0 | M10: =IFERROR(M8/SUM(G8+R8,0),"") -> 3.5 | O10: =IFERROR(O8/N8,0) -> 0 | Q10: =IFERROR(Q8/P8,0) -> 0
B11: Edward Leon | C11: =SUMIF(B:B,B11,T:T) -> 1955 | E11: =SUMIFS(T:T,B:B,B11,D:D,"Y") -> 0 | F11: =SUMIF(B39:B1137,B11,G39:G1137) -> 5 | G11: =SUMIF(B39:B1137,B11,H39:H1137) -> 5 | H11: =SUMIF(B39:B1137,B11,I39:I1137) -> 1 | I11: =SUMIF(B39:B1137,B11,P39:P1137) -> 0 | J11: =SUMIF(B39:B1137,B11,Q39:Q1137) -> 0 | K11: =SUMIF(B39:B1137,B11,R39:R1137) -> 3 | L11: =SUMIF(B39:B1137,B11,S39:S1137) -> 1 | M11: =SUMIF(B39:B1137,B11,M39:M1137) -> 22 | N11: =SUMIF(B39:B1137,B11,N39:N1137) -> 1 | O11: =SUMIF(B39:B1137,B11,O39:O1137) -> 0 | P11: =SUMIF(B39:B1137,B11,J39:J1137) -> 2 | Q11: =SUMIF(B39:B1137,B11,K39:K1137) -> 0 | R11: =SUMIF(B39:B1137,B11,L39:L1137) -> 0
C12: # of Agents | E12: ALP per sale | F12: Show Rate | G12: Close Ratio | H12: ALP/Agent | J12: POS Close | L12: VET Close | M12: REF Per Sit | O12: REF Close | Q12: OTS Close
C13: =COUNTIFS(B39:B1137,B11) -> 7 | E13: =IFERROR(C11/H11,0) -> 1955 | F13: =IFERROR((G11+R11)/F11,0) -> 1 | G13: =IFERROR(H11/G11,0) -> 0.2 | H13: =(C11/C13) -> 279.28571 | J13: =IFERROR(J11/I11,0) -> 0 | L13: =IFERROR(L11/K11,0) -> 0.33333333 | M13: =IFERROR(M11/SUM(R11+G11,0),"") -> 4.4 | O13: =IFERROR(O11/N11,0) -> 0 | Q13: =IFERROR(Q11/P11,0) -> 0
B14: Melissa Elam | C14: =SUMIF(B:B,B14,T:T) -> 0 | E14: =SUMIFS(T:T,B:B,B14,D:D,"Y") -> 0 | F14: =SUMIF(B39:B1137,B14,G39:G1137) -> 6 | G14: =SUMIF(B39:B1137,B14,H39:H1137) -> 1 | H14: =SUMIF(B39:B1137,B14,I39:I1137) -> 0 | I14: =SUMIF(B39:B1137,B14,P39:P1137) -> 0 | J14: =SUMIF(B39:B1137,B14,Q39:Q1137) -> 0 | K14: =SUMIF(B39:B1137,B14,R39:R1137) -> 0 | L14: =SUMIF(B39:B1137,B14,S39:S1137) -> 0 | M14: =SUMIF(B39:B1137,B14,M39:M1137) -> 2 | N14: =SUMIF(B39:B1137,B14,N39:N1137) -> 0 | O14: =SUMIF(B39:B1137,B14,O39:O1137) -> 0 | P14: =SUMIF(B39:B1137,B14,J39:J1137) -> 0 | Q14: =SUMIF(B39:B1137,B14,K39:K1137) -> 0 | R14: =SUMIF(B39:B1137,B14,L39:L1137) -> 0
C15: # of Agents | E15: ALP per sale | F15: Show Rate | G15: Close Ratio | H15: ALP/Agent | J15: POS Close | L15: VET Close | M15: REF Per Sit | O15: REF Close | Q15: OTS Close
C16: =COUNTIFS(B39:B1137,B14) -> 7 | E16: =IFERROR(C14/H14,0) -> 0 | F16: =IFERROR((G14+R14)/F14,0) -> 0.16666667 | G16: =IFERROR(H14/G14,0) -> 0 | H16: =(C14/C16) -> 0 | J16: =IFERROR(J14/I14,0) -> 0 | L16: =IFERROR(L14/K14,0) -> 0 | M16: =IFERROR(M14/SUM(R14+G14,0),"") -> 2 | O16: =IFERROR(O14/N14,0) -> 0 | Q16: =IFERROR(Q14/P14,0) -> 0
B17: Timothy Noe | C17: =SUMIF(B:B,B17,T:T) -> 5155 | E17: =SUMIFS(T:T,B:B,B17,D:D,"Y") -> 5155 | F17: =SUMIF(B44:B1137,B17,G44:G1137) -> 14 | G17: =SUMIF(B44:B1137,B17,H44:H1137) -> 5 | H17: =SUMIF(B44:B1137,B17,I44:I1137) -> 4 | I17: =SUMIF(B44:B1137,B17,P44:P1137) -> 3 | J17: =SUMIF(B44:B1137,B17,Q44:Q1137) -> 2 | K17: =SUMIF(B44:B1137,B17,R44:R1137) -> 0 | L17: =SUMIF(B44:B1137,B17,S44:S1137) -> 0 | M17: =SUMIF(B44:B1137,B17,M44:M1137) -> 15 | N17: =SUMIF(B44:B1137,B17,N44:N1137) -> 2 | O17: =SUMIF(B44:B1137,B17,O44:O1137) -> 2 | P17: =SUMIF(B44:B1137,B17,J44:J1137) -> 1 | Q17: =SUMIF(B44:B1137,B17,K44:K1137) -> 1 | R17: =SUMIF(B44:B1137,B17,L44:L1137) -> 0
C18: # of Agents | E18: ALP per sale | F18: Show Rate | G18: Close Ratio | H18: ALP/Agent | J18: POS Close | L18: VET Close | M18: REF Per Sit | O18: REF Close | Q18: OTS Close
C19: =COUNTIFS(B44:B1137,B17) -> 4 | E19: =IFERROR(C17/H17,0) -> 1288.75 | F19: =IFERROR((G17+R17)/F17,0) -> 0.35714286 | G19: =IFERROR(H17/G17,0) -> 0.8 | H19: =(C17/C19) -> 1288.75 | J19: =IFERROR(J17/I17,0) -> 0.66666667 | L19: =IFERROR(L17/K17,0) -> 0 | M19: =IFERROR(M17/SUM(R17+G17,0),"") -> 3 | O19: =IFERROR(O17/N17,0) -> 1 | Q19: =IFERROR(Q17/P17,0) -> 1
B20: Javier Sandoval | C20: =SUMIF(A:A,B20,T:T) -> 0 | E20: =SUMIFS(T:T,A:A,B20,D:D,"Y") -> 0 | F20: =SUMIF(A:A,B20,G:G) -> 0 | G20: =SUMIF(A:A,B20,H:H) -> 0 | H20: =SUMIF(A:A,B20,I:I) -> 0 | I20: =SUMIF(A:A,B20,P:P) -> 0 | J20: =SUMIF(A:A,B20,Q:Q) -> 0 | K20: =SUMIF(A:A,B20,R:R) -> 0 | L20: =SUMIF(A:A,B20,S:S) -> 0 | M20: =SUMIF(A:A,B20,M:M) -> 0 | N20: =SUMIF(A:A,B20,N:N) -> 0 | O20: =SUMIF(A:A,B20,O:O) -> 0 | P20: =SUMIF(A:A,B20,J:J) -> 0 | Q20: =SUMIF(A:A,B20,K:K) -> 0 | R20: =SUMIF(A:A,B20,L:L) -> 0
C21: # of Agents | E21: ALP per sale | F21: Show Rate | G21: Close Ratio | H21: ALP/Agent | J21: POS Close | L21: VET Close | M21: REF Per Sit | O21: REF Close | Q21: OTS Close
C22: =COUNTIFS(A:A,B20) -> 5 | E22: =IFERROR(C20/H20,0) -> 0 | F22: =IFERROR((G20+R20)/F20,0) -> 0 | G22: =IFERROR(H20/G20,0) -> 0 | H22: =(C20/C22) -> 0 | J22: =IFERROR(J20/I20,0) -> 0 | L22: =IFERROR(L20/K20,0) -> 0 | M22: =IFERROR(M20/SUM(R20+G20,0),"") | O22: =IFERROR(O20/N20,0) -> 0 | Q22: =IFERROR(Q20/P20,0) -> 0
B23: Derron Alexander | C23: =SUMIF(A:A,B23,T:T) -> 0 | E23: =SUMIFS(T:T,A:A,B23,D:D,"Y") -> 0 | F23: =SUMIF(A:A,B23,G:G) -> 0 | G23: =SUMIF(A:A,B23,H:H) -> 0 | H23: =SUMIF(A:A,B23,I:I) -> 0 | I23: =SUMIF(A:A,B23,P:P) -> 0 | J23: =SUMIF(A:A,B23,Q:Q) -> 0 | K23: =SUMIF(A:A,B23,R:R) -> 0 | L23: =SUMIF(A:A,B23,S:S) -> 0 | M23: =SUMIF(A:A,B23,M:M) -> 0 | N23: =SUMIF(A:A,B23,N:N) -> 0 | O23: =SUMIF(A:A,B23,O:O) -> 0 | P23: =SUMIF(A:A,B23,J:J) -> 0 | Q23: =SUMIF(A:A,B23,K:K) -> 0 | R23: =SUMIF(A:A,B23,L:L) -> 0
C24: # of Agents | E24: ALP per sale | F24: Show Rate | G24: Close Ratio | H24: ALP/Agent | J24: POS Close | L24: VET Close | M24: REF Per Sit | O24: REF Close | Q24: OTS Close
C25: =COUNTIFS(A:A,B23) -> 10 | E25: =IFERROR(C23/H23,0) -> 0 | F25: =IFERROR((G23+R23)/F23,0) -> 0 | G25: =IFERROR(H23/G23,0) -> 0 | H25: =(C23/C25) -> 0 | J25: =IFERROR(J23/I23,0) -> 0 | L25: =IFERROR(L23/K23,0) -> 0 | M25: =IFERROR(M23/SUM(R23+G23,0),"") | O25: =IFERROR(O23/N23,0) -> 0 | Q25: =IFERROR(Q23/P23,0) -> 0
B26: David Fulfer | C26: =SUMIF(A:A,B26,T:T) -> 831.24 | E26: =SUMIFS(T:T,A:A,B26,D:D,"Y") -> 831.24 | F26: =SUMIF(A:A,B26,G:G) -> 0 | G26: =SUMIF(A:A,B26,H:H) -> 1 | H26: =SUMIF(A:A,B26,I:I) -> 1 | I26: =SUMIF(A:A,B26,P:P) -> 0 | J26: =SUMIF(A:A,B26,Q:Q) -> 0 | K26: =SUMIF(A:A,B26,R:R) -> 1 | L26: =SUMIF(A:A,B26,S:S) -> 1 | M26: =SUMIF(A:A,B26,M:M) -> 2 | N26: =SUMIF(A:A,B26,N:N) -> 1 | O26: =SUMIF(A:A,B26,O:O) -> 1 | P26: =SUMIF(A:A,B26,J:J) -> 1 | Q26: =SUMIF(A:A,B26,K:K) -> 1 | R26: =SUMIF(A:A,B26,L:L) -> 0
C27: # of Agents | E27: ALP per sale | F27: Show Rate | G27: Close Ratio | H27: ALP/Agent | J27: POS Close | L27: VET Close | M27: REF Per Sit | O27: REF Close | Q27: OTS Close
C28: =COUNTIFS(A:A,B26) -> 5 | E28: =IFERROR(C26/H26,0) -> 831.24 | F28: =IFERROR((G26+R26)/F26,0) -> 0 | G28: =IFERROR(H26/G26,0) -> 1 | H28: =(C26/C28) -> 166.248 | J28: =IFERROR(J26/I26,0) -> 0 | L28: =IFERROR(L26/K26,0) -> 1 | M28: =IFERROR(M26/SUM(R26+G26,0),"") -> 2 | O28: =IFERROR(O26/N26,0) -> 1 | Q28: =IFERROR(Q26/P26,0) -> 1
B29: Ashlynn Orng | C29: =SUMIF(A:A,B29,T:T) -> 0 | E29: =SUMIFS(T:T,A:A,B29,D:D,"Y") -> 0 | F29: =SUMIF(A:A,B29,G:G) -> 0 | G29: =SUMIF(A:A,B29,H:H) -> 0 | H29: =SUMIF(A:A,B29,I:I) -> 0 | I29: =SUMIF(A:A,B29,P:P) -> 0 | J29: =SUMIF(A:A,B29,Q:Q) -> 0 | K29: =SUMIF(A:A,B29,R:R) -> 0 | L29: =SUMIF(A:A,B29,S:S) -> 0 | M29: =SUMIF(A:A,B29,M:M) -> 0 | N29: =SUMIF(A:A,B29,N:N) -> 0 | O29: =SUMIF(A:A,B29,O:O) -> 0 | P29: =SUMIF(A:A,B29,J:J) -> 0 | Q29: =SUMIF(A:A,B29,K:K) -> 0 | R29: =SUMIF(A:A,B29,L:L) -> 0
C30: # of Agents | E30: ALP per sale | F30: Show Rate | G30: Close Ratio | H30: ALP/Agent | J30: POS Close | L30: VET Close | M30: REF Per Sit | O30: REF Close | Q30: OTS Close
C31: =COUNTIFS(A:A,B29) -> 17 | E31: =IFERROR(C29/H29,0) -> 0 | F31: =IFERROR((G29+R29)/F29,0) -> 0 | G31: =IFERROR(H29/G29,0) -> 0 | H31: =(C29/C31) -> 0 | J31: =IFERROR(J29/I29,0) -> 0 | L31: =IFERROR(L29/K29,0) -> 0 | M31: =IFERROR(M29/SUM(R29+G29,0),"") | O31: =IFERROR(O29/N29,0) -> 0 | Q31: =IFERROR(Q29/P29,0) -> 0
B32: Kenneth Preston | C32: =SUMIF(A:A,B32,T:T) -> 0 | E32: =SUMIFS(T:T,A:A,B32,D:D,"Y") -> 0 | F32: =SUMIF(A:A,B32,G:G) -> 0 | G32: =SUMIF(A:A,B32,H:H) -> 0 | H32: =SUMIF(A:A,B32,I:I) -> 0 | I32: =SUMIF(A:A,B32,P:P) -> 0 | J32: =SUMIF(A:A,B32,Q:Q) -> 0 | K32: =SUMIF(A:A,B32,R:R) -> 0 | L32: =SUMIF(A:A,B32,S:S) -> 0 | M32: =SUMIF(A:A,B32,M:M) -> 0 | N32: =SUMIF(A:A,B32,N:N) -> 0 | O32: =SUMIF(A:A,B32,O:O) -> 0 | P32: =SUMIF(A:A,B32,J:J) -> 0 | Q32: =SUMIF(A:A,B32,K:K) -> 0 | R32: =SUMIF(A:A,B32,L:L) -> 0
C33: # of Agents | E33: ALP per sale | F33: Show Rate | G33: Close Ratio | H33: ALP/Agent | J33: POS Close | L33: VET Close | M33: REF Per Sit | O33: REF Close | Q33: OTS Close
C34: =COUNTIFS(A:A,B32) -> 2 | E34: =IFERROR(C32/H32,0) -> 0 | F34: =IFERROR((G32+R32)/F32,0) -> 0 | G34: =IFERROR(H32/G32,0) -> 0 | H34: =(C32/C34) -> 0 | J34: =IFERROR(J32/I32,0) -> 0 | L34: =IFERROR(L32/K32,0) -> 0 | M34: =IFERROR(M32/SUM(R32+G32,0),"") | O34: =IFERROR(O32/N32,0) -> 0 | Q34: =IFERROR(Q32/P32,0) -> 0
A36: MGA | B36: GA | C36: SA | E36: State | F36: Agent | G36: SETS | H36: SITS | I36: SALES | J36: OTS SITS | K36: OTS SALES | L36: N1 | M36: REF OBT | N36: REF SITS | O36: REF SALES | P36: POS SITS | Q36: POS SALES | R36: VETS SITS | S36: VET SALES | T36: ALP | U36: Close | V36: Show | W36: Code Date
A37: Joseph Gojcaj | D37: Y | E37: MI | F37: Joseph Gojcaj | U37: =IFERROR(I37/H37,0) -> 0 | V37: =IFERROR(SUM(H37+L37)/G37,0) -> 0
A38: Joseph Gojcaj | B38: Jacob Brown | D38: Y | E38: MI | F38: Jacob Brown | U38: =IFERROR(I38/H38,0) -> 0 | V38: =IFERROR(SUM(H38+L38)/G38,0) -> 0
A39: Joseph Gojcaj | B39: Jacob Brown | C39: Kristen Fox | D39: Y | E39: NC | F39: Kristen Fox | G39: 1 | H39: 1 | I39: 0 | J39: 1 | K39: 0 | L39: 0 | M39: 0 | N39: 0 | O39: 0 | P39: 0 | Q39: 0 | R39: 1 | S39: 0 | U39: =IFERROR(I39/H39,0) -> 0 | V39: =IFERROR(SUM(H39+L39)/G39,0) -> 1
A40: Joseph Gojcaj | B40: Jacob Brown | C40: Kristen Fox | F40: Marci Dyer | G40: 0 | H40: 0 | I40: 0 | J40: 0 | K40: 0 | L40: 0 | M40: 0 | N40: 0 | O40: 0 | P40: 0 | Q40: 0 | R40: 0 | S40: 0 | U40: =IFERROR(I40/H40,0) -> 0 | V40: =IFERROR(SUM(H40+L40)/G40,0) -> 0
A41: Joseph Gojcaj | B41: Jacob Brown | C41: Joylynn Harris | D41: Y | E41: CA | F41: Joylynn Harris | G41: 0 | H41: 1 | I41: 0 | J41: 1 | K41: 0 | L41: 0 | M41: 7 | N41: 1 | O41: 0 | P41: 0 | Q41: 0 | R41: 0 | S41: 0 | T41: 0 | U41: =IFERROR(I41/H41,0) -> 0 | V41: =IFERROR(SUM(H41+L41)/G41,0) -> 0
...

Sheet Sat
C1: ALP | E1: LEADERSHIP ALP | F1: Appts | G1: Pres | H1: Sales | I1: POS SITS | J1: POS SA | K1: VET SITS | L1: VET SA | M1: REF OBT | N1: REF SITS | O1: REF SA | P1: OTS SITS | Q1: OTS SA | R1: N1
B2: GOJCAJ RGA | C2: =SUM(C5,C20,C23,C26,C29,C32) -> 7369 | E2: =SUM(E5,E20,E23,E26,E29,E32) -> 6064 | F2: =SUM(F5,F20,F23,F26,F29,F32) -> 19 | G2: =SUM(G5,G20,G23,G26,G29,G32) -> 12 | H2: =SUM(H5,H20,H23,H26,H29,H32) -> 4 | I2: =SUM(I5,I20,I23,I26,I29,I32) -> 3 | J2: =SUM(J5,J20,J23,J26,J29,J32) -> 1 | K2: =SUM(K5,K20,K23,K26,K29,K32) -> 3 | L2: =SUM(L5,L20,L23,L26,L29,L32) -> 2 | ... R2: =SUM(R5,R20,R23,R26,R29,R32) -> 2
C3: # of Agents | E3: ALP per sale | F3: Show Rate | G3: Close Ratio | H3: ALP/Agent | J3: POS Close | L3: VET Close | M3: REF Per Sit | O3: REF Close | Q3: OTS Close
C4: =SUM(C7,C25,C22,C28,C31,C34) -> 63 | E4: =IFERROR(C2/H2,0) -> 1842.25 | F4: =IFERROR((G2+R2)/F2,0) -> 0.73684211 | G4: =IFERROR(H2/G2,0) -> 0.33333333 | H4: =(C2/C4) -> 116.96825 | J4: =IFERROR(J2/I2,0) -> 0.33333333 | L4: =IFERROR(L2/K2,0) -> 0.66666667 | M4: =IFERROR(M2/G2,0) -> 3.3333333 | O4: =IFERROR(O2/N2,0) -> 0.2 | Q4: =IFERROR(Q2/P2,0) -> 0.25
B5: Joseph Gojcaj | C5: =SUMIF(A:A,B5,T:T) -> 7369 | E5: =SUMIFS(T:T,A:A,B5,D:D,"Y") -> 6064 | F5: =SUMIF(A:A,B5,G:G) -> 19 | G5: =SUMIF(A:A,B5,H:H) -> 12 | H5: =SUMIF(A:A,B5,I:I) -> 4 | I5: =SUMIF(A:A,B5,P:P) -> 3 | J5: =SUMIF(A:A,B5,Q:Q) -> 1 | K5: =SUMIF(A:A,B5,R:R) -> 3 | L5: =SUMIF(A:A,B5,S:S) -> 2 | M5: =SUMIF(A:A,B5,M:M) -> 40 | N5: =SUMIF(A:A,B5,N:N) -> 5 | O5: =SUMIF(A:A,B5,O:O) -> 1 | P5: =SUMIF(A:A,B5,J:J) -> 4 | Q5: =SUMIF(A:A,B5,K:K) -> 1 | R5: =SUMIF(A:A,B5,L:L) -> 2
