Workbook

Sheet Weekly Totals
C1: ALP | E1: LEADERSHIP ALP | F1: Appts | G1: Pres | H1: Sales | I1: POS SITS | J1: POS SA | K1: VET SITS | L1: VET SA | M1: REF OBT | N1: REF SITS | O1: REF SA | P1: OTS SITS | Q1: OTS SA | R1: N1
B2: Mohamed Aljahmi RGA | C2: =SUM(C5) -> 48446 | E2: =SUM(E5) -> 17404 | F2: =SUM(F5) -> #REF! | G2: =SUM(G5) -> 60 | H2: =SUM(H5) -> 32 | I2: =SUM(I5) -> 12 | J2: =SUM(J5) -> 5 | K2: =SUM(K5) -> 13 | L2: =SUM(L5) -> 3 | ... R2: =SUM(R5) -> 11
C3: # of Agents | E3: ALP per sale | F3: SHOW RATE | G3: CLOSE RATIO | H3: ALP/ AGENT | J3: POS CLOSE | L3: VET CLOSE | M3: REF PER SIT | O3: REF CLOSE | Q3: OTS CLOSE
C4: =SUM(C7,) -> 28 | E4: =IFERROR(C2/H2,0) -> 1513.9375 | F4: =IFERROR((G2+R2)/F2,0) -> 0 | G4: =IFERROR(H2/G2,0) -> 0.53333333 | H4: =(C2/C4) -> 1730.2143 | J4: =IFERROR(J2/I2,0) -> 0.41666667 | L4: =IFERROR(L2/K2,0) -> 0.23076923 | M4: =IFERROR(M2/G2,0) -> 2.7166667 | O4: =IFERROR(O2/N2,0) -> 0.66666667 | Q4: =IFERROR(Q2/P2,0) -> 0.48275862
B5: Mohamed Aljahmi | C5: =SUMIF(A:A,B5,T:T) -> 48446 | E5: =SUMIFS(T:T,A:A,B5,D:D,"Y") -> 17404 | F5: =SUMIF(A:A,B5,G:G) -> #REF! | G5: =SUMIF(A:A,B5,H:H) -> 60 | H5: =SUMIF(A:A,B5,I:I) -> 32 | I5: =SUMIF(A:A,B5,P:P) -> 12 | J5: =SUMIF(A:A,B5,Q:Q) -> 5 | K5: =SUMIF(A:A,B5,R:R) -> 13 | L5: =SUMIF(A:A,B5,S:S) -> 3 | M5: =SUMIF(A:A,B5,M:M) -> 163 | N5: =SUMIF(A:A,B5,N:N) -> 33 | O5: =SUMIF(A:A,B5,O:O) -> 22 | P5: =SUMIF(A:A,B5,J:J) -> 29 | Q5: =SUMIF(A:A,B5,K:K) -> 14 | R5: =SUMIF(A:A,B5,L:L) -> 11
C6: # of Agents | E6: ALP per sale | F6: SHOW RATE | G6: CLOSE RATIO | H6: ALP/ AGENT | J6: POS CLOSE | L6: VET CLOSE | M6: REF PER SIT | O6: REF CLOSE | Q6: OTS CLOSE
C7: =COUNTIFS(A:A,B5) -> 28 | E7: =IFERROR(C5/H5,0) -> 1513.9375 | F7: =IFERROR((G5+R5)/F5,0) -> 0 | G7: =IFERROR(H5/G5,0) -> 0.53333333 | H7: =(C5/C7) -> 1730.2143 | J7: =IFERROR(J5/I5,0) -> 0.41666667 | L7: =IFERROR(L5/K5,0) -> 0.23076923 | M7: =IFERROR(M5/SUM(R5+G5,0),"") -> 2.2957746 | O7: =IFERROR(O5/N5,0) -> 0.66666667 | Q7: =IFERROR(Q5/P5,0) -> 0.48275862
B8: Ali Musa | C8: =SUMIF(B:B,B8,T:T) -> 48446 | E8: =SUMIFS(T:T,B:B,B8,D:D,"Y") -> 17404 | F8: =SUMIF(B16:B1037,B8,G16:G1037) -> #REF! | G8: =SUMIF(B16:B1037,B8,H16:H1037) -> 60 | H8: =SUMIF(B16:B1037,B8,I16:I1037) -> 32 | I8: =SUMIF(B16:B1037,B8,P16:P1037) -> 12 | J8: =SUMIF(B16:B1037,B8,Q16:Q1037) -> 5 | K8: =SUMIF(B16:B1037,B8,R16:R1037) -> 13 | L8: =SUMIF(B16:B1037,B8,S16:S1037) -> 3 | M8: =SUMIF(B16:B1037,B8,M16:M1037) -> 163 | N8: =SUMIF(B16:B1037,B8,N16:N1037) -> 33 | O8: =SUMIF(B16:B1037,B8,O16:O1037) -> 22 | P8: =SUMIF(B16:B1037,B8,J16:J1037) -> 29 | Q8: =SUMIF(B16:B1037,B8,K16:K1037) -> 14 | R8: =SUMIF(B16:B1037,B8,L16:L1037) -> 11
C9: # of Agents | E9: ALP per sale | F9: SHOW RATE | G9: CLOSE RATIO | H9: ALP/ AGENT | J9: POS CLOSE | L9: VET CLOSE | M9: REF PER SIT | O9: REF CLOSE | Q9: OTS CLOSE
C10: =COUNTIFS(B16:B1037,B8) -> 25 | E10: =IFERROR(C8/H8,0) -> 1513.9375 | F10: =IFERROR((G8+R8)/F8,0) -> 0 | G10: =IFERROR(H8/G8,0) -> 0.53333333 | H10: =(C8/C10) -> 1937.84 | J10: =IFERROR(J8/I8,0) -> 0.41666667 | L10: =IFERROR(L8/K8,0) -> 0.23076923 | M10: =IFERROR(M8/SUM(G8+R8,0),"") -> 2.2957746 | O10: =IFERROR(O8/N8,0) -> 0.66666667 | Q10: =IFERROR(Q8/P8,0) -> 0.48275862
B11: Jeanieliza Solis | C11: =SUMIF(B:B,B11,T:T) -> 0 | E11: =SUMIFS(T:T,B:B,B11,D:D,"Y") -> 0 | F11: =SUMIF(B45:B1037,B11,G45:G1037) -> 0 | G11: =SUMIF(B45:B1037,B11,H45:H1037) -> 0 | H11: =SUMIF(B45:B1037,B11,I45:I1037) -> 0 | I11: =SUMIF(B45:B1037,B11,P45:P1037) -> 0 | J11: =SUMIF(B45:B1037,B11,Q45:Q1037) -> 0 | K11: =SUMIF(B45:B1037,B11,R45:R1037) -> 0 | L11: =SUMIF(B45:B1037,B11,S45:S1037) -> 0 | M11: =SUMIF(B45:B1037,B11,M45:M1037) -> 0 | N11: =SUMIF(B45:B1037,B11,N45:N1037) -> 0 | O11: =SUMIF(B45:B1037,B11,O45:O1037) -> 0 | P11: =SUMIF(B45:B1037,B11,J45:J1037) -> 0 | Q11: =SUMIF(B45:B1037,B11,K45:K1037) -> 0 | R11: =SUMIF(B45:B1037,B11,L45:L1037) -> 0
C12: # of Agents | E12: ALP per sale | F12: SHOW RATE | G12: CLOSE RATIO | H12: ALP/ AGENT | J12: POS CLOSE | L12: VET CLOSE | M12: REF PER SIT | O12: REF CLOSE | Q12: OTS CLOSE
C13: =COUNTIFS(B16:B1037,B11) -> 2 | E13: =IFERROR(C11/H11,0) -> 0 | F13: =IFERROR((G11+R11)/F11,0) -> 0 | G13: =IFERROR(H11/G11,0) -> 0 | H13: =(C11/C13) -> 0 | J13: =IFERROR(J11/I11,0) -> 0 | L13: =IFERROR(L11/K11,0) -> 0 | M13: =IFERROR(M11/SUM(G11+R11,0),"") | O13: =IFERROR(O11/N11,0) -> 0 | Q13: =IFERROR(Q11/P11,0) -> 0
A16: MGA | B16: GA | C16: SA | D16: LDR | E16: RESIDENT STATE | F16: Agent | G16: SETS | H16: SITS | I16: SALES | J16: OTS SITS | K16: OTS SALES | L16: N1 | M16: REF OBT | N16: REF SITS | O16: REF SALES | P16: POS SITS | Q16: POS SALES | R16: VETS SITS | S16: VET SALES | T16: ALP | U16: Close Rate | V16: Show Rate
A17: Mohamed Aljahmi | D17: Y | E17: MI | F17: Mohamed Aljahmi | G17: =('Thurs (2)'!G17+Thurs!G17+'Tues '!G17+Wed!G17+Fri!G17+'Mon '!G17+'Wed (2)'!G17+Sun!G17+Sat!G17) -> 0 | H17: =('Thurs (2)'!H17+Thurs!H17+'Tues '!H17+Wed!H17+Fri!H17+'Mon '!H17+'Wed (2)'!H17+Sun!H17+Sat!H17) -> 0 | I17: =('Thurs (2)'!I17+Thurs!I17+'Tues '!I17+Wed!I17+Fri!I17+'Mon '!I17+'Wed (2)'!I17+Sun!I17+Sat!I17) -> 0 | J17: =('Thurs (2)'!J17+Thurs!J17+'Tues '!J17+Wed!J17+Fri!J17+'Mon '!J17+'Wed (2)'!J17+Sun!J17+Sat!J17) -> 0 | K17: =('Thurs (2)'!K17+Thurs!K17+'Tues '!K17+Wed!K17+Fri!K17+'Mon '!K17+'Wed (2)'!K17+Sun!K17+Sat!K17) -> 0 | L17: =('Thurs (2)'!L17+Thurs!L17+'Tues '!L17+Wed!L17+Fri!L17+'Mon '!L17+'Wed (2)'!L17+Sun!L17+Sat!L17) -> 0 | M17: =('Thurs (2)'!M17+Thurs!M17+'Tues '!M17+Wed!M17+Fri!M17+'Mon '!M17+'Wed (2)'!M17+Sun!M17+Sat!M17) -> 0 | N17: =('Thurs (2)'!N17+Thurs!N17+'Tues '!N17+Wed!N17+Fri!N17+'Mon '!N17+'Wed (2)'!N17+Sun!N17+Sat!N17) -> 0 | ... T17: =('Thurs (2)'!T17+Thurs!T17+'Tues '!T17+Wed!T17+Fri!T17+'Mon '!T17+'Wed (2)'!T17+Sun!T17+Sat!T17) -> 0 | U17: =IFERROR(I17/H17,0) -> 0 | V17: =IFERROR(SUM(H17+L17)/G17,0) -> 0
A18: Mohamed Aljahmi | B18: Ali Musa | D18: Y | E18: MI | F18: Ali Musa | G18: =('Thurs (2)'!G18+Thurs!G18+'Tues '!G18+Wed!G18+Fri!G18+'Mon '!G18+'Wed (2)'!G18+Sun!G18+Sat!G18) -> 0 | H18: =('Thurs (2)'!H18+Thurs!H18+'Tues '!H18+Wed!H18+Fri!H18+'Mon '!H18+'Wed (2)'!H18+Sun!H18+Sat!H18) -> 0 | I18: =('Thurs (2)'!I18+Thurs!I18+'Tues '!I18+Wed!I18+Fri!I18+'Mon '!I18+'Wed (2)'!I18+Sun!I18+Sat!I18) -> 0 | J18: =('Thurs (2)'!J18+Thurs!J18+'Tues '!J18+Wed!J18+Fri!J18+'Mon '!J18+'Wed (2)'!J18+Sun!J18+Sat!J18) -> 0 | K18: =('Thurs (2)'!K18+Thurs!K18+'Tues '!K18+Wed!K18+Fri!K18+'Mon '!K18+'Wed (2)'!K18+Sun!K18+Sat!K18) -> 0 | L18: =('Thurs (2)'!L18+Thurs!L18+'Tues '!L18+Wed!L18+Fri!L18+'Mon '!L18+'Wed (2)'!L18+Sun!L18+Sat!L18) -> 0 | M18: =('Thurs (2)'!M18+Thurs!M18+'Tues '!M18+Wed!M18+Fri!M18+'Mon '!M18+'Wed (2)'!M18+Sun!M18+Sat!M18) -> 0 | N18: =('Thurs (2)'!N18+Thurs!N18+'Tues '!N18+Wed!N18+Fri!N18+'Mon '!N18+'Wed (2)'!N18+Sun!N18+Sat!N18) -> 0 | ... T18: =('Thurs (2)'!T18+Thurs!T18+'Tues '!T18+Wed!T18+Fri!T18+'Mon '!T18+'Wed (2)'!T18+Sun!T18+Sat!T18) -> 0 | U18: =IFERROR(I18/H18,0) -> 0 | V18: =IFERROR(SUM(H18+L18)/G18,0) -> 0
A19: Mohamed Aljahmi | B19: Ali Musa | E19: MI | F19: Adam Youssef | G19: =('Thurs (2)'!G19+Thurs!G19+'Tues '!G19+Wed!G19+Fri!G19+'Mon '!G19+'Wed (2)'!G19+Sun!G19+Sat!G19) -> 0 | H19: =('Thurs (2)'!H19+Thurs!H19+'Tues '!H19+Wed!H19+Fri!H19+'Mon '!H19+'Wed (2)'!H19+Sun!H19+Sat!H19) -> 0 | I19: =('Thurs (2)'!I19+Thurs!I19+'Tues '!I19+Wed!I19+Fri!I19+'Mon '!I19+'Wed (2)'!I19+Sun!I19+Sat!I19) -> 0 | J19: =('Thurs (2)'!J19+Thurs!J19+'Tues '!J19+Wed!J19+Fri!J19+'Mon '!J19+'Wed (2)'!J19+Sun!J19+Sat!J19) -> 0 | K19: =('Thurs (2)'!K19+Thurs!K19+'Tues '!K19+Wed!K19+Fri!K19+'Mon '!K19+'Wed (2)'!K19+Sun!K19+Sat!K19) -> 0 | L19: =('Thurs (2)'!L19+Thurs!L19+'Tues '!L19+Wed!L19+Fri!L19+'Mon '!L19+'Wed (2)'!L19+Sun!L19+Sat!L19) -> 0 | M19: =('Thurs (2)'!M19+Thurs!M19+'Tues '!M19+Wed!M19+Fri!M19+'Mon '!M19+'Wed (2)'!M19+Sun!M19+Sat!M19) -> 0 | N19: =('Thurs (2)'!N19+Thurs!N19+'Tues '!N19+Wed!N19+Fri!N19+'Mon '!N19+'Wed (2)'!N19+Sun!N19+Sat!N19) -> 0 | ... T19: =('Thurs (2)'!T19+Thurs!T19+'Tues '!T19+Wed!T19+Fri!T19+'Mon '!T19+'Wed (2)'!T19+Sun!T19+Sat!T19) -> 0 | U19: =IFERROR(I19/H19,0) -> 0 | V19: =IFERROR(SUM(H19+L19)/G19,0) -> 0
A20: Mohamed Aljahmi | B20: Ali Musa | E20: MI | F20: Aleskander Murshed | G20: =('Thurs (2)'!G20+Thurs!G20+'Tues '!G20+Wed!G20+Fri!G20+'Mon '!G20+'Wed (2)'!G20+Sun!G20+Sat!G20) -> 0 | H20: =('Thurs (2)'!H20+Thurs!H20+'Tues '!H20+Wed!H20+Fri!H20+'Mon '!H20+'Wed (2)'!H20+Sun!H20+Sat!H20) -> 0 | I20: =('Thurs (2)'!I20+Thurs!I20+'Tues '!I20+Wed!I20+Fri!I20+'Mon '!I20+'Wed (2)'!I20+Sun!I20+Sat!I20) -> 0 | J20: =('Thurs (2)'!J20+Thurs!J20+'Tues '!J20+Wed!J20+Fri!J20+'Mon '!J20+'Wed (2)'!J20+Sun!J20+Sat!J20) -> 0 | K20: =('Thurs (2)'!K20+Thurs!K20+'Tues '!K20+Wed!K20+Fri!K20+'Mon '!K20+'Wed (2)'!K20+Sun!K20+Sat!K20) -> 0 | L20: =('Thurs (2)'!L20+Thurs!L20+'Tues '!L20+Wed!L20+Fri!L20+'Mon '!L20+'Wed (2)'!L20+Sun!L20+Sat!L20) -> 0 | M20: =('Thurs (2)'!M20+Thurs!M20+'Tues '!M20+Wed!M20+Fri!M20+'Mon '!M20+'Wed (2)'!M20+Sun!M20+Sat!M20) -> 0 | N20: =('Thurs (2)'!N20+Thurs!N20+'Tues '!N20+Wed!N20+Fri!N20+'Mon '!N20+'Wed (2)'!N20+Sun!N20+Sat!N20) -> 0 | ... T20: =('Thurs (2)'!T20+Thurs!T20+'Tues '!T20+Wed!T20+Fri!T20+'Mon '!T20+'Wed (2)'!T20+Sun!T20+Sat!T20) -> 0 | U20: =IFERROR(I20/H20,0) -> 0 | V20: =IFERROR(SUM(H20+L20)/G20,0) -> 0
A21: Mohamed Aljahmi | B21: Ali Musa | E21: OH | F21: Connor Cook | G21: =('Thurs (2)'!G21+Thurs!G21+'Tues '!G21+Wed!G21+Fri!G21+'Mon '!G21+'Wed (2)'!G21+Sun!G21+Sat!G21) -> 0 | H21: =('Thurs (2)'!H21+Thurs!H21+'Tues '!H21+Wed!H21+Fri!H21+'Mon '!H21+'Wed (2)'!H21+Sun!H21+Sat!H21) -> 0 | I21: =('Thurs (2)'!I21+Thurs!I21+'Tues '!I21+Wed!I21+Fri!I21+'Mon '!I21+'Wed (2)'!I21+Sun!I21+Sat!I21) -> 0 | J21: =('Thurs (2)'!J21+Thurs!J21+'Tues '!J21+Wed!J21+Fri!J21+'Mon '!J21+'Wed (2)'!J21+Sun!J21+Sat!J21) -> 0 | K21: =('Thurs (2)'!K21+Thurs!K21+'Tues '!K21+Wed!K21+Fri!K21+'Mon '!K21+'Wed (2)'!K21+Sun!K21+Sat!K21) -> 0 | L21: =('Thurs (2)'!L21+Thurs!L21+'Tues '!L21+Wed!L21+Fri!L21+'Mon '!L21+'Wed (2)'!L21+Sun!L21+Sat!L21) -> 0 | M21: =('Thurs (2)'!M21+Thurs!M21+'Tues '!M21+Wed!M21+Fri!M21+'Mon '!M21+'Wed (2)'!M21+Sun!M21+Sat!M21) -> 0 | N21: =('Thurs (2)'!N21+Thurs!N21+'Tues '!N21+Wed!N21+Fri!N21+'Mon '!N21+'Wed (2)'!N21+Sun!N21+Sat!N21) -> 0 | ... T21: =('Thurs (2)'!T21+Thurs!T21+'Tues '!T21+Wed!T21+Fri!T21+'Mon '!T21+'Wed (2)'!T21+Sun!T21+Sat!T21) -> 0 | U21: =IFERROR(I21/H21,0) -> 0 | V21: =IFERROR(SUM(H21+L21)/G21,0) -> 0
A22: Mohamed Aljahmi | B22: Ali Musa | C22: Cameron Porter | D22: Y | E22: CA | F22: Cameron Porter | G22: =('Thurs (2)'!G22+Thurs!G22+'Tues '!G22+Wed!G22+Fri!G22+'Mon '!G22+'Wed (2)'!G22+Sun!G22+Sat!G22) -> 10 | H22: =('Thurs (2)'!H22+Thurs!H22+'Tues '!H22+Wed!H22+Fri!H22+'Mon '!H22+'Wed (2)'!H22+Sun!H22+Sat!H22) -> 5 | I22: =('Thurs (2)'!I22+Thurs!I22+'Tues '!I22+Wed!I22+Fri!I22+'Mon '!I22+'Wed (2)'!I22+Sun!I22+Sat!I22) -> 3 | J22: =('Thurs (2)'!J22+Thurs!J22+'Tues '!J22+Wed!J22+Fri!J22+'Mon '!J22+'Wed (2)'!J22+Sun!J22+Sat!J22) -> 1 | K22: =('Thurs (2)'!K22+Thurs!K22+'Tues '!K22+Wed!K22+Fri!K22+'Mon '!K22+'Wed (2)'!K22+Sun!K22+Sat!K22) -> 1 | L22: =('Thurs (2)'!L22+Thurs!L22+'Tues '!L22+Wed!L22+Fri!L22+'Mon '!L22+'Wed (2)'!L22+Sun!L22+Sat!L22) -> 0 | M22: =('Thurs (2)'!M22+Thurs!M22+'Tues '!M22+Wed!M22+Fri!M22+'Mon '!M22+'Wed (2)'!M22+Sun!M22+Sat!M22) -> 14 | N22: =('Thurs (2)'!N22+Thurs!N22+'Tues '!N22+Wed!N22+Fri!N22+'Mon '!N22+'Wed (2)'!N22+Sun!N22+Sat!N22) -> 0 | ... T22: =('Thurs (2)'!T22+Thurs!T22+'Tues '!T22+Wed!T22+Fri!T22+'Mon '!T22+'Wed (2)'!T22+Sun!T22+Sat!T22) -> 3323 | U22: =IFERROR(I22/H22,0) -> 0.6 | V22: =IFERROR(SUM(H22+L22)/G22,0) -> 0.5
A23: Mohamed Aljahmi | B23: Ali Musa | C23: Cameron Porter | E23: CA | F23: Gabriela Romero | G23: =('Thurs (2)'!G23+Thurs!G23+'Tues '!G23+Wed!G23+Fri!G23+'Mon '!G23+'Wed (2)'!G23+Sun!G23+Sat!G23) -> 9 | H23: =('Thurs (2)'!H23+Thurs!H23+'Tues '!H23+Wed!H23+Fri!H23+'Mon '!H23+'Wed (2)'!H23+Sun!H23+Sat!H23) -> 3 | I23: =('Thurs (2)'!I23+Thurs!I23+'Tues '!I23+Wed!I23+Fri!I23+'Mon '!I23+'Wed (2)'!I23+Sun!I23+Sat!I23) -> 0 | J23: =('Thurs (2)'!J23+Thurs!J23+'Tues '!J23+Wed!J23+Fri!J23+'Mon '!J23+'Wed (2)'!J23+Sun!J23+Sat!J23) -> 1 | K23: =('Thurs (2)'!K23+Thurs!K23+'Tues '!K23+Wed!K23+Fri!K23+'Mon '!K23+'Wed (2)'!K23+Sun!K23+Sat!K23) -> 0 | L23: =('Thurs (2)'!L23+Thurs!L23+'Tues '!L23+Wed!L23+Fri!L23+'Mon '!L23+'Wed (2)'!L23+Sun!L23+Sat!L23) -> 1 | M23: =('Thurs (2)'!M23+Thurs!M23+'Tues '!M23+Wed!M23+Fri!M23+'Mon '!M23+'Wed (2)'!M23+Sun!M23+Sat!M23) -> 11 | N23: =('Thurs (2)'!N23+Thurs!N23+'Tues '!N23+Wed!N23+Fri!N23+'Mon '!N23+'Wed (2)'!N23+Sun!N23+Sat!N23) -> 1 | ... T23: =('Thurs (2)'!T23+Thurs!T23+'Tues '!T23+Wed!T23+Fri!T23+'Mon '!T23+'Wed (2)'!T23+Sun!T23+Sat!T23) -> 0 | U23: =IFERROR(I23/H23,0) -> 0 | V23: =IFERROR(SUM(H23+L23)/G23,0) -> 0.44444444
A24: Mohamed Aljahmi | B24: Ali Musa | C24: Cameron Porter | E24: GA | F24: Hannah Sanders | G24: =('Thurs (2)'!G24+Thurs!G24+'Tues '!G24+Wed!G24+Fri!G24+'Mon '!G24+'Wed (2)'!G24+Sun!G24+Sat!G25) -> 17 | H24: =('Thurs (2)'!H24+Thurs!H24+'Tues '!H24+Wed!H24+Fri!H24+'Mon '!H24+'Wed (2)'!H24+Sun!H24+Sat!H24) -> 7 | I24: =('Thurs (2)'!I24+Thurs!I24+'Tues '!I24+Wed!I24+Fri!I24+'Mon '!I24+'Wed (2)'!I24+Sun!I24+Sat!I24) -> 4 | J24: =('Thurs (2)'!J24+Thurs!J24+'Tues '!J24+Wed!J24+Fri!J24+'Mon '!J24+'Wed (2)'!J24+Sun!J24+Sat!J24) -> 1 | K24: =('Thurs (2)'!K24+Thurs!K24+'Tues '!K24+Wed!K24+Fri!K24+'Mon '!K24+'Wed (2)'!K24+Sun!K24+Sat!K24) -> 0 | L24: =('Thurs (2)'!L24+Thurs!L24+'Tues '!L24+Wed!L24+Fri!L24+'Mon '!L24+'Wed (2)'!L24+Sun!L24+Sat!L24) -> 2 | M24: =('Thurs (2)'!M24+Thurs!M24+'Tues '!M24+Wed!M24+Fri!M24+'Mon '!M24+'Wed (2)'!M24+Sun!M24+Sat!M24) -> 25 | N24: =('Thurs (2)'!N24+Thurs!N24+'Tues '!N24+Wed!N24+Fri!N24+'Mon '!N24+'Wed (2)'!N24+Sun!N24+Sat!N24) -> 6 | O24: =('Thurs (2)'!O24+Thurs!O24+'Tues '!O24+Wed!O24+Fri!O24+'Mon '!O24+'Wed (2)'!O24+Sun!O24+Sat!O24) -> 4 | ... T24: =('Thurs (2)'!T24+Thurs!T24+'Tues '!T24+Wed!T24+Fri!T24+'Mon '!T24+'Wed (2)'!T24+Sun!T24+Sat!T24) -> 7121 | U24: =IFERROR(I24/H24,0) -> 0.57142857 | V24: =IFERROR(SUM(H24+L24)/G24,0) -> 0.52941176
A25: Mohamed Aljahmi | B25: Ali Musa | C25: Cameron Porter | F25: Tyren Cosare | G25: =('Thurs (2)'!G25+Thurs!G25+'Tues '!G25+Wed!G25+Fri!G25+'Mon '!G25+'Wed (2)'!G25+Sun!G25+#REF!) -> #REF! | H25: =('Thurs (2)'!H25+Thurs!H25+'Tues '!H25+Wed!H25+Fri!H25+'Mon '!H25+'Wed (2)'!H25+Sun!H25+Sat!H25) -> 2 | I25: =('Thurs (2)'!I25+Thurs!I25+'Tues '!I25+Wed!I25+Fri!I25+'Mon '!I25+'Wed (2)'!I25+Sun!I25+Sat!I25) -> 1 | J25: =('Thurs (2)'!J25+Thurs!J25+'Tues '!J25+Wed!J25+Fri!J25+'Mon '!J25+'Wed (2)'!J25+Sun!J25+Sat!J25) -> 2 | K25: =('Thurs (2)'!K25+Thurs!K25+'Tues '!K25+Wed!K25+Fri!K25+'Mon '!K25+'Wed (2)'!K25+Sun!K25+Sat!K25) -> 1 | L25: =('Thurs (2)'!L25+Thurs!L25+'Tues '!L25+Wed!L25+Fri!L25+'Mon '!L25+'Wed (2)'!L25+Sun!L25+Sat!L25) -> 0 | M25: =('Thurs (2)'!M25+Thurs!M25+'Tues '!M25+Wed!M25+Fri!M25+'Mon '!M25+'Wed (2)'!M25+Sun!M25+Sat!M25) -> 0 | N25: =('Thurs (2)'!N25+Thurs!N25+'Tues '!N25+Wed!N25+Fri!N25+'Mon '!N25+'Wed (2)'!N25+Sun!N25+Sat!N25) -> 1 | O25: =('Thurs (2)'!O25+Thurs!O25+'Tues '!O25+Wed!O25+Fri!O25+'Mon '!O25+'Wed (2)'!O25+Sun!O25+Sat!O25) -> 1 | ... T25: =('Thurs (2)'!T25+Thurs!T25+'Tues '!T25+Wed!T25+Fri!T25+'Mon '!T25+'Wed (2)'!T25+Sun!T25+Sat!T25) -> 909 | U25: =IFERROR(I25/H25,0) -> 0.5 | V25: =IFERROR(SUM(H25+L25)/G25,0) -> 0
A26: Mohamed Aljahmi | B26: Ali Musa | C26: Henry Long | D26: Y | E26: MI | F26: Henry Long | G26: =('Thurs (2)'!G26+Thurs!G26+'Tues '!G26+Wed!G26+Fri!G26+'Mon '!G26+'Wed (2)'!G26+Sun!G26+Sat!G26) -> 0 | H26: =('Thurs (2)'!H26+Thurs!H26+'Tues '!H26+Wed!H26+Fri!H26+'Mon '!H26+'Wed (2)'!H26+Sun!H26+Sat!H26) -> 0 | I26: =('Thurs (2)'!I26+Thurs!I26+'Tues '!I26+Wed!I26+Fri!I26+'Mon '!I26+'Wed (2)'!I26+Sun!I26+Sat!I26) -> 0 | J26: =('Thurs (2)'!J26+Thurs!J26+'Tues '!J26+Wed!J26+Fri!J26+'Mon '!J26+'Wed (2)'!J26+Sun!J26+Sat!J26) -> 0 | K26: =('Thurs (2)'!K26+Thurs!K26+'Tues '!K26+Wed!K26+Fri!K26+'Mon '!K26+'Wed (2)'!K26+Sun!K26+Sat!K26) -> 0 | L26: =('Thurs (2)'!L26+Thurs!L26+'Tues '!L26+Wed!L26+Fri!L26+'Mon '!L26+'Wed (2)'!L26+Sun!L26+Sat!L26) -> 0 | M26: =('Thurs (2)'!M26+Thurs!M26+'Tues '!M26+Wed!M26+Fri!M26+'Mon '!M26+'Wed (2)'!M26+Sun!M26+Sat!M26) -> 0 | N26: =('Thurs (2)'!N26+Thurs!N26+'Tues '!N26+Wed!N26+Fri!N26+'Mon '!N26+'Wed (2)'!N26+Sun!N26+Sat!N26) -> 0 | ... T26: =('Thurs (2)'!T26+Thurs!T26+'Tues '!T26+Wed!T26+Fri!T26+'Mon '!T26+'Wed (2)'!T26+Sun!T26+Sat!T26) -> 0 | U26: =IFERROR(I26/H26,0) -> 0 | V26: =IFERROR(SUM(H26+L26)/G26,0) -> 0
A27: Mohamed Aljahmi | B27: Ali Musa | C27: Henry Long | E27: MI | F27: Awni Shuaib | G27: =('Thurs (2)'!G27+Thurs!G27+'Tues '!G27+Wed!G27+Fri!G27+'Mon '!G27+'Wed (2)'!G27+Sun!G27+Sat!G27) -> 28 | H27: =('Thurs (2)'!H27+Thurs!H27+'Tues '!H27+Wed!H27+Fri!H27+'Mon '!H27+'Wed (2)'!H27+Sun!H27+Sat!H27) -> 10 | I27: =('Thurs (2)'!I27+Thurs!I27+'Tues '!I27+Wed!I27+Fri!I27+'Mon '!I27+'Wed (2)'!I27+Sun!I27+Sat!I27) -> 8 | J27: =('Thurs (2)'!J27+Thurs!J27+'Tues '!J27+Wed!J27+Fri!J27+'Mon '!J27+'Wed (2)'!J27+Sun!J27+Sat!J27) -> 8 | K27: =('Thurs (2)'!K27+Thurs!K27+'Tues '!K27+Wed!K27+Fri!K27+'Mon '!K27+'Wed (2)'!K27+Sun!K27+Sat!K27) -> 7 | L27: =('Thurs (2)'!L27+Thurs!L27+'Tues '!L27+Wed!L27+Fri!L27+'Mon '!L27+'Wed (2)'!L27+Sun!L27+Sat!L27) -> 3 | M27: =('Thurs (2)'!M27+Thurs!M27+'Tues '!M27+Wed!M27+Fri!M27+'Mon '!M27+'Wed (2)'!M27+Sun!M27+Sat!M27) -> 33 | N27: =('Thurs (2)'!N27+Thurs!N27+'Tues '!N27+Wed!N27+Fri!N27+'Mon '!N27+'Wed (2)'!N27+Sun!N27+Sat!N27) -> 9 | ... T27: =('Thurs (2)'!T27+Thurs!T27+'Tues '!T27+Wed!T27+Fri!T27+'Mon '!T27+'Wed (2)'!T27+Sun!T27+Sat!T27) -> 13105 | U27: =IFERROR(I27/H27,0) -> 0.8 | V27: =IFERROR(SUM(H27+L27)/G27,0) -> 0.46428571
A28: Mohamed Aljahmi | B28: Ali Musa | C28: Ali Eltanoukhi | D28: Y | E28: MI | F28: Ali Eltanoukhi | G28: =('Thurs (2)'!G28+Thurs!G28+'Tues '!G28+Wed!G28+Fri!G28+'Mon '!G28+'Wed (2)'!G28+Sun!G28+Sat!G28) -> 7 | H28: =('Thurs (2)'!H28+Thurs!H28+'Tues '!H28+Wed!H28+Fri!H28+'Mon '!H28+'Wed (2)'!H28+Sun!H28+Sat!H28) -> 3 | I28: =('Thurs (2)'!I28+Thurs!I28+'Tues '!I28+Wed!I28+Fri!I28+'Mon '!I28+'Wed (2)'!I28+Sun!I28+Sat!I28) -> 2 | J28: =('Thurs (2)'!J28+Thurs!J28+'Tues '!J28+Wed!J28+Fri!J28+'Mon '!J28+'Wed (2)'!J28+Sun!J28+Sat!J28) -> 3 | K28: =('Thurs (2)'!K28+Thurs!K28+'Tues '!K28+Wed!K28+Fri!K28+'Mon '!K28+'Wed (2)'!K28+Sun!K28+Sat!K28) -> 2 | L28: =('Thurs (2)'!L28+Thurs!L28+'Tues '!L28+Wed!L28+Fri!L28+'Mon '!L28+'Wed (2)'!L28+Sun!L28+Sat!L28) -> 0 | M28: =('Thurs (2)'!M28+Thurs!M28+'Tues '!M28+Wed!M28+Fri!M28+'Mon '!M28+'Wed (2)'!M28+Sun!M28+Sat!M28) -> 3 | N28: =('Thurs (2)'!N28+Thurs!N28+'Tues '!N28+Wed!N28+Fri!N28+'Mon '!N28+'Wed (2)'!N28+Sun!N28+Sat!N28) -> 2 | ... T28: =('Thurs (2)'!T28+Thurs!T28+'Tues '!T28+Wed!T28+Fri!T28+'Mon '!T28+'Wed (2)'!T28+Sun!T28+Sat!T28) -> 2800 | U28: =IFERROR(I28/H28,0) -> 0.66666667 | V28: =IFERROR(SUM(H28+L28)/G28,0) -> 0.42857143
A29: Mohamed Aljahmi | B29: Ali Musa | C29: Ali Eltanoukhi | E29: MI | F29: Sajad Aljanaby | G29: =('Thurs (2)'!G29+Thurs!G29+'Tues '!G29+Wed!G29+Fri!G29+'Mon '!G29+'Wed (2)'!G29+Sun!G29+Sat!G29) -> 2 | H29: =('Thurs (2)'!H29+Thurs!H29+'Tues '!H29+Wed!H29+Fri!H29+'Mon '!H29+'Wed (2)'!H29+Sun!H29+Sat!H29) -> 0 | I29: =('Thurs (2)'!I29+Thurs!I29+'Tues '!I29+Wed!I29+Fri!I29+'Mon '!I29+'Wed (2)'!I29+Sun!I29+Sat!I29) -> 0 | J29: =('Thurs (2)'!J29+Thurs!J29+'Tues '!J29+Wed!J29+Fri!J29+'Mon '!J29+'Wed (2)'!J29+Sun!J29+Sat!J29) -> 0 | K29: =('Thurs (2)'!K29+Thurs!K29+'Tues '!K29+Wed!K29+Fri!K29+'Mon '!K29+'Wed (2)'!K29+Sun!K29+Sat!K29) -> 0 | L29: =('Thurs (2)'!L29+Thurs!L29+'Tues '!L29+Wed!L29+Fri!L29+'Mon '!L29+'Wed (2)'!L29+Sun!L29+Sat!L29) -> 0 | M29: =('Thurs (2)'!M29+Thurs!M29+'Tues '!M29+Wed!M29+Fri!M29+'Mon '!M29+'Wed (2)'!M29+Sun!M29+Sat!M29) -> 0 | N29: =('Thurs (2)'!N29+Thurs!N29+'Tues '!N29+Wed!N29+Fri!N29+'Mon '!N29+'Wed (2)'!N29+Sun!N29+Sat!N29) -> 0 | ... T29: =('Thurs (2)'!T29+Thurs!T29+'Tues '!T29+Wed!T29+Fri!T29+'Mon '!T29+'Wed (2)'!T29+Sun!T29+Sat!T29) -> 0 | U29: =IFERROR(I29/H29,0) -> 0 | V29: =IFERROR(SUM(H29+L29)/G29,0) -> 0
A30: Mohamed Aljahmi | B30: Ali Musa | C30: Ali Eltanoukhi | E30: MI | F30: Ali Elrez | G30: =('Thurs (2)'!G30+Thurs!G30+'Tues '!G30+Wed!G30+Fri!G30+'Mon '!G30+'Wed (2)'!G30+Sun!G30+Sat!G30) -> 1 | H30: =('Thurs (2)'!H30+Thurs!H30+'Tues '!H30+Wed!H30+Fri!H30+'Mon '!H30+'Wed (2)'!H30+Sun!H30+Sat!H30) -> 1 | I30: =('Thurs (2)'!I30+Thurs!I30+'Tues '!I30+Wed!I30+Fri!I30+'Mon '!I30+'Wed (2)'!I30+Sun!I30+Sat!I30) -> 1 | J30: =('Thurs (2)'!J30+Thurs!J30+'Tues '!J30+Wed!J30+Fri!J30+'Mon '!J30+'Wed (2)'!J30+Sun!J30+Sat!J30) -> 1 | K30: =('Thurs (2)'!K30+Thurs!K30+'Tues '!K30+Wed!K30+Fri!K30+'Mon '!K30+'Wed (2)'!K30+Sun!K30+Sat!K30) -> 0 | L30: =('Thurs (2)'!L30+Thurs!L30+'Tues '!L30+Wed!L30+Fri!L30+'Mon '!L30+'Wed (2)'!L30+Sun!L30+Sat!L30) -> 0 | M30: =('Thurs (2)'!M30+Thurs!M30+'Tues '!M30+Wed!M30+Fri!M30+'Mon '!M30+'Wed (2)'!M30+Sun!M30+Sat!M30) -> 8 | N30: =('Thurs (2)'!N30+Thurs!N30+'Tues '!N30+Wed!N30+Fri!N30+'Mon '!N30+'Wed (2)'!N30+Sun!N30+Sat!N30) -> 0 | ... T30: =('Thurs (2)'!T30+Thurs!T30+'Tues '!T30+Wed!T30+Fri!T30+'Mon '!T30+'Wed (2)'!T30+Sun!T30+Sat!T30) -> 0 | U30: =IFERROR(I30/H30,0) -> 1 | V30: =IFERROR(SUM(H30+L30)/G30,0) -> 1
A31: Mohamed Aljahmi | B31: Ali Musa | C31: Ali Eltanoukhi | E31: FL | F31: Christine Demaras | G31: =('Thurs (2)'!G31+Thurs!G31+'Tues '!G31+Wed!G31+Fri!G31+'Mon '!G31+'Wed (2)'!G31+Sun!G31+Sat!G31) -> 6 | H31: =('Thurs (2)'!H31+Thurs!H31+'Tues '!H31+Wed!H31+Fri!H31+'Mon '!H31+'Wed (2)'!H31+Sun!H31+Sat!H31) -> 0 | I31: =('Thurs (2)'!I31+Thurs!I31+'Tues '!I31+Wed!I31+Fri!I31+'Mon '!I31+'Wed (2)'!I31+Sun!I31+Sat!I31) -> 0 | J31: =('Thurs (2)'!J31+Thurs!J31+'Tues '!J31+Wed!J31+Fri!J31+'Mon '!J31+'Wed (2)'!J31+Sun!J31+Sat!J31) -> 0 | K31: =('Thurs (2)'!K31+Thurs!K31+'Tues '!K31+Wed!K31+Fri!K31+'Mon '!K31+'Wed (2)'!K31+Sun!K31+Sat!K31) -> 0 | L31: =('Thurs (2)'!L31+Thurs!L31+'Tues '!L31+Wed!L31+Fri!L31+'Mon '!L31+'Wed (2)'!L31+Sun!L31+Sat!L31) -> 0 | M31: =('Thurs (2)'!M31+Thurs!M31+'Tues '!M31+Wed!M31+Fri!M31+'Mon '!M31+'Wed (2)'!M31+Sun!M31+Sat!M31) -> 0 | N31: =('Thurs (2)'!N31+Thurs!N31+'Tues '!N31+Wed!N31+Fri!N31+'Mon '!N31+'Wed (2)'!N31+Sun!N31+Sat!N31) -> 0 | ... T31: =('Thurs (2)'!T31+Thurs!T31+'Tues '!T31+Wed!T31+Fri!T31+'Mon '!T31+'Wed (2)'!T31+Sun!T31+Sat!T31) -> 0 | U31: =IFERROR(I31/H31,0) -> 0 | V31: =IFERROR(SUM(H31+L31)/G31,0) -> 0
A32: Mohamed Aljahmi | B32: Ali Musa | C32: Ali Eltanoukhi | E32: MI | F32: Maher Altairi | G32: =('Thurs (2)'!G32+Thurs!G32+'Tues '!G32+Wed!G32+Fri!G32+'Mon '!G32+'Wed (2)'!G32+Sun!G32+Sat!G32) -> 0 | H32: =('Thurs (2)'!H32+Thurs!H32+'Tues '!H32+Wed!H32+Fri!H32+'Mon '!H32+'Wed (2)'!H32+Sun!H32+Sat!H32) -> 0 | I32: =('Thurs (2)'!I32+Thurs!I32+'Tues '!I32+Wed!I32+Fri!I32+'Mon '!I32+'Wed (2)'!I32+Sun!I32+Sat!I32) -> 0 | J32: =('Thurs (2)'!J32+Thurs!J32+'Tues '!J32+Wed!J32+Fri!J32+'Mon '!J32+'Wed (2)'!J32+Sun!J32+Sat!J32) -> 0 | K32: =('Thurs (2)'!K32+Thurs!K32+'Tues '!K32+Wed!K32+Fri!K32+'Mon '!K32+'Wed (2)'!K32+Sun!K32+Sat!K32) -> 0 | L32: =('Thurs (2)'!L32+Thurs!L32+'Tues '!L32+Wed!L32+Fri!L32+'Mon '!L32+'Wed (2)'!L32+Sun!L32+Sat!L32) -> 2 | M32: =('Thurs (2)'!M32+Thurs!M32+'Tues '!M32+Wed!M32+Fri!M32+'Mon '!M32+'Wed (2)'!M32+Sun!M32+Sat!M32) -> 7 | N32: =('Thurs (2)'!N32+Thurs!N32+'Tues '!N32+Wed!N32+Fri!N32+'Mon '!N32+'Wed (2)'!N32+Sun!N32+Sat!N32) -> 0 | ... T32: =('Thurs (2)'!T32+Thurs!T32+'Tues '!T32+Wed!T32+Fri!T32+'Mon '!T32+'Wed (2)'!T32+Sun!T32+Sat!T32) -> 0 | U32: =IFERROR(I32/H32,0) -> 0 | V32: =IFERROR(SUM(H32+L32)/G32,0) -> 0
A33: Mohamed Aljahmi | B33: Ali Musa | C33: Ali Eltanoukhi | E33: MI | F33: Basel Musaed | G33: =('Thurs (2)'!G33+Thurs!G33+'Tues '!G33+Wed!G33+Fri!G33+'Mon '!G33+'Wed (2)'!G33+Sun!G33+Sat!G33) -> 7 | H33: =('Thurs (2)'!H33+Thurs!H33+'Tues '!H33+Wed!H33+Fri!H33+'Mon '!H33+'Wed (2)'!H33+Sun!H33+Sat!H33) -> 5 | I33: =('Thurs (2)'!I33+Thurs!I33+'Tues '!I33+Wed!I33+Fri!I33+'Mon '!I33+'Wed (2)'!I33+Sun!I33+Sat!I33) -> 1 | J33: =('Thurs (2)'!J33+Thurs!J33+'Tues '!J33+Wed!J33+Fri!J33+'Mon '!J33+'Wed (2)'!J33+Sun!J33+Sat!J33) -> 5 | K33: =('Thurs (2)'!K33+Thurs!K33+'Tues '!K33+Wed!K33+Fri!K33+'Mon '!K33+'Wed (2)'!K33+Sun!K33+Sat!K33) -> 1 | L33: =('Thurs (2)'!L33+Thurs!L33+'Tues '!L33+Wed!L33+Fri!L33+'Mon '!L33+'Wed (2)'!L33+Sun!L33+Sat!L33) -> 0 | M33: =('Thurs (2)'!M33+Thurs!M33+'Tues '!M33+Wed!M33+Fri!M33+'Mon '!M33+'Wed (2)'!M33+Sun!M33+Sat!M33) -> 18 | N33: =('Thurs (2)'!N33+Thurs!N33+'Tues '!N33+Wed!N33+Fri!N33+'Mon '!N33+'Wed (2)'!N33+Sun!N33+Sat!N33) -> 3 | ... T33: =('Thurs (2)'!T33+Thurs!T33+'Tues '!T33+Wed!T33+Fri!T33+'Mon '!T33+'Wed (2)'!T33+Sun!T33+Sat!T33) -> 1500 | U33: =IFERROR(I33/H33,0) -> 0.2 | V33: =IFERROR(SUM(H33+L33)/G33,0) -> 0.71428571
A34: Mohamed Aljahmi | B34: Ali Musa | C34: Ali Eltanoukhi | E34: NJ | F34: Lamese Bader | G34: =('Thurs (2)'!G34+Thurs!G34+'Tues '!G34+Wed!G34+Fri!G34+'Mon '!G34+'Wed (2)'!G34+Sun!G34+Sat!G34) -> 5 | H34: =('Thurs (2)'!H34+Thurs!H34+'Tues '!H34+Wed!H34+Fri!H34+'Mon '!H34+'Wed (2)'!H34+Sun!H34+Sat!H34) -> 0 | I34: =('Thurs (2)'!I34+Thurs!I34+'Tues '!I34+Wed!I34+Fri!I34+'Mon '!I34+'Wed (2)'!I34+Sun!I34+Sat!I34) -> 0 | J34: =('Thurs (2)'!J34+Thurs!J34+'Tues '!J34+Wed!J34+Fri!J34+'Mon '!J34+'Wed (2)'!J34+Sun!J34+Sat!J34) -> 0 | K34: =('Thurs (2)'!K34+Thurs!K34+'Tues '!K34+Wed!K34+Fri!K34+'Mon '!K34+'Wed (2)'!K34+Sun!K34+Sat!K34) -> 0 | L34: =('Thurs (2)'!L34+Thurs!L34+'Tues '!L34+Wed!L34+Fri!L34+'Mon '!L34+'Wed (2)'!L34+Sun!L34+Sat!L34) -> 0 | M34: =('Thurs (2)'!M34+Thurs!M34+'Tues '!M34+Wed!M34+Fri!M34+'Mon '!M34+'Wed (2)'!M34+Sun!M34+Sat!M34) -> 0 | N34: =('Thurs (2)'!N34+Thurs!N34+'Tues '!N34+Wed!N34+Fri!N34+'Mon '!N34+'Wed (2)'!N34+Sun!N34+Sat!N34) -> 0 | ... T34: =('Thurs (2)'!T34+Thurs!T34+'Tues '!T34+Wed!T34+Fri!T34+'Mon '!T34+'Wed (2)'!T34+Sun!T34+Sat!T34) -> 0 | U34: =IFERROR(I34/H34,0) -> 0 | V34: =IFERROR(SUM(H34+L34)/G34,0) -> 0
A35: Mohamed Aljahmi | B35: Ali Musa | C35: Snoor Qaradaghi | D35: Y | E35: MI | F35: Snoor Qaradaghi | G35: =('Thurs (2)'!G35+Thurs!G35+'Tues '!G35+Wed!G35+Fri!G35+'Mon '!G35+'Wed (2)'!G35+Sun!G35+Sat!G35) -> 21 | H35: =('Thurs (2)'!H35+Thurs!H35+'Tues '!H35+Wed!H35+Fri!H35+'Mon '!H35+'Wed (2)'!H35+Sun!H35+Sat!H35) -> 12 | I35: =('Thurs (2)'!I35+Thurs!I35+'Tues '!I35+Wed!I35+Fri!I35+'Mon '!I35+'Wed (2)'!I35+Sun!I35+Sat!I35) -> 6 | J35: =('Thurs (2)'!J35+Thurs!J35+'Tues '!J35+Wed!J35+Fri!J35+'Mon '!J35+'Wed (2)'!J35+Sun!J35+Sat!J35) -> 3 | K35: =('Thurs (2)'!K35+Thurs!K35+'Tues '!K35+Wed!K35+Fri!K35+'Mon '!K35+'Wed (2)'!K35+Sun!K35+Sat!K35) -> 2 | L35: =('Thurs (2)'!L35+Thurs!L35+'Tues '!L35+Wed!L35+Fri!L35+'Mon '!L35+'Wed (2)'!L35+Sun!L35+Sat!L35) -> 1 | M35: =('Thurs (2)'!M35+Thurs!M35+'Tues '!M35+Wed!M35+Fri!M35+'Mon '!M35+'Wed (2)'!M35+Sun!M35+Sat!M35) -> 17 | N35: =('Thurs (2)'!N35+Thurs!N35+'Tues '!N35+Wed!N35+Fri!N35+'Mon '!N35+'Wed (2)'!N35+Sun!N35+Sat!N35) -> 0 | ... T35: =('Thurs (2)'!T35+Thurs!T35+'Tues '!T35+Wed!T35+Fri!T35+'Mon '!T35+'Wed (2)'!T35+Sun!T35+Sat!T35) -> 11281 | U35: =IFERROR(I35/H35,0) -> 0.5 | V35: =IFERROR(SUM(H35+L35)/G35,0) -> 0.61904762
A36: Mohamed Aljahmi | B36: Ali Musa | C36: Snoor Qaradaghi | E36: NC | F36: Kimberly Villacampa | G36: =('Thurs (2)'!G36+Thurs!G36+'Tues '!G36+Wed!G36+Fri!G36+'Mon '!G36+'Wed (2)'!G36+Sun!G36+Sat!G36) -> 3 | H36: =('Thurs (2)'!H36+Thurs!H36+'Tues '!H36+Wed!H36+Fri!H36+'Mon '!H36+'Wed (2)'!H36+Sun!H36+Sat!H36) -> 2 | I36: =('Thurs (2)'!I36+Thurs!I36+'Tues '!I36+Wed!I36+Fri!I36+'Mon '!I36+'Wed (2)'!I36+Sun!I36+Sat!I36) -> 1 | J36: =('Thurs (2)'!J36+Thurs!J36+'Tues '!J36+Wed!J36+Fri!J36+'Mon '!J36+'Wed (2)'!J36+Sun!J36+Sat!J36) -> 1 | K36: =('Thurs (2)'!K36+Thurs!K36+'Tues '!K36+Wed!K36+Fri!K36+'Mon '!K36+'Wed (2)'!K36+Sun!K36+Sat!K36) -> 0 | L36: =('Thurs (2)'!L36+Thurs!L36+'Tues '!L36+Wed!L36+Fri!L36+'Mon '!L36+'Wed (2)'!L36+Sun!L36+Sat!L36) -> 1 | M36: =('Thurs (2)'!M36+Thurs!M36+'Tues '!M36+Wed!M36+Fri!M36+'Mon '!M36+'Wed (2)'!M36+Sun!M36+Sat!M36) -> 6 | N36: =('Thurs (2)'!N36+Thurs!N36+'Tues '!N36+Wed!N36+Fri!N36+'Mon '!N36+'Wed (2)'!N36+Sun!N36+Sat!N36) -> 1 | ... T36: =('Thurs (2)'!T36+Thurs!T36+'Tues '!T36+Wed!T36+Fri!T36+'Mon '!T36+'Wed (2)'!T36+Sun!T36+Sat!T36) -> 1325 | U36: =IFERROR(I36/H36,0) -> 0.5 | V36: =IFERROR(SUM(H36+L36)/G36,0) -> 1
A37: Mohamed Aljahmi | B37: Ali Musa | C37: Snoor Qaradaghi | E37: MI | F37: Shiko Qaradaghi | G37: =('Thurs (2)'!G37+Thurs!G37+'Tues '!G37+Wed!G37+Fri!G37+'Mon '!G37+'Wed (2)'!G37+Sun!G37+Sat!G37) -> 12 | H37: =('Thurs (2)'!H37+Thurs!H37+'Tues '!H37+Wed!H37+Fri!H37+'Mon '!H37+'Wed (2)'!H37+Sun!H37+Sat!H37) -> 9 | I37: =('Thurs (2)'!I37+Thurs!I37+'Tues '!I37+Wed!I37+Fri!I37+'Mon '!I37+'Wed (2)'!I37+Sun!I37+Sat!I37) -> 5 | J37: =('Thurs (2)'!J37+Thurs!J37+'Tues '!J37+Wed!J37+Fri!J37+'Mon '!J37+'Wed (2)'!J37+Sun!J37+Sat!J37) -> 2 | K37: =('Thurs (2)'!K37+Thurs!K37+'Tues '!K37+Wed!K37+Fri!K37+'Mon '!K37+'Wed (2)'!K37+Sun!K37+Sat!K37) -> 0 | L37: =('Thurs (2)'!L37+Thurs!L37+'Tues '!L37+Wed!L37+Fri!L37+'Mon '!L37+'Wed (2)'!L37+Sun!L37+Sat!L37) -> 1 | M37: =('Thurs (2)'!M37+Thurs!M37+'Tues '!M37+Wed!M37+Fri!M37+'Mon '!M37+'Wed (2)'!M37+Sun!M37+Sat!M37) -> 19 | N37: =('Thurs (2)'!N37+Thurs!N37+'Tues '!N37+Wed!N37+Fri!N37+'Mon '!N37+'Wed (2)'!N37+Sun!N37+Sat!N37) -> 9 | ... T37: =('Thurs (2)'!T37+Thurs!T37+'Tues '!T37+Wed!T37+Fri!T37+'Mon '!T37+'Wed (2)'!T37+Sun!T37+Sat!T37) -> 7082 | U37: =IFERROR(I37/H37,0) -> 0.55555556 | V37: =IFERROR(SUM(H37+L37)/G37,0) -> 0.83333333
A38: Mohamed Aljahmi | B38: Ali Musa | C38: Snoor Qaradaghi | E38: LA | F38: Tina Tilley | G38: =('Thurs (2)'!G38+Thurs!G38+'Tues '!G38+Wed!G38+Fri!G38+'Mon '!G38+'Wed (2)'!G38+Sun!G38+Sat!G38) -> 1 | H38: =('Thurs (2)'!H38+Thurs!H38+'Tues '!H38+Wed!H38+Fri!H38+'Mon '!H38+'Wed (2)'!H38+Sun!H38+Sat!H38) -> 1 | I38: =('Thurs (2)'!I38+Thurs!I38+'Tues '!I38+Wed!I38+Fri!I38+'Mon '!I38+'Wed (2)'!I38+Sun!I38+Sat!I38) -> 0 | J38: =('Thurs (2)'!J38+Thurs!J38+'Tues '!J38+Wed!J38+Fri!J38+'Mon '!J38+'Wed (2)'!J38+Sun!J38+Sat!J38) -> 1 | K38: =('Thurs (2)'!K38+Thurs!K38+'Tues '!K38+Wed!K38+Fri!K38+'Mon '!K38+'Wed (2)'!K38+Sun!K38+Sat!K38) -> 0 | L38: =('Thurs (2)'!L38+Thurs!L38+'Tues '!L38+Wed!L38+Fri!L38+'Mon '!L38+'Wed (2)'!L38+Sun!L38+Sat!L38) -> 0 | M38: =('Thurs (2)'!M38+Thurs!M38+'Tues '!M38+Wed!M38+Fri!M38+'Mon '!M38+'Wed (2)'!M38+Sun!M38+Sat!M38) -> 2 | N38: =('Thurs (2)'!N38+Thurs!N38+'Tues '!N38+Wed!N38+Fri!N38+'Mon '!N38+'Wed (2)'!N38+Sun!N38+Sat!N38) -> 1 | ... T38: =('Thurs (2)'!T38+Thurs!T38+'Tues '!T38+Wed!T38+Fri!T38+'Mon '!T38+'Wed (2)'!T38+Sun!T38+Sat!T38) -> 0 | U38: =IFERROR(I38/H38,0) -> 0 | V38: =IFERROR(SUM(H38+L38)/G38,0) -> 1
A39: Mohamed Aljahmi | B39: Ali Musa | C39: Snoor Qaradaghi | E39: MI | F39: Bruce Curry | G39: =('Thurs (2)'!G39+Thurs!G39+'Tues '!G39+Wed!G39+Fri!G39+'Mon '!G39+'Wed (2)'!G39+Sun!G39+Sat!G39) -> 0 | H39: =('Thurs (2)'!H39+Thurs!H39+'Tues '!H39+Wed!H39+Fri!H39+'Mon '!H39+'Wed (2)'!H39+Sun!H39+Sat!H39) -> 0 | I39: =('Thurs (2)'!I39+Thurs!I39+'Tues '!I39+Wed!I39+Fri!I39+'Mon '!I39+'Wed (2)'!I39+Sun!I39+Sat!I39) -> 0 | J39: =('Thurs (2)'!J39+Thurs!J39+'Tues '!J39+Wed!J39+Fri!J39+'Mon '!J39+'Wed (2)'!J39+Sun!J39+Sat!J39) -> 0 | K39: =('Thurs (2)'!K39+Thurs!K39+'Tues '!K39+Wed!K39+Fri!K39+'Mon '!K39+'Wed (2)'!K39+Sun!K39+Sat!K39) -> 0 | L39: =('Thurs (2)'!L39+Thurs!L39+'Tues '!L39+Wed!L39+Fri!L39+'Mon '!L39+'Wed (2)'!L39+Sun!L39+Sat!L39) -> 0 | M39: =('Thurs (2)'!M39+Thurs!M39+'Tues '!M39+Wed!M39+Fri!M39+'Mon '!M39+'Wed (2)'!M39+Sun!M39+Sat!M39) -> 0 | N39: =('Thurs (2)'!N39+Thurs!N39+'Tues '!N39+Wed!N39+Fri!N39+'Mon '!N39+'Wed (2)'!N39+Sun!N39+Sat!N39) -> 0 | ... T39: =('Thurs (2)'!T39+Thurs!T39+'Tues '!T39+Wed!T39+Fri!T39+'Mon '!T39+'Wed (2)'!T39+Sun!T39+Sat!T39) -> 0 | U39: =IFERROR(I39/H39,0) -> 0 | V39: =IFERROR(SUM(H39+L39)/G39,0) -> 0
A40: Mohamed Aljahmi | B40: Ali Musa | C40: Snoor Qaradaghi | E40: MI | F40: Bilal Olayan | G40: =('Thurs (2)'!G40+Thurs!G40+'Tues '!G40+Wed!G40+Fri!G40+'Mon '!G40+'Wed (2)'!G40+Sun!G40+Sat!G40) -> 0 | H40: =('Thurs (2)'!H40+Thurs!H40+'Tues '!H40+Wed!H40+Fri!H40+'Mon '!H40+'Wed (2)'!H40+Sun!H40+Sat!H40) -> 0 | I40: =('Thurs (2)'!I40+Thurs!I40+'Tues '!I40+Wed!I40+Fri!I40+'Mon '!I40+'Wed (2)'!I40+Sun!I40+Sat!I40) -> 0 | J40: =('Thurs (2)'!J40+Thurs!J40+'Tues '!J40+Wed!J40+Fri!J40+'Mon '!J40+'Wed (2)'!J40+Sun!J40+Sat!J40) -> 0 | K40: =('Thurs (2)'!K40+Thurs!K40+'Tues '!K40+Wed!K40+Fri!K40+'Mon '!K40+'Wed (2)'!K40+Sun!K40+Sat!K40) -> 0 | L40: =('Thurs (2)'!L40+Thurs!L40+'Tues '!L40+Wed!L40+Fri!L40+'Mon '!L40+'Wed (2)'!L40+Sun!L40+Sat!L40) -> 0 | M40: =('Thurs (2)'!M40+Thurs!M40+'Tues '!M40+Wed!M40+Fri!M40+'Mon '!M40+'Wed (2)'!M40+Sun!M40+Sat!M40) -> 0 | N40: =('Thurs (2)'!N40+Thurs!N40+'Tues '!N40+Wed!N40+Fri!N40+'Mon '!N40+'Wed (2)'!N40+Sun!N40+Sat!N40) -> 0 | ... T40: =('Thurs (2)'!T40+Thurs!T40+'Tues '!T40+Wed!T40+Fri!T40+'Mon '!T40+'Wed (2)'!T40+Sun!T40+Sat!T40) -> 0 | U40: =IFERROR(I40/H40,0) -> 0 | V40: =IFERROR(SUM(H40+L40)/G40,0) -> 0
A41: Mohamed Aljahmi | B41: Ali Musa | C41: Snoor Qaradaghi | E41: CO | F41: Daniella Robinson | G41: =('Thurs (2)'!G41+Thurs!G41+'Tues '!G41+Wed!G41+Fri!G41+'Mon '!G41+'Wed (2)'!G41+Sun!G41+Sat!G41) -> 0 | H41: =('Thurs (2)'!H41+Thurs!H41+'Tues '!H41+Wed!H41+Fri!H41+'Mon '!H41+'Wed (2)'!H41+Sun!H41+Sat!H41) -> 0 | I41: =('Thurs (2)'!I41+Thurs!I41+'Tues '!I41+Wed!I41+Fri!I41+'Mon '!I41+'Wed (2)'!I41+Sun!I41+Sat!I41) -> 0 | J41: =('Thurs (2)'!J41+Thurs!J41+'Tues '!J41+Wed!J41+Fri!J41+'Mon '!J41+'Wed (2)'!J41+Sun!J41+Sat!J41) -> 0 | K41: =('Thurs (2)'!K41+Thurs!K41+'Tues '!K41+Wed!K41+Fri!K41+'Mon '!K41+'Wed (2)'!K41+Sun!K41+Sat!K41) -> 0 | L41: =('Thurs (2)'!L41+Thurs!L41+'Tues '!L41+Wed!L41+Fri!L41+'Mon '!L41+'Wed (2)'!L41+Sun!L41+Sat!L41) -> 0 | M41: =('Thurs (2)'!M41+Thurs!M41+'Tues '!M41+Wed!M41+Fri!M41+'Mon '!M41+'Wed (2)'!M41+Sun!M41+Sat!M41) -> 0 | N41: =('Thurs (2)'!N41+Thurs!N41+'Tues '!N41+Wed!N41+Fri!N41+'Mon '!N41+'Wed (2)'!N41+Sun!N41+Sat!N41) -> 0 | ... T41: =('Thurs (2)'!T41+Thurs!T41+'Tues '!T41+Wed!T41+Fri!T41+'Mon '!T41+'Wed (2)'!T41+Sun!T41+Sat!T41) -> 0 | U41: =IFERROR(I41/H41,0) -> 0 | V41: =IFERROR(SUM(H41+L41)/G41,0) -> 0
A42: Mohamed Aljahmi | B42: Ali Musa | C42: Snoor Qaradaghi | E42: MI | F42: Waleed Othman | G42: =('Thurs (2)'!G42+Thurs!G42+'Tues '!G42+Wed!G42+Fri!G42+'Mon '!G42+'Wed (2)'!G42+Sun!G42+Sat!G42) -> 0 | H42: =('Thurs (2)'!H42+Thurs!H42+'Tues '!H42+Wed!H42+Fri!H42+'Mon '!H42+'Wed (2)'!H42+Sun!H42+Sat!H42) -> 0 | I42: =('Thurs (2)'!I42+Thurs!I42+'Tues '!I42+Wed!I42+Fri!I42+'Mon '!I42+'Wed (2)'!I42+Sun!I42+Sat!I42) -> 0 | J42: =('Thurs (2)'!J42+Thurs!J42+'Tues '!J42+Wed!J42+Fri!J42+'Mon '!J42+'Wed (2)'!J42+Sun!J42+Sat!J42) -> 0 | K42: =('Thurs (2)'!K42+Thurs!K42+'Tues '!K42+Wed!K42+Fri!K42+'Mon '!K42+'Wed (2)'!K42+Sun!K42+Sat!K42) -> 0 | L42: =('Thurs (2)'!L42+Thurs!L42+'Tues '!L42+Wed!L42+Fri!L42+'Mon '!L42+'Wed (2)'!L42+Sun!L42+Sat!L42) -> 0 | M42: =('Thurs (2)'!M42+Thurs!M42+'Tues '!M42+Wed!M42+Fri!M42+'Mon '!M42+'Wed (2)'!M42+Sun!M42+Sat!M42) -> 0 | N42: =('Thurs (2)'!N42+Thurs!N42+'Tues '!N42+Wed!N42+Fri!N42+'Mon '!N42+'Wed (2)'!N42+Sun!N42+Sat!N42) -> 0 | ... T42: =('Thurs (2)'!T42+Thurs!T42+'Tues '!T42+Wed!T42+Fri!T42+'Mon '!T42+'Wed (2)'!T42+Sun!T42+Sat!T42) -> 0 | U42: =IFERROR(I42/H42,0) -> 0 | V42: =IFERROR(SUM(H42+L42)/G42,0) -> 0
...

Sheet Wed
C1: ALP | E1: LEADERSHIP ALP | F1: Appts | G1: Pres | H1: Sales | I1: POS SITS | J1: POS SA | K1: VET SITS | L1: VET SA | M1: REF OBT | N1: REF SITS | O1: REF SA | P1: OTS SITS | Q1: OTS SA | R1: N1
B2: Mohamed Aljahmi RGA | C2: =SUM(C5) -> 909 | E2: =SUM(E5) -> 0 | F2: =SUM(F5) -> 25 | G2: =SUM(G5) -> 5 | H2: =SUM(H5) -> 1 | I2: =SUM(I5) -> 3 | J2: =SUM(J5) -> 0 | K2: =SUM(K5) -> 0 | L2: =SUM(L5) -> 0 | ... R2: =SUM(R5) -> 1
C3: # of Agents | E3: ALP per sale | F3: SHOW RATE | G3: CLOSE RATIO | H3: ALP/ AGENT | J3: POS CLOSE | L3: VET CLOSE | M3: REF PER SIT | O3: REF CLOSE | Q3: OTS CLOSE
C4: =SUM(C7,) -> 28 | E4: =IFERROR(C2/H2,0) -> 909 | F4: =IFERROR((G2+R2)/F2,0) -> 0.24 | G4: =IFERROR(H2/G2,0) -> 0.2 | H4: =(C2/C4) -> 32.464286 | J4: =IFERROR(J2/I2,0) -> 0 | L4: =IFERROR(L2/K2,0) -> 0 | M4: =IFERROR(M2/G2,0) -> 1 | O4: =IFERROR(O2/N2,0) -> 0.5 | Q4: =IFERROR(Q2/P2,0) -> 0.5
B5: Mohamed Aljahmi | C5: =SUMIF(A:A,B5,T:T) -> 909 | E5: =SUMIFS(T:T,A:A,B5,D:D,"Y") -> 0 | F5: =SUMIF(A:A,B5,G:G) -> 25 | G5: =SUMIF(A:A,B5,H:H) -> 5 | H5: =SUMIF(A:A,B5,I:I) -> 1 | I5: =SUMIF(A:A,B5,P:P) -> 3 | J5: =SUMIF(A:A,B5,Q:Q) -> 0 | K5: =SUMIF(A:A,B5,R:R) -> 0 | L5: =SUMIF(A:A,B5,S:S) -> 0 | M5: =SUMIF(A:A,B5,M:M) -> 5 | N5: =SUMIF(A:A,B5,N:N) -> 2 | O5: =SUMIF(A:A,B5,O:O) -> 1 | P5: =SUMIF(A:A,B5,J:J) -> 2 | Q5: =SUMIF(A:A,B5,K:K) -> 1 | R5: =SUMIF(A:A,B5,L:L) -> 1
C6: # of Agents | E6: ALP per sale | F6: SHOW RATE | G6: CLOSE RATIO | H6: ALP/ AGENT | J6: POS CLOSE | L6: VET CLOSE | M6: REF PER SIT | O6: REF CLOSE | Q6: OTS CLOSE
C7: =COUNTIFS(A:A,B5) -> 28 | E7: =IFERROR(C5/H5,0) -> 909 | F7: =IFERROR((G5+R5)/F5,0) -> 0.24 | G7: =IFERROR(H5/G5,0) -> 0.2 | H7: =(C5/C7) -> 32.464286 | J7: =IFERROR(J5/I5,0) -> 0 | L7: =IFERROR(L5/K5,0) -> 0 | M7: =IFERROR(M5/SUM(R5+G5,0),"") -> 0.83333333 | O7: =IFERROR(O5/N5,0) -> 0.5 | Q7: =IFERROR(Q5/P5,0) -> 0.5
B8: Ali Musa | C8: =SUMIF(B:B,B8,T:T) -> 909 | E8: =SUMIFS(T:T,B:B,B8,D:D,"Y") -> 0 | F8: =SUMIF(B16:B1129,B8,G16:G1129) -> 25 | G8: =SUMIF(B16:B1129,B8,H16:H1129) -> 5 | H8: =SUMIF(B16:B1129,B8,I16:I1129) -> 1 | I8: =SUMIF(B16:B1129,B8,P16:P1129) -> 3 | J8: =SUMIF(B16:B1129,B8,Q16:Q1129) -> 0 | K8: =SUMIF(B16:B1129,B8,R16:R1129) -> 0 | L8: =SUMIF(B16:B1129,B8,S16:S1129) -> 0 | M8: =SUMIF(B16:B1129,B8,M16:M1129) -> 5 | N8: =SUMIF(B16:B1129,B8,N16:N1129) -> 2 | O8: =SUMIF(B16:B1129,B8,O16:O1129) -> 1 | P8: =SUMIF(B16:B1129,B8,J16:J1129) -> 2 | Q8: =SUMIF(B16:B1129,B8,K16:K1129) -> 1 | R8: =SUMIF(B16:B1129,B8,L16:L1129) -> 1
C9: # of Agents | E9: ALP per sale | F9: SHOW RATE | G9: CLOSE RATIO | H9: ALP/ AGENT | J9: POS CLOSE | L9: VET CLOSE | M9: REF PER SIT | O9: REF CLOSE | Q9: OTS CLOSE
C10: =COUNTIFS(B16:B1129,B8) -> 25 | E10: =IFERROR(C8/H8,0) -> 909 | F10: =IFERROR((G8+R8)/F8,0) -> 0.24 | G10: =IFERROR(H8/G8,0) -> 0.2 | H10: =(C8/C10) -> 36.36 | J10: =IFERROR(J8/I8,0) -> 0 | L10: =IFERROR(L8/K8,0) -> 0 | M10: =IFERROR(M8/SUM(G8+R8,0),"") -> 0.83333333 | O10: =IFERROR(O8/N8,0) -> 0.5 | Q10: =IFERROR(Q8/P8,0) -> 0.5
B11: Jeanieliza Solis | C11: =SUMIF(B:B,B11,T:T) -> 0 | E11: =SUMIFS(T:T,B:B,B11,D:D,"Y") -> 0 | F11: =SUMIF(B45:B1129,B11,G45:G1129) -> 0 | G11: =SUMIF(B45:B1129,B11,H45:H1129) -> 0 | H11: =SUMIF(B45:B1129,B11,I45:I1129) -> 0 | I11: =SUMIF(B45:B1129,B11,P45:P1129) -> 0 | J11: =SUMIF(B45:B1129,B11,Q45:Q1129) -> 0 | K11: =SUMIF(B45:B1129,B11,R45:R1129) -> 0 | L11: =SUMIF(B45:B1129,B11,S45:S1129) -> 0 | M11: =SUMIF(B45:B1129,B11,M45:M1129) -> 0 | N11: =SUMIF(B45:B1129,B11,N45:N1129) -> 0 | O11: =SUMIF(B45:B1129,B11,O45:O1129) -> 0 | P11: =SUMIF(B45:B1129,B11,J45:J1129) -> 0 | Q11: =SUMIF(B45:B1129,B11,K45:K1129) -> 0 | R11: =SUMIF(B45:B1129,B11,L45:L1129) -> 0
C12: # of Agents | E12: ALP per sale | F12: SHOW RATE | G12: CLOSE RATIO | H12: ALP/ AGENT | J12: POS CLOSE | L12: VET CLOSE | M12: REF PER SIT | O12: REF CLOSE | Q12: OTS CLOSE
C13: =COUNTIFS(B16:B1129,B11) -> 2 | E13: =IFERROR(C11/H11,0) -> 0 | F13: =IFERROR((G11+R11)/F11,0) -> 0 | G13: =IFERROR(H11/G11,0) -> 0 | H13: =(C11/C13) -> 0 | J13: =IFERROR(J11/I11,0) -> 0 | L13: =IFERROR(L11/K11,0) -> 0 | M13: =IFERROR(M11/SUM(G11+R11,0),"") | O13: =IFERROR(O11/N11,0) -> 0 | Q13: =IFERROR(Q11/P11,0) -> 0
A16: MGA | B16: GA | C16: SA | D16: LDR | E16: RESIDENT STATE | F16: Agent | G16: SETS | H16: SITS | I16: SALES | J16: OTS SITS | K16: OTS SALES | L16: N1 | M16: REF OBT | N16: REF SITS | O16: REF SALES | P16: POS SITS | Q16: POS SALES | R16: VETS SITS | S16: VET SALES | T16: ALP | U16: Close Rate | V16: Show Rate
A17: Mohamed Aljahmi | D17: Y | E17: MI | F17: Mohamed Aljahmi | U17: =IFERROR(I17/H17,0) -> 0 | V17: =IFERROR(SUM(H17+L17)/G17,0) -> 0
A18: Mohamed Aljahmi | B18: Ali Musa | D18: Y | E18: MI | F18: Ali Musa | U18: =IFERROR(I18/H18,0) -> 0 | V18: =IFERROR(SUM(H18+L18)/G18,0) -> 0
A19: Mohamed Aljahmi | B19: Ali Musa | E19: MI | F19: Adam Youssef | U19: =IFERROR(I19/H19,0) -> 0 | V19: =IFERROR(SUM(H19+L19)/G19,0) -> 0
A20: Mohamed Aljahmi | B20: Ali Musa | E20: MI | F20: Aleskander Murshed | U20: =IFERROR(I20/H20,0) -> 0 | V20: =IFERROR(SUM(H20+L20)/G20,0) -> 0
A21: Mohamed Aljahmi | B21: Ali Musa | E21: OH | F21: Connor Cook | U21: =IFERROR(I21/H21,0) -> 0 | V21: =IFERROR(SUM(H21+L21)/G21,0) -> 0
A22: Mohamed Aljahmi | B22: Ali Musa | C22: Cameron Porter | D22: Y | E22: CA | F22: Cameron Porter | G22: 2 | H22: 0 | I22: 0 | J22: 0 | K22: 0 | L22: 0 | M22: 0 | N22: 0 | O22: 0 | P22: 0 | Q22: 0 | R22: 0 | S22: 0 | T22: 0 | U22: =IFERROR(I22/H22,0) -> 0 | V22: =IFERROR(SUM(H22+L22)/G22,0) -> 0
A23: Mohamed Aljahmi | B23: Ali Musa | C23: Cameron Porter | E23: CA | F23: Gabriela Romero | G23: 2 | H23: 0 | I23: 0 | J23: 0 | K23: 0 | L23: 0 | M23: 0 | N23: 0 | O23: 0 | P23: 0 | Q23: 0 | R23: 0 | S23: 0 | T23: 0 | U23: =IFERROR(I23/H23,0) -> 0 | V23: =IFERROR(SUM(H23+L23)/G23,0) -> 0
A24: Mohamed Aljahmi | B24: Ali Musa | C24: Cameron Porter | E24: GA | F24: Hannah Sanders | G24: 0 | H24: 0 | I24: 0 | J24: 0 | K24: 0 | L24: 0 | M24: 0 | N24: 0 | O24: 0 | P24: 0 | Q24: 0 | R24: 0 | S24: 0 | T24: 0 | U24: =IFERROR(I24/H24,0) -> 0 | V24: =IFERROR(SUM(H24+L24)/G24,0) -> 0
A25: Mohamed Aljahmi | B25: Ali Musa | C25: Cameron Porter | F25: Tyren Cosare | G25: 2 | H25: 2 | I25: 1 | J25: 2 | K25: 1 | L25: 0 | M25: 0 | N25: 1 | O25: 1 | P25: 1 | Q25: 0 | R25: 0 | S25: 0 | T25: 909 | U25: =IFERROR(I25/H25,0) -> 0.5 | V25: =IFERROR(SUM(H25+L25)/G25,0) -> 1
A26: Mohamed Aljahmi | B26: Ali Musa | C26: Henry Long | D26: Y | E26: MI | F26: Henry Long | U26: =IFERROR(I26/H26,0) -> 0 | V26: =IFERROR(SUM(H26+L26)/G26,0) -> 0
A27: Mohamed Aljahmi | B27: Ali Musa | C27: Henry Long | E27: MI | F27: Awni Shuaib | G27: 3 | H27: 0 | I27: 0 | J27: 0 | K27: 0 | L27: 0 | M27: 0 | N27: 0 | O27: 0 | P27: 0 | Q27: 0 | R27: 0 | S27: 0 | T27: 0 | U27: 0 | V27: 0
A28: Mohamed Aljahmi | B28: Ali Musa | C28: Ali Eltanoukhi | D28: Y | E28: MI | F28: Ali Eltanoukhi | G28: 2 | H28: 0 | I28: 0 | J28: 0 | K28: 0 | L28: 0 | M28: 0 | N28: 0 | O28: 0 | P28: 0 | Q28: 0 | R28: 0 | S28: 0 | T28: 0 | U28: 0 | V28: 0
A29: Mohamed Aljahmi | B29: Ali Musa | C29: Ali Eltanoukhi | E29: MI | F29: Sajad Aljanaby | G29: 2 | H29: 0 | I29: 0 | J29: 0 | K29: 0 | L29: 0 | M29: 0 | N29: 0 | O29: 0 | P29: 0 | Q29: 0 | R29: 0 | S29: 0 | T29: 0 | U29: 0 | V29: 0
A30: Mohamed Aljahmi | B30: Ali Musa | C30: Ali Eltanoukhi | E30: MI | F30: Ali Elrez | G30: 0 | H30: 0 | I30: 0 | J30: 0 | K30: 0 | L30: 0 | M30: 0 | N30: 0 | O30: 0 | P30: 0 | Q30: 0 | R30: 0 | S30: 0 | T30: 0 | U30: =IFERROR(I30/H30,0) -> 0 | V30: =IFERROR(SUM(H30+L30)/G30,0) -> 0
A31: Mohamed Aljahmi | B31: Ali Musa | C31: Ali Eltanoukhi | E31: FL | F31: Christine Demaras | G31: 2 | H31: 0 | I31: 0 | J31: 0 | K31: 0 | L31: 0 | M31: 0 | N31: 0 | O31: 0 | P31: 0 | Q31: 0 | R31: 0 | S31: 0 | T31: 0 | U31: 0 | V31: =IFERROR(SUM(H31+L31)/G31,0) -> 0
A32: Mohamed Aljahmi | B32: Ali Musa | C32: Ali Eltanoukhi | E32: MI | F32: Maher Altairi | G32: 0 | H32: 0 | I32: 0 | J32: 0 | K32: 0 | L32: 0 | M32: 0 | N32: 0 | O32: 0 | P32: 0 | Q32: 0 | R32: 0 | S32: 0 | T32: 0 | U32: =IFERROR(I32/H32,0) -> 0 | V32: =IFERROR(SUM(H32+L32)/G32,0) -> 0
A33: Mohamed Aljahmi | B33: Ali Musa | C33: Ali Eltanoukhi | E33: MI | F33: Basel Musaed | G33: 0 | H33: 0 | I33: 0 | J33: 0 | K33: 0 | L33: 0 | M33: 0 | N33: 0 | O33: 0 | P33: 0 | Q33: 0 | R33: 0 | S33: 0 | T33: 0 | U33: =IFERROR(I33/H33,0) -> 0 | V33: =IFERROR(SUM(H33+L33)/G33,0) -> 0
A34: Mohamed Aljahmi | B34: Ali Musa | C34: Ali Eltanoukhi | E34: NJ | F34: Lamese Bader | G34: 4 | H34: 0 | I34: 0 | J34: 0 | K34: 0 | L34: 0 | M34: 0 | N34: 0 | O34: 0 | P34: 0 | Q34: 0 | R34: 0 | S34: 0 | T34: 0 | U34: 0 | V34: =IFERROR(SUM(H34+L34)/G34,0) -> 0
A35: Mohamed Aljahmi | B35: Ali Musa | C35: Snoor Qaradaghi | D35: Y | E35: MI | F35: Snoor Qaradaghi | G35: 4 | H35: 2 | I35: 0 | J35: 0 | K35: 0 | L35: 1 | M35: 0 | N35: 0 | O35: 0 | P35: 2 | Q35: 0 | R35: 0 | S35: 0 | T35: 0 | U35: =IFERROR(I35/H35,0) -> 0 | V35: =IFERROR(SUM(H35+L35)/G35,0) -> 0.75
A36: Mohamed Aljahmi | B36: Ali Musa | C36: Snoor Qaradaghi | E36: NC | F36: Kimberly Villacampa | G36: 1 | H36: 0 | I36: 0 | J36: 0 | K36: 0 | L36: 0 | M36: 0 | N36: 0 | O36: 0 | P36: 0 | Q36: 0 | R36: 0 | S36: 0 | T36: 0 | U36: =IFERROR(I36/H36,0) -> 0 | V36: =IFERROR(SUM(H36+L36)/G36,0) -> 0
A37: Mohamed Aljahmi | B37: Ali Musa | C37: Snoor Qaradaghi | E37: MI | F37: Shiko Qaradaghi | G37: 1 | H37: 1 | I37: 0 | J37: 0 | K37: 0 | L37: 0 | M37: 5 | N37: 1 | O37: 0 | P37: 0 | Q37: 0 | R37: 0 | S37: 0 | T37: 0 | U37: =IFERROR(I37/H37,0) -> 0 | V37: =IFERROR(SUM(H37+L37)/G37,0) -> 1
A38: Mohamed Aljahmi | B38: Ali Musa | C38: Snoor Qaradaghi | E38: LA | F38: Tina Tilley | G38: 0 | H38: 0 | I38: 0 | J38: 0 | K38: 0 | L38: 0 | M38: 0 | N38: 0 | O38: 0 | P38: 0 | Q38: 0 | R38: 0 | S38: 0 | T38: 0 | U38: =IFERROR(I38/H38,0) -> 0 | V38: =IFERROR(SUM(H38+L38)/G38,0) -> 0
A39: Mohamed Aljahmi | B39: Ali Musa | C39: Snoor Qaradaghi | E39: MI | F39: Bruce Curry | G39: 0 | H39: 0 | I39: 0 | J39: 0 | K39: 0 | L39: 0 | M39: 0 | N39: 0 | O39: 0 | P39: 0 | Q39: 0 | R39: 0 | S39: 0 | T39: 0 | U39: =IFERROR(I39/H39,0) -> 0 | V39: =IFERROR(SUM(H39+L39)/G39,0) -> 0
A40: Mohamed Aljahmi | B40: Ali Musa | C40: Snoor Qaradaghi | E40: MI | F40: Bilal Olayan | G40: 0 | H40: 0 | I40: 0 | J40: 0 | K40: 0 | L40: 0 | M40: 0 | N40: 0 | O40: 0 | P40: 0 | Q40: 0 | R40: 0 | S40: 0 | T40: 0 | U40: =IFERROR(I40/H40,0) -> 0 | V40: =IFERROR(SUM(H40+L40)/G40,0) -> 0
A41: Mohamed Aljahmi | B41: Ali Musa | C41: Snoor Qaradaghi | E41: CO | F41: Daniella Robinson | G41: 0 | H41: 0 | I41: 0 | J41: 0 | K41: 0 | L41: 0 | M41: 0 | N41: 0 | O41: 0 | P41: 0 | Q41: 0 | R41: 0 | S41: 0 | T41: 0 | U41: =IFERROR(I41/H41,0) -> 0 | V41: =IFERROR(SUM(H41+L41)/G41,0) -> 0
A42: Mohamed Aljahmi | B42: Ali Musa | C42: Snoor Qaradaghi | E42: MI | F42: Waleed Othman | G42: 0 | H42: 0 | I42: 0 | J42: 0 | K42: 0 | L42: 0 | M42: 0 | N42: 0 | O42: 0 | P42: 0 | Q42: 0 | R42: 0 | S42: 0 | T42: 0 | U42: =IFERROR(I42/H42,0) -> 0 | V42: =IFERROR(SUM(H42+L42)/G42,0) -> 0
...

Sheet Thurs
C1: ALP | E1: LEADERSHIP ALP | F1: Appts | G1: Pres | H1: Sales | I1: POS SITS | J1: POS SA | K1: VET SITS | L1: VET SA | M1: REF OBT | N1: REF SITS | O1: REF SA | P1: OTS SITS | Q1: OTS SA | R1: N1
B2: Mohamed Aljahmi RGA | C2: =SUM(C5) -> 1731 | E2: =SUM(E5) -> 0 | F2: =SUM(F5) -> 19 | G2: =SUM(G5) -> 9 | H2: =SUM(H5) -> 1 | I2: =SUM(I5) -> 3 | J2: =SUM(J5) -> 0 | K2: =SUM(K5) -> 1 | L2: =SUM(L5) -> 0 | ... R2: =SUM(R5) -> 3
C3: # of Agents | E3: ALP per sale | F3: SHOW RATE | G3: CLOSE RATIO | H3: ALP/ AGENT | J3: POS CLOSE | L3: VET CLOSE | M3: REF PER SIT | O3: REF CLOSE | Q3: OTS CLOSE
C4: =SUM(C7,) -> 28 | E4: =IFERROR(C2/H2,0) -> 1731 | F4: =IFERROR((G2+R2)/F2,0) -> 0.63157895 | G4: =IFERROR(H2/G2,0) -> 0.11111111 | H4: =(C2/C4) -> 61.821429 | J4: =IFERROR(J2/I2,0) -> 0 | L4: =IFERROR(L2/K2,0) -> 0 | M4: =IFERROR(M2/G2,0) -> 2.8888889 | O4: =IFERROR(O2/N2,0) -> 0.25 | Q4: =IFERROR(Q2/P2,0) -> 0
B5: Mohamed Aljahmi | C5: =SUMIF(A:A,B5,T:T) -> 1731 | E5: =SUMIFS(T:T,A:A,B5,D:D,"Y") -> 0 | F5: =SUMIF(A:A,B5,G:G) -> 19 | G5: =SUMIF(A:A,B5,H:H) -> 9 | H5: =SUMIF(A:A,B5,I:I) -> 1 | I5: =SUMIF(A:A,B5,P:P) -> 3 | J5: =SUMIF(A:A,B5,Q:Q) -> 0 | K5: =SUMIF(A:A,B5,R:R) -> 1 | L5: =SUMIF(A:A,B5,S:S) -> 0 | M5: =SUMIF(A:A,B5,M:M) -> 26 | N5: =SUMIF(A:A,B5,N:N) -> 4 | O5: =SUMIF(A:A,B5,O:O) -> 1 | P5: =SUMIF(A:A,B5,J:J) -> 5 | Q5: =SUMIF(A:A,B5,K:K) -> 0 | R5: =SUMIF(A:A,B5,L:L) -> 3
C6: # of Agents | E6: ALP per sale | F6: SHOW RATE | G6: CLOSE RATIO | H6: ALP/ AGENT | J6: POS CLOSE | L6: VET CLOSE | M6: REF PER SIT | O6: REF CLOSE | Q6: OTS CLOSE
C7: =COUNTIFS(A:A,B5) -> 28 | E7: =IFERROR(C5/H5,0) -> 1731 | F7: =IFERROR((G5+R5)/F5,0) -> 0.63157895 | G7: =IFERROR(H5/G5,0) -> 0.11111111 | H7: =(C5/C7) -> 61.821429 | J7: =IFERROR(J5/I5,0) -> 0 | L7: =IFERROR(L5/K5,0) -> 0 | M7: =IFERROR(M5/SUM(R5+G5,0),"") -> 2.1666667 | O7: =IFERROR(O5/N5,0) -> 0.25 | Q7: =IFERROR(Q5/P5,0) -> 0
B8: Ali Musa | C8: =SUMIF(B:B,B8,T:T) -> 1731 | E8: =SUMIFS(T:T,B:B,B8,D:D,"Y") -> 0 | F8: =SUMIF(B16:B1129,B8,G16:G1129) -> 19 | G8: =SUMIF(B16:B1129,B8,H16:H1129) -> 9 | H8: =SUMIF(B16:B1129,B8,I16:I1129) -> 1 | I8: =SUMIF(B16:B1129,B8,P16:P1129) -> 3 | J8: =SUMIF(B16:B1129,B8,Q16:Q1129) -> 0 | K8: =SUMIF(B16:B1129,B8,R16:R1129) -> 1 | L8: =SUMIF(B16:B1129,B8,S16:S1129) -> 0 | M8: =SUMIF(B16:B1129,B8,M16:M1129) -> 26 | N8: =SUMIF(B16:B1129,B8,N16:N1129) -> 4 | O8: =SUMIF(B16:B1129,B8,O16:O1129) -> 1 | P8: =SUMIF(B16:B1129,B8,J16:J1129) -> 5 | Q8: =SUMIF(B16:B1129,B8,K16:K1129) -> 0 | R8: =SUMIF(B16:B1129,B8,L16:L1129) -> 3
C9: # of Agents | E9: ALP per sale | F9: SHOW RATE | G9: CLOSE RATIO | H9: ALP/ AGENT | J9: POS CLOSE | L9: VET CLOSE | M9: REF PER SIT | O9: REF CLOSE | Q9: OTS CLOSE
C10: =COUNTIFS(B16:B1129,B8) -> 25 | E10: =IFERROR(C8/H8,0) -> 1731 | F10: =IFERROR((G8+R8)/F8,0) -> 0.63157895 | G10: =IFERROR(H8/G8,0) -> 0.11111111 | H10: =(C8/C10) -> 69.24 | J10: =IFERROR(J8/I8,0) -> 0 | L10: =IFERROR(L8/K8,0) -> 0 | M10: =IFERROR(M8/SUM(G8+R8,0),"") -> 2.1666667 | O10: =IFERROR(O8/N8,0) -> 0.25 | Q10: =IFERROR(Q8/P8,0) -> 0
B11: Jeanieliza Solis | C11: =SUMIF(B:B,B11,T:T) -> 0 | E11: =SUMIFS(T:T,B:B,B11,D:D,"Y") -> 0 | F11: =SUMIF(B45:B1129,B11,G45:G1129) -> 0 | G11: =SUMIF(B45:B1129,B11,H45:H1129) -> 0 | H11: =SUMIF(B45:B1129,B11,I45:I1129) -> 0 | I11: =SUMIF(B45:B1129,B11,P45:P1129) -> 0 | J11: =SUMIF(B45:B1129,B11,Q45:Q1129) -> 0 | K11: =SUMIF(B45:B1129,B11,R45:R1129) -> 0 | L11: =SUMIF(B45:B1129,B11,S45:S1129) -> 0 | M11: =SUMIF(B45:B1129,B11,M45:M1129) -> 0 | N11: =SUMIF(B45:B1129,B11,N45:N1129) -> 0 | O11: =SUMIF(B45:B1129,B11,O45:O1129) -> 0 | P11: =SUMIF(B45:B1129,B11,J45:J1129) -> 0 | Q11: =SUMIF(B45:B1129,B11,K45:K1129) -> 0 | R11: =SUMIF(B45:B1129,B11,L45:L1129) -> 0
C12: # of Agents | E12: ALP per sale | F12: SHOW RATE | G12: CLOSE RATIO | H12: ALP/ AGENT | J12: POS CLOSE | L12: VET CLOSE | M12: REF PER SIT | O12: REF CLOSE | Q12: OTS CLOSE
C13: =COUNTIFS(B16:B1129,B11) -> 2 | E13: =IFERROR(C11/H11,0) -> 0 | F13: =IFERROR((G11+R11)/F11,0) -> 0 | G13: =IFERROR(H11/G11,0) -> 0 | H13: =(C11/C13) -> 0 | J13: =IFERROR(J11/I11,0) -> 0 | L13: =IFERROR(L11/K11,0) -> 0 | M13: =IFERROR(M11/SUM(G11+R11,0),"") | O13: =IFERROR(O11/N11,0) -> 0 | Q13: =IFERROR(Q11/P11,0) -> 0
A16: MGA | B16: GA | C16: SA | D16: LDR | E16: RESIDENT STATE | F16: Agent | G16: SETS | H16: SITS | I16: SALES | J16: OTS SITS | K16: OTS SALES | L16: N1 | M16: REF OBT | N16: REF SITS | O16: REF SALES | P16: POS SITS | Q16: POS SALES | R16: VETS SITS | S16: VET SALES | T16: ALP | U16: Close Rate | V16: Show Rate
A17: Mohamed Aljahmi | D17: Y | E17: MI | F17: Mohamed Aljahmi | U17: =IFERROR(I17/H17,0) -> 0 | V17: =IFERROR(SUM(H17+L17)/G17,0) -> 0
A18: Mohamed Aljahmi | B18: Ali Musa | D18: Y | E18: MI | F18: Ali Musa | U18: =IFERROR(I18/H18,0) -> 0 | V18: =IFERROR(SUM(H18+L18)/G18,0) -> 0
A19: Mohamed Aljahmi | B19: Ali Musa | E19: MI | F19: Adam Youssef | U19: =IFERROR(I19/H19,0) -> 0 | V19: =IFERROR(SUM(H19+L19)/G19,0) -> 0
A20: Mohamed Aljahmi | B20: Ali Musa | E20: MI | F20: Aleskander Murshed | U20: =IFERROR(I20/H20,0) -> 0 | V20: =IFERROR(SUM(H20+L20)/G20,0) -> 0
A21: Mohamed Aljahmi | B21: Ali Musa | E21: OH | F21: Connor Cook | U21: =IFERROR(I21/H21,0) -> 0 | V21: =IFERROR(SUM(H21+L21)/G21,0) -> 0
A22: Mohamed Aljahmi | B22: Ali Musa | C22: Cameron Porter | D22: Y | E22: CA | F22: Cameron Porter | G22: 2 | H22: 1 | I22: 0 | J22: 0 | K22: 0 | L22: 0 | M22: 0 | N22: 0 | O22: 0 | P22: 0 | Q22: 0 | R22: 0 | S22: 0 | T22: 0 | U22: =IFERROR(I22/H22,0) -> 0 | V22: =IFERROR(SUM(H22+L22)/G22,0) -> 0.5
A23: Mohamed Aljahmi | B23: Ali Musa | C23: Cameron Porter | E23: CA | F23: Gabriela Romero | G23: 2 | H23: 0 | I23: 0 | J23: 0 | K23: 0 | L23: 0 | M23: 0 | N23: 0 | O23: 0 | P23: 0 | Q23: 0 | R23: 0 | S23: 0 | T23: 0 | U23: =IFERROR(I23/H23,0) -> 0 | V23: =IFERROR(SUM(H23+L23)/G23,0) -> 0
A24: Mohamed Aljahmi | B24: Ali Musa | C24: Cameron Porter | E24: GA | F24: Hannah Sanders | G24: 0 | H24: 0 | I24: 0 | J24: 0 | K24: 0 | L24: 0 | M24: 0 | N24: 0 | O24: 0 | P24: 0 | Q24: 0 | R24: 0 | S24: 0 | T24: 0 | U24: =IFERROR(I24/H24,0) -> 0 | V24: =IFERROR(SUM(H24+L24)/G24,0) -> 0
A25: Mohamed Aljahmi | B25: Ali Musa | C25: Cameron Porter | F25: Tyren Cosare | G25: 0 | H25: 0 | I25: 0 | J25: 0 | K25: 0 | L25: 0 | M25: 0 | N25: 0 | O25: 0 | P25: 0 | Q25: 0 | R25: 0 | S25: 0 | T25: 0 | U25: =IFERROR(I25/H25,0) -> 0 | V25: =IFERROR(SUM(H25+L25)/G25,0) -> 0
A26: Mohamed Aljahmi | B26: Ali Musa | C26: Henry Long | D26: Y | E26: MI | F26: Henry Long | U26: =IFERROR(I26/H26,0) -> 0 | V26: =IFERROR(SUM(H26+L26)/G26,0) -> 0
A27: Mohamed Aljahmi | B27: Ali Musa | C27: Henry Long | E27: MI | F27: Awni Shuaib | G27: 4 | H27: 3 | I27: 1 | J27: 1 | K27: 0 | L27: 1 | M27: 12 | N27: 2 | O27: 1 | P27: 0 | Q27: 0 | R27: 1 | S27: 0 | T27: 1731 | U27: =IFERROR(I27/H27,0) -> 0.33333333 | V27: =IFERROR(SUM(H27+L27)/G27,0) -> 1
A28: Mohamed Aljahmi | B28: Ali Musa | C28: Ali Eltanoukhi | D28: Y | E28: MI | F28: Ali Eltanoukhi | G28: 2 | H28: 0 | I28: 0 | J28: 0 | K28: 0 | L28: 0 | M28: 0 | N28: 0 | O28: 0 | P28: 0 | Q28: 0 | R28: 0 | S28: 0 | T28: 0 | U28: 0 | V28: =IFERROR(SUM(H28+L28)/G28,0) -> 0
A29: Mohamed Aljahmi | B29: Ali Musa | C29: Ali Eltanoukhi | E29: MI | F29: Sajad Aljanaby | G29: 0 | H29: 0 | I29: 0 | J29: 0 | K29: 0 | L29: 0 | M29: 0 | N29: 0 | O29: 0 | P29: 0 | Q29: 0 | R29: 0 | S29: 0 | T29: 0 | U29: =IFERROR(I29/H29,0) -> 0 | V29: =IFERROR(SUM(H29+L29)/G29,0) -> 0
A30: Mohamed Aljahmi | B30: Ali Musa | C30: Ali Eltanoukhi | E30: MI | F30: Ali Elrez | G30: 0 | H30: 0 | I30: 0 | J30: 0 | K30: 0 | L30: 0 | M30: 0 | N30: 0 | O30: 0 | P30: 0 | Q30: 0 | R30: 0 | S30: 0 | T30: 0 | U30: =IFERROR(I30/H30,0) -> 0 | V30: =IFERROR(SUM(H30+L30)/G30,0) -> 0
A31: Mohamed Aljahmi | B31: Ali Musa | C31: Ali Eltanoukhi | E31: FL | F31: Christine Demaras | G31: 0 | H31: 0 | I31: 0 | J31: 0 | K31: 0 | L31: 0 | M31: 0 | N31: 0 | O31: 0 | P31: 0 | Q31: 0 | R31: 0 | S31: 0 | T31: 0 | U31: =IFERROR(I31/H31,0) -> 0 | V31: =IFERROR(SUM(H31+L31)/G31,0) -> 0
A32: Mohamed Aljahmi | B32: Ali Musa | C32: Ali Eltanoukhi | E32: MI | F32: Maher Altairi | G32: 0 | H32: 0 | I32: 0 | J32: 0 | K32: 0 | L32: 2 | M32: 7 | N32: 0 | O32: 0 | P32: 0 | Q32: 0 | R32: 0 | S32: 0 | T32: 0 | U32: 0 | V32: =IFERROR(SUM(H32+L32)/G32,0) -> 0
A33: Mohamed Aljahmi | B33: Ali Musa | C33: Ali Eltanoukhi | E33: MI | F33: Basel Musaed | G33: 2 | H33: 1 | I33: 0 | J33: 1 | K33: 0 | L33: 0 | M33: 3 | N33: 1 | O33: 0 | P33: 0 | Q33: 0 | R33: 0 | S33: 0 | T33: 0 | U33: =IFERROR(I33/H33,0) -> 0 | V33: =IFERROR(SUM(H33+L33)/G33,0) -> 0.5
A34: Mohamed Aljahmi | B34: Ali Musa | C34: Ali Eltanoukhi | E34: NJ | F34: Lamese Bader | G34: 1 | H34: 0 | I34: 0 | J34: 0 | K34: 0 | L34: 0 | M34: 0 | N34: 0 | O34: 0 | P34: 0 | Q34: 0 | R34: 0 | S34: 0 | T34: 0 | U34: =IFERROR(I34/H34,0) -> 0 | V34: =IFERROR(SUM(H34+L34)/G34,0) -> 0
A35: Mohamed Aljahmi | B35: Ali Musa | C35: Snoor Qaradaghi | D35: Y | E35: MI | F35: Snoor Qaradaghi | G35: 5 | H35: 3 | I35: 0 | J35: 2 | K35: 0 | L35: 0 | M35: 2 | N35: 0 | O35: 0 | P35: 3 | Q35: 0 | R35: 0 | S35: 0 | T35: 0 | U35: =IFERROR(I35/H35,0) -> 0 | V35: =IFERROR(SUM(H35+L35)/G35,0) -> 0.6
A36: Mohamed Aljahmi | B36: Ali Musa | C36: Snoor Qaradaghi | E36: NC | F36: Kimberly Villacampa | G36: 0 | H36: 0 | I36: 0 | J36: 0 | K36: 0 | L36: 0 | M36: 0 | N36: 0 | O36: 0 | P36: 0 | Q36: 0 | R36: 0 | S36: 0 | T36: 0 | U36: =IFERROR(I36/H36,0) -> 0 | V36: =IFERROR(SUM(H36+L36)/G36,0) -> 0
A37: Mohamed Aljahmi | B37: Ali Musa | C37: Snoor Qaradaghi | E37: MI | F37: Shiko Qaradaghi | G37: 0 | H37: 0 | I37: 0 | J37: 0 | K37: 0 | L37: 0 | M37: 0 | N37: 0 | O37: 0 | P37: 0 | Q37: 0 | R37: 0 | S37: 0 | T37: 0 | U37: =IFERROR(I37/H37,0) -> 0 | V37: =IFERROR(SUM(H37+L37)/G37,0) -> 0
A38: Mohamed Aljahmi | B38: Ali Musa | C38: Snoor Qaradaghi | E38: LA | F38: Tina Tilley | G38: 1 | H38: 1 | I38: 0 | J38: 1 | K38: 0 | L38: 0 | M38: 2 | N38: 1 | O38: 0 | P38: 0 | Q38: 0 | R38: 0 | S38: 0 | T38: 0 | U38: =IFERROR(I38/H38,0) -> 0 | V38: =IFERROR(SUM(H38+L38)/G38,0) -> 1
A39: Mohamed Aljahmi | B39: Ali Musa | C39: Snoor Qaradaghi | E39: MI | F39: Bruce Curry | G39: 0 | H39: 0 | I39: 0 | J39: 0 | K39: 0 | L39: 0 | M39: 0 | N39: 0 | O39: 0 | P39: 0 | Q39: 0 | R39: 0 | S39: 0 | T39: 0 | U39: =IFERROR(I39/H39,0) -> 0 | V39: =IFERROR(SUM(H39+L39)/G39,0) -> 0
A40: Mohamed Aljahmi | B40: Ali Musa | C40: Snoor Qaradaghi | E40: MI | F40: Bilal Olayan | G40: 0 | H40: 0 | I40: 0 | J40: 0 | K40: 0 | L40: 0 | M40: 0 | N40: 0 | O40: 0 | P40: 0 | Q40: 0 | R40: 0 | S40: 0 | T40: 0 | U40: =IFERROR(I40/H40,0) -> 0 | V40: =IFERROR(SUM(H40+L40)/G40,0) -> 0
A41: Mohamed Aljahmi | B41: Ali Musa | C41: Snoor Qaradaghi | E41: CO | F41: Daniella Robinson | G41: 0 | H41: 0 | I41: 0 | J41: 0 | K41: 0 | L41: 0 | M41: 0 | N41: 0 | O41: 0 | P41: 0 | Q41: 0 | R41: 0 | S41: 0 | T41: 0 | U41: =IFERROR(I41/H41,0) -> 0 | V41: =IFERROR(SUM(H41+L41)/G41,0) -> 0
A42: Mohamed Aljahmi | B42: Ali Musa | C42: Snoor Qaradaghi | E42: MI | F42: Waleed Othman | G42: 0 | H42: 0 | I42: 0 | J42: 0 | K42: 0 | L42: 0 | M42: 0 | N42: 0 | O42: 0 | P42: 0 | Q42: 0 | R42: 0 | S42: 0 | T42: 0 | U42: =IFERROR(I42/H42,0) -> 0 | V42: =IFERROR(SUM(H42+L42)/G42,0) -> 0
...

Sheet Fri
C1: ALP | E1: LEADERSHIP ALP | F1: Appts | G1: Pres | H1: Sales | I1: POS SITS | J1: POS SA | K1: VET SITS | L1: VET SA | M1: REF OBT | N1: REF SITS | O1: REF SA | P1: OTS SITS | Q1: OTS SA | R1: N1
B2: Mohamed Aljahmi RGA | C2: =SUM(C5) -> 9071 | E2: =SUM(E5) -> 4339 | F2: =SUM(F5) -> 22 | G2: =SUM(G5) -> 13 | H2: =SUM(H5) -> 7 | I2: =SUM(I5) -> 2 | J2: =SUM(J5) -> 1 | K2: =SUM(K5) -> 6 | L2: =SUM(L5) -> 1 | ... R2: =SUM(R5) -> 2
C3: # of Agents | E3: ALP per sale | F3: SHOW RATE | G3: CLOSE RATIO | H3: ALP/ AGENT | J3: POS CLOSE | L3: VET CLOSE | M3: REF PER SIT | O3: REF CLOSE | Q3: OTS CLOSE
C4: =SUM(C7,) -> 28 | E4: =IFERROR(C2/H2,0) -> 1295.8571 | F4: =IFERROR((G2+R2)/F2,0) -> 0.68181818 | G4: =IFERROR(H2/G2,0) -> 0.53846154 | H4: =(C2/C4) -> 323.96429 | J4: =IFERROR(J2/I2,0) -> 0.5 | L4: =IFERROR(L2/K2,0) -> 0.16666667 | M4: =IFERROR(M2/G2,0) -> 3.5384615 | O4: =IFERROR(O2/N2,0) -> 0.6 | Q4: =IFERROR(Q2/P2,0) -> 0.42857143
B5: Mohamed Aljahmi | C5: =SUMIF(A:A,B5,T:T) -> 9071 | E5: =SUMIFS(T:T,A:A,B5,D:D,"Y") -> 4339 | F5: =SUMIF(A:A,B5,G:G) -> 22 | G5: =SUMIF(A:A,B5,H:H) -> 13 | H5: =SUMIF(A:A,B5,I:I) -> 7 | I5: =SUMIF(A:A,B5,P:P) -> 2 | J5: =SUMIF(A:A,B5,Q:Q) -> 1 | K5: =SUMIF(A:A,B5,R:R) -> 6 | L5: =SUMIF(A:A,B5,S:S) -> 1 | M5: =SUMIF(A:A,B5,M:M) -> 46 | N5: =SUMIF(A:A,B5,N:N) -> 5 | O5: =SUMIF(A:A,B5,O:O) -> 3 | P5: =SUMIF(A:A,B5,J:J) -> 7 | Q5: =SUMIF(A:A,B5,K:K) -> 3 | R5: =SUMIF(A:A,B5,L:L) -> 2
C6: # of Agents | E6: ALP per sale | F6: SHOW RATE | G6: CLOSE RATIO | H6: ALP/ AGENT | J6: POS CLOSE | L6: VET CLOSE | M6: REF PER SIT | O6: REF CLOSE | Q6: OTS CLOSE
C7: =COUNTIFS(A:A,B5) -> 28 | E7: =IFERROR(C5/H5,0) -> 1295.8571 | F7: =IFERROR((G5+R5)/F5,0) -> 0.68181818 | G7: =IFERROR(H5/G5,0) -> 0.53846154 | H7: =(C5/C7) -> 323.96429 | J7: =IFERROR(J5/I5,0) -> 0.5 | L7: =IFERROR(L5/K5,0) -> 0.16666667 | M7: =IFERROR(M5/SUM(R5+G5,0),"") -> 3.0666667 | O7: =IFERROR(O5/N5,0) -> 0.6 | Q7: =IFERROR(Q5/P5,0) -> 0.42857143
B8: Ali Musa | C8: =SUMIF(B:B,B8,T:T) -> 9071 | E8: =SUMIFS(T:T,B:B,B8,D:D,"Y") -> 4339 | F8: =SUMIF(B16:B1129,B8,G16:G1129) -> 22 | G8: =SUMIF(B16:B1129,B8,H16:H1129) -> 13 | H8: =SUMIF(B16:B1129,B8,I16:I1129) -> 7 | I8: =SUMIF(B16:B1129,B8,P16:P1129) -> 2 | J8: =SUMIF(B16:B1129,B8,Q16:Q1129) -> 1 | K8: =SUMIF(B16:B1129,B8,R16:R1129) -> 6 | L8: =SUMIF(B16:B1129,B8,S16:S1129) -> 1 | M8: =SUMIF(B16:B1129,B8,M16:M1129) -> 46 | N8: =SUMIF(B16:B1129,B8,N16:N1129) -> 5 | O8: =SUMIF(B16:B1129,B8,O16:O1129) -> 3 | P8: =SUMIF(B16:B1129,B8,J16:J1129) -> 7 | Q8: =SUMIF(B16:B1129,B8,K16:K1129) -> 3 | R8: =SUMIF(B16:B1129,B8,L16:L1129) -> 2
