Workbook

Sheet Weekly Totals
C1: ALP | E1: LEADERSHIP ALP | F1: Appts | G1: Pres | H1: Sales | I1: POS SITS | J1: POS SA | K1: VET SITS | L1: VET SA | M1: REF OBT | N1: REF SITS | O1: REF SA | P1: OTS SITS | Q1: OTS SA | R1: N1
B2: RUST RGA | C2: =SUM(C5,C14,C17) -> 8032 | E2: =SUM(E5,E14,E17) -> 5447 | F2: =SUM(F5,F14,F17) -> 94 | G2: =SUM(G5,G14,G17) -> 42 | H2: =SUM(H5,H14,H17) -> 8 | I2: =SUM(I5,I14,I17) -> 8 | J2: =SUM(J5,J14,J17) -> 0 | K2: =SUM(K5,K14,K17) -> 23 | L2: =SUM(L5,L14,L17) -> 2 | ... R2: =SUM(R5,R14,R17) -> 15
C3: # of Agents | E3: ALP per sale | F3: Show Rate | G3: Close Ratio | H3: ALP/Agent | J3: POS Close | L3: VET Close | M3: REF Per Sit | O3: REF Close | Q3: OTS Close
C4: =SUM(C7,C19,C16) -> 45 | E4: =IFERROR(C2/H2,0) -> 1004 | F4: =IFERROR((G2+R2)/F2,0) -> 0.60638298 | G4: =IFERROR(H2/G2,0) -> 0.19047619 | H4: =(C2/C4) -> 178.48889 | J4: =IFERROR(J2/I2,0) -> 0 | L4: =IFERROR(L2/K2,0) -> 0.086956522 | M4: =IFERROR(M2/G2,0) -> 2.047619 | O4: =IFERROR(O2/N2,0) -> 0.55555556 | Q4: =IFERROR(Q2/P2,0) -> 0.0625
B5: Ashley Rust | C5: =SUMIF(A:A,B5,T:T) -> 670 | E5: =SUMIFS(T:T,A:A,B5,D:D,"Y") -> 0 | F5: =SUMIF(A:A,B5,G:G) -> 33 | G5: =SUMIF(A:A,B5,H:H) -> 13 | H5: =SUMIF(A:A,B5,I:I) -> 1 | I5: =SUMIF(A:A,B5,P:P) -> 0 | J5: =SUMIF(A:A,B5,Q:Q) -> 0 | K5: =SUMIF(A:A,B5,R:R) -> 4 | L5: =SUMIF(A:A,B5,S:S) -> 0 | M5: =SUMIF(A:A,B5,M:M) -> 46 | N5: =SUMIF(A:A,B5,N:N) -> 4 | O5: =SUMIF(A:A,B5,O:O) -> 1 | P5: =SUMIF(A:A,B5,J:J) -> 4 | Q5: =SUMIF(A:A,B5,K:K) -> 0 | R5: =SUMIF(A:A,B5,L:L) -> 6
C6: # of Agents | E6: ALP per sale | F6: Show Rate | G6: Close Ratio | H6: ALP/Agent | J6: POS Close | L6: VET Close | M6: REF Per Sit | O6: REF Close | Q6: OTS Close
C7: =COUNTIFS(A:A,B5) -> 19 | E7: =IFERROR(C5/H5,0) -> 670 | F7: =IFERROR((G5+R5)/F5,0) -> 0.57575758 | G7: =IFERROR(H5/G5,0) -> 0.076923077 | H7: =(C5/C7) -> 35.263158 | J7: =IFERROR(J5/I5,0) -> 0 | L7: =IFERROR(L5/K5,0) -> 0 | M7: =IFERROR(M5/SUM(R5+G5,0),"") -> 2.4210526 | O7: =IFERROR(O5/N5,0) -> 0.25 | Q7: =IFERROR(Q5/P5,0) -> 0
B8: Troy Williams | C8: =SUMIF(B:B,B8,T:T) -> 0 | E8: =SUMIFS(T:T,B:B,B8,D:D,"Y") -> 0 | F8: =SUMIF(B39:B1066,B8,G39:G1066) -> 0 | G8: =SUMIF(B39:B1066,B8,H39:H1066) -> 0 | H8: =SUMIF(B39:B1066,B8,I39:I1066) -> 0 | I8: =SUMIF(B39:B1066,B8,P39:P1066) -> 0 | J8: =SUMIF(B39:B1066,B8,Q39:Q1066) -> 0 | K8: =SUMIF(B39:B1066,B8,R39:R1066) -> 0 | L8: =SUMIF(B39:B1066,B8,S39:S1066) -> 0 | M8: =SUMIF(B39:B1066,B8,M39:M1066) -> 0 | N8: =SUMIF(B39:B1066,B8,N39:N1066) -> 0 | O8: =SUMIF(B39:B1066,B8,O39:O1066) -> 0 | P8: =SUMIF(B39:B1066,B8,J39:J1066) -> 0 | Q8: =SUMIF(B39:B1066,B8,K39:K1066) -> 0 | R8: =SUMIF(B39:B1066,B8,L39:L1066) -> 0
C9: # of Agents | E9: ALP per sale | F9: Show Rate | G9: Close Ratio | H9: ALP/Agent | J9: POS Close | L9: VET Close | M9: REF Per Sit | O9: REF Close | Q9: OTS Close
C10: =COUNTIFS(B28:B1066,B8) -> 5 | E10: =IFERROR(C8/H8,0) -> 0 | F10: =IFERROR((G8+R8)/F8,0) -> 0 | G10: =IFERROR(H8/G8,0) -> 0 | H10: =(C8/C10) -> 0 | J10: =IFERROR(J8/I8,0) -> 0 | L10: =IFERROR(L8/K8,0) -> 0 | M10: =IFERROR(M8/SUM(G8+R8,0),"") | O10: =IFERROR(O8/N8,0) -> 0 | Q10: =IFERROR(Q8/P8,0) -> 0
B11: Karami Kovar | C11: =SUMIF(B:B,B11,T:T) -> 670 | E11: =SUMIFS(T:T,B:B,B11,D:D,"Y") -> 0 | F11: =SUMIF(B28:B1066,B11,G28:G1066) -> 25 | G11: =SUMIF(C28:C1066,C11,H28:H1066) -> 0 | H11: =SUMIF(D28:D1066,D11,I28:I1066) -> 0 | I11: =SUMIF(E28:E1066,E11,J28:J1066) -> 0 | J11: =SUMIF(F28:F1066,F11,K28:K1066) -> 0 | K11: =SUMIF(G28:G1066,G11,L28:L1066) -> 0 | L11: =SUMIF(H28:H1066,H11,M28:M1066) -> 0 | M11: =SUMIF(I28:I1066,I11,N28:N1066) -> 3 | ... R11: =SUMIF(N28:N1066,N11,S28:S1066) -> 0
C12: # of Agents | E12: ALP per sale | F12: Show Rate | G12: Close Ratio | H12: ALP/Agent | J12: POS Close | L12: VET Close | M12: REF Per Sit | O12: REF Close | Q12: OTS Close
C13: =COUNTIFS(B27:B1066,B11) -> 11 | E13: =IFERROR(C11/H11,0) -> 0 | F13: =IFERROR((G11+R11)/F11,0) -> 0 | G13: =IFERROR(H11/G11,0) -> 0 | H13: =(C11/C13) -> 60.909091 | J13: =IFERROR(J11/I11,0) -> 0 | L13: =IFERROR(L11/K11,0) -> 0 | M13: =IFERROR(M11/SUM(G11+R11,0),"") | O13: =IFERROR(O11/N11,0) -> 2.6666667 | Q13: =IFERROR(Q11/P11,0) -> 0
B14: Joy Vann-Austin | C14: =SUMIF(A:A,B14,T:T) -> 774 | E14: =SUMIFS(T:T,A:A,B14,D:D,"Y") -> 774 | F14: =SUMIF(A:A,B14,G:G) -> 7 | G14: =SUMIF(A:A,B14,H:H) -> 4 | H14: =SUMIF(A:A,B14,I:I) -> 1 | I14: =SUMIF(A:A,B14,P:P) -> 0 | J14: =SUMIF(A:A,B14,Q:Q) -> 0 | K14: =SUMIF(A:A,B14,R:R) -> 3 | L14: =SUMIF(A:A,B14,S:S) -> 0 | M14: =SUMIF(A:A,B14,M:M) -> 7 | N14: =SUMIF(A:A,B14,N:N) -> 0 | O14: =SUMIF(A:A,B14,O:O) -> 0 | P14: =SUMIF(A:A,B14,J:J) -> 2 | Q14: =SUMIF(A:A,B14,K:K) -> 0 | R14: =SUMIF(A:A,B14,L:L) -> 2
C15: # of Agents | E15: ALP per sale | F15: Show Rate | G15: Close Ratio | H15: ALP/Agent | J15: POS Close | L15: VET Close | M15: REF Per Sit | O15: REF Close | Q15: OTS Close
C16: =COUNTIFS(A:A,B14) -> 4 | E16: =IFERROR(C14/H14,0) -> 774 | F16: =IFERROR((G14+R14)/F14,0) -> 0.85714286 | G16: =IFERROR(H14/G14,0) -> 0.25 | H16: =(C14/C16) -> 193.5 | J16: =IFERROR(J14/I14,0) -> 0 | L16: =IFERROR(L14/K14,0) -> 0 | M16: =IFERROR(M14/SUM(R14+G14,0),"") -> 1.1666667 | O16: =IFERROR(O14/N14,0) -> 0 | Q16: =IFERROR(Q14/P14,0) -> 0
B17: Torian Fields | C17: =SUMIF(A:A,B17,T:T) -> 6588 | E17: =SUMIFS(T:T,A:A,B17,D:D,"Y") -> 4673 | F17: =SUMIF(A:A,B17,G:G) -> 54 | G17: =SUMIF(A:A,B17,H:H) -> 25 | H17: =SUMIF(A:A,B17,I:I) -> 6 | I17: =SUMIF(A:A,B17,P:P) -> 8 | J17: =SUMIF(A:A,B17,Q:Q) -> 0 | K17: =SUMIF(A:A,B17,R:R) -> 16 | L17: =SUMIF(A:A,B17,S:S) -> 2 | M17: =SUMIF(A:A,B17,M:M) -> 33 | N17: =SUMIF(A:A,B17,N:N) -> 5 | O17: =SUMIF(A:A,B17,O:O) -> 4 | P17: =SUMIF(A:A,B17,J:J) -> 10 | Q17: =SUMIF(A:A,B17,K:K) -> 1 | R17: =SUMIF(A:A,B17,L:L) -> 7
C18: # of Agents | E18: ALP per sale | F18: Show Rate | G18: Close Ratio | H18: ALP/Agent | J18: POS Close | L18: VET Close | M18: REF Per Sit | O18: REF Close | Q18: OTS Close
C19: =COUNTIFS(A:A,B17) -> 22 | E19: =IFERROR(C17/H17,0) -> 1098 | F19: =IFERROR((G17+R17)/F17,0) -> 0.59259259 | G19: =IFERROR(H17/G17,0) -> 0.24 | H19: =(C17/C19) -> 299.45455 | J19: =IFERROR(J17/I17,0) -> 0 | L19: =IFERROR(L17/K17,0) -> 0.125 | M19: =IFERROR(M17/SUM(G17+R17,0),"") -> 1.03125 | O19: =IFERROR(O17/N17,0) -> 0.8 | Q19: =IFERROR(Q17/P17,0) -> 0.1
B20: Devin Gould | C20: =SUMIF(B:B,B20,T:T) -> 6588 | E20: =SUMIFS(T:T,B:B,B20,D:D,"Y") -> 4673 | F20: =SUMIF(B47:B1066,B20,G47:G1066) -> 53 | G20: =SUMIF(B47:B1066,B20,H47:H1066) -> 24 | H20: =SUMIF(B47:B1066,B20,I47:I1066) -> 6 | I20: =SUMIF(B47:B1066,B20,P47:P1066) -> 8 | J20: =SUMIF(B47:B1066,B20,Q47:Q1066) -> 0 | K20: =SUMIF(B47:B1066,B20,R47:R1066) -> 15 | L20: =SUMIF(B47:B1066,B20,S47:S1066) -> 2 | M20: =SUMIF(B47:B1066,B20,M47:M1066) -> 33 | N20: =SUMIF(B47:B1066,B20,N47:N1066) -> 5 | O20: =SUMIF(B47:B1066,B20,O47:O1066) -> 4 | P20: =SUMIF(B47:B1066,B20,J47:J1066) -> 9 | Q20: =SUMIF(B47:B1066,B20,K47:K1066) -> 1 | R20: =SUMIF(B47:B1066,B20,L47:L1066) -> 7
C21: # of Agents | E21: ALP per sale | F21: Show Rate | G21: Close Ratio | H21: ALP/Agent | J21: POS Close | L21: VET Close | M21: REF Per Sit | O21: REF Close | Q21: OTS Close
C22: =COUNTIFS(B28:B1066,B20) -> 14 | E22: =IFERROR(C20/H20,0) -> 1098 | F22: =IFERROR((G20+R20)/F20,0) -> 0.58490566 | G22: =IFERROR(H20/G20,0) -> 0.25 | H22: =(C20/C22) -> 470.57143 | J22: =IFERROR(J20/I20,0) -> 0 | L22: =IFERROR(L20/K20,0) -> 0.13333333 | M22: =IFERROR(M20/SUM(G20+R20,0),"") -> 1.0645161 | O22: =IFERROR(O20/N20,0) -> 0.8 | Q22: =IFERROR(Q20/P20,0) -> 0.11111111
B23: Mikaela Hayes | C23: =SUMIF(B:B,B23,T:T) -> 0 | E23: =SUMIFS(T:T,B:B,B23,D:D,"Y") -> 0 | F23: =SUMIF(B50:B1066,B23,G50:G1066) -> 1 | G23: =SUMIF(B50:B1066,B23,H50:H1066) -> 1 | H23: =SUMIF(B50:B1066,B23,I50:I1066) -> 0 | I23: =SUMIF(B50:B1066,B23,P50:P1066) -> 0 | J23: =SUMIF(B50:B1066,B23,Q50:Q1066) -> 0 | K23: =SUMIF(B50:B1066,B23,R50:R1066) -> 1 | L23: =SUMIF(B50:B1066,B23,S50:S1066) -> 0 | M23: =SUMIF(B50:B1066,B23,M50:M1066) -> 0 | N23: =SUMIF(B50:B1066,B23,N50:N1066) -> 0 | O23: =SUMIF(B50:B1066,B23,O50:O1066) -> 0 | P23: =SUMIF(B50:B1066,B23,J50:J1066) -> 1 | Q23: =SUMIF(B50:B1066,B23,K50:K1066) -> 0 | R23: =SUMIF(B50:B1066,B23,L50:L1066) -> 0
C24: # of Agents | E24: ALP per sale | F24: Show Rate | G24: Close Ratio | H24: ALP/Agent | J24: POS Close | L24: VET Close | M24: REF Per Sit | O24: REF Close | Q24: OTS Close
C25: =COUNTIFS(B33:B1066,B23) -> 5 | E25: =IFERROR(C23/H23,0) -> 0 | F25: =IFERROR((G23+R23)/F23,0) -> 1 | G25: =IFERROR(H23/G23,0) -> 0 | H25: =(C23/C25) -> 0 | J25: =IFERROR(J23/I23,0) -> 0 | L25: =IFERROR(L23/K23,0) -> 0 | M25: =IFERROR(M23/SUM(G23+R23,0),"") -> 0 | O25: =IFERROR(O23/N23,0) -> 0 | Q25: =IFERROR(Q23/P23,0) -> 0
A27: MGA | B27: GA | C27: SA | E27: State | F27: Agent | G27: SETS | H27: SITS | I27: SALES | J27: OTS SITS | K27: OTS SALES | L27: N1 | M27: REF OBT | N27: REF SITS | O27: REF SALES | P27: POS SITS | Q27: POS SALES | R27: VETS SITS | S27: VET SALES | T27: ALP | U27: Close | V27: Show | W27: Code Date
A28: Ashley Rust | D28: Y | F28: Ashley Rust | G28: =('Thurs (2)'!G28+Thurs!G28+'Tues '!G28+Wed!G28+Fri!G28+'Mon '!G28+'Wed (2)'!G28+Sun!G28+Sat!G28) -> 0 | H28: =('Thurs (2)'!H28+Thurs!H28+'Tues '!H28+Wed!H28+Fri!H28+'Mon '!H28+'Wed (2)'!H28+Sun!H28+Sat!H28) -> 0 | I28: =('Thurs (2)'!I28+Thurs!I28+'Tues '!I28+Wed!I28+Fri!I28+'Mon '!I28+'Wed (2)'!I28+Sun!I28+Sat!I28) -> 0 | J28: =('Thurs (2)'!J28+Thurs!J28+'Tues '!J28+Wed!J28+Fri!J28+'Mon '!J28+'Wed (2)'!J28+Sun!J28+Sat!J28) -> 0 | K28: =('Thurs (2)'!K28+Thurs!K28+'Tues '!K28+Wed!K28+Fri!K28+'Mon '!K28+'Wed (2)'!K28+Sun!K28+Sat!K28) -> 0 | L28: =('Thurs (2)'!L28+Thurs!L28+'Tues '!L28+Wed!L28+Fri!L28+'Mon '!L28+'Wed (2)'!L28+Sun!L28+Sat!L28) -> 0 | M28: =('Thurs (2)'!M28+Thurs!M28+'Tues '!M28+Wed!M28+Fri!M28+'Mon '!M28+'Wed (2)'!M28+Sun!M28+Sat!M28) -> 0 | N28: =('Thurs (2)'!N28+Thurs!N28+'Tues '!N28+Wed!N28+Fri!N28+'Mon '!N28+'Wed (2)'!N28+Sun!N28+Sat!N28) -> 0 | ... T28: =('Thurs (2)'!T28+Thurs!T28+'Tues '!T28+Wed!T28+Fri!T28+'Mon '!T28+'Wed (2)'!T28+Sun!T28+Sat!T28) -> 0 | U28: =IFERROR(I28/H28,0) -> 0 | V28: =IFERROR(SUM(H28+L28)/G28,0) -> 0
A29: Ashley Rust | F29: Karly Kelly | G29: =('Thurs (2)'!G29+Thurs!G29+'Tues '!G29+Wed!G29+Fri!G29+'Mon '!G29+'Wed (2)'!G29+Sun!G29+Sat!G29) -> 0 | H29: =('Thurs (2)'!H29+Thurs!H29+'Tues '!H29+Wed!H29+Fri!H29+'Mon '!H29+'Wed (2)'!H29+Sun!H29+Sat!H29) -> 0 | I29: =('Thurs (2)'!I29+Thurs!I29+'Tues '!I29+Wed!I29+Fri!I29+'Mon '!I29+'Wed (2)'!I29+Sun!I29+Sat!I29) -> 0 | J29: =('Thurs (2)'!J29+Thurs!J29+'Tues '!J29+Wed!J29+Fri!J29+'Mon '!J29+'Wed (2)'!J29+Sun!J29+Sat!J29) -> 0 | K29: =('Thurs (2)'!K29+Thurs!K29+'Tues '!K29+Wed!K29+Fri!K29+'Mon '!K29+'Wed (2)'!K29+Sun!K29+Sat!K29) -> 0 | L29: =('Thurs (2)'!L29+Thurs!L29+'Tues '!L29+Wed!L29+Fri!L29+'Mon '!L29+'Wed (2)'!L29+Sun!L29+Sat!L29) -> 0 | M29: =('Thurs (2)'!M29+Thurs!M29+'Tues '!M29+Wed!M29+Fri!M29+'Mon '!M29+'Wed (2)'!M29+Sun!M29+Sat!M29) -> 0 | N29: =('Thurs (2)'!N29+Thurs!N29+'Tues '!N29+Wed!N29+Fri!N29+'Mon '!N29+'Wed (2)'!N29+Sun!N29+Sat!N29) -> 0 | ... T29: =('Thurs (2)'!T29+Thurs!T29+'Tues '!T29+Wed!T29+Fri!T29+'Mon '!T29+'Wed (2)'!T29+Sun!T29+Sat!T29) -> 0 | U29: =IFERROR(I29/H29,0) -> 0 | V29: =IFERROR(SUM(H29+L29)/G29,0) -> 0
A30: Ashley Rust | F30: Andrea Mulder | G30: =('Thurs (2)'!G30+Thurs!G30+'Tues '!G30+Wed!G30+Fri!G30+'Mon '!G30+'Wed (2)'!G30+Sun!G30+Sat!G30) -> 8 | H30: =('Thurs (2)'!H30+Thurs!H30+'Tues '!H30+Wed!H30+Fri!H30+'Mon '!H30+'Wed (2)'!H30+Sun!H30+Sat!H30) -> 5 | I30: =('Thurs (2)'!I30+Thurs!I30+'Tues '!I30+Wed!I30+Fri!I30+'Mon '!I30+'Wed (2)'!I30+Sun!I30+Sat!I30) -> 0 | J30: =('Thurs (2)'!J30+Thurs!J30+'Tues '!J30+Wed!J30+Fri!J30+'Mon '!J30+'Wed (2)'!J30+Sun!J30+Sat!J30) -> 2 | K30: =('Thurs (2)'!K30+Thurs!K30+'Tues '!K30+Wed!K30+Fri!K30+'Mon '!K30+'Wed (2)'!K30+Sun!K30+Sat!K30) -> 0 | L30: =('Thurs (2)'!L30+Thurs!L30+'Tues '!L30+Wed!L30+Fri!L30+'Mon '!L30+'Wed (2)'!L30+Sun!L30+Sat!L30) -> 4 | M30: =('Thurs (2)'!M30+Thurs!M30+'Tues '!M30+Wed!M30+Fri!M30+'Mon '!M30+'Wed (2)'!M30+Sun!M30+Sat!M30) -> 0 | N30: =('Thurs (2)'!N30+Thurs!N30+'Tues '!N30+Wed!N30+Fri!N30+'Mon '!N30+'Wed (2)'!N30+Sun!N30+Sat!N30) -> 1 | ... T30: =('Thurs (2)'!T30+Thurs!T30+'Tues '!T30+Wed!T30+Fri!T30+'Mon '!T30+'Wed (2)'!T30+Sun!T30+Sat!T30) -> 0 | U30: =IFERROR(I30/H30,0) -> 0 | V30: =IFERROR(SUM(H30+L30)/G30,0) -> 1.125
A31: Ashley Rust | B31: Karami Kovar | D31: Y | F31: Karami Kovar | G31: =('Thurs (2)'!G31+Thurs!G31+'Tues '!G31+Wed!G31+Fri!G31+'Mon '!G31+'Wed (2)'!G31+Sun!G31+Sat!G31) -> 0 | H31: =('Thurs (2)'!H31+Thurs!H31+'Tues '!H31+Wed!H31+Fri!H31+'Mon '!H31+'Wed (2)'!H31+Sun!H31+Sat!H31) -> 0 | I31: =('Thurs (2)'!I31+Thurs!I31+'Tues '!I31+Wed!I31+Fri!I31+'Mon '!I31+'Wed (2)'!I31+Sun!I31+Sat!I31) -> 0 | J31: =('Thurs (2)'!J31+Thurs!J31+'Tues '!J31+Wed!J31+Fri!J31+'Mon '!J31+'Wed (2)'!J31+Sun!J31+Sat!J31) -> 0 | K31: =('Thurs (2)'!K31+Thurs!K31+'Tues '!K31+Wed!K31+Fri!K31+'Mon '!K31+'Wed (2)'!K31+Sun!K31+Sat!K31) -> 0 | L31: =('Thurs (2)'!L31+Thurs!L31+'Tues '!L31+Wed!L31+Fri!L31+'Mon '!L31+'Wed (2)'!L31+Sun!L31+Sat!L31) -> 0 | M31: =('Thurs (2)'!M31+Thurs!M31+'Tues '!M31+Wed!M31+Fri!M31+'Mon '!M31+'Wed (2)'!M31+Sun!M31+Sat!M31) -> 0 | N31: =('Thurs (2)'!N31+Thurs!N31+'Tues '!N31+Wed!N31+Fri!N31+'Mon '!N31+'Wed (2)'!N31+Sun!N31+Sat!N31) -> 0 | ... T31: =('Thurs (2)'!T31+Thurs!T31+'Tues '!T31+Wed!T31+Fri!T31+'Mon '!T31+'Wed (2)'!T31+Sun!T31+Sat!T31) -> 0 | U31: =IFERROR(I31/H31,0) -> 0 | V31: =IFERROR(SUM(H31+L31)/G31,0) -> 0
A32: Ashley Rust | B32: Karami Kovar | F32: Bridgett McDaniels Russell | G32: =('Thurs (2)'!G32+Thurs!G32+'Tues '!G32+Wed!G32+Fri!G32+'Mon '!G32+'Wed (2)'!G32+Sun!G32+Sat!G32) -> 0 | H32: =('Thurs (2)'!H32+Thurs!H32+'Tues '!H32+Wed!H32+Fri!H32+'Mon '!H32+'Wed (2)'!H32+Sun!H32+Sat!H32) -> 0 | I32: =('Thurs (2)'!I32+Thurs!I32+'Tues '!I32+Wed!I32+Fri!I32+'Mon '!I32+'Wed (2)'!I32+Sun!I32+Sat!I32) -> 0 | J32: =('Thurs (2)'!J32+Thurs!J32+'Tues '!J32+Wed!J32+Fri!J32+'Mon '!J32+'Wed (2)'!J32+Sun!J32+Sat!J32) -> 0 | K32: =('Thurs (2)'!K32+Thurs!K32+'Tues '!K32+Wed!K32+Fri!K32+'Mon '!K32+'Wed (2)'!K32+Sun!K32+Sat!K32) -> 0 | L32: =('Thurs (2)'!L32+Thurs!L32+'Tues '!L32+Wed!L32+Fri!L32+'Mon '!L32+'Wed (2)'!L32+Sun!L32+Sat!L32) -> 0 | M32: =('Thurs (2)'!M32+Thurs!M32+'Tues '!M32+Wed!M32+Fri!M32+'Mon '!M32+'Wed (2)'!M32+Sun!M32+Sat!M32) -> 0 | N32: =('Thurs (2)'!N32+Thurs!N32+'Tues '!N32+Wed!N32+Fri!N32+'Mon '!N32+'Wed (2)'!N32+Sun!N32+Sat!N32) -> 0 | ... T32: =('Thurs (2)'!T32+Thurs!T32+'Tues '!T32+Wed!T32+Fri!T32+'Mon '!T32+'Wed (2)'!T32+Sun!T32+Sat!T32) -> 0 | U32: =IFERROR(I32/H32,0) -> 0 | V32: =IFERROR(SUM(H32+L32)/G32,0) -> 0
A33: Ashley Rust | B33: Karami Kovar | C33: Jasmine Marquez | D33: Y | F33: Jasmine Marquez | G33: =('Thurs (2)'!G33+Thurs!G33+'Tues '!G33+Wed!G33+Fri!G33+'Mon '!G33+'Wed (2)'!G33+Sun!G33+Sat!G33) -> 2 | H33: =('Thurs (2)'!H33+Thurs!H33+'Tues '!H33+Wed!H33+Fri!H33+'Mon '!H33+'Wed (2)'!H33+Sun!H33+Sat!H33) -> 1 | I33: =('Thurs (2)'!I33+Thurs!I33+'Tues '!I33+Wed!I33+Fri!I33+'Mon '!I33+'Wed (2)'!I33+Sun!I33+Sat!I33) -> 0 | J33: =('Thurs (2)'!J33+Thurs!J33+'Tues '!J33+Wed!J33+Fri!J33+'Mon '!J33+'Wed (2)'!J33+Sun!J33+Sat!J33) -> 1 | K33: =('Thurs (2)'!K33+Thurs!K33+'Tues '!K33+Wed!K33+Fri!K33+'Mon '!K33+'Wed (2)'!K33+Sun!K33+Sat!K33) -> 0 | L33: =('Thurs (2)'!L33+Thurs!L33+'Tues '!L33+Wed!L33+Fri!L33+'Mon '!L33+'Wed (2)'!L33+Sun!L33+Sat!L33) -> 1 | M33: =('Thurs (2)'!M33+Thurs!M33+'Tues '!M33+Wed!M33+Fri!M33+'Mon '!M33+'Wed (2)'!M33+Sun!M33+Sat!M33) -> 7 | N33: =('Thurs (2)'!N33+Thurs!N33+'Tues '!N33+Wed!N33+Fri!N33+'Mon '!N33+'Wed (2)'!N33+Sun!N33+Sat!N33) -> 1 | ... T33: =('Thurs (2)'!T33+Thurs!T33+'Tues '!T33+Wed!T33+Fri!T33+'Mon '!T33+'Wed (2)'!T33+Sun!T33+Sat!T33) -> 0 | U33: =IFERROR(I33/H33,0) -> 0 | V33: =IFERROR(SUM(H33+L33)/G33,0) -> 1
A34: Ashley Rust | B34: Karami Kovar | C34: Jasmine Marquez | F34: Ashley Varner-Warren | G34: =('Thurs (2)'!G34+Thurs!G34+'Tues '!G34+Wed!G34+Fri!G34+'Mon '!G34+'Wed (2)'!G34+Sun!G34+Sat!G34) -> 3 | H34: =('Thurs (2)'!H34+Thurs!H34+'Tues '!H34+Wed!H34+Fri!H34+'Mon '!H34+'Wed (2)'!H34+Sun!H34+Sat!H34) -> 0 | I34: =('Thurs (2)'!I34+Thurs!I34+'Tues '!I34+Wed!I34+Fri!I34+'Mon '!I34+'Wed (2)'!I34+Sun!I34+Sat!I34) -> 0 | J34: =('Thurs (2)'!J34+Thurs!J34+'Tues '!J34+Wed!J34+Fri!J34+'Mon '!J34+'Wed (2)'!J34+Sun!J34+Sat!J34) -> 0 | K34: =('Thurs (2)'!K34+Thurs!K34+'Tues '!K34+Wed!K34+Fri!K34+'Mon '!K34+'Wed (2)'!K34+Sun!K34+Sat!K34) -> 0 | L34: =('Thurs (2)'!L34+Thurs!L34+'Tues '!L34+Wed!L34+Fri!L34+'Mon '!L34+'Wed (2)'!L34+Sun!L34+Sat!L34) -> 0 | M34: =('Thurs (2)'!M34+Thurs!M34+'Tues '!M34+Wed!M34+Fri!M34+'Mon '!M34+'Wed (2)'!M34+Sun!M34+Sat!M34) -> 0 | N34: =('Thurs (2)'!N34+Thurs!N34+'Tues '!N34+Wed!N34+Fri!N34+'Mon '!N34+'Wed (2)'!N34+Sun!N34+Sat!N34) -> 0 | ... T34: =('Thurs (2)'!T34+Thurs!T34+'Tues '!T34+Wed!T34+Fri!T34+'Mon '!T34+'Wed (2)'!T34+Sun!T34+Sat!T34) -> 0 | U34: =IFERROR(I34/H34,0) -> 0 | V34: =IFERROR(SUM(H34+L34)/G34,0) -> 0
A35: Ashley Rust | B35: Karami Kovar | C35: Jasmine Marquez | F35: Kristen Walton | G35: =('Thurs (2)'!G35+Thurs!G35+'Tues '!G35+Wed!G35+Fri!G35+'Mon '!G35+'Wed (2)'!G35+Sun!G35+Sat!G35) -> 9 | H35: =('Thurs (2)'!H35+Thurs!H35+'Tues '!H35+Wed!H35+Fri!H35+'Mon '!H35+'Wed (2)'!H35+Sun!H35+Sat!H35) -> 3 | I35: =('Thurs (2)'!I35+Thurs!I35+'Tues '!I35+Wed!I35+Fri!I35+'Mon '!I35+'Wed (2)'!I35+Sun!I35+Sat!I35) -> 0 | J35: =('Thurs (2)'!J35+Thurs!J35+'Tues '!J35+Wed!J35+Fri!J35+'Mon '!J35+'Wed (2)'!J35+Sun!J35+Sat!J35) -> 0 | K35: =('Thurs (2)'!K35+Thurs!K35+'Tues '!K35+Wed!K35+Fri!K35+'Mon '!K35+'Wed (2)'!K35+Sun!K35+Sat!K35) -> 0 | L35: =('Thurs (2)'!L35+Thurs!L35+'Tues '!L35+Wed!L35+Fri!L35+'Mon '!L35+'Wed (2)'!L35+Sun!L35+Sat!L35) -> 1 | M35: =('Thurs (2)'!M35+Thurs!M35+'Tues '!M35+Wed!M35+Fri!M35+'Mon '!M35+'Wed (2)'!M35+Sun!M35+Sat!M35) -> 22 | N35: =('Thurs (2)'!N35+Thurs!N35+'Tues '!N35+Wed!N35+Fri!N35+'Mon '!N35+'Wed (2)'!N35+Sun!N35+Sat!N35) -> 0 | ... T35: =('Thurs (2)'!T35+Thurs!T35+'Tues '!T35+Wed!T35+Fri!T35+'Mon '!T35+'Wed (2)'!T35+Sun!T35+Sat!T35) -> 0 | U35: =IFERROR(I35/H35,0) -> 0 | V35: =IFERROR(SUM(H35+L35)/G35,0) -> 0.44444444
A36: Ashley Rust | B36: Karami Kovar | C36: Jasmine Marquez | F36: Sara Subo | G36: =('Thurs (2)'!G36+Thurs!G36+'Tues '!G36+Wed!G36+Fri!G36+'Mon '!G36+'Wed (2)'!G36+Sun!G36+Sat!G36) -> 0 | H36: =('Thurs (2)'!H36+Thurs!H36+'Tues '!H36+Wed!H36+Fri!H36+'Mon '!H36+'Wed (2)'!H36+Sun!H36+Sat!H36) -> 0 | I36: =('Thurs (2)'!I36+Thurs!I36+'Tues '!I36+Wed!I36+Fri!I36+'Mon '!I36+'Wed (2)'!I36+Sun!I36+Sat!I36) -> 0 | J36: =('Thurs (2)'!J36+Thurs!J36+'Tues '!J36+Wed!J36+Fri!J36+'Mon '!J36+'Wed (2)'!J36+Sun!J36+Sat!J36) -> 0 | K36: =('Thurs (2)'!K36+Thurs!K36+'Tues '!K36+Wed!K36+Fri!K36+'Mon '!K36+'Wed (2)'!K36+Sun!K36+Sat!K36) -> 0 | L36: =('Thurs (2)'!L36+Thurs!L36+'Tues '!L36+Wed!L36+Fri!L36+'Mon '!L36+'Wed (2)'!L36+Sun!L36+Sat!L36) -> 0 | M36: =('Thurs (2)'!M36+Thurs!M36+'Tues '!M36+Wed!M36+Fri!M36+'Mon '!M36+'Wed (2)'!M36+Sun!M36+Sat!M36) -> 0 | N36: =('Thurs (2)'!N36+Thurs!N36+'Tues '!N36+Wed!N36+Fri!N36+'Mon '!N36+'Wed (2)'!N36+Sun!N36+Sat!N36) -> 0 | ... T36: =('Thurs (2)'!T36+Thurs!T36+'Tues '!T36+Wed!T36+Fri!T36+'Mon '!T36+'Wed (2)'!T36+Sun!T36+Sat!T36) -> 0 | U36: =IFERROR(I36/H36,0) -> 0 | V36: =IFERROR(SUM(H36+L36)/G36,0) -> 0
A37: Ashley Rust | B37: Karami Kovar | C37: Jasmine Marquez | F37: Thomas Kirk | G37: =('Thurs (2)'!G37+Thurs!G37+'Tues '!G37+Wed!G37+Fri!G37+'Mon '!G37+'Wed (2)'!G37+Sun!G37+Sat!G37) -> 1 | H37: =('Thurs (2)'!H37+Thurs!H37+'Tues '!H37+Wed!H37+Fri!H37+'Mon '!H37+'Wed (2)'!H37+Sun!H37+Sat!H37) -> 1 | I37: =('Thurs (2)'!I37+Thurs!I37+'Tues '!I37+Wed!I37+Fri!I37+'Mon '!I37+'Wed (2)'!I37+Sun!I37+Sat!I37) -> 1 | J37: =('Thurs (2)'!J37+Thurs!J37+'Tues '!J37+Wed!J37+Fri!J37+'Mon '!J37+'Wed (2)'!J37+Sun!J37+Sat!J37) -> 0 | K37: =('Thurs (2)'!K37+Thurs!K37+'Tues '!K37+Wed!K37+Fri!K37+'Mon '!K37+'Wed (2)'!K37+Sun!K37+Sat!K37) -> 0 | L37: =('Thurs (2)'!L37+Thurs!L37+'Tues '!L37+Wed!L37+Fri!L37+'Mon '!L37+'Wed (2)'!L37+Sun!L37+Sat!L37) -> 0 | M37: =('Thurs (2)'!M37+Thurs!M37+'Tues '!M37+Wed!M37+Fri!M37+'Mon '!M37+'Wed (2)'!M37+Sun!M37+Sat!M37) -> 3 | N37: =('Thurs (2)'!N37+Thurs!N37+'Tues '!N37+Wed!N37+Fri!N37+'Mon '!N37+'Wed (2)'!N37+Sun!N37+Sat!N37) -> 1 | ... T37: =('Thurs (2)'!T37+Thurs!T37+'Tues '!T37+Wed!T37+Fri!T37+'Mon '!T37+'Wed (2)'!T37+Sun!T37+Sat!T37) -> 670 | U37: =IFERROR(I37/H37,0) -> 1 | V37: =IFERROR(SUM(H37+L37)/G37,0) -> 1
A38: Ashley Rust | B38: Karami Kovar | C38: Jasmine Marquez | F38: Isabela Maneiro | G38: =('Thurs (2)'!G38+Thurs!G38+'Tues '!G38+Wed!G38+Fri!G38+'Mon '!G38+'Wed (2)'!G38+Sun!G38+Sat!G38) -> 10 | H38: =('Thurs (2)'!H38+Thurs!H38+'Tues '!H38+Wed!H38+Fri!H38+'Mon '!H38+'Wed (2)'!H38+Sun!H38+Sat!H38) -> 3 | I38: =('Thurs (2)'!I38+Thurs!I38+'Tues '!I38+Wed!I38+Fri!I38+'Mon '!I38+'Wed (2)'!I38+Sun!I38+Sat!I38) -> 0 | J38: =('Thurs (2)'!J38+Thurs!J38+'Tues '!J38+Wed!J38+Fri!J38+'Mon '!J38+'Wed (2)'!J38+Sun!J38+Sat!J38) -> 1 | K38: =('Thurs (2)'!K38+Thurs!K38+'Tues '!K38+Wed!K38+Fri!K38+'Mon '!K38+'Wed (2)'!K38+Sun!K38+Sat!K38) -> 0 | L38: =('Thurs (2)'!L38+Thurs!L38+'Tues '!L38+Wed!L38+Fri!L38+'Mon '!L38+'Wed (2)'!L38+Sun!L38+Sat!L38) -> 0 | M38: =('Thurs (2)'!M38+Thurs!M38+'Tues '!M38+Wed!M38+Fri!M38+'Mon '!M38+'Wed (2)'!M38+Sun!M38+Sat!M38) -> 14 | N38: =('Thurs (2)'!N38+Thurs!N38+'Tues '!N38+Wed!N38+Fri!N38+'Mon '!N38+'Wed (2)'!N38+Sun!N38+Sat!N38) -> 1 | ... T38: =('Thurs (2)'!T38+Thurs!T38+'Tues '!T38+Wed!T38+Fri!T38+'Mon '!T38+'Wed (2)'!T38+Sun!T38+Sat!T38) -> 0 | U38: =IFERROR(I38/H38,0) -> 0 | V38: =IFERROR(SUM(H38+L38)/G38,0) -> 0.3
A39: Ashley Rust | B39: Karami Kovar | C39: Ryan Cummings | D39: Y | F39: Ryan Cummings | G39: =('Thurs (2)'!G39+Thurs!G39+'Tues '!G39+Wed!G39+Fri!G39+'Mon '!G39+'Wed (2)'!G39+Sun!G39+Sat!G39) -> 0 | H39: =('Thurs (2)'!H39+Thurs!H39+'Tues '!H39+Wed!H39+Fri!H39+'Mon '!H39+'Wed (2)'!H39+Sun!H39+Sat!H39) -> 0 | I39: =('Thurs (2)'!I39+Thurs!I39+'Tues '!I39+Wed!I39+Fri!I39+'Mon '!I39+'Wed (2)'!I39+Sun!I39+Sat!I39) -> 0 | J39: =('Thurs (2)'!J39+Thurs!J39+'Tues '!J39+Wed!J39+Fri!J39+'Mon '!J39+'Wed (2)'!J39+Sun!J39+Sat!J39) -> 0 | K39: =('Thurs (2)'!K39+Thurs!K39+'Tues '!K39+Wed!K39+Fri!K39+'Mon '!K39+'Wed (2)'!K39+Sun!K39+Sat!K39) -> 0 | L39: =('Thurs (2)'!L39+Thurs!L39+'Tues '!L39+Wed!L39+Fri!L39+'Mon '!L39+'Wed (2)'!L39+Sun!L39+Sat!L39) -> 0 | M39: =('Thurs (2)'!M39+Thurs!M39+'Tues '!M39+Wed!M39+Fri!M39+'Mon '!M39+'Wed (2)'!M39+Sun!M39+Sat!M39) -> 0 | N39: =('Thurs (2)'!N39+Thurs!N39+'Tues '!N39+Wed!N39+Fri!N39+'Mon '!N39+'Wed (2)'!N39+Sun!N39+Sat!N39) -> 0 | ... T39: =('Thurs (2)'!T39+Thurs!T39+'Tues '!T39+Wed!T39+Fri!T39+'Mon '!T39+'Wed (2)'!T39+Sun!T39+Sat!T39) -> 0 | U39: =IFERROR(I39/H39,0) -> 0 | V39: =IFERROR(SUM(H39+L39)/G39,0) -> 0
A40: Ashley Rust | B40: Karami Kovar | C40: Ryan Cummings | F40: Charlie Hudson | G40: =('Thurs (2)'!G40+Thurs!G40+'Tues '!G40+Wed!G40+Fri!G40+'Mon '!G40+'Wed (2)'!G40+Sun!G40+Sat!G40) -> 0 | H40: =('Thurs (2)'!H40+Thurs!H40+'Tues '!H40+Wed!H40+Fri!H40+'Mon '!H40+'Wed (2)'!H40+Sun!H40+Sat!H40) -> 0 | I40: =('Thurs (2)'!I40+Thurs!I40+'Tues '!I40+Wed!I40+Fri!I40+'Mon '!I40+'Wed (2)'!I40+Sun!I40+Sat!I40) -> 0 | J40: =('Thurs (2)'!J40+Thurs!J40+'Tues '!J40+Wed!J40+Fri!J40+'Mon '!J40+'Wed (2)'!J40+Sun!J40+Sat!J40) -> 0 | K40: =('Thurs (2)'!K40+Thurs!K40+'Tues '!K40+Wed!K40+Fri!K40+'Mon '!K40+'Wed (2)'!K40+Sun!K40+Sat!K40) -> 0 | L40: =('Thurs (2)'!L40+Thurs!L40+'Tues '!L40+Wed!L40+Fri!L40+'Mon '!L40+'Wed (2)'!L40+Sun!L40+Sat!L40) -> 0 | M40: =('Thurs (2)'!M40+Thurs!M40+'Tues '!M40+Wed!M40+Fri!M40+'Mon '!M40+'Wed (2)'!M40+Sun!M40+Sat!M40) -> 0 | N40: =('Thurs (2)'!N40+Thurs!N40+'Tues '!N40+Wed!N40+Fri!N40+'Mon '!N40+'Wed (2)'!N40+Sun!N40+Sat!N40) -> 0 | ... T40: =('Thurs (2)'!T40+Thurs!T40+'Tues '!T40+Wed!T40+Fri!T40+'Mon '!T40+'Wed (2)'!T40+Sun!T40+Sat!T40) -> 0 | U40: =IFERROR(I40/H40,0) -> 0 | V40: =IFERROR(SUM(H40+L40)/G40,0) -> 0
A41: Ashley Rust | B41: Karami Kovar | C41: Ryan Cummings | F41: Bayle Kizer | G41: =('Thurs (2)'!G41+Thurs!G41+'Tues '!G41+Wed!G41+Fri!G41+'Mon '!G41+'Wed (2)'!G41+Sun!G41+Sat!G41) -> 0 | H41: =('Thurs (2)'!H41+Thurs!H41+'Tues '!H41+Wed!H41+Fri!H41+'Mon '!H41+'Wed (2)'!H41+Sun!H41+Sat!H41) -> 0 | I41: =('Thurs (2)'!I41+Thurs!I41+'Tues '!I41+Wed!I41+Fri!I41+'Mon '!I41+'Wed (2)'!I41+Sun!I41+Sat!I41) -> 0 | J41: =('Thurs (2)'!J41+Thurs!J41+'Tues '!J41+Wed!J41+Fri!J41+'Mon '!J41+'Wed (2)'!J41+Sun!J41+Sat!J41) -> 0 | K41: =('Thurs (2)'!K41+Thurs!K41+'Tues '!K41+Wed!K41+Fri!K41+'Mon '!K41+'Wed (2)'!K41+Sun!K41+Sat!K41) -> 0 | L41: =('Thurs (2)'!L41+Thurs!L41+'Tues '!L41+Wed!L41+Fri!L41+'Mon '!L41+'Wed (2)'!L41+Sun!L41+Sat!L41) -> 0 | M41: =('Thurs (2)'!M41+Thurs!M41+'Tues '!M41+Wed!M41+Fri!M41+'Mon '!M41+'Wed (2)'!M41+Sun!M41+Sat!M41) -> 0 | N41: =('Thurs (2)'!N41+Thurs!N41+'Tues '!N41+Wed!N41+Fri!N41+'Mon '!N41+'Wed (2)'!N41+Sun!N41+Sat!N41) -> 0 | ... T41: =('Thurs (2)'!T41+Thurs!T41+'Tues '!T41+Wed!T41+Fri!T41+'Mon '!T41+'Wed (2)'!T41+Sun!T41+Sat!T41) -> 0 | U41: =IFERROR(I41/H41,0) -> 0 | V41: =IFERROR(SUM(H41+L41)/G41,0) -> 0
...

Sheet Wed
C1: ALP | E1: LEADERSHIP ALP | F1: Appts | G1: Pres | H1: Sales | I1: POS SITS | J1: POS SA | K1: VET SITS | L1: VET SA | M1: REF OBT | N1: REF SITS | O1: REF SA | P1: OTS SITS | Q1: OTS SA | R1: N1
B2: RUST RGA | C2: =SUM(C5,C14,C17) -> 774 | E2: =SUM(E5,E14,E17) -> 774 | F2: =SUM(F5,F14,F17) -> 19 | G2: =SUM(G5,G14,G17) -> 9 | H2: =SUM(H5,H14,H17) -> 1 | I2: =SUM(I5,I14,I17) -> 0 | J2: =SUM(J5,J14,J17) -> 0 | K2: =SUM(K5,K14,K17) -> 5 | L2: =SUM(L5,L14,L17) -> 0 | ... R2: =SUM(R5,R14,R17) -> 3
C3: # of Agents | E3: ALP per sale | F3: Show Rate | G3: Close Ratio | H3: ALP/Agent | J3: POS Close | L3: VET Close | M3: REF Per Sit | O3: REF Close | Q3: OTS Close
C4: =SUM(C7,C19,C16) -> 45 | E4: =IFERROR(C2/H2,0) -> 774 | F4: =IFERROR((G2+R2)/F2,0) -> 0.63157895 | G4: =IFERROR(H2/G2,0) -> 0.11111111 | H4: =(C2/C4) -> 17.2 | J4: =IFERROR(J2/I2,0) -> 0 | L4: =IFERROR(L2/K2,0) -> 0 | M4: =IFERROR(M2/G2,0) -> 1.4444444 | O4: =IFERROR(O2/N2,0) -> 0 | Q4: =IFERROR(Q2/P2,0) -> 0
B5: Ashley Rust | C5: =SUMIF(A:A,B5,T:T) -> 0 | E5: =SUMIFS(T:T,A:A,B5,D:D,"Y") -> 0 | F5: =SUMIF(A:A,B5,G:G) -> 8 | G5: =SUMIF(A:A,B5,H:H) -> 2 | H5: =SUMIF(A:A,B5,I:I) -> 0 | I5: =SUMIF(A:A,B5,P:P) -> 0 | J5: =SUMIF(A:A,B5,Q:Q) -> 0 | K5: =SUMIF(A:A,B5,R:R) -> 0 | L5: =SUMIF(A:A,B5,S:S) -> 0 | M5: =SUMIF(A:A,B5,M:M) -> 7 | N5: =SUMIF(A:A,B5,N:N) -> 1 | O5: =SUMIF(A:A,B5,O:O) -> 0 | P5: =SUMIF(A:A,B5,J:J) -> 1 | Q5: =SUMIF(A:A,B5,K:K) -> 0 | R5: =SUMIF(A:A,B5,L:L) -> 1
C6: # of Agents | E6: ALP per sale | F6: Show Rate | G6: Close Ratio | H6: ALP/Agent | J6: POS Close | L6: VET Close | M6: REF Per Sit | O6: REF Close | Q6: OTS Close
C7: =COUNTIFS(A:A,B5) -> 19 | E7: =IFERROR(C5/H5,0) -> 0 | F7: =IFERROR((G5+R5)/F5,0) -> 0.375 | G7: =IFERROR(H5/G5,0) -> 0 | H7: =(C5/C7) -> 0 | J7: =IFERROR(J5/I5,0) -> 0 | L7: =IFERROR(L5/K5,0) -> 0 | M7: =IFERROR(M5/SUM(R5+G5,0),"") -> 2.3333333 | O7: =IFERROR(O5/N5,0) -> 0 | Q7: =IFERROR(Q5/P5,0) -> 0
B8: Troy Williams | C8: =SUMIF(B:B,B8,T:T) -> 0 | E8: =SUMIFS(T:T,B:B,B8,D:D,"Y") -> 0 | F8: =SUMIF(B39:B1137,B8,G39:G1137) -> 0 | G8: =SUMIF(B39:B1137,B8,H39:H1137) -> 0 | H8: =SUMIF(B39:B1137,B8,I39:I1137) -> 0 | I8: =SUMIF(B39:B1137,B8,P39:P1137) -> 0 | J8: =SUMIF(B39:B1137,B8,Q39:Q1137) -> 0 | K8: =SUMIF(B39:B1137,B8,R39:R1137) -> 0 | L8: =SUMIF(B39:B1137,B8,S39:S1137) -> 0 | M8: =SUMIF(B39:B1137,B8,M39:M1137) -> 0 | N8: =SUMIF(B39:B1137,B8,N39:N1137) -> 0 | O8: =SUMIF(B39:B1137,B8,O39:O1137) -> 0 | P8: =SUMIF(B39:B1137,B8,J39:J1137) -> 0 | Q8: =SUMIF(B39:B1137,B8,K39:K1137) -> 0 | R8: =SUMIF(B39:B1137,B8,L39:L1137) -> 0
C9: # of Agents | E9: ALP per sale | F9: Show Rate | G9: Close Ratio | H9: ALP/Agent | J9: POS Close | L9: VET Close | M9: REF Per Sit | O9: REF Close | Q9: OTS Close
C10: =COUNTIFS(B28:B1137,B8) -> 5 | E10: =IFERROR(C8/H8,0) -> 0 | F10: =IFERROR((G8+R8)/F8,0) -> 0 | G10: =IFERROR(H8/G8,0) -> 0 | H10: =(C8/C10) -> 0 | J10: =IFERROR(J8/I8,0) -> 0 | L10: =IFERROR(L8/K8,0) -> 0 | M10: =IFERROR(M8/SUM(G8+R8,0),"") | O10: =IFERROR(O8/N8,0) -> 0 | Q10: =IFERROR(Q8/P8,0) -> 0
B11: Karami Kovar | C11: =SUMIF(B:B,B11,T:T) -> 0 | E11: =SUMIFS(T:T,B:B,B11,D:D,"Y") -> 0 | F11: =SUMIF(B28:B1137,B11,G28:G1137) -> 6 | G11: =SUMIF(C28:C1137,C11,H28:H1137) -> 0 | H11: =SUMIF(D28:D1137,D11,I28:I1137) -> 0 | I11: =SUMIF(E28:E1137,E11,J28:J1137) -> 0 | J11: =SUMIF(F28:F1137,F11,K28:K1137) -> 0 | K11: =SUMIF(G28:G1137,G11,L28:L1137) -> 0 | L11: =SUMIF(H28:H1137,H11,M28:M1137) -> 0 | M11: =SUMIF(I28:I1137,I11,N28:N1137) -> 2 | ... R11: =SUMIF(N28:N1137,N11,S28:S1137) -> 0
C12: # of Agents | E12: ALP per sale | F12: Show Rate | G12: Close Ratio | H12: ALP/Agent | J12: POS Close | L12: VET Close | M12: REF Per Sit | O12: REF Close | Q12: OTS Close
C13: =COUNTIFS(B27:B1137,B11) -> 11 | E13: =IFERROR(C11/H11,0) -> 0 | F13: =IFERROR((G11+R11)/F11,0) -> 0 | G13: =IFERROR(H11/G11,0) -> 0 | H13: =(C11/C13) -> 0 | J13: =IFERROR(J11/I11,0) -> 0 | L13: =IFERROR(L11/K11,0) -> 0 | M13: =IFERROR(M11/SUM(G11+R11,0),"") | O13: =IFERROR(O11/N11,0) -> 0 | Q13: =IFERROR(Q11/P11,0) -> 0
B14: Joy Vann-Austin | C14: =SUMIF(A:A,B14,T:T) -> 774 | E14: =SUMIFS(T:T,A:A,B14,D:D,"Y") -> 774 | F14: =SUMIF(A:A,B14,G:G) -> 2 | G14: =SUMIF(A:A,B14,H:H) -> 2 | H14: =SUMIF(A:A,B14,I:I) -> 1 | I14: =SUMIF(A:A,B14,P:P) -> 0 | J14: =SUMIF(A:A,B14,Q:Q) -> 0 | K14: =SUMIF(A:A,B14,R:R) -> 1 | L14: =SUMIF(A:A,B14,S:S) -> 0 | M14: =SUMIF(A:A,B14,M:M) -> 2 | N14: =SUMIF(A:A,B14,N:N) -> 0 | O14: =SUMIF(A:A,B14,O:O) -> 0 | P14: =SUMIF(A:A,B14,J:J) -> 1 | Q14: =SUMIF(A:A,B14,K:K) -> 0 | R14: =SUMIF(A:A,B14,L:L) -> 1
C15: # of Agents | E15: ALP per sale | F15: Show Rate | G15: Close Ratio | H15: ALP/Agent | J15: POS Close | L15: VET Close | M15: REF Per Sit | O15: REF Close | Q15: OTS Close
C16: =COUNTIFS(A:A,B14) -> 4 | E16: =IFERROR(C14/H14,0) -> 774 | F16: =IFERROR((G14+R14)/F14,0) -> 1.5 | G16: =IFERROR(H14/G14,0) -> 0.5 | H16: =(C14/C16) -> 193.5 | J16: =IFERROR(J14/I14,0) -> 0 | L16: =IFERROR(L14/K14,0) -> 0 | M16: =IFERROR(M14/SUM(R14+G14,0),"") -> 0.66666667 | O16: =IFERROR(O14/N14,0) -> 0 | Q16: =IFERROR(Q14/P14,0) -> 0
B17: Torian Fields | C17: =SUMIF(A:A,B17,T:T) -> 0 | E17: =SUMIFS(T:T,A:A,B17,D:D,"Y") -> 0 | F17: =SUMIF(A:A,B17,G:G) -> 9 | G17: =SUMIF(A:A,B17,H:H) -> 5 | H17: =SUMIF(A:A,B17,I:I) -> 0 | I17: =SUMIF(A:A,B17,P:P) -> 0 | J17: =SUMIF(A:A,B17,Q:Q) -> 0 | K17: =SUMIF(A:A,B17,R:R) -> 4 | L17: =SUMIF(A:A,B17,S:S) -> 0 | M17: =SUMIF(A:A,B17,M:M) -> 4 | N17: =SUMIF(A:A,B17,N:N) -> 1 | O17: =SUMIF(A:A,B17,O:O) -> 0 | P17: =SUMIF(A:A,B17,J:J) -> 3 | Q17: =SUMIF(A:A,B17,K:K) -> 0 | R17: =SUMIF(A:A,B17,L:L) -> 1
C18: # of Agents | E18: ALP per sale | F18: Show Rate | G18: Close Ratio | H18: ALP/Agent | J18: POS Close | L18: VET Close | M18: REF Per Sit | O18: REF Close | Q18: OTS Close
C19: =COUNTIFS(A:A,B17) -> 22 | E19: =IFERROR(C17/H17,0) -> 0 | F19: =IFERROR((G17+R17)/F17,0) -> 0.66666667 | G19: =IFERROR(H17/G17,0) -> 0 | H19: =(C17/C19) -> 0 | J19: =IFERROR(J17/I17,0) -> 0 | L19: =IFERROR(L17/K17,0) -> 0 | M19: =IFERROR(M17/SUM(G17+R17,0),"") -> 0.66666667 | O19: =IFERROR(O17/N17,0) -> 0 | Q19: =IFERROR(Q17/P17,0) -> 0
B20: Devin Gould | C20: =SUMIF(B:B,B20,T:T) -> 0 | E20: =SUMIFS(T:T,B:B,B20,D:D,"Y") -> 0 | F20: =SUMIF(B47:B1137,B20,G47:G1137) -> 8 | G20: =SUMIF(B47:B1137,B20,H47:H1137) -> 4 | H20: =SUMIF(B47:B1137,B20,I47:I1137) -> 0 | I20: =SUMIF(B47:B1137,B20,P47:P1137) -> 0 | J20: =SUMIF(B47:B1137,B20,Q47:Q1137) -> 0 | K20: =SUMIF(B47:B1137,B20,R47:R1137) -> 3 | L20: =SUMIF(B47:B1137,B20,S47:S1137) -> 0 | M20: =SUMIF(B47:B1137,B20,M47:M1137) -> 4 | N20: =SUMIF(B47:B1137,B20,N47:N1137) -> 1 | O20: =SUMIF(B47:B1137,B20,O47:O1137) -> 0 | P20: =SUMIF(B47:B1137,B20,J47:J1137) -> 2 | Q20: =SUMIF(B47:B1137,B20,K47:K1137) -> 0 | R20: =SUMIF(B47:B1137,B20,L47:L1137) -> 1
C21: # of Agents | E21: ALP per sale | F21: Show Rate | G21: Close Ratio | H21: ALP/Agent | J21: POS Close | L21: VET Close | M21: REF Per Sit | O21: REF Close | Q21: OTS Close
C22: =COUNTIFS(B28:B1137,B20) -> 14 | E22: =IFERROR(C20/H20,0) -> 0 | F22: =IFERROR((G20+R20)/F20,0) -> 0.625 | G22: =IFERROR(H20/G20,0) -> 0 | H22: =(C20/C22) -> 0 | J22: =IFERROR(J20/I20,0) -> 0 | L22: =IFERROR(L20/K20,0) -> 0 | M22: =IFERROR(M20/SUM(G20+R20,0),"") -> 0.8 | O22: =IFERROR(O20/N20,0) -> 0 | Q22: =IFERROR(Q20/P20,0) -> 0
B23: Mikaela Hayes | C23: =SUMIF(B:B,B23,T:T) -> 0 | E23: =SUMIFS(T:T,B:B,B23,D:D,"Y") -> 0 | F23: =SUMIF(B50:B1137,B23,G50:G1137) -> 1 | G23: =SUMIF(B50:B1137,B23,H50:H1137) -> 1 | H23: =SUMIF(B50:B1137,B23,I50:I1137) -> 0 | I23: =SUMIF(B50:B1137,B23,P50:P1137) -> 0 | J23: =SUMIF(B50:B1137,B23,Q50:Q1137) -> 0 | K23: =SUMIF(B50:B1137,B23,R50:R1137) -> 1 | L23: =SUMIF(B50:B1137,B23,S50:S1137) -> 0 | M23: =SUMIF(B50:B1137,B23,M50:M1137) -> 0 | N23: =SUMIF(B50:B1137,B23,N50:N1137) -> 0 | O23: =SUMIF(B50:B1137,B23,O50:O1137) -> 0 | P23: =SUMIF(B50:B1137,B23,J50:J1137) -> 1 | Q23: =SUMIF(B50:B1137,B23,K50:K1137) -> 0 | R23: =SUMIF(B50:B1137,B23,L50:L1137) -> 0
C24: # of Agents | E24: ALP per sale | F24: Show Rate | G24: Close Ratio | H24: ALP/Agent | J24: POS Close | L24: VET Close | M24: REF Per Sit | O24: REF Close | Q24: OTS Close
C25: =COUNTIFS(B33:B1137,B23) -> 5 | E25: =IFERROR(C23/H23,0) -> 0 | F25: =IFERROR((G23+R23)/F23,0) -> 1 | G25: =IFERROR(H23/G23,0) -> 0 | H25: =(C23/C25) -> 0 | J25: =IFERROR(J23/I23,0) -> 0 | L25: =IFERROR(L23/K23,0) -> 0 | M25: =IFERROR(M23/SUM(G23+R23,0),"") -> 0 | O25: =IFERROR(O23/N23,0) -> 0 | Q25: =IFERROR(Q23/P23,0) -> 0
A27: MGA | B27: GA | C27: SA | E27: State | F27: Agent | G27: SETS | H27: SITS | I27: SALES | J27: OTS SITS | K27: OTS SALES | L27: N1 | M27: REF OBT | N27: REF SITS | O27: REF SALES | P27: POS SITS | Q27: POS SALES | R27: VETS SITS | S27: VET SALES | T27: ALP | U27: Close | V27: Show | W27: Code Date
A28: Ashley Rust | D28: Y | F28: Ashley Rust | U28: =IFERROR(I28/H28,0) -> 0 | V28: =IFERROR(SUM(H28+L28)/G28,0) -> 0
A29: Ashley Rust | F29: Karly Kelly | U29: =IFERROR(I29/H29,0) -> 0 | V29: =IFERROR(SUM(H29+L29)/G29,0) -> 0
A30: Ashley Rust | F30: Andrea Mulder | G30: 2 | H30: 0 | I30: 0 | J30: 0 | K30: 0 | L30: 0 | M30: 0 | N30: 0 | O30: 0 | P30: 0 | Q30: 0 | R30: 0 | S30: 0 | T30: 0 | U30: =IFERROR(I30/H30,0) -> 0 | V30: =IFERROR(SUM(H30+L30)/G30,0) -> 0
A31: Ashley Rust | B31: Karami Kovar | D31: Y | F31: Karami Kovar | U31: =IFERROR(I31/H31,0) -> 0 | V31: =IFERROR(SUM(H31+L31)/G31,0) -> 0
A32: Ashley Rust | B32: Karami Kovar | F32: Bridgett McDaniels Russell | U32: =IFERROR(I32/H32,0) -> 0 | V32: =IFERROR(SUM(H32+L32)/G32,0) -> 0
A33: Ashley Rust | B33: Karami Kovar | C33: Jasmine Marquez | D33: Y | F33: Jasmine Marquez | G33: 0 | H33: 0 | I33: 0 | J33: 0 | K33: 0 | L33: 0 | M33: 0 | N33: 0 | O33: 0 | P33: 0 | Q33: 0 | R33: 0 | S33: 0 | T33: 0 | U33: =IFERROR(I33/H33,0) -> 0 | V33: =IFERROR(SUM(H33+L33)/G33,0) -> 0
A34: Ashley Rust | B34: Karami Kovar | C34: Jasmine Marquez | F34: Ashley Varner-Warren | G34: 1 | H34: 0 | I34: 0 | J34: 0 | K34: 0 | L34: 0 | M34: 0 | N34: 0 | O34: 0 | P34: 0 | Q34: 0 | R34: 0 | S34: 0 | T34: 0 | U34: =IFERROR(I34/H34,0) -> 0 | V34: =IFERROR(SUM(H34+L34)/G34,0) -> 0
A35: Ashley Rust | B35: Karami Kovar | C35: Jasmine Marquez | F35: Kristen Walton | G35: 2 | H35: 1 | I35: 0 | J35: 0 | K35: 0 | L35: 1 | M35: 4 | N35: 0 | O35: 0 | P35: 0 | Q35: 0 | R35: 0 | S35: 0 | T35: 0 | U35: =IFERROR(I35/H35,0) -> 0 | V35: =IFERROR(SUM(H35+L35)/G35,0) -> 1
A36: Ashley Rust | B36: Karami Kovar | C36: Jasmine Marquez | F36: Sara Subo | G36: 0 | H36: 0 | I36: 0 | J36: 0 | K36: 0 | L36: 0 | M36: 0 | N36: 0 | O36: 0 | P36: 0 | Q36: 0 | R36: 0 | S36: 0 | T36: 0 | U36: =IFERROR(I36/H36,0) -> 0 | V36: =IFERROR(SUM(H36+L36)/G36,0) -> 0
A37: Ashley Rust | B37: Karami Kovar | C37: Jasmine Marquez | F37: Thomas Kirk | G37: 0 | H37: 0 | I37: 0 | J37: 0 | K37: 0 | L37: 0 | M37: 0 | N37: 0 | O37: 0 | P37: 0 | Q37: 0 | R37: 0 | S37: 0 | T37: 0 | U37: =IFERROR(I37/H37,0) -> 0 | V37: =IFERROR(SUM(H37+L37)/G37,0) -> 0
A38: Ashley Rust | B38: Karami Kovar | C38: Jasmine Marquez | F38: Isabela Maneiro | G38: 3 | H38: 1 | I38: 0 | J38: 1 | K38: 0 | L38: 0 | M38: 3 | N38: 1 | O38: 0 | P38: 0 | Q38: 0 | R38: 0 | S38: 0 | T38: 0 | U38: =IFERROR(I38/H38,0) -> 0 | V38: =IFERROR(SUM(H38+L38)/G38,0) -> 0.33333333
A39: Ashley Rust | B39: Karami Kovar | C39: Ryan Cummings | D39: Y | F39: Ryan Cummings | U39: =IFERROR(I39/H39,0) -> 0 | V39: =IFERROR(SUM(H39+L39)/G39,0) -> 0
A40: Ashley Rust | B40: Karami Kovar | C40: Ryan Cummings | F40: Charlie Hudson | U40: =IFERROR(I40/H40,0) -> 0 | V40: =IFERROR(SUM(H40+L40)/G40,0) -> 0
A41: Ashley Rust | B41: Karami Kovar | C41: Ryan Cummings | F41: Bayle Kizer | U41: =IFERROR(I41/H41,0) -> 0 | V41: =IFERROR(SUM(H41+L41)/G41,0) -> 0
...

Sheet Thurs
C1: ALP | E1: LEADERSHIP ALP | F1: Appts | G1: Pres | H1: Sales | I1: POS SITS | J1: POS SA | K1: VET SITS | L1: VET SA | M1: REF OBT | N1: REF SITS | O1: REF SA | P1: OTS SITS | Q1: OTS SA | R1: N1
B2: RUST RGA | C2: =SUM(C5,C14,C17) -> 670 | E2: =SUM(E5,E14,E17) -> 0 | F2: =SUM(F5,F14,F17) -> 18 | G2: =SUM(G5,G14,G17) -> 6 | H2: =SUM(H5,H14,H17) -> 1 | I2: =SUM(I5,I14,I17) -> 0 | J2: =SUM(J5,J14,J17) -> 0 | K2: =SUM(K5,K14,K17) -> 4 | L2: =SUM(L5,L14,L17) -> 0 | ... R2: =SUM(R5,R14,R17) -> 2
C3: # of Agents | E3: ALP per sale | F3: Show Rate | G3: Close Ratio | H3: ALP/Agent | J3: POS Close | L3: VET Close | M3: REF Per Sit | O3: REF Close | Q3: OTS Close
C4: =SUM(C7,C19,C16) -> 45 | E4: =IFERROR(C2/H2,0) -> 670 | F4: =IFERROR((G2+R2)/F2,0) -> 0.44444444 | G4: =IFERROR(H2/G2,0) -> 0.16666667 | H4: =(C2/C4) -> 14.888889 | J4: =IFERROR(J2/I2,0) -> 0 | L4: =IFERROR(L2/K2,0) -> 0 | M4: =IFERROR(M2/G2,0) -> 1.5 | O4: =IFERROR(O2/N2,0) -> 0.5 | Q4: =IFERROR(Q2/P2,0) -> 0
B5: Ashley Rust | C5: =SUMIF(A:A,B5,T:T) -> 670 | E5: =SUMIFS(T:T,A:A,B5,D:D,"Y") -> 0 | F5: =SUMIF(A:A,B5,G:G) -> 8 | G5: =SUMIF(A:A,B5,H:H) -> 5 | H5: =SUMIF(A:A,B5,I:I) -> 1 | I5: =SUMIF(A:A,B5,P:P) -> 0 | J5: =SUMIF(A:A,B5,Q:Q) -> 0 | K5: =SUMIF(A:A,B5,R:R) -> 3 | L5: =SUMIF(A:A,B5,S:S) -> 0 | M5: =SUMIF(A:A,B5,M:M) -> 8 | N5: =SUMIF(A:A,B5,N:N) -> 2 | O5: =SUMIF(A:A,B5,O:O) -> 1 | P5: =SUMIF(A:A,B5,J:J) -> 0 | Q5: =SUMIF(A:A,B5,K:K) -> 0 | R5: =SUMIF(A:A,B5,L:L) -> 2
C6: # of Agents | E6: ALP per sale | F6: Show Rate | G6: Close Ratio | H6: ALP/Agent | J6: POS Close | L6: VET Close | M6: REF Per Sit | O6: REF Close | Q6: OTS Close
C7: =COUNTIFS(A:A,B5) -> 19 | E7: =IFERROR(C5/H5,0) -> 670 | F7: =IFERROR((G5+R5)/F5,0) -> 0.875 | G7: =IFERROR(H5/G5,0) -> 0.2 | H7: =(C5/C7) -> 35.263158 | J7: =IFERROR(J5/I5,0) -> 0 | L7: =IFERROR(L5/K5,0) -> 0 | M7: =IFERROR(M5/SUM(R5+G5,0),"") -> 1.1428571 | O7: =IFERROR(O5/N5,0) -> 0.5 | Q7: =IFERROR(Q5/P5,0) -> 0
B8: Troy Williams | C8: =SUMIF(B:B,B8,T:T) -> 0 | E8: =SUMIFS(T:T,B:B,B8,D:D,"Y") -> 0 | F8: =SUMIF(B39:B1137,B8,G39:G1137) -> 0 | G8: =SUMIF(B39:B1137,B8,H39:H1137) -> 0 | H8: =SUMIF(B39:B1137,B8,I39:I1137) -> 0 | I8: =SUMIF(B39:B1137,B8,P39:P1137) -> 0 | J8: =SUMIF(B39:B1137,B8,Q39:Q1137) -> 0 | K8: =SUMIF(B39:B1137,B8,R39:R1137) -> 0 | L8: =SUMIF(B39:B1137,B8,S39:S1137) -> 0 | M8: =SUMIF(B39:B1137,B8,M39:M1137) -> 0 | N8: =SUMIF(B39:B1137,B8,N39:N1137) -> 0 | O8: =SUMIF(B39:B1137,B8,O39:O1137) -> 0 | P8: =SUMIF(B39:B1137,B8,J39:J1137) -> 0 | Q8: =SUMIF(B39:B1137,B8,K39:K1137) -> 0 | R8: =SUMIF(B39:B1137,B8,L39:L1137) -> 0
C9: # of Agents | E9: ALP per sale | F9: Show Rate | G9: Close Ratio | H9: ALP/Agent | J9: POS Close | L9: VET Close | M9: REF Per Sit | O9: REF Close | Q9: OTS Close
C10: =COUNTIFS(B28:B1137,B8) -> 5 | E10: =IFERROR(C8/H8,0) -> 0 | F10: =IFERROR((G8+R8)/F8,0) -> 0 | G10: =IFERROR(H8/G8,0) -> 0 | H10: =(C8/C10) -> 0 | J10: =IFERROR(J8/I8,0) -> 0 | L10: =IFERROR(L8/K8,0) -> 0 | M10: =IFERROR(M8/SUM(G8+R8,0),"") | O10: =IFERROR(O8/N8,0) -> 0 | Q10: =IFERROR(Q8/P8,0) -> 0
B11: Karami Kovar | C11: =SUMIF(B:B,B11,T:T) -> 670 | E11: =SUMIFS(T:T,B:B,B11,D:D,"Y") -> 0 | F11: =SUMIF(B28:B1137,B11,G28:G1137) -> 5 | G11: =SUMIF(C28:C1137,C11,H28:H1137) -> 0 | H11: =SUMIF(D28:D1137,D11,I28:I1137) -> 0 | I11: =SUMIF(E28:E1137,E11,J28:J1137) -> 0 | J11: =SUMIF(F28:F1137,F11,K28:K1137) -> 0 | K11: =SUMIF(G28:G1137,G11,L28:L1137) -> 0 | L11: =SUMIF(H28:H1137,H11,M28:M1137) -> 0 | M11: =SUMIF(I28:I1137,I11,N28:N1137) -> 1 | ... R11: =SUMIF(N28:N1137,N11,S28:S1137) -> 0
C12: # of Agents | E12: ALP per sale | F12: Show Rate | G12: Close Ratio | H12: ALP/Agent | J12: POS Close | L12: VET Close | M12: REF Per Sit | O12: REF Close | Q12: OTS Close
C13: =COUNTIFS(B27:B1137,B11) -> 11 | E13: =IFERROR(C11/H11,0) -> 0 | F13: =IFERROR((G11+R11)/F11,0) -> 0 | G13: =IFERROR(H11/G11,0) -> 0 | H13: =(C11/C13) -> 60.909091 | J13: =IFERROR(J11/I11,0) -> 0 | L13: =IFERROR(L11/K11,0) -> 0 | M13: =IFERROR(M11/SUM(G11+R11,0),"") | O13: =IFERROR(O11/N11,0) -> 0 | Q13: =IFERROR(Q11/P11,0) -> 0
B14: Joy Vann-Austin | C14: =SUMIF(A:A,B14,T:T) -> 0 | E14: =SUMIFS(T:T,A:A,B14,D:D,"Y") -> 0 | F14: =SUMIF(A:A,B14,G:G) -> 2 | G14: =SUMIF(A:A,B14,H:H) -> 0 | H14: =SUMIF(A:A,B14,I:I) -> 0 | I14: =SUMIF(A:A,B14,P:P) -> 0 | J14: =SUMIF(A:A,B14,Q:Q) -> 0 | K14: =SUMIF(A:A,B14,R:R) -> 0 | L14: =SUMIF(A:A,B14,S:S) -> 0 | M14: =SUMIF(A:A,B14,M:M) -> 0 | N14: =SUMIF(A:A,B14,N:N) -> 0 | O14: =SUMIF(A:A,B14,O:O) -> 0 | P14: =SUMIF(A:A,B14,J:J) -> 0 | Q14: =SUMIF(A:A,B14,K:K) -> 0 | R14: =SUMIF(A:A,B14,L:L) -> 0
C15: # of Agents | E15: ALP per sale | F15: Show Rate | G15: Close Ratio | H15: ALP/Agent | J15: POS Close | L15: VET Close | M15: REF Per Sit | O15: REF Close | Q15: OTS Close
C16: =COUNTIFS(A:A,B14) -> 4 | E16: =IFERROR(C14/H14,0) -> 0 | F16: =IFERROR((G14+R14)/F14,0) -> 0 | G16: =IFERROR(H14/G14,0) -> 0 | H16: =(C14/C16) -> 0 | J16: =IFERROR(J14/I14,0) -> 0 | L16: =IFERROR(L14/K14,0) -> 0 | M16: =IFERROR(M14/SUM(R14+G14,0),"") | O16: =IFERROR(O14/N14,0) -> 0 | Q16: =IFERROR(Q14/P14,0) -> 0
B17: Torian Fields | C17: =SUMIF(A:A,B17,T:T) -> 0 | E17: =SUMIFS(T:T,A:A,B17,D:D,"Y") -> 0 | F17: =SUMIF(A:A,B17,G:G) -> 8 | G17: =SUMIF(A:A,B17,H:H) -> 1 | H17: =SUMIF(A:A,B17,I:I) -> 0 | I17: =SUMIF(A:A,B17,P:P) -> 0 | J17: =SUMIF(A:A,B17,Q:Q) -> 0 | K17: =SUMIF(A:A,B17,R:R) -> 1 | L17: =SUMIF(A:A,B17,S:S) -> 0 | M17: =SUMIF(A:A,B17,M:M) -> 1 | N17: =SUMIF(A:A,B17,N:N) -> 0 | O17: =SUMIF(A:A,B17,O:O) -> 0 | P17: =SUMIF(A:A,B17,J:J) -> 0 | Q17: =SUMIF(A:A,B17,K:K) -> 0 | R17: =SUMIF(A:A,B17,L:L) -> 0
C18: # of Agents | E18: ALP per sale | F18: Show Rate | G18: Close Ratio | H18: ALP/Agent | J18: POS Close | L18: VET Close | M18: REF Per Sit | O18: REF Close | Q18: OTS Close
C19: =COUNTIFS(A:A,B17) -> 22 | E19: =IFERROR(C17/H17,0) -> 0 | F19: =IFERROR((G17+R17)/F17,0) -> 0.125 | G19: =IFERROR(H17/G17,0) -> 0 | H19: =(C17/C19) -> 0 | J19: =IFERROR(J17/I17,0) -> 0 | L19: =IFERROR(L17/K17,0) -> 0 | M19: =IFERROR(M17/SUM(G17+R17,0),"") -> 1 | O19: =IFERROR(O17/N17,0) -> 0 | Q19: =IFERROR(Q17/P17,0) -> 0
B20: Devin Gould | C20: =SUMIF(B:B,B20,T:T) -> 0 | E20: =SUMIFS(T:T,B:B,B20,D:D,"Y") -> 0 | F20: =SUMIF(B47:B1137,B20,G47:G1137) -> 8 | G20: =SUMIF(B47:B1137,B20,H47:H1137) -> 1 | H20: =SUMIF(B47:B1137,B20,I47:I1137) -> 0 | I20: =SUMIF(B47:B1137,B20,P47:P1137) -> 0 | J20: =SUMIF(B47:B1137,B20,Q47:Q1137) -> 0 | K20: =SUMIF(B47:B1137,B20,R47:R1137) -> 1 | L20: =SUMIF(B47:B1137,B20,S47:S1137) -> 0 | M20: =SUMIF(B47:B1137,B20,M47:M1137) -> 1 | N20: =SUMIF(B47:B1137,B20,N47:N1137) -> 0 | O20: =SUMIF(B47:B1137,B20,O47:O1137) -> 0 | P20: =SUMIF(B47:B1137,B20,J47:J1137) -> 0 | Q20: =SUMIF(B47:B1137,B20,K47:K1137) -> 0 | R20: =SUMIF(B47:B1137,B20,L47:L1137) -> 0
C21: # of Agents | E21: ALP per sale | F21: Show Rate | G21: Close Ratio | H21: ALP/Agent | J21: POS Close | L21: VET Close | M21: REF Per Sit | O21: REF Close | Q21: OTS Close
C22: =COUNTIFS(B28:B1137,B20) -> 14 | E22: =IFERROR(C20/H20,0) -> 0 | F22: =IFERROR((G20+R20)/F20,0) -> 0.125 | G22: =IFERROR(H20/G20,0) -> 0 | H22: =(C20/C22) -> 0 | J22: =IFERROR(J20/I20,0) -> 0 | L22: =IFERROR(L20/K20,0) -> 0 | M22: =IFERROR(M20/SUM(G20+R20,0),"") -> 1 | O22: =IFERROR(O20/N20,0) -> 0 | Q22: =IFERROR(Q20/P20,0) -> 0
B23: Mikaela Hayes | C23: =SUMIF(B:B,B23,T:T) -> 0 | E23: =SUMIFS(T:T,B:B,B23,D:D,"Y") -> 0 | F23: =SUMIF(B50:B1137,B23,G50:G1137) -> 0 | G23: =SUMIF(B50:B1137,B23,H50:H1137) -> 0 | H23: =SUMIF(B50:B1137,B23,I50:I1137) -> 0 | I23: =SUMIF(B50:B1137,B23,P50:P1137) -> 0 | J23: =SUMIF(B50:B1137,B23,Q50:Q1137) -> 0 | K23: =SUMIF(B50:B1137,B23,R50:R1137) -> 0 | L23: =SUMIF(B50:B1137,B23,S50:S1137) -> 0 | M23: =SUMIF(B50:B1137,B23,M50:M1137) -> 0 | N23: =SUMIF(B50:B1137,B23,N50:N1137) -> 0 | O23: =SUMIF(B50:B1137,B23,O50:O1137) -> 0 | P23: =SUMIF(B50:B1137,B23,J50:J1137) -> 0 | Q23: =SUMIF(B50:B1137,B23,K50:K1137) -> 0 | R23: =SUMIF(B50:B1137,B23,L50:L1137) -> 0
C24: # of Agents | E24: ALP per sale | F24: Show Rate | G24: Close Ratio | H24: ALP/Agent | J24: POS Close | L24: VET Close | M24: REF Per Sit | O24: REF Close | Q24: OTS Close
C25: =COUNTIFS(B33:B1137,B23) -> 5 | E25: =IFERROR(C23/H23,0) -> 0 | F25: =IFERROR((G23+R23)/F23,0) -> 0 | G25: =IFERROR(H23/G23,0) -> 0 | H25: =(C23/C25) -> 0 | J25: =IFERROR(J23/I23,0) -> 0 | L25: =IFERROR(L23/K23,0) -> 0 | M25: =IFERROR(M23/SUM(G23+R23,0),"") | O25: =IFERROR(O23/N23,0) -> 0 | Q25: =IFERROR(Q23/P23,0) -> 0
A27: MGA | B27: GA | C27: SA | E27: State | F27: Agent | G27: SETS | H27: SITS | I27: SALES | J27: OTS SITS | K27: OTS SALES | L27: N1 | M27: REF OBT | N27: REF SITS | O27: REF SALES | P27: POS SITS | Q27: POS SALES | R27: VETS SITS | S27: VET SALES | T27: ALP | U27: Close | V27: Show | W27: Code Date
A28: Ashley Rust | D28: Y | F28: Ashley Rust | U28: =IFERROR(I28/H28,0) -> 0 | V28: =IFERROR(SUM(H28+L28)/G28,0) -> 0
A29: Ashley Rust | F29: Karly Kelly | U29: =IFERROR(I29/H29,0) -> 0 | V29: =IFERROR(SUM(H29+L29)/G29,0) -> 0
A30: Ashley Rust | F30: Andrea Mulder | G30: 3 | H30: 3 | I30: 0 | J30: 0 | K30: 0 | L30: 2 | M30: 0 | N30: 1 | O30: 0 | P30: 0 | Q30: 0 | R30: 2 | S30: 0 | T30: 0 | U30: =IFERROR(I30/H30,0) -> 0 | V30: =IFERROR(SUM(H30+L30)/G30,0) -> 1.6666667
A31: Ashley Rust | B31: Karami Kovar | D31: Y | F31: Karami Kovar | U31: =IFERROR(I31/H31,0) -> 0 | V31: =IFERROR(SUM(H31+L31)/G31,0) -> 0
A32: Ashley Rust | B32: Karami Kovar | F32: Bridgett McDaniels Russell | U32: =IFERROR(I32/H32,0) -> 0 | V32: =IFERROR(SUM(H32+L32)/G32,0) -> 0
A33: Ashley Rust | B33: Karami Kovar | C33: Jasmine Marquez | D33: Y | F33: Jasmine Marquez | G33: 1 | H33: 0 | I33: 0 | J33: 0 | K33: 0 | L33: 0 | M33: 0 | N33: 0 | O33: 0 | P33: 0 | Q33: 0 | R33: 0 | S33: 0 | T33: 0 | U33: =IFERROR(I33/H33,0) -> 0 | V33: =IFERROR(SUM(H33+L33)/G33,0) -> 0
A34: Ashley Rust | B34: Karami Kovar | C34: Jasmine Marquez | F34: Ashley Varner-Warren | G34: 0 | H34: 0 | I34: 0 | J34: 0 | K34: 0 | L34: 0 | M34: 0 | N34: 0 | O34: 0 | P34: 0 | Q34: 0 | R34: 0 | S34: 0 | T34: 0 | U34: =IFERROR(I34/H34,0) -> 0 | V34: =IFERROR(SUM(H34+L34)/G34,0) -> 0
A35: Ashley Rust | B35: Karami Kovar | C35: Jasmine Marquez | F35: Kristen Walton | G35: 1 | H35: 0 | I35: 0 | J35: 0 | K35: 0 | L35: 0 | M35: 0 | N35: 0 | O35: 0 | P35: 0 | Q35: 0 | R35: 0 | S35: 0 | T35: 0 | U35: =IFERROR(I35/H35,0) -> 0 | V35: =IFERROR(SUM(H35+L35)/G35,0) -> 0
A36: Ashley Rust | B36: Karami Kovar | C36: Jasmine Marquez | F36: Sara Subo | G36: 0 | H36: 0 | I36: 0 | J36: 0 | K36: 0 | L36: 0 | M36: 0 | N36: 0 | O36: 0 | P36: 0 | Q36: 0 | R36: 0 | S36: 0 | T36: 0 | U36: =IFERROR(I36/H36,0) -> 0 | V36: =IFERROR(SUM(H36+L36)/G36,0) -> 0
A37: Ashley Rust | B37: Karami Kovar | C37: Jasmine Marquez | F37: Thomas Kirk | G37: 1 | H37: 1 | I37: 1 | J37: 0 | K37: 0 | L37: 0 | M37: 3 | N37: 1 | O37: 1 | P37: 0 | Q37: 0 | R37: 0 | S37: 0 | T37: 670 | U37: =IFERROR(I37/H37,0) -> 1 | V37: =IFERROR(SUM(H37+L37)/G37,0) -> 1
A38: Ashley Rust | B38: Karami Kovar | C38: Jasmine Marquez | F38: Isabela Maneiro | G38: 2 | H38: 1 | I38: 0 | J38: 0 | K38: 0 | L38: 0 | M38: 5 | N38: 0 | O38: 0 | P38: 0 | Q38: 0 | R38: 1 | S38: 0 | T38: 0 | U38: =IFERROR(I38/H38,0) -> 0 | V38: =IFERROR(SUM(H38+L38)/G38,0) -> 0.5
A39: Ashley Rust | B39: Karami Kovar | C39: Ryan Cummings | D39: Y | F39: Ryan Cummings | U39: =IFERROR(I39/H39,0) -> 0 | V39: =IFERROR(SUM(H39+L39)/G39,0) -> 0
A40: Ashley Rust | B40: Karami Kovar | C40: Ryan Cummings | F40: Charlie Hudson | U40: =IFERROR(I40/H40,0) -> 0 | V40: =IFERROR(SUM(H40+L40)/G40,0) -> 0
A41: Ashley Rust | B41: Karami Kovar | C41: Ryan Cummings | F41: Bayle Kizer | U41: =IFERROR(I41/H41,0) -> 0 | V41: =IFERROR(SUM(H41+L41)/G41,0) -> 0
...

Sheet Fri
C1: ALP | E1: LEADERSHIP ALP | F1: Appts | G1: Pres | H1: Sales | I1: POS SITS | J1: POS SA | K1: VET SITS | L1: VET SA | M1: REF OBT | N1: REF SITS | O1: REF SA | P1: OTS SITS | Q1: OTS SA | R1: N1
B2: RUST RGA | C2: =SUM(C5,C14,C17) -> 1392 | E2: =SUM(E5,E14,E17) -> 1392 | F2: =SUM(F5,F14,F17) -> 13 | G2: =SUM(G5,G14,G17) -> 6 | H2: =SUM(H5,H14,H17) -> 1 | I2: =SUM(I5,I14,I17) -> 2 | J2: =SUM(J5,J14,J17) -> 0 | K2: =SUM(K5,K14,K17) -> 5 | L2: =SUM(L5,L14,L17) -> 0 | ... R2: =SUM(R5,R14,R17) -> 4
C3: # of Agents | E3: ALP per sale | F3: Show Rate | G3: Close Ratio | H3: ALP/Agent | J3: POS Close | L3: VET Close | M3: REF Per Sit | O3: REF Close | Q3: OTS Close
C4: =SUM(C7,C19,C16) -> 45 | E4: =IFERROR(C2/H2,0) -> 1392 | F4: =IFERROR((G2+R2)/F2,0) -> 0.76923077 | G4: =IFERROR(H2/G2,0) -> 0.16666667 | H4: =(C2/C4) -> 30.933333 | J4: =IFERROR(J2/I2,0) -> 0 | L4: =IFERROR(L2/K2,0) -> 0 | M4: =IFERROR(M2/G2,0) -> 2.1666667 | O4: =IFERROR(O2/N2,0) -> 1 | Q4: =IFERROR(Q2/P2,0) -> 0
B5: Ashley Rust | C5: =SUMIF(A:A,B5,T:T) -> 0 | E5: =SUMIFS(T:T,A:A,B5,D:D,"Y") -> 0 | F5: =SUMIF(A:A,B5,G:G) -> 1 | G5: =SUMIF(A:A,B5,H:H) -> 0 | H5: =SUMIF(A:A,B5,I:I) -> 0 | I5: =SUMIF(A:A,B5,P:P) -> 0 | J5: =SUMIF(A:A,B5,Q:Q) -> 0 | K5: =SUMIF(A:A,B5,R:R) -> 0 | L5: =SUMIF(A:A,B5,S:S) -> 0 | M5: =SUMIF(A:A,B5,M:M) -> 0 | N5: =SUMIF(A:A,B5,N:N) -> 0 | O5: =SUMIF(A:A,B5,O:O) -> 0 | P5: =SUMIF(A:A,B5,J:J) -> 0 | Q5: =SUMIF(A:A,B5,K:K) -> 0 | R5: =SUMIF(A:A,B5,L:L) -> 0
C6: # of Agents | E6: ALP per sale | F6: Show Rate | G6: Close Ratio | H6: ALP/Agent | J6: POS Close | L6: VET Close | M6: REF Per Sit | O6: REF Close | Q6: OTS Close
C7: =COUNTIFS(A:A,B5) -> 19 | E7: =IFERROR(C5/H5,0) -> 0 | F7: =IFERROR((G5+R5)/F5,0) -> 0 | G7: =IFERROR(H5/G5,0) -> 0 | H7: =(C5/C7) -> 0 | J7: =IFERROR(J5/I5,0) -> 0 | L7: =IFERROR(L5/K5,0) -> 0 | M7: =IFERROR(M5/SUM(R5+G5,0),"") | O7: =IFERROR(O5/N5,0) -> 0 | Q7: =IFERROR(Q5/P5,0) -> 0
B8: Troy Williams | C8: =SUMIF(B:B,B8,T:T) -> 0 | E8: =SUMIFS(T:T,B:B,B8,D:D,"Y") -> 0 | F8: =SUMIF(B39:B1137,B8,G39:G1137) -> 0 | G8: =SUMIF(B39:B1137,B8,H39:H1137) -> 0 | H8: =SUMIF(B39:B1137,B8,I39:I1137) -> 0 | I8: =SUMIF(B39:B1137,B8,P39:P1137) -> 0 | J8: =SUMIF(B39:B1137,B8,Q39:Q1137) -> 0 | K8: =SUMIF(B39:B1137,B8,R39:R1137) -> 0 | L8: =SUMIF(B39:B1137,B8,S39:S1137) -> 0 | M8: =SUMIF(B39:B1137,B8,M39:M1137) -> 0 | N8: =SUMIF(B39:B1137,B8,N39:N1137) -> 0 | O8: =SUMIF(B39:B1137,B8,O39:O1137) -> 0 | P8: =SUMIF(B39:B1137,B8,J39:J1137) -> 0 | Q8: =SUMIF(B39:B1137,B8,K39:K1137) -> 0 | R8: =SUMIF(B39:B1137,B8,L39:L1137) -> 0
C9: # of Agents | E9: ALP per sale | F9: Show Rate | G9: Close Ratio | H9: ALP/Agent | J9: POS Close | L9: VET Close | M9: REF Per Sit | O9: REF Close | Q9: OTS Close
C10: =COUNTIFS(B28:B1137,B8) -> 5 | E10: =IFERROR(C8/H8,0) -> 0 | F10: =IFERROR((G8+R8)/F8,0) -> 0 | G10: =IFERROR(H8/G8,0) -> 0 | H10: =(C8/C10) -> 0 | J10: =IFERROR(J8/I8,0) -> 0 | L10: =IFERROR(L8/K8,0) -> 0 | M10: =IFERROR(M8/SUM(G8+R8,0),"") | O10: =IFERROR(O8/N8,0) -> 0 | Q10: =IFERROR(Q8/P8,0) -> 0
B11: Karami Kovar | C11: =SUMIF(B:B,B11,T:T) -> 0 | E11: =SUMIFS(T:T,B:B,B11,D:D,"Y") -> 0 | F11: =SUMIF(B28:B1137,B11,G28:G1137) -> 1 | G11: =SUMIF(C28:C1137,C11,H28:H1137) -> 0 | H11: =SUMIF(D28:D1137,D11,I28:I1137) -> 0 | I11: =SUMIF(E28:E1137,E11,J28:J1137) -> 0 | J11: =SUMIF(F28:F1137,F11,K28:K1137) -> 0 | K11: =SUMIF(G28:G1137,G11,L28:L1137) -> 0 | L11: =SUMIF(H28:H1137,H11,M28:M1137) -> 0 | M11: =SUMIF(I28:I1137,I11,N28:N1137) -> 0 | ... R11: =SUMIF(N28:N1137,N11,S28:S1137) -> 0
C12: # of Agents | E12: ALP per sale | F12: Show Rate | G12: Close Ratio | H12: ALP/Agent | J12: POS Close | L12: VET Close | M12: REF Per Sit | O12: REF Close | Q12: OTS Close
C13: =COUNTIFS(B27:B1137,B11) -> 11 | E13: =IFERROR(C11/H11,0) -> 0 | F13: =IFERROR((G11+R11)/F11,0) -> 0 | G13: =IFERROR(H11/G11,0) -> 0 | H13: =(C11/C13) -> 0 | J13: =IFERROR(J11/I11,0) -> 0 | L13: =IFERROR(L11/K11,0) -> 0 | M13: =IFERROR(M11/SUM(G11+R11,0),"") | O13: =IFERROR(O11/N11,0) -> 2 | Q13: =IFERROR(Q11/P11,0) -> 0
B14: Joy Vann-Austin | C14: =SUMIF(A:A,B14,T:T) -> 0 | E14: =SUMIFS(T:T,A:A,B14,D:D,"Y") -> 0 | F14: =SUMIF(A:A,B14,G:G) -> 1 | G14: =SUMIF(A:A,B14,H:H) -> 1 | H14: =SUMIF(A:A,B14,I:I) -> 0 | I14: =SUMIF(A:A,B14,P:P) -> 0 | J14: =SUMIF(A:A,B14,Q:Q) -> 0 | K14: =SUMIF(A:A,B14,R:R) -> 1 | L14: =SUMIF(A:A,B14,S:S) -> 0 | M14: =SUMIF(A:A,B14,M:M) -> 2 | N14: =SUMIF(A:A,B14,N:N) -> 0 | O14: =SUMIF(A:A,B14,O:O) -> 0 | P14: =SUMIF(A:A,B14,J:J) -> 0 | Q14: =SUMIF(A:A,B14,K:K) -> 0 | R14: =SUMIF(A:A,B14,L:L) -> 1
C15: # of Agents | E15: ALP per sale | F15: Show Rate | G15: Close Ratio | H15: ALP/Agent | J15: POS Close | L15: VET Close | M15: REF Per Sit | O15: REF Close | Q15: OTS Close
C16: =COUNTIFS(A:A,B14) -> 4 | E16: =IFERROR(C14/H14,0) -> 0 | F16: =IFERROR((G14+R14)/F14,0) -> 2 | G16: =IFERROR(H14/G14,0) -> 0 | H16: =(C14/C16) -> 0 | J16: =IFERROR(J14/I14,0) -> 0 | L16: =IFERROR(L14/K14,0) -> 0 | M16: =IFERROR(M14/SUM(R14+G14,0),"") -> 1 | O16: =IFERROR(O14/N14,0) -> 0 | Q16: =IFERROR(Q14/P14,0) -> 0
B17: Torian Fields | C17: =SUMIF(A:A,B17,T:T) -> 1392 | E17: =SUMIFS(T:T,A:A,B17,D:D,"Y") -> 1392 | F17: =SUMIF(A:A,B17,G:G) -> 11 | G17: =SUMIF(A:A,B17,H:H) -> 5 | H17: =SUMIF(A:A,B17,I:I) -> 1 | I17: =SUMIF(A:A,B17,P:P) -> 2 | J17: =SUMIF(A:A,B17,Q:Q) -> 0 | K17: =SUMIF(A:A,B17,R:R) -> 4 | L17: =SUMIF(A:A,B17,S:S) -> 0 | M17: =SUMIF(A:A,B17,M:M) -> 11 | N17: =SUMIF(A:A,B17,N:N) -> 1 | O17: =SUMIF(A:A,B17,O:O) -> 1 | P17: =SUMIF(A:A,B17,J:J) -> 3 | Q17: =SUMIF(A:A,B17,K:K) -> 0 | R17: =SUMIF(A:A,B17,L:L) -> 3
C18: # of Agents | E18: ALP per sale | F18: Show Rate | G18: Close Ratio | H18: ALP/Agent | J18: POS Close | L18: VET Close | M18: REF Per Sit | O18: REF Close | Q18: OTS Close
C19: =COUNTIFS(A:A,B17) -> 22 | E19: =IFERROR(C17/H17,0) -> 1392 | F19: =IFERROR((G17+R17)/F17,0) -> 0.72727273 | G19: =IFERROR(H17/G17,0) -> 0.2 | H19: =(C17/C19) -> 63.272727 | J19: =IFERROR(J17/I17,0) -> 0 | L19: =IFERROR(L17/K17,0) -> 0 | M19: =IFERROR(M17/SUM(G17+R17,0),"") -> 1.375 | O19: =IFERROR(O17/N17,0) -> 1 | Q19: =IFERROR(Q17/P17,0) -> 0
B20: Devin Gould | C20: =SUMIF(B:B,B20,T:T) -> 1392 | E20: =SUMIFS(T:T,B:B,B20,D:D,"Y") -> 1392 | F20: =SUMIF(B47:B1137,B20,G47:G1137) -> 11 | G20: =SUMIF(B47:B1137,B20,H47:H1137) -> 5 | H20: =SUMIF(B47:B1137,B20,I47:I1137) -> 1 | I20: =SUMIF(B47:B1137,B20,P47:P1137) -> 2 | J20: =SUMIF(B47:B1137,B20,Q47:Q1137) -> 0 | K20: =SUMIF(B47:B1137,B20,R47:R1137) -> 4 | L20: =SUMIF(B47:B1137,B20,S47:S1137) -> 0 | M20: =SUMIF(B47:B1137,B20,M47:M1137) -> 11 | N20: =SUMIF(B47:B1137,B20,N47:N1137) -> 1 | O20: =SUMIF(B47:B1137,B20,O47:O1137) -> 1 | P20: =SUMIF(B47:B1137,B20,J47:J1137) -> 3 | Q20: =SUMIF(B47:B1137,B20,K47:K1137) -> 0 | R20: =SUMIF(B47:B1137,B20,L47:L1137) -> 3
C21: # of Agents | E21: ALP per sale | F21: Show Rate | G21: Close Ratio | H21: ALP/Agent | J21: POS Close | L21: VET Close | M21: REF Per Sit | O21: REF Close | Q21: OTS Close
C22: =COUNTIFS(B28:B1137,B20) -> 14 | E22: =IFERROR(C20/H20,0) -> 1392 | F22: =IFERROR((G20+R20)/F20,0) -> 0.72727273 | G22: =IFERROR(H20/G20,0) -> 0.2 | H22: =(C20/C22) -> 99.428571 | J22: =IFERROR(J20/I20,0) -> 0 | L22: =IFERROR(L20/K20,0) -> 0 | M22: =IFERROR(M20/SUM(G20+R20,0),"") -> 1.375 | O22: =IFERROR(O20/N20,0) -> 1 | Q22: =IFERROR(Q20/P20,0) -> 0
B23: Mikaela Hayes | C23: =SUMIF(B:B,B23,T:T) -> 0 | E23: =SUMIFS(T:T,B:B,B23,D:D,"Y") -> 0 | F23: =SUMIF(B50:B1137,B23,G50:G1137) -> 0 | G23: =SUMIF(B50:B1137,B23,H50:H1137) -> 0 | H23: =SUMIF(B50:B1137,B23,I50:I1137) -> 0 | I23: =SUMIF(B50:B1137,B23,P50:P1137) -> 0 | J23: =SUMIF(B50:B1137,B23,Q50:Q1137) -> 0 | K23: =SUMIF(B50:B1137,B23,R50:R1137) -> 0 | L23: =SUMIF(B50:B1137,B23,S50:S1137) -> 0 | M23: =SUMIF(B50:B1137,B23,M50:M1137) -> 0 | N23: =SUMIF(B50:B1137,B23,N50:N1137) -> 0 | O23: =SUMIF(B50:B1137,B23,O50:O1137) -> 0 | P23: =SUMIF(B50:B1137,B23,J50:J1137) -> 0 | Q23: =SUMIF(B50:B1137,B23,K50:K1137) -> 0 | R23: =SUMIF(B50:B1137,B23,L50:L1137) -> 0
C24: # of Agents | E24: ALP per sale | F24: Show Rate | G24: Close Ratio | H24: ALP/Agent | J24: POS Close | L24: VET Close | M24: REF Per Sit | O24: REF Close | Q24: OTS Close
C25: =COUNTIFS(B33:B1137,B23) -> 5 | E25: =IFERROR(C23/H23,0) -> 0 | F25: =IFERROR((G23+R23)/F23,0) -> 0 | G25: =IFERROR(H23/G23,0) -> 0 | H25: =(C23/C25) -> 0 | J25: =IFERROR(J23/I23,0) -> 0 | L25: =IFERROR(L23/K23,0) -> 0 | M25: =IFERROR(M23/SUM(G23+R23,0),"") | O25: =IFERROR(O23/N23,0) -> 0 | Q25: =IFERROR(Q23/P23,0) -> 0
A27: MGA | B27: GA | C27: SA | E27: State | F27: Agent | G27: SETS | H27: SITS | I27: SALES | J27: OTS SITS | K27: OTS SALES | L27: N1 | M27: REF OBT | N27: REF SITS | O27: REF SALES | P27: POS SITS | Q27: POS SALES | R27: VETS SITS | S27: VET SALES | T27: ALP | U27: Close | V27: Show | W27: Code Date
A28: Ashley Rust | D28: Y | F28: Ashley Rust | U28: =IFERROR(I28/H28,0) -> 0 | V28: =IFERROR(SUM(H28+L28)/G28,0) -> 0
A29: Ashley Rust | F29: Karly Kelly | U29: =IFERROR(I29/H29,0) -> 0 | V29: =IFERROR(SUM(H29+L29)/G29,0) -> 0
A30: Ashley Rust | F30: Andrea Mulder | G30: 0 | H30: 0 | I30: 0 | J30: 0 | K30: 0 | L30: 0 | M30: 0 | N30: 0 | O30: 0 | P30: 0 | Q30: 0 | R30: 0 | S30: 0 | T30: 0 | U30: =IFERROR(I30/H30,0) -> 0 | V30: =IFERROR(SUM(H30+L30)/G30,0) -> 0
A31: Ashley Rust | B31: Karami Kovar | D31: Y | F31: Karami Kovar | U31: =IFERROR(I31/H31,0) -> 0 | V31: =IFERROR(SUM(H31+L31)/G31,0) -> 0
A32: Ashley Rust | B32: Karami Kovar | F32: Bridgett McDaniels Russell | U32: =IFERROR(I32/H32,0) -> 0 | V32: =IFERROR(SUM(H32+L32)/G32,0) -> 0
A33: Ashley Rust | B33: Karami Kovar | C33: Jasmine Marquez | D33: Y | F33: Jasmine Marquez | G33: 0 | H33: 0 | I33: 0 | J33: 0 | K33: 0 | L33: 0 | M33: 0 | N33: 0 | O33: 0 | P33: 0 | Q33: 0 | R33: 0 | S33: 0 | T33: 0 | U33: =IFERROR(I33/H33,0) -> 0 | V33: =IFERROR(SUM(H33+L33)/G33,0) -> 0
A34: Ashley Rust | B34: Karami Kovar | C34: Jasmine Marquez | F34: Ashley Varner-Warren | G34: 0 | H34: 0 | I34: 0 | J34: 0 | K34: 0 | L34: 0 | M34: 0 | N34: 0 | O34: 0 | P34: 0 | Q34: 0 | R34: 0 | S34: 0 | T34: 0 | U34: =IFERROR(I34/H34,0) -> 0 | V34: =IFERROR(SUM(H34+L34)/G34,0) -> 0
A35: Ashley Rust | B35: Karami Kovar | C35: Jasmine Marquez | F35: Kristen Walton | G35: 0 | H35: 0 | I35: 0 | J35: 0 | K35: 0 | L35: 0 | M35: 0 | N35: 0 | O35: 0 | P35: 0 | Q35: 0 | R35: 0 | S35: 0 | T35: 0 | U35: =IFERROR(I35/H35,0) -> 0 | V35: =IFERROR(SUM(H35+L35)/G35,0) -> 0
A36: Ashley Rust | B36: Karami Kovar | C36: Jasmine Marquez | F36: Sara Subo | G36: 0 | H36: 0 | I36: 0 | J36: 0 | K36: 0 | L36: 0 | M36: 0 | N36: 0 | O36: 0 | P36: 0 | Q36: 0 | R36: 0 | S36: 0 | T36: 0 | U36: =IFERROR(I36/H36,0) -> 0 | V36: =IFERROR(SUM(H36+L36)/G36,0) -> 0
A37: Ashley Rust | B37: Karami Kovar | C37: Jasmine Marquez | F37: Thomas Kirk | G37: 0 | H37: 0 | I37: 0 | J37: 0 | K37: 0 | L37: 0 | M37: 0 | N37: 0 | O37: 0 | P37: 0 | Q37: 0 | R37: 0 | S37: 0 | T37: 0 | U37: =IFERROR(I37/H37,0) -> 0 | V37: =IFERROR(SUM(H37+L37)/G37,0) -> 0
A38: Ashley Rust | B38: Karami Kovar | C38: Jasmine Marquez | F38: Isabela Maneiro | G38: 1 | H38: 0 | I38: 0 | J38: 0 | K38: 0 | L38: 0 | M38: 0 | N38: 0 | O38: 0 | P38: 0 | Q38: 0 | R38: 0 | S38: 0 | T38: 0 | U38: =IFERROR(I38/H38,0) -> 0 | V38: =IFERROR(SUM(H38+L38)/G38,0) -> 0
A39: Ashley Rust | B39: Karami Kovar | C39: Ryan Cummings | D39: Y | F39: Ryan Cummings | U39: =IFERROR(I39/H39,0) -> 0 | V39: =IFERROR(SUM(H39+L39)/G39,0) -> 0
A40: Ashley Rust | B40: Karami Kovar | C40: Ryan Cummings | F40: Charlie Hudson | U40: =IFERROR(I40/H40,0) -> 0 | V40: =IFERROR(SUM(H40+L40)/G40,0) -> 0
A41: Ashley Rust | B41: Karami Kovar | C41: Ryan Cummings | F41: Bayle Kizer | U41: =IFERROR(I41/H41,0) -> 0 | V41: =IFERROR(SUM(H41+L41)/G41,0) -> 0
...

Sheet Sat
